File: Chapter5/lowT/LB6_FC.dat
[Header]
; MPMS3 Data File (default extension .dat)
; Copyright (c) 2007, Quantum Design, Inc. All rights reserved.
TITLE,
FILEOPENTIME,3869715539.62458,08/15/2022,11:10 am
BYAPP,MPMS3 w/ AC,1.0,1.1
INFO,MPMS3 Measurement Release 1.1.16 Build 424, MultiVu Release 2.3.4.19,APPNAME
INFO,Linear Motor Servo Controller,MOTOR_MODULE_NAME
INFO,3101-100 N0,MOTOR_HW_VERSION
INFO,MMC1047,MOTOR_SERIAL_NUMBER
INFO,01.04.28,MOTOR_SOFTWARE_VERSION
INFO,Quantum Design Squid Module,SQUID_MODULE_NAME
INFO,3101-501 B0,SQUID_HW_VERSION
INFO,SQM278,SQUID_SERIAL_NUMBER
INFO,01.03.04,SQUID_SOFTWARE_VERSION
INFO,Quantum Design VSM Oven,OVEN_MODULE_NAME
INFO,3101-201 A3,OVEN_HW_VERSION
INFO,OVB323,OVEN_SERIAL_NUMBER
INFO,01.07.07,OVEN_SOFTWARE_VERSION
INFO,SQUID AC,AC_MODULE_NAME
INFO,3101-401 G0,AC_HW_VERSION
INFO,SAC258,AC_SERIAL_NUMBER
INFO,SQUID AC 00.95.07,AC_SOFTWARE_VERSION
INFO,TCI127,COIL_SERIAL_NUMBER
INFO,0,MOMENT_UNITS
INFO,greigite,SAMPLE_MATERIAL
INFO,,SAMPLE_COMMENT
INFO,,SAMPLE_MASS
INFO,,SAMPLE_VOLUME
INFO,,SAMPLE_MOLECULAR_WEIGHT
INFO,,SAMPLE_SIZE
INFO,,SAMPLE_SHAPE
INFO,Straw,SAMPLE_HOLDER
INFO,Standard,SAMPLE_HOLDER_DETAIL
INFO,66.36,SAMPLE_OFFSET
DATATYPE,COMMENT,1
DATATYPE,TIME,2
STARTUPAXIS,X,2
STARTUPAXIS,Y1,5
FIELDGROUP, VSM,2,3,4,5,6,8,9,10,11,14,15
FIELDGROUP, DC, 2,3,4,14,56,57,58,59,60,61,62,63,64,65,66,67,68,69
FIELDGROUP, AC, 2,3,4,11,16,17,18,19,20,21,22,23,24,25,26,27,28,29,30
STARTUPGROUP, All
[Data]
Comment,Time Stamp (sec),Temperature (K),Magnetic Field (Oe),Moment (emu),M. Std. Err. (emu),Transport Action,Averaging Time (sec),Frequency (Hz),Peak Amplitude (mm),Center Position (mm),Lockin Signal' (V),Lockin Signal (V),Range,M. Quad. Signal (emu),AC Moment (emu),AC M. Std Err. (emu),AC Phase (deg),AC Phase Std. Err. (deg),AC Susceptibility (emu/Oe),AC Suscept. Std Err. (emu/Oe),AC X' (emu/Oe),AC X' Std Err. (emu/Oe),AC X'' (emu/Oe),AC X'' Std Err. (emu/Oe),AC Drive (Oe),AC Frequency (Hz),AC Averaging Time (sec),AC Cycles,AC Range,AC Measure Type,AC Signal' (V),AC Signal'' (V),AC Trim Coil Ratio,AC Trim Coil Phase,Min. Temperature (K),Max. Temperature (K),Min. Field (Oe),Max. Field (Oe),Mass (grams),Motor Lag (deg),Pressure (Torr),Measure Count,Measurement Number,SQUID Status (code),Motor Status (code),Measure Status (code),Motor Current (amps),Motor Temp. (C),Temp. Status (code),Field Status (code),Chamber Status (code),Chamber Temp (K),Redirection State,Evercool Status,Average Temp (K),Rotation Angle (deg),Rotator state,DC Moment Fixed Ctr (emu),DC Moment Err Fixed Ctr (emu),DC Moment Free Ctr (emu),DC Moment Err Free Ctr (emu),DC Fixed Fit,DC Free Fit,DC Calculated Center (mm),DC Calculated Center Err (mm),DC Scan Length (mm),DC Scan Time (s),DC Number of Points,DC Squid Drift,DC Min V (V),DC Max V (V),DC Scans per Measure,Map 01,Map 02,Map 03,Map 04,Map 05,Map 06,Map 07,Map 08,Map 09,Map 10,Map 11,Map 12,Map 13,Map 14,Map 15,Map 16
,3869720023.76945,11.1413135528564,0,,,6,,,,31.3127648668671,,,1,,,,,,,,,,,,,,,,,,,,,,10.0286951065063,11.9827718734741,0,0,,,4.80931997299194,,1,0,0,0,0.0138092041015625,29.8142719268799,6,1,1,12.2539319992065,0,1816670208,10.9132895903154,,,0.000710436139000252,2.47632530872133E-5,0.000717337426965194,2.47732339758657E-5,0.858016073703766,0.957161724567413,30.7917289733887,0,30,2,200,-0.0065010441467166,-2.86716651916504,0.211591780185699,2,,,,,,,,,,,,,,,,
,3869720162.84244,15.0011291503906,0,,,6,,,,31.3127648668671,,,1,,,,,,,,,,,,,,,,,,,,,,14.999026298523,15.0027341842651,0,0,,,5.47315979003906,,1,0,0,0,0,29.8142719268799,5,1,1,15.0005397796631,0,1816670208,15.000737508138,,,0.000648468219721228,2.25933790053205E-5,0.000654502683152543,2.26025972390256E-5,0.861069321632385,0.957817852497101,30.8034553527832,2.76832888630452E-5,30,2,200,-0.00551582779735327,-2.6799144744873,0.125903353095055,2,,,,,,,,,,,,,,,,
,3869720313.14185,20.0002765655518,0,,,6,,,,31.3127648668671,,,1,,,,,,,,,,,,,,,,,,,,,,19.9992809295654,20.0006370544434,0,0,,,5.75796985626221,,1,0,0,0,0,29.8142719268799,5,1,1,20.0007476806641,0,1816670208,19.999996026357,,,0.000593260114295607,2.06606727446396E-5,0.000598509502538792,2.06683763527912E-5,0.864249110221863,0.958462119102478,30.8155632019043,0,30,2,200,-0.00502970488741994,-2.52233290672302,0.044259924441576,2,,,,,,,,,,,,,,,,
,3869720472.87361,24.900764465332,0,,,6,,,,31.3181831479212,,,1,,,,,,,,,,,,,,,,,,,,,,24.8342876434326,24.9634895324707,0,0,,,5.95453834533691,,1,0,0,0,0.0138092041015625,31.2805480957031,6,1,1,24.9672412872314,0,1816670208,24.9131576220194,,,0.000555820042717966,1.93524161755437E-5,0.000560609548040656,1.93592079436439E-5,0.865896761417389,0.958920538425446,30.8273468017578,0,30,2,200,-0.00499824294820428,-2.3823676109314,0.0242999047040939,2,,,,,,,,,,,,,,,,
,3869720611.20915,27.4997463226318,0,,,6,,,,31.3181831479212,,,1,,,,,,,,,,,,,,,,,,,,,,27.4990215301514,27.5001945495605,0,0,,,6.05484199523926,,1,0,0,0,0.0138092041015625,30.3030319213867,5,1,1,27.5001525878906,0,1816670208,27.4996229807536,,,0.000532500922023329,1.85344995313626E-5,0.000536917876090631,1.85408197387218E-5,0.86828601360321,0.95925360918045,30.8366146087646,0.250510275363922,30,2,200,-0.00487506808713079,-2.30135583877563,0.000203006420633756,2,,,,,,,,,,,,,,,,
,3869720772.7432,32.3686351776123,0,,,6,,,,31.3231858295472,,,1,,,,,,,,,,,,,,,,,,,,,,32.3027877807617,32.4311180114746,0,0,,,6.18578481674194,,1,0,0,0,0.0138092041015625,30.3030319213867,6,1,1,32.4344825744629,0,1816670208,32.3746585845947,,,0.000506350792336667,1.76173762728709E-5,0.000510357577086175,1.76233540223443E-5,0.871257066726685,0.959664165973663,30.8532524108887,0,30,2,200,-0.00378861068747938,-2.23409223556519,-0.0445638708770275,2,,,,,,,,,,,,,,,,
,3869720911.46282,34.9889144897461,0,,,6,,,,31.3231858295472,,,1,,,,,,,,,,,,,,,,,,,,,,34.9837074279785,34.9928703308105,0,0,,,6.25317001342773,,1,0,0,0,0,30.3030319213867,5,1,1,34.9941215515137,0,1816670208,34.9890343348185,,,0.00049190738982163,1.71078532697531E-5,0.000495600816908526,1.71136207486107E-5,0.874418318271637,0.959892332553864,30.8658657073975,0.248385727405548,30,2,200,-0.00354842282831669,-2.19467878341675,-0.0697845965623856,2,,,,,,,,,,,,,,,,
,3869721072.69326,38.5818767547607,0,,,6,,,,31.3284403443618,,,1,,,,,,,,,,,,,,,,,,,,,,38.1961441040039,38.9676094055176,0,0,,,6.34176063537598,,1,0,0,0,0,29.8142719268799,2,1,1,38.9676094055176,0,1816670208,38.6321064631144,,,0.000480088977313718,1.66912190634144E-5,0.000483516993801165,1.66962194441597E-5,0.877079904079437,0.960094571113586,30.8817405700684,0.000216653075767681,30,2,200,-0.00352378841489553,-2.16723942756653,-0.0929136201739311,2,,,,,,,,,,,,,,,,
,3869721220.33049,42.1115550994873,0,,,6,,,,31.3336152923258,,,1,,,,,,,,,,,,,,,,,,,,,,41.9912376403809,42.2178764343262,0,0,,,6.40874767303467,,1,0,0,0,0,30.3030319213867,6,1,1,42.2318725585937,0,1816670208,42.1113026936849,,,0.000470602411068237,1.63561314372965E-5,0.000473811435738478,1.63609902739525E-5,0.879692912101746,0.960242033004761,30.8974418640137,0,30,2,200,-0.00338513823226094,-2.14249682426453,-0.11030562967062,2,,,,,,,,,,,,,,,,
,3869721361.20057,44.7061614990234,0,,,6,,,,31.3336152923258,,,1,,,,,,,,,,,,,,,,,,,,,,44.613883972168,44.7889938354492,0,0,,,6.47718095779419,,1,0,0,0,0,30.3030319213867,6,1,1,44.7984390258789,0,1816670208,44.7057450034402,,,0.000464408029553476,1.61347716283188E-5,0.000467389237010763,1.6139168545163E-5,0.882812440395355,0.960325181484222,30.9100914001465,0,30,2,200,-0.00336554064415395,-2.1275463104248,-0.123159550130367,2,,,,,,,,,,,,,,,,
,3869721514.56402,47.4436550140381,0,,,6,,,,31.3387601541975,,,1,,,,,,,,,,,,,,,,,,,,,,47.4259338378906,47.4606742858887,0,0,,,6.57907390594482,,1,0,0,0,0,29.8142719268799,5,1,1,47.4613761901855,0,1816670208,47.4450702667236,,,0.000458417959427863,1.5923047682396E-5,0.000461260360520563,1.59274842631877E-5,0.88473254442215,0.960390031337738,30.9230422973633,,30,2,200,-0.00348083395510912,-2.11393189430237,-0.136292308568954,2,,,,,,,,,,,,,,,,
,3869721655.75947,49.9823703765869,0,,,6,,,,31.3387601541975,,,1,,,,,,,,,,,,,,,,,,,,,,49.977222442627,49.9866180419922,0,0,,,6.7189130783081,,1,0,0,0,0,30.7917900085449,5,1,1,49.9875183105469,0,1816670208,49.9826615651449,,,0.000453477770870942,1.57462116781052E-5,0.000456126424438373,1.57501937211381E-5,0.887623965740204,0.960430562496185,30.9348545074463,0,30,2,200,-0.00384909776039422,-2.10313606262207,-0.147427543997765,2,,,,,,,,,,,,,,,,
,3869721815.78001,54.0499801635742,0,,,6,,,,31.3442915137937,,,1,,,,,,,,,,,,,,,,,,,,,,53.8055992126465,54.2863693237305,0,0,,,6.83859205245972,,1,0,0,0,0,29.8142719268799,6,1,1,54.294361114502,0,1816670208,54.0598141352336,,,0.000447869198503478,1.55466453598393E-5,0.000450342275580387,1.5550414482352E-5,0.890379786491394,0.960508108139038,30.9516658782959,3.28269670717418E-5,30,2,200,-0.00320653175003827,-2.09359788894653,-0.161756291985512,2,,,,,,,,,,,,,,,,
,3869721966.39052,57.2400722503662,0,,,6,,,,31.3495991952824,,,1,,,,,,,,,,,,,,,,,,,,,,57.1713066101074,57.302375793457,0,0,,,6.88197946548462,,1,0,0,0,0,30.7917900085449,6,1,1,57.308837890625,0,1816670208,57.242112159729,,,0.000442659743114799,1.53625579301856E-5,0.000445007120010633,1.5366184645319E-5,0.892306923866272,0.960519731044769,30.9649085998535,0,30,2,200,-0.00384844397194684,-2.07930135726929,-0.170689061284065,2,,,,,,,,,,,,,,,,
,3869722105.73502,59.8601493835449,0,,,6,,,,31.3495991952824,,,1,,,,,,,,,,,,,,,,,,,,,,59.8267593383789,59.8910713195801,0,0,,,6.91107559204102,,1,0,0,0,0.0138092041015625,29.8142719268799,5,1,1,59.8935394287109,0,1816670208,59.8626416524251,,,0.000438539611577917,1.52150997054843E-5,0.000440729634195621,1.52184476689134E-5,0.895036518573761,0.960574686527252,30.9761161804199,0.240184560418129,30,2,200,-0.00408423924818635,-2.06811618804932,-0.178215980529785,2,,,,,,,,,,,,,,,,
,3869722253.8854,62.4365711212158,0,,,6,,,,31.3546774899305,,,1,,,,,,,,,,,,,,,,,,,,,,62.4225997924805,62.4480438232422,0,0,,,6.94930648803711,,1,0,0,0,0,30.3030319213867,5,1,1,62.4505424499512,0,1816670208,62.436618458141,,,0.000434470208893129,1.50715222728699E-5,0.000436570786953557,1.50747957637471E-5,0.896542489528656,0.960655450820923,30.9873275756836,0,30,2,200,-0.00321630970574915,-2.05847644805908,-0.186261653900146,2,,,,,,,,,,,,,,,,
,3869722410.83983,65.1236801147461,0,,,6,,,,31.3603398177278,,,1,,,,,,,,,,,,,,,,,,,,,,64.9702529907227,65.2771072387695,0,0,,,6.97185039520264,,1,0,0,0,0.0138092041015625,32.2580642700195,6,1,1,65.2771072387695,0,1816670208,65.0533259465144,,,0.000430481563726296,1.49307848826893E-5,0.00043248371317632,1.49336742838411E-5,0.898074090480804,0.960646629333496,30.9993991851807,5.56771039962769,30,2,200,-0.00404130760580301,-2.04904270172119,-0.193691477179527,2,,,,,,,,,,,,,,,,
,3869722565.35284,68.6503105163574,0,,,6,,,,31.3654716617834,,,1,,,,,,,,,,,,,,,,,,,,,,68.4025039672852,68.888786315918,0,0,,,7.00379800796509,,1,0,0,0,0,30.7917900085449,6,1,1,68.9154663085938,0,1816670208,68.659153620402,,,0.000425995793712599,1.47716573561405E-5,0.000427873021881856,1.4774425161017E-5,0.900435149669647,0.960729956626892,31.0142688751221,0.131235644221306,30,2,200,-0.00323051726445556,-2.04105567932129,-0.205766648054123,2,,,,,,,,,,,,,,,,
,3869722716.7845,71.7785415649414,0,,,6,,,,31.3706686637613,,,1,,,,,,,,,,,,,,,,,,,,,,71.6357650756836,71.9136199951172,0,0,,,7.03238391876221,,1,0,0,0,0.0138092041015625,28.8367557525635,6,1,1,71.9282684326172,0,1816670208,71.7785771687826,,,0.000421567833486479,1.46154624119122E-5,0.000423347128643665,1.4618107360296E-5,0.90225225687027,0.96078610420227,31.0269546508789,0,30,2,200,-0.00334779592230916,-2.03043818473816,-0.21438817679882,2,,,,,,,,,,,,,,,,
,3869722862.26121,74.4792747497559,0,,,6,,,,31.3759553155773,,,1,,,,,,,,,,,,,,,,,,,,,,74.3752517700195,74.5798797607422,0,0,,,7.04981756210327,,1,0,0,0,0.0138092041015625,30.7917900085449,6,1,1,74.5832977294922,0,1816670208,74.4877293904622,,,0.000417508366391743,1.44727163027986E-5,0.000419211488776429,1.44752996412463E-5,0.903662502765656,0.960781216621399,31.0382251739502,0,30,2,200,-0.00317358295433223,-2.02070188522339,-0.222390174865723,2,,,,,,,,,,,,,,,,
,3869723000.9864,77.0357856750488,0,,,6,,,,31.3759553155773,,,1,,,,,,,,,,,,,,,,,,,,,,76.9413909912109,77.1200408935547,0,0,,,7.0669322013855,,1,0,0,0,0,30.3030319213867,6,1,1,77.1301803588867,0,1816670208,77.0338859558105,,,0.000413644813475655,1.43350544717531E-5,0.000415215693179709,1.4337313490116E-5,0.906384110450745,0.960813045501709,31.0496444702148,3.73119437426794E-5,30,2,200,-0.00356290815398097,-2.01140570640564,-0.230032086372375,2,,,,,,,,,,,,,,,,
,3869723149.35997,79.659366607666,0,,,6,,,,31.3810729163501,,,1,,,,,,,,,,,,,,,,,,,,,,79.5948715209961,79.7179946899414,0,0,,,7.08865165710449,,1,0,0,0,0,30.3030319213867,6,1,1,79.7238616943359,0,1816670208,79.6615727742513,,,0.000409414022855088,1.41863316033094E-5,0.000410904715892822,1.41884357721226E-5,0.907971441745758,0.960860252380371,31.0614337921143,0,30,2,200,-0.0036279670894146,-2.00044059753418,-0.237603798508644,2,,,,,,,,,,,,,,,,
,3869723293.11577,82.1983413696289,0,,,6,,,,31.3869993790192,,,1,,,,,,,,,,,,,,,,,,,,,,82.1459732055664,82.2507019042969,0,0,,,7.11281108856201,,1,0,0,0,0,29.8142719268799,6,1,1,82.25341796875,0,1816670208,82.2024618784587,,,0.000405227095690894,1.40395458050733E-5,0.000406653867060325,1.40416370226507E-5,0.909284651279449,0.960877597332001,31.0729064941406,1.00000047683716,30,2,200,-0.00356888631358743,-1.99019420146942,-0.245699882507324,2,,,,,,,,,,,,,,,,
,3869723443.68272,84.7832641601562,0,,,6,,,,31.3924130845432,,,1,,,,,,,,,,,,,,,,,,,,,,84.7439498901367,84.8141708374023,0,0,,,7.13800096511841,,1,0,0,0,0,28.3479976654053,5,1,1,84.8225784301758,0,1816670208,84.7810051657937,,,0.000400728029104484,1.38816265087687E-5,0.000402077937742248,1.38835811417474E-5,0.910914421081543,0.960982382297516,31.085075378418,0,30,2,200,-0.00258586253039539,-1.91009831428528,-0.185085624456406,2,,,,,,,,,,,,,,,,
,3869723594.89629,87.3468894958496,0,,,6,,,,31.3977252480605,,,1,,,,,,,,,,,,,,,,,,,,,,87.3201599121094,87.3708343505859,0,0,,,7.16057252883911,,1,0,0,0,0,30.3030319213867,5,1,1,87.3736190795898,0,1816670208,87.3481038411458,,,0.000396064000319349,1.37179681247486E-5,0.000397339564454947,1.37199431420903E-5,0.91262811422348,0.961025059223175,31.0976448059082,3.49090805684682E-5,30,2,200,-0.00248006172478199,-1.89893293380737,-0.19428788125515,2,,,,,,,,,,,,,,,,
,3869723745.63702,89.8836326599121,0,,,6,,,,31.402834069318,,,1,,,,,,,,,,,,,,,,,,,,,,89.8633270263672,89.9016571044922,0,0,,,7.17841005325317,,1,0,0,0,0.0138092041015625,29.8142719268799,5,1,1,89.903938293457,0,1816670208,89.8839384714762,,,0.000391259584464562,1.35495234077172E-5,0.000392456083980634,1.35513252614187E-5,0.914353549480438,0.961008489131928,31.1102733612061,3.8439487980213E-5,30,2,200,-0.00333837606012821,-1.88715970516205,-0.203507378697395,2,,,,,,,,,,,,,,,,
,3869723910.84141,92.5179824829102,0,,,6,,,,31.4081164354777,,,1,,,,,,,,,,,,,,,,,,,,,,92.4293365478516,92.598991394043,0,0,,,7.20135021209717,,1,0,0,0,0,29.3255138397217,6,1,1,92.6066284179688,0,1816670208,92.4815540313721,,,0.00038597068527543,1.33640757985547E-5,0.000387081663074612,1.33657188868711E-5,0.916368782520294,0.961077511310577,31.124174118042,,30,2,200,-0.0033307617995888,-1.87337112426758,-0.212286278605461,2,,,,,,,,,,,,,,,,
,3869724063.14154,95.361743927002,0,,,6,,,,31.4133307094498,,,1,,,,,,,,,,,,,,,,,,,,,,95.1259384155273,95.5781097412109,0,0,,,7.21540832519531,,1,0,0,0,0.0138092041015625,30.3030319213867,6,1,1,95.5975494384766,0,1816670208,95.3537705739339,,,0.000380479576827279,1.31716004388723E-5,0.000381492988075904,1.31729131509323E-5,0.918509840965271,0.960744738578796,31.1393699645996,0.131007865071297,30,2,200,-0.00287431548349559,-1.8599978685379,-0.223434939980507,2,,,,,,,,,,,,,,,,
,3869724213.84848,98.3605461120605,0,,,6,,,,31.4184379047194,,,1,,,,,,,,,,,,,,,,,,,,,,98.1481094360352,98.5648651123047,0,0,,,7.23752307891846,,1,0,0,0,0.0145721435546875,29.8142719268799,6,1,1,98.5729827880859,0,1816670208,98.3574371337891,,,0.000374164895658812,1.29500745598209E-5,0.000375084674373394,1.29513878942136E-5,0.921309649944305,0.961235165596008,31.1557884216309,INF,30,2,200,-0.00296833226457238,-1.83881103992462,-0.228829085826874,2,,,,,,,,,,,,,,,,
,3869724365.1524,101.224765777588,0,,,6,,,,31.4236653059513,,,1,,,,,,,,,,,,,,,,,,,,,,101.03377532959,101.380378723145,0,0,,,7.25870609283447,,1,0,0,0,0,30.3030319213867,6,1,1,101.415756225586,0,1816670208,101.210110057484,,,0.00036753742738371,1.27183841723044E-5,0.000368368686801323,1.27194773417173E-5,0.923634231090546,0.961253702640534,31.1712608337402,5.09210940435878E-6,30,2,200,-0.0031909835524857,-1.82096779346466,-0.239565402269363,2,,,,,,,,,,,,,,,,
,3869724517.10037,104.049713134766,0,,,6,,,,31.4289706036946,,,1,,,,,,,,,,,,,,,,,,,,,,103.901733398438,104.187576293945,0,0,,,7.28020000457764,,1,0,0,0,0.0138092041015625,30.3030319213867,6,1,1,104.197692871094,0,1816670208,104.0519212087,,,0.000360199502324105,1.24622337885181E-5,0.000360951791411545,1.24633567849804E-5,0.925995826721191,0.961295366287231,31.1870594024658,0,30,2,200,-0.00280151655897498,-1.80010688304901,-0.250199913978577,2,,,,,,,,,,,,,,,,
,3869724680.26386,106.952667236328,0,,,6,,,,31.4393366058078,,,1,,,,,,,,,,,,,,,,,,,,,,106.862945556641,107.036460876465,0,0,,,7.30747318267822,,1,0,0,0,0,29.8142719268799,6,1,1,107.042388916016,0,1816670208,106.953666051229,,,0.000351880733856474,1.21730146399227E-5,0.000352568632126245,1.21739115452919E-5,0.927567005157471,0.961263000965118,31.2046146392822,5.10326162839192E-6,30,2,200,-0.00293075107038021,-1.76901733875275,-0.25551438331604,2,,,,,,,,,,,,,,,,
,3869724833.29485,109.590675354004,0,,,6,,,,31.4444200441942,,,1,,,,,,,,,,,,,,,,,,,,,,109.527305603027,109.647552490234,0,0,,,7.3333568572998,,1,0,0,0,0,30.7917900085449,6,1,1,109.65404510498,0,1816670208,109.591477711995,,,0.000344017744613372,1.1898864558146E-5,0.00034462402486654,1.18996236726724E-5,0.930079936981201,0.961197137832642,31.2213592529297,0,30,2,200,-0.00291901431046426,-1.74666547775269,-0.267421007156372,2,,,,,,,,,,,,,,,,
,3869724988.32354,112.201560974121,0,,,6,,,,31.4494204726398,,,1,,,,,,,,,,,,,,,,,,,,,,112.156951904297,112.244567871094,0,0,,,7.3473744392395,,1,0,0,0,0,30.3030319213867,5,1,1,112.246170043945,0,1816670208,112.203409194946,,,0.000335610820022621,1.16065325822214E-5,0.000336156581785033,1.16073189440122E-5,0.932008385658264,0.961035668849945,31.2357406616211,0,30,2,200,-0.0027084774337709,-1.72300040721893,-0.280223220586777,2,,,,,,,,,,,,,,,,
,3869725143.93938,114.775257110596,0,,,6,,,,31.4552561647891,,,1,,,,,,,,,,,,,,,,,,,,,,114.740821838379,114.803024291992,0,0,,,7.3646674156189,,1,0,0,0,0.0177764892578125,30.3030319213867,5,1,1,114.809692382813,0,1816670208,114.774705366655,,,0.000326210029786713,1.12812301900606E-5,0.000326726150956272,1.12818962977023E-5,0.932255983352661,0.960568487644196,31.2439670562744,0,30,2,200,-0.00272163888439536,-1.69612765312195,-0.29400447010994,2,,,,,,,,,,,,,,,,
,3869725303.149,117.334907531738,0,,,6,,,,31.4613689212097,,,1,,,,,,,,,,,,,,,,,,,,,,117.309875488281,117.357879638672,0,0,,,7.38202333450317,,1,0,0,0,0,31.2805480957031,5,1,1,117.359939575195,0,1816670208,117.336271286011,,,0.000316340619847106,1.09404254103688E-5,0.000316853800925102,1.09412043618119E-5,0.931574881076813,0.960096836090088,31.2481288909912,0,30,2,200,-0.000633415416814387,-1.66851270198822,-0.309181213378906,2,,,,,,,,,,,,,,,,
,3869725458.56936,119.872230529785,0,,,6,,,,31.467508693026,,,1,,,,,,,,,,,,,,,,,,,,,,119.85343170166,119.888526916504,0,0,,,7.41325235366821,,1,0,0,0,0.000152587890625,30.3030319213867,6,1,1,119.89102935791,0,1816670208,119.87257194519,,,0.000306610930028104,1.06049811009696E-5,0.000307132860150033,1.06058082048191E-5,0.930150508880615,0.959454894065857,31.2492446899414,7.63915157318115,30,2,200,-0.00259946985170245,-1.64212000370026,-0.324804812669754,2,,,,,,,,,,,,,,,,
,3869725605.7594,122.367725372314,0,,,6,,,,31.4726625114252,,,1,,,,,,,,,,,,,,,,,,,,,,122.348846435547,122.385345458984,0,0,,,7.42354249954224,,1,0,0,0,0.02197265625,30.3030319213867,6,1,1,122.386604309082,0,1816670208,122.369414011637,,,0.000301088588932512,1.04131967062902E-5,0.000301573663219594,1.0413911979868E-5,0.93122535943985,0.959286034107208,31.2599792480469,0,30,2,200,-0.00261085969395936,-1.62628126144409,-0.332791447639465,2,,,,,,,,,,,,,,,,
,3869725753.28068,124.867042541504,0,,,6,,,,31.4791450359123,,,1,,,,,,,,,,,,,,,,,,,,,,124.848526000977,124.88419342041,0,0,,,7.43760871887207,,1,0,0,0,0.01495361328125,29.8142719268799,6,1,1,124.885559082031,0,1816670208,124.868257522583,,,0.000297530837384465,1.02892288217251E-5,0.000297979219779338,1.02897997892072E-5,0.932544529438019,0.959275603294373,31.2728080749512,0,30,2,200,-0.00244229193776846,-1.61682116985321,-0.3388332426548,2,,,,,,,,,,,,,,,,
,3869725916.18238,127.498966217041,0,,,6,,,,31.4895826389782,,,1,,,,,,,,,,,,,,,,,,,,,,127.401840209961,127.569290161133,0,0,,,7.45911312103271,,1,0,0,0,0.000152587890625,30.3030319213867,6,1,1,127.596092224121,0,1816670208,127.454701741536,,,0.000294478228098358,1.01831531806504E-5,0.000294908374006943,1.01837404356719E-5,0.933282256126404,0.959307551383972,31.2867164611816,0,30,2,200,-0.0020898834336549,-1.60904860496521,-0.34376072883606,2,,,,,,,,,,,,,,,,
,3869726063.98149,129.99796295166,0,,,6,,,,31.4946372239144,,,1,,,,,,,,,,,,,,,,,,,,,,129.902145385742,130.06330871582,0,0,,,7.46386480331421,,1,0,0,0,0,30.3030319213867,6,1,1,130.093780517578,0,1816670208,129.955449422201,,,0.000291848518350338,1.0091144597482E-5,0.000292243234624748,1.00917093087026E-5,0.934888303279877,0.959306299686432,31.2996139526367,5.59460592269897,30,2,200,-0.00264016585424542,-1.60326552391052,-0.34941753745079,2,,,,,,,,,,,,,,,,
,3869726212.15767,132.498695373535,0,,,6,,,,31.5005276758371,,,1,,,,,,,,,,,,,,,,,,,,,,132.39860534668,132.569793701172,0,0,,,7.48209762573242,,1,0,0,0,0.0145721435546875,29.8142719268799,6,1,1,132.598785400391,0,1816670208,132.453335101788,,,0.000289314056700627,1.00024833170808E-5,0.000289673432488319,1.00029445084224E-5,0.936473846435547,0.959357678890228,31.3132019042969,0,30,2,200,-0.00261156773194671,-1.5981262922287,-0.355328291654587,2,,,,,,,,,,,,,,,,
,3869726373.80247,135.293113708496,0,,,6,,,,31.5113574098202,,,1,,,,,,,,,,,,,,,,,,,,,,135.089416503906,135.479583740234,0,0,,,7.50610303878784,,1,0,0,0,0.00030517578125,30.7917900085449,6,1,1,135.496810913086,0,1816670208,135.279992421468,,,0.000286706846199419,9.91177373066197E-6,0.000287044430019708,9.91215560436666E-6,0.937389552593231,0.959380507469177,31.3285636901855,5.77504306420451E-6,30,2,200,-0.00266886223107576,-1.59367871284485,-0.362253427505493,2,,,,,,,,,,,,,,,,
,3869726523.72154,137.784469604492,0,,,6,,,,31.5168746530284,,,1,,,,,,,,,,,,,,,,,,,,,,137.575973510742,137.97541809082,0,0,,,7.52467346191406,,1,0,0,0,0,30.3030319213867,6,1,1,137.992965698242,0,1816670208,137.773123423258,,,0.000284413959273571,9.83159537100413E-6,0.00028472170532967,9.83193161018119E-6,0.93887460231781,0.959411203861237,31.3415374755859,0.508991897106171,30,2,200,-0.00249839061871171,-1.58854293823242,-0.367167562246323,2,,,,,,,,,,,,,,,,
,3869726681.58136,140.562377929688,0,,,6,,,,31.527831865444,,,1,,,,,,,,,,,,,,,,,,,,,,140.34700012207,140.739547729492,0,0,,,7.54200315475464,,1,0,0,0,0,30.3030319213867,6,1,1,140.777755737305,0,1816670208,140.544511159261,,,0.000281985212306481,9.74719598152394E-6,0.000282278098328732,9.74752639710367E-6,0.939628481864929,0.959483444690704,31.3561344146729,5.65464006285765E-6,30,2,200,-0.00230020401068032,-1.58386671543121,-0.372985512018204,2,,,,,,,,,,,,,,,,
,3869726835.7149,143.182052612305,0,,,6,,,,31.5329817533677,,,1,,,,,,,,,,,,,,,,,,,,,,142.981781005859,143.370895385742,0,0,,,7.54933547973633,,1,0,0,0,0.0138092041015625,29.3255138397217,6,1,1,143.38232421875,0,1816670208,143.181148529053,,,0.00027967054449228,9.66618315203906E-6,0.000279932553778557,9.66652497395748E-6,0.941365838050842,0.959497570991516,31.3703365325928,INF,30,2,200,-0.00245177373290062,-1.57879447937012,-0.377805322408676,2,,,,,,,,,,,,,,,,
,3869726993.09601,145.932319641113,0,,,6,,,,31.5441226269953,,,1,,,,,,,,,,,,,,,,,,,,,,145.727798461914,146.109146118164,0,0,,,7.55990791320801,,1,0,0,0,0,29.8142719268799,6,1,1,146.136840820313,0,1816670208,145.927013397217,,,0.000277311669661003,9.58430747767079E-6,0.00027756252423896,9.58464975531367E-6,0.94197541475296,0.959574162960052,31.3844413757324,3.56133787136059E-5,30,2,200,-0.0023070175666362,-1.57441902160645,-0.383465141057968,2,,,,,,,,,,,,,,,,
,3869727143.64398,148.448104858398,0,,,6,,,,31.550408599493,,,1,,,,,,,,,,,,,,,,,,,,,,148.256530761719,148.624114990234,0,0,,,7.59212112426758,,1,0,0,0,0,30.3030319213867,6,1,1,148.639678955078,0,1816670208,148.451243082682,,,0.000275149728571199,9.50878981090898E-6,0.000275374649974987,9.50908152940673E-6,0.94343489408493,0.959620118141174,31.3984642028809,1,30,2,200,-0.00240516196936369,-1.57017552852631,-0.388757348060608,2,,,,,,,,,,,,,,,,
,3869727308.26049,151.309257507324,0,,,6,,,,31.5607875791649,,,1,,,,,,,,,,,,,,,,,,,,,,151.150177001953,151.452194213867,0,0,,,7.60814619064331,,1,0,0,0,0.01617431640625,30.7917900085449,6,1,1,151.468338012695,0,1816670208,151.30833307902,,,0.000272752990255714,9.42543850426331E-6,0.000272963669470866,9.42578108015226E-6,0.944425046443939,0.95974463224411,31.413818359375,0,30,2,200,-0.00150183727964759,-1.56456923484802,-0.393205672502518,2,,,,,,,,,,,,,,,,
,3869727458.82837,153.766693115234,0,,,6,,,,31.5660554558781,,,1,,,,,,,,,,,,,,,,,,,,,,153.605041503906,153.91130065918,0,0,,,7.61451530456543,,1,0,0,0,0,29.8142719268799,6,1,1,153.928344726562,0,1816670208,153.764265696208,,,0.000270685458611603,9.35321207558971E-6,0.000270868290626979,9.35341432122541E-6,0.945939362049103,0.959771394729614,31.4275455474854,5.60602760314941,30,2,200,-0.00222580810077488,-1.56005895137787,-0.397806346416473,2,,,,,,,,,,,,,,,,
,3869727612.58776,156.263031005859,0,,,6,,,,31.5768090795499,,,1,,,,,,,,,,,,,,,,,,,,,,156.097579956055,156.410980224609,0,0,,,7.62808609008789,,1,0,0,0,0,28.8367557525635,6,1,1,156.428482055664,0,1816670208,156.259332021077,,,0.000268582359925467,9.28028426210735E-6,0.000268756116675962,9.28045413639902E-6,0.946453511714935,0.959835469722748,31.4409885406494,5.60722637176514,30,2,200,-0.00210801907815039,-1.55596494674683,-0.402801036834717,2,,,,,,,,,,,,,,,,
,3869727766.29356,158.814399719238,0,,,6,,,,31.5825617619226,,,1,,,,,,,,,,,,,,,,,,,,,,158.671966552734,158.951538085938,0,0,,,7.6537971496582,,1,0,0,0,0,31.2805480957031,6,1,1,158.963897705078,0,1816670208,158.818391164144,,,0.00026649956871485,9.20760864776586E-6,0.000266652896085434,9.20781801560836E-6,0.947909474372864,0.959863483905792,31.4552021026611,0.000246526964474469,30,2,200,-0.00213807518593967,-1.55204784870148,-0.4074746966362,2,,,,,,,,,,,,,,,,
,3869727917.10465,161.253028869629,0,,,6,,,,31.5933279848399,,,1,,,,,,,,,,,,,,,,,,,,,,161.089279174805,161.399841308594,0,0,,,7.66572427749634,,1,0,0,0,0,30.3030319213867,6,1,1,161.416778564453,0,1816670208,161.247679392497,,,0.000264479767007569,9.13754936710808E-6,0.000264624530491949,9.13775199345241E-6,0.948490262031555,0.959932148456573,31.4691772460937,,30,2,200,-0.00220594112761319,-1.54767036437988,-0.412237644195557,2,,,,,,,,,,,,,,,,
,3869728072.87447,163.751091003418,0,,,6,,,,31.599047553811,,,1,,,,,,,,,,,,,,,,,,,,,,163.593719482422,163.886688232422,0,0,,,7.68223762512207,,1,0,0,0,0,28.8367557525635,6,1,1,163.908462524414,0,1816670208,163.75510152181,,,0.000262442668539137,9.06650195377197E-6,0.000262567685736143,9.06668868034856E-6,0.949933528900146,0.960034787654877,31.4833946228027,0,30,2,200,-0.00183007761370391,-1.54381811618805,-0.417044192552567,2,,,,,,,,,,,,,,,,
,3869728226.58572,166.231895446777,0,,,6,,,,31.6104267522367,,,1,,,,,,,,,,,,,,,,,,,,,,166.071701049805,166.37548828125,0,0,,,7.69577312469482,,1,0,0,0,0.0138092041015625,29.8142719268799,6,1,1,166.39208984375,0,1816670208,166.235097249349,,,0.000260431854134748,8.99687733826149E-6,0.000260551314358767,8.99705343522991E-6,0.950287044048309,0.960061073303223,31.4969120025635,0.130725458264351,30,2,200,-0.00190339039545506,-1.54001688957214,-0.421834707260132,2,,,,,,,,,,,,,,,,
,3869728381.78999,168.768898010254,0,,,6,,,,31.6164087530668,,,1,,,,,,,,,,,,,,,,,,,,,,168.618957519531,168.902587890625,0,0,,,7.71007680892944,,1,0,0,0,0.0002288818359375,30.3030319213867,6,1,1,168.918838500977,0,1816670208,168.766765594482,,,0.000258406206249843,8.92635180285181E-6,0.000258508064869459,8.92649873929459E-6,0.951536357402802,0.960063457489014,31.5111198425293,5.61347675323486,30,2,200,-0.00205545942299068,-1.53593099117279,0.657364308834076,2,,,,,,,,,,,,,,,,
,3869728538.18569,171.277000427246,0,,,6,,,,31.6269676649368,,,1,,,,,,,,,,,,,,,,,,,,,,171.126983642578,171.416091918945,0,0,,,7.72734498977661,,1,0,0,0,0.017852783203125,30.7917900085449,6,1,1,171.427017211914,0,1816670208,171.276925404867,,,0.00025642524467655,8.85763180049507E-6,0.000256518568585249,8.85776695378058E-6,0.95220410823822,0.960143208503723,31.5257968902588,0,30,2,200,-0.00219859275966883,-1.53187084197998,0.652549624443054,2,,,,,,,,,,,,,,,,
,3869728685.75986,173.550643920898,0,,,6,,,,31.6321217652564,,,1,,,,,,,,,,,,,,,,,,,,,,173.379547119141,173.69270324707,0,0,,,7.73995685577393,,1,0,0,0,0.0138092041015625,30.3030319213867,6,1,1,173.721740722656,0,1816670208,173.540618896484,,,0.000254568023277307,8.7930237638521E-6,0.000254647287073729,8.79313720608653E-6,0.953305184841156,0.96019172668457,31.5385246276855,5.61591720581055,30,2,200,-0.00151864753570408,-1.52880382537842,0.647931098937988,2,,,,,,,,,,,,,,,,
,3869728848.70341,176.245529174805,0,,,6,,,,31.6431276713422,,,1,,,,,,,,,,,,,,,,,,,,,,176.081924438477,176.391906738281,0,0,,,7.74794435501099,,1,0,0,0,0,30.3030319213867,6,1,1,176.409133911133,0,1816670208,176.248668670654,,,0.000252460578303377,8.71996972957561E-6,0.000252532601391173,8.72008280230799E-6,0.953946173191071,0.960283398628235,31.5537071228027,0,30,2,200,-0.00186051009222865,-1.52484595775604,0.642994701862335,2,,,,,,,,,,,,,,,,
,3869729005.7794,178.758720397949,0,,,6,,,,31.6542526076194,,,1,,,,,,,,,,,,,,,,,,,,,,178.61213684082,178.888473510742,0,0,,,7.77394247055054,,1,0,0,0,0.0160980224609375,30.7917900085449,6,1,1,178.905303955078,0,1816670208,178.75608698527,,,0.000250481022712468,8.65138604324745E-6,0.000250546141976914,8.65146338458328E-6,0.954482078552246,0.96036684513092,31.5684127807617,0,30,2,200,-0.0019104554085061,-0.437069892883301,0.638270020484924,2,,,,,,,,,,,,,,,,
,3869729161.56454,181.241348266602,0,,,6,,,,31.6647882879195,,,1,,,,,,,,,,,,,,,,,,,,,,181.08528137207,181.386108398438,0,0,,,7.79822444915772,,1,0,0,0,0,30.7917900085449,6,1,1,181.397415161133,0,1816670208,181.240774790446,,,0.000248540639087838,8.58417468127517E-6,0.000248600553673601,8.58426499141184E-6,0.954967379570007,0.960405349731445,31.5825386047363,0,30,2,200,-0.00198463164269924,-0.433917760848999,0.632875323295593,2,,,,,,,,,,,,,,,,
,3869729317.81854,183.752746582031,0,,,6,,,,31.6712621078263,,,1,,,,,,,,,,,,,,,,,,,,,,183.6015625,183.892608642578,0,0,,,7.81732749938965,,1,0,0,0,0,31.2805480957031,6,1,1,183.903930664062,0,1816670208,183.751126607259,,,0.000246586779680404,8.5163231851273E-6,0.000246634718934713,8.51637767456046E-6,0.955939531326294,0.960427343845367,31.5969867706299,0,30,2,200,-0.00171621784102172,-0.429419755935669,0.629198491573334,2,,,,,,,,,,,,,,,,
,3869729473.68651,186.231422424316,0,,,6,,,,31.6825409925005,,,1,,,,,,,,,,,,,,,,,,,,,,186.077301025391,186.375900268555,0,0,,,7.83486890792847,,1,0,0,0,0.0185394287109375,30.7917900085449,6,1,1,186.385543823242,0,1816670208,186.234058380127,,,0.000244648847708069,8.44924962700437E-6,0.000244692639387167,8.44929694072221E-6,0.956324756145477,0.960485875606537,31.6112079620361,0,30,2,200,-0.00194844231009483,-0.42487707734108,0.625336945056915,2,,,,,,,,,,,,,,,,
,3869729628.49379,188.690383911133,0,,,6,,,,31.6934164573804,,,1,,,,,,,,,,,,,,,,,,,,,,188.518676757813,188.845565795898,0,0,,,7.84281206130982,,1,0,0,0,0.0199127197265625,30.7917900085449,6,1,1,188.862091064453,0,1816670208,188.696258544922,,,0.000242700825499185,8.38181227556341E-6,0.000242739876154177,8.38185202606178E-6,0.956759452819824,0.960528612136841,31.625732421875,,30,2,200,-0.00184108479879797,-0.421669095754623,0.620194971561432,2,,,,,,,,,,,,,,,,
,3869729776.04731,190.906021118164,0,,,6,,,,31.7003353467129,,,1,,,,,,,,,,,,,,,,,,,,,,190.718048095703,191.093994140625,0,0,,,7.87395191192627,,1,0,0,0,0,31.2805480957031,6,1,1,191.093994140625,0,1816670208,190.909954364483,,,0.000240949963054027,8.32108961314511E-6,0.000240982275142516,8.32113504176535E-6,0.957480072975159,0.960615932941437,31.6388874053955,7.65091419219971,30,2,200,-0.00157073023729026,-0.418367803096771,0.615939199924469,2,,,,,,,,,,,,,,,,
,3869729931.73905,193.387344360352,0,,,6,,,,31.7120088577228,,,1,,,,,,,,,,,,,,,,,,,,,,193.192855834961,193.548645019531,0,0,,,7.90034103393555,,1,0,0,0,0.022430419921875,31.7693061828613,6,1,1,193.581832885742,0,1816670208,193.375433603923,,,0.000239053673390076,8.25548967174568E-6,0.000239082266457042,8.25552238511005E-6,0.957796037197113,0.960626423358917,31.6537475585937,0,30,2,200,-0.00194282864686102,-0.415066361427307,0.611096858978271,2,,,,,,,,,,,,,,,,
,3869730080.9393,195.675476074219,0,,,6,,,,31.7171022582584,,,1,,,,,,,,,,,,,,,,,,,,,,195.464324951172,195.859924316406,0,0,,,7.91954660415649,,1,0,0,0,0.000152587890625,29.8142719268799,6,1,1,195.886627197266,0,1816670208,195.674293518066,,,0.000237250963857083,8.19296376179472E-6,0.000237271411018009,8.19298114893787E-6,0.958584725856781,0.960663199424744,31.6674289703369,2.00250979105476E-5,30,2,200,-0.00198995275422931,-0.41134312748909,0.60733836889267,2,,,,,,,,,,,,,,,,
,3869730245.21991,198.371063232422,0,,,6,,,,31.7303822544299,,,1,,,,,,,,,,,,,,,,,,,,,,198.183181762695,198.531997680664,0,0,,,7.93382930755615,,1,0,0,0,0,31.2805480957031,6,1,1,198.558944702148,0,1816670208,198.360057830811,,,0.000235229821241042,8.12308503673356E-6,0.000235247426324806,8.12308327449068E-6,0.958840548992157,0.960703313350678,31.6834545135498,5.62880563735962,30,2,200,-0.00197799527086318,-0.406855791807175,0.603009700775146,2,,,,,,,,,,,,,,,,
,3869730404.09868,200.880401611328,0,,,6,,,,31.7425660484877,,,1,,,,,,,,,,,,,,,,,,,,,,200.687744140625,201.053451538086,0,0,,,7.94992065429688,,1,0,0,0,0,31.2805480957031,6,1,1,201.073059082031,0,1816670208,200.876502990723,,,0.000233219421338218,8.05357539053797E-6,0.000233235475040614,8.05358879162358E-6,0.959092140197754,0.960765719413757,31.698169708252,5.63011264801025,30,2,200,-0.00178904377389699,-0.401456862688065,0.599641859531403,2,,,,,,,,,,,,,,,,
,3869730562.50574,203.341682434082,0,,,6,,,,31.7527998003266,,,1,,,,,,,,,,,,,,,,,,,,,,203.147079467773,203.508972167969,0,0,,,7.97180366516113,,1,0,0,0,0,32.2580642700195,6,1,1,203.536285400391,0,1816670208,203.333754221598,,,0.000231183140476994,7.98315056653612E-6,0.000231196267845439,7.98316795871322E-6,0.959429204463959,0.960795938968658,31.7127704620361,0,30,2,200,-0.00191151187755167,-0.396596968173981,0.595858812332153,2,,,,,,,,,,,,,,,,
,3869730720.74729,205.853088378906,0,,,6,,,,31.7632192402156,,,1,,,,,,,,,,,,,,,,,,,,,,205.643203735352,206.044006347656,0,0,,,7.97709655761719,,1,0,0,0,0.000152587890625,30.7917900085449,6,1,1,206.062973022461,0,1816670208,205.849210298978,,,0.000229293006622288,7.91776435919181E-6,0.000229302837404294,7.91776951663269E-6,0.959788858890534,0.96085125207901,31.7280254364014,,30,2,200,-0.00197384343482554,-0.392811954021454,0.591568470001221,2,,,,,,,,,,,,,,,,
,3869730880.57663,208.395072937012,0,,,6,,,,31.7741724997945,,,1,,,,,,,,,,,,,,,,,,,,,,208.200897216797,208.555816650391,0,0,,,7.99399757385254,,1,0,0,0,0,30.3030319213867,6,1,1,208.589248657227,0,1816670208,208.385052998861,,,0.000227459228554621,7.85435110259118E-6,0.000227466118690569,7.85434238964369E-6,0.960083961486816,0.960877299308777,31.7438220977783,7.65342378616333,30,2,200,-0.00196105614304543,-0.389980465173721,0.586476027965546,2,,,,,,,,,,,,,,,,
,3869731038.84649,210.852897644043,0,,,6,,,,31.7847098190046,,,1,,,,,,,,,,,,,,,,,,,,,,210.667098999023,211.019439697266,0,0,,,8.02167510986328,,1,0,0,0,0.0002288818359375,31.2805480957031,6,1,1,211.038696289062,0,1816670208,210.844785054525,,,0.000225639684985117,7.79141940439466E-6,0.000225644544720832,7.79141541095274E-6,0.960399389266968,0.960959315299988,31.7592697143555,,30,2,200,-0.00200071395374835,-0.386662095785141,0.581922113895416,2,,,,,,,,,,,,,,,,
,3869731196.33718,213.327392578125,0,,,6,,,,31.7953701875999,,,1,,,,,,,,,,,,,,,,,,,,,,213.129364013672,213.517837524414,0,0,,,8.02374935150146,,1,0,0,0,0.0214385986328125,31.2805480957031,6,1,1,213.525421142578,0,1816670208,213.323487501878,,,0.000223853801119004,7.72967309344926E-6,0.000223856937693301,7.72966858947962E-6,0.960649788379669,0.961021900177002,31.77467918396,0,30,2,200,-0.00192503514699638,-0.38240459561348,0.578649580478668,2,,,,,,,,,,,,,,,,
,3869731355.27498,215.855712890625,0,,,6,,,,31.8064640876652,,,1,,,,,,,,,,,,,,,,,,,,,,215.660064697266,216.025604248047,0,0,,,8.04413795471191,,1,0,0,0,0.000152587890625,30.7917900085449,6,1,1,216.051361083984,0,1816670208,215.842309315999,,,0.000222030372968084,7.66665191943389E-6,0.00022203209334404,7.66664649207512E-6,0.960853278636932,0.961069583892822,31.7907123565674,0,30,2,200,-0.00181307329330593,-0.377726495265961,0.575841248035431,2,,,,,,,,,,,,,,,,
,3869731512.57984,218.32682800293,0,,,6,,,,31.8172883857577,,,1,,,,,,,,,,,,,,,,,,,,,,218.144256591797,218.477722167969,0,0,,,8.05659961700439,,1,0,0,0,0,31.2805480957031,6,1,1,218.509399414062,0,1816670208,218.317184448242,,,0.000220236385816511,7.6046423810473E-6,0.000220237191535847,7.60464141422515E-6,0.961058855056763,0.961156070232391,31.8067493438721,0,30,2,200,-0.00180295773316175,-0.372582077980041,0.573012888431549,2,,,,,,,,,,,,,,,,
,3869731671.70473,220.85523223877,0,,,6,,,,31.8284858564934,,,1,,,,,,,,,,,,,,,,,,,,,,220.657943725586,221.039398193359,0,0,,,8.07795143127441,,1,0,0,0,0.0185394287109375,31.2805480957031,6,1,1,221.052520751953,0,1816670208,220.853964487712,,,0.000218385830751984,7.54071675687226E-6,0.000218386098379943,7.54071625918209E-6,0.961158931255341,0.961192131042481,31.8223304748535,0,30,2,200,-0.0022312100045383,-0.370704084634781,0.568759560585022,2,,,,,,,,,,,,,,,,
,3869731830.11514,223.304252624512,0,,,6,,,,31.8393854347503,,,1,,,,,,,,,,,,,,,,,,,,,,223.114654541016,223.473907470703,0,0,,,8.09579849243164,,1,0,0,0,0,31.2805480957031,6,1,1,223.493850708008,0,1816670208,223.301598866781,,,0.000216614890099744,7.47955112532541E-6,0.000216614886419335,7.47955098125571E-6,0.96123480796814,0.961234867572784,31.8391265869141,0,30,2,200,-0.00203281012363732,-0.365789800882339,0.564383208751678,2,,,,,,,,,,,,,,,,
,3869731991.13541,225.843933105469,0,,,6,,,,31.8508075412438,,,1,,,,,,,,,,,,,,,,,,,,,,225.646484375,226.014144897461,0,0,,,8.10618209838867,,1,0,0,0,0,30.7917900085449,6,1,1,226.041381835938,0,1816670208,225.837423960368,,,0.000214808937763457,7.41717245550742E-6,0.000214809158220012,7.41717387185004E-6,0.961300313472748,0.961321890354157,31.8557586669922,4.11285638809204,30,2,200,-0.00168941228184849,-0.360628992319107,0.561757266521454,2,,,,,,,,,,,,,,,,
,3869732149.98358,228.299194335938,0,,,6,,,,31.8620327470881,,,1,,,,,,,,,,,,,,,,,,,,,,228.106826782227,228.467727661133,0,0,,,8.13282108306885,,1,0,0,0,0.0138092041015625,31.2805480957031,6,1,1,228.491561889648,0,1816670208,228.29425684611,,,0.000213028373118079,7.355687411839E-6,0.000213029155472836,7.35568939067084E-6,0.961301147937775,0.961389064788818,31.8720245361328,7.6524019241333,30,2,200,-0.00170584756415337,-0.356431543827057,0.558505117893219,2,,,,,,,,,,,,,,,,
,3869732311.06057,230.845680236816,0,,,6,,,,31.8736206657689,,,1,,,,,,,,,,,,,,,,,,,,,,230.658172607422,231.007293701172,0,0,,,8.16650104522705,,1,0,0,0,0,29.8142719268799,6,1,1,231.033187866211,0,1816670208,230.83876546224,,,0.000211264893328568,7.29481958392647E-6,0.000211266620592675,7.29482160627138E-6,0.961219131946564,0.96142303943634,31.8888416290283,0,30,2,200,-0.00184025906492025,-0.352458387613297,0.554768621921539,2,,,,,,,,,,,,,,,,
,3869732468.90394,233.319374084473,0,,,6,,,,31.8852549061074,,,1,,,,,,,,,,,,,,,,,,,,,,233.138442993164,233.493194580078,0,0,,,8.19861793518066,,1,0,0,0,0,31.2805480957031,6,1,1,233.500305175781,0,1816670208,233.318841298421,,,0.000209512526508512,7.23433505572918E-6,0.000209515686073466,7.23434081906184E-6,0.961134254932404,0.961502969264984,31.905725479126,0,30,2,200,-0.00174436334054917,-0.348747104406357,0.551087617874146,2,,,,,,,,,,,,,,,,
,3869732629.02575,235.830322265625,0,,,6,,,,31.897105399538,,,1,,,,,,,,,,,,,,,,,,,,,,235.652587890625,235.996154785156,0,0,,,8.21975135803223,,1,0,0,0,0.0138092041015625,31.2805480957031,6,1,1,236.008056640625,0,1816137728,235.825750986735,,,0.000207777929197237,7.1744784705017E-6,0.000207782850011365,7.17448910134146E-6,0.960997521877289,0.961570084095001,31.9226245880127,0,30,2,200,-0.00182520365342498,-0.345123946666718,0.547783434391022,2,,,,,,,,,,,,,,,,
,3869732787.77652,238.295211791992,0,,,6,,,,31.9089060561815,,,1,,,,,,,,,,,,,,,,,,,,,,238.113998413086,238.451629638672,0,0,,,8.24972629547119,,1,0,0,0,0,29.8142719268799,6,1,1,238.476425170898,0,2085105664,238.288733164469,,,0.000206034921353375,7.11434474114871E-6,0.000206042040236827,7.11435830378101E-6,0.960812151432037,0.961652934551239,31.9398517608643,0,30,2,200,-0.00159833452198654,-0.340679526329041,0.54440051317215,2,,,,,,,,,,,,,,,,
,3869732948.82502,240.816917419434,0,,,6,,,,31.9190101659008,,,1,,,,,,,,,,,,,,,,,,,,,,240.637603759766,240.974502563477,0,0,,,8.28267002105713,,1,0,0,0,0,31.7693061828613,6,1,1,240.996231079102,0,2085105664,240.815905253092,,,0.000204284741622833,7.05403174785201E-6,0.000204296168794609,7.05406639451252E-6,0.96038293838501,0.961690485477448,31.9576969146729,0,30,2,200,-0.00188986328430474,-0.336227804422379,0.541242122650146,2,,,,,,,,,,,,,,,,
,3869733108.35848,243.297431945801,0,,,6,,,,31.9308747314864,,,1,,,,,,,,,,,,,,,,,,,,,,243.118423461914,243.462524414062,0,0,,,8.30708980560303,,1,0,0,0,0,31.7693061828613,6,1,1,243.476440429687,0,2085105664,243.297724405924,,,0.000202563334550532,6.99469032516764E-6,0.000202578070650887,6.99472901868013E-6,0.960017323493958,0.961732625961304,31.9752750396729,0,30,2,200,-0.00189208891242743,-0.332484364509583,0.537744104862213,2,,,,,,,,,,,,,,,,
,3869733268.7382,245.813552856445,0,,,6,,,,31.9432781647073,,,1,,,,,,,,,,,,,,,,,,,,,,245.624313354492,245.984741210938,0,0,,,8.34846782684326,,1,0,0,0,0,31.2805480957031,6,1,1,246.002792358398,0,2085105664,245.808747609456,,,0.000200824697525616,6.93475332428299E-6,0.000200843038462482,6.93479029301853E-6,0.959667980670929,0.961856186389923,31.993501663208,0,30,2,200,-0.00172585633117706,-0.32857745885849,0.534165859222412,2,,,,,,,,,,,,,,,,
,3869733428.72126,248.296607971191,0,,,6,,,,31.9554777206797,,,1,,,,,,,,,,,,,,,,,,,,,,248.113906860352,248.459518432617,0,0,,,8.37533378601074,,1,0,0,0,0.0138092041015625,32.2580642700195,6,1,1,248.479309082031,0,2085105664,248.292779286702,,,0.000199043573704564,6.87338373083477E-6,0.00019906703762372,6.87344519922963E-6,0.959186553955078,0.96194463968277,32.0119972229004,0,30,2,200,-0.00167405535466969,-0.32481575012207,0.530339896678925,2,,,,,,,,,,,,,,,,
,3869733589.73035,250.77564239502,0,,,6,,,,31.9676041659366,,,1,,,,,,,,,,,,,,,,,,,,,,250.585296630859,250.950912475586,0,0,,,8.41692161560059,,1,0,0,0,0,31.7693061828613,6,1,1,250.96598815918,0,2085105664,250.780128479004,,,0.00019726320605074,6.81206362842516E-6,0.00019729151350805,6.81212038672301E-6,0.958613634109497,0.962013900279999,32.0305671691895,0,30,2,200,-0.00180192629341036,-0.320659160614014,0.527060270309448,2,,,,,,,,,,,,,,,,
,3869733751.10833,253.307769775391,0,,,6,,,,31.9805007154119,,,1,,,,,,,,,,,,,,,,,,,,,,253.125564575195,253.473159790039,0,0,,,8.47560405731201,,1,0,0,0,0,31.2805480957031,6,1,1,253.489974975586,0,2085105664,253.306532541911,,,0.000195512320925217,6.75178262162356E-6,0.000195546764282341,6.75185908213696E-6,0.957974255084991,0.96209180355072,32.0500221252441,0,30,2,200,-0.00174403539858758,-0.316080123186111,0.524201214313507,2,,,,,,,,,,,,,,,,
,3869733912.33447,255.780563354492,0,,,6,,,,31.9961439258895,,,1,,,,,,,,,,,,,,,,,,,,,,255.596038818359,255.944290161133,0,0,,,8.54545116424561,,1,0,0,0,0,31.2805480957031,6,1,1,255.965087890625,0,2085105664,255.769495183771,,,0.000193799568976144,6.69273792659589E-6,0.000193837645268108,6.69282297327409E-6,0.957601726055145,0.962175250053406,32.0695571899414,0,30,2,200,-0.00159014901146293,-0.311815202236176,0.520927309989929,2,,,,,,,,,,,,,,,,
,3869734063.29286,257.892837524414,0,,,6,,,,32.0070590429286,,,1,,,,,,,,,,,,,,,,,,,,,,257.707641601562,258.056762695313,0,0,,,8.6293478012085,,1,0,0,0,0,31.7693061828613,6,1,1,258.078033447266,0,2085105664,257.883575439453,,,0.000192204726029166,6.63787718458622E-6,0.000192249951273374,6.6379808815066E-6,0.956845998764038,0.962268114089966,32.0873107910156,0,30,2,200,-0.00158883235417306,-0.307110756635666,0.519067168235779,2,,,,,,,,,,,,,,,,
,3869734221.26645,260.213088989258,0,,,6,,,,32.0174971778666,,,1,,,,,,,,,,,,,,,,,,,,,,260.031951904297,260.371368408203,0,0,,,8.74969482421875,,1,0,0,0,0,32.2580642700195,6,1,1,260.394226074219,0,2085105664,260.199381510417,,,0.000190517869839208,6.57996404022059E-6,0.000190574082284574,6.58009179024617E-6,0.955649256706238,0.962360441684723,32.1073837280273,0,30,2,200,-0.00160870514810085,-0.303904056549072,0.515343606472015,2,,,,,,,,,,,,,,,,
,3869734388.82439,262.916320800781,0,,,6,,,,32.0344251612734,,,1,,,,,,,,,,,,,,,,,,,,,,262.729309082031,263.088317871094,0,0,,,8.88192939758301,,1,0,0,0,0.0138092041015625,31.2805480957031,6,1,1,263.103332519531,0,2085105664,262.910395304362,,,0.000188725918087302,6.51834118200963E-6,0.000188790435496333,6.51847618899578E-6,0.954744100570679,0.962489545345306,32.1314392089844,0,30,2,200,-0.00155409029684961,-0.300049126148224,0.511328339576721,2,,,,,,,,,,,,,,,,
,3869734543.91085,265.206680297852,0,,,6,,,,32.0447293908054,,,1,,,,,,,,,,,,,,,,,,,,,,265.028350830078,265.369873046875,0,0,,,9.0451545715332,,1,0,0,0,0.0138092041015625,32.7468223571777,6,1,1,265.385009765625,0,2085105664,265.199356079102,,,0.000187004555476773,6.45938168528913E-6,0.000187083957279557,6.459527663882E-6,0.953086256980896,0.962603151798248,32.1532783508301,0,30,2,200,-0.0014943853020668,-0.295509934425354,0.508627414703369,2,,,,,,,,,,,,,,,,
,3869734695.10607,267.44792175293,0,,,6,,,,32.0559772013604,,,1,,,,,,,,,,,,,,,,,,,,,,267.373321533203,267.504730224609,0,0,,,9.22955131530762,,1,0,0,0,0,31.7693061828613,6,1,1,267.522521972656,0,2085105664,267.416637714093,,,0.000185257786390894,6.39953051144063E-6,0.000185352529231642,6.39971830132779E-6,0.951505839824676,0.962722420692444,32.1748390197754,0,30,2,200,-0.00158991839271039,-0.290970236063004,0.505915284156799,2,,,,,,,,,,,,,,,,
,3869734858.2124,269.954803466797,0,,,6,,,,32.0728918229899,,,1,,,,,,,,,,,,,,,,,,,,,,269.871856689453,270.020050048828,0,0,,,9.47052192687988,,1,0,0,0,0,32.7468223571777,6,1,1,270.037750244141,0,2085105664,269.92578125,,,0.000183281103568871,6.33166547826135E-6,0.000183388522565231,6.33185739731031E-6,0.950163245201111,0.962923943996429,32.200496673584,0.103568159043789,30,2,200,-0.00146807183045894,-0.285982757806778,0.502365827560425,2,,,,,,,,,,,,,,,,
,3869735018.82206,272.441955566406,0,,,6,,,,32.0842039248001,,,1,,,,,,,,,,,,,,,,,,,,,,272.376190185547,272.469116210938,0,0,,,9.75877666473389,,1,0,0,0,0.001678466796875,31.2805480957031,6,1,1,272.507720947266,0,2085105664,272.406893412272,,,0.000181203982179228,6.26063240899695E-6,0.000181333048242319,6.26084804502738E-6,0.947905421257019,0.963101983070374,32.2251014709473,0,30,2,200,-0.00155955529771745,-0.280500769615173,0.499294281005859,2,,,,,,,,,,,,,,,,
,3869735182.4925,274.95686340332,0,,,6,,,,32.101087114867,,,1,,,,,,,,,,,,,,,,,,,,,,274.875701904297,275.031188964844,0,0,,,10.115532875061,,1,0,0,0,0.0138092041015625,30.3030319213867,6,1,1,275.038024902344,0,2085105664,274.932418823242,,,0.000178500771085048,6.16786590612523E-6,0.000178649340950873,6.16816674545288E-6,0.94598799943924,0.963199973106384,32.2525596618652,0,30,2,200,-0.00165293202735484,-0.273787349462509,0.494548082351685,2,,,,,,,,,,,,,,,,
,3869735343.78365,277.445571899414,0,,,6,,,,32.1130559111925,,,1,,,,,,,,,,,,,,,,,,,,,,277.37744140625,277.485931396484,0,0,,,10.5278377532959,,1,0,0,0,0,31.2805480957031,6,1,1,277.513702392578,0,2085105664,277.412905375163,,,0.000176582619274266,6.10248614022691E-6,0.000176756025780377,6.10276167183376E-6,0.94333028793335,0.96335357427597,32.2786865234375,0,30,2,200,-0.00142787990625948,-0.268489599227905,0.491630733013153,2,,,,,,,,,,,,,,,,
,3869735507.52933,279.950607299805,0,,,6,,,,32.1301033585549,,,1,,,,,,,,,,,,,,,,,,,,,,279.874694824219,280.014129638672,0,0,,,10.923731803894,,1,0,0,0,0.0138092041015625,31.7693061828613,6,1,1,280.026519775391,0,2085105664,279.922884427584,,,0.000174908857019513,6.04529403046869E-6,0.000175104205558442,6.04568193292692E-6,0.941466271877289,0.96357125043869,32.3056640625,0,30,2,200,-0.000876705278642476,-0.264303296804428,0.488665640354156,2,,,,,,,,,,,,,,,,
,3869735653.65262,282.340072631836,0,,,6,,,,32.142181360098,,,1,,,,,,,,,,,,,,,,,,,,,,282.320617675781,282.357604980469,0,0,,,11.1485376358032,,1,0,0,0,0.0138092041015625,32.7468223571777,5,1,1,282.359527587891,0,2085105664,282.341634114583,,,0.000173472463761997,5.99646943526425E-6,0.000173689601824174,5.9968406144377E-6,0.939185440540314,0.963581383228302,32.3287734985352,0,30,2,200,-0.00138959381729364,-0.259562402963638,0.487510502338409,2,,,,,,,,,,,,,,,,
,3869735811.31372,284.815811157227,0,,,6,,,,32.1596932802026,,,1,,,,,,,,,,,,,,,,,,,,,,284.794372558594,284.836334228516,0,0,,,11.0680313110352,,1,0,0,0,0,31.2805480957031,5,1,1,284.837249755859,0,2085105664,284.817738850911,,,0.000172035818645229,5.94711790579614E-6,0.000172260066384287,5.94745846208758E-6,0.938332498073578,0.963688969612122,32.350658416748,0,30,2,200,-0.00146871793549508,-0.256634950637817,0.484440475702286,2,,,,,,,,,,,,,,,,
,3869735966.20121,287.288604736328,0,,,6,,,,32.1718302571978,,,1,,,,,,,,,,,,,,,,,,,,,,287.263122558594,287.312316894531,0,0,,,10.9567708969116,,1,0,0,0,0.0138092041015625,32.2580642700195,5,1,1,287.314086914062,0,2085105664,287.290883382161,,,0.000170641684529226,5.90012837692892E-6,0.000170902837063061,5.90057748994292E-6,0.935122728347778,0.963794648647308,32.3780746459961,0,30,2,200,-0.00157904846128076,-0.253814309835434,0.481328636407852,2,,,,,,,,,,,,,,,,
,3869736124.54342,289.764663696289,0,,,6,,,,32.1893267632579,,,1,,,,,,,,,,,,,,,,,,,,,,289.736877441406,289.791137695313,0,0,,,10.9192533493042,,1,0,0,0,0,31.7693061828613,5,1,1,289.792449951172,0,2085105664,289.76767985026,,,0.000169276429772539,5.85383461159656E-6,0.000169562300666995,5.85428139473757E-6,0.932775735855103,0.963855624198914,32.4064826965332,0.000215213367482647,30,2,200,-0.00135338329710066,-0.251112163066864,0.478612273931503,2,,,,,,,,,,,,,,,,
,3869736278.59631,292.223052978516,0,,,6,,,,32.2021676906875,,,1,,,,,,,,,,,,,,,,,,,,,,292.188537597656,292.254943847656,0,0,,,10.9564418792725,,1,0,0,0,0.0138092041015625,33.7243423461914,5,1,1,292.257568359375,0,2085105664,292.225156148275,,,0.000167948515566236,5.80948092433523E-6,0.000168282064285543,5.81004505719023E-6,0.928890645503998,0.964018940925598,32.437183380127,0,30,2,200,-0.00116080697625875,-0.248917892575264,0.475175797939301,2,,,,,,,,,,,,,,,,
,3869736436.73697,294.685852050781,0,,,6,,,,32.2199364579245,,,1,,,,,,,,,,,,,,,,,,,,,,294.646545410156,294.722137451172,0,0,,,11.0617094039917,,1,0,0,0,0,31.7693061828613,5,1,1,294.725158691406,0,2085105664,294.688092549642,,,0.000166581853913607,5.76353165980263E-6,0.000166953834378609,5.76418034499909E-6,0.925747036933899,0.964056313037872,32.4688720703125,,30,2,200,-0.00128014478832483,-0.244632750749588,0.473517239093781,2,,,,,,,,,,,,,,,,
,3869736593.20623,297.150177001953,0,,,6,,,,32.2329294337411,,,1,,,,,,,,,,,,,,,,,,,,,,297.10791015625,297.189697265625,0,0,,,11.2616853713989,,1,0,0,0,0.0138092041015625,31.7693061828613,5,1,1,297.192443847656,0,2085105664,297.152793884277,,,0.000165136466840965,5.71577356758532E-6,0.000165575049442849,5.71653463272276E-6,0.920651614665985,0.964267373085022,32.5043678283691,7.63478422164917,30,2,200,-0.00114578846842051,-0.240842118859291,0.471623599529266,2,,,,,,,,,,,,,,,,
,3869736744.98863,299.546371459961,0,,,6,,,,32.2457355014638,,,1,,,,,,,,,,,,,,,,,,,,,,299.491363525391,299.597442626953,0,0,,,11.507794380188,,1,0,0,0,0.0138092041015625,31.7693061828613,6,1,1,299.601379394531,0,2085105664,299.549621582031,,,0.000163577978366741,5.66437886144717E-6,0.00016409048993029,5.66525719393505E-6,0.915201306343079,0.964368283748627,32.5406112670898,0,30,2,200,-0.00119561224710196,-0.237651288509369,0.468600183725357,2,,,,,,,,,,,,,,,,
,3869736787.78513,299.812896728516,0,,,6,,,,32.2510204688741,,,1,,,,,,,,,,,,,,,,,,,,,,299.790679931641,299.833709716797,0,0,,,11.5885562896729,,1,0,0,0,0.0138092041015625,33.2355842590332,5,1,1,299.835113525391,0,2085105664,299.816162109375,,,0.000163135686382538,5.64923807258694E-6,0.000163651717114459,5.65009643986195E-6,0.914841234683991,0.964431941509247,32.5475540161133,,30,2,200,-0.00124360143672675,-0.236330345273018,0.468054622411728,2,,,,,,,,,,,,,,,,