File: Chapter5/lowT/LB6_ZFC.dat
[Header]
; MPMS3 Data File (default extension .dat)
; Copyright (c) 2007, Quantum Design, Inc. All rights reserved.
TITLE,
FILEOPENTIME,3869736802.91173,08/15/2022,5:04 pm
BYAPP,MPMS3 w/ AC,1.0,1.1
INFO,MPMS3 Measurement Release 1.1.16 Build 424, MultiVu Release 2.3.4.19,APPNAME
INFO,Linear Motor Servo Controller,MOTOR_MODULE_NAME
INFO,3101-100 N0,MOTOR_HW_VERSION
INFO,MMC1047,MOTOR_SERIAL_NUMBER
INFO,01.04.28,MOTOR_SOFTWARE_VERSION
INFO,Quantum Design Squid Module,SQUID_MODULE_NAME
INFO,3101-501 B0,SQUID_HW_VERSION
INFO,SQM278,SQUID_SERIAL_NUMBER
INFO,01.03.04,SQUID_SOFTWARE_VERSION
INFO,Quantum Design VSM Oven,OVEN_MODULE_NAME
INFO,3101-201 A3,OVEN_HW_VERSION
INFO,OVB323,OVEN_SERIAL_NUMBER
INFO,01.07.07,OVEN_SOFTWARE_VERSION
INFO,SQUID AC,AC_MODULE_NAME
INFO,3101-401 G0,AC_HW_VERSION
INFO,SAC258,AC_SERIAL_NUMBER
INFO,SQUID AC 00.95.07,AC_SOFTWARE_VERSION
INFO,TCI127,COIL_SERIAL_NUMBER
INFO,0,MOMENT_UNITS
INFO,greigite,SAMPLE_MATERIAL
INFO,,SAMPLE_COMMENT
INFO,,SAMPLE_MASS
INFO,,SAMPLE_VOLUME
INFO,,SAMPLE_MOLECULAR_WEIGHT
INFO,,SAMPLE_SIZE
INFO,,SAMPLE_SHAPE
INFO,Straw,SAMPLE_HOLDER
INFO,Standard,SAMPLE_HOLDER_DETAIL
INFO,66.36,SAMPLE_OFFSET
DATATYPE,COMMENT,1
DATATYPE,TIME,2
STARTUPAXIS,X,2
STARTUPAXIS,Y1,5
FIELDGROUP, VSM,2,3,4,5,6,8,9,10,11,14,15
FIELDGROUP, DC, 2,3,4,14,56,57,58,59,60,61,62,63,64,65,66,67,68,69
FIELDGROUP, AC, 2,3,4,11,16,17,18,19,20,21,22,23,24,25,26,27,28,29,30
STARTUPGROUP, All
[Data]
Comment,Time Stamp (sec),Temperature (K),Magnetic Field (Oe),Moment (emu),M. Std. Err. (emu),Transport Action,Averaging Time (sec),Frequency (Hz),Peak Amplitude (mm),Center Position (mm),Lockin Signal' (V),Lockin Signal (V),Range,M. Quad. Signal (emu),AC Moment (emu),AC M. Std Err. (emu),AC Phase (deg),AC Phase Std. Err. (deg),AC Susceptibility (emu/Oe),AC Suscept. Std Err. (emu/Oe),AC X' (emu/Oe),AC X' Std Err. (emu/Oe),AC X'' (emu/Oe),AC X'' Std Err. (emu/Oe),AC Drive (Oe),AC Frequency (Hz),AC Averaging Time (sec),AC Cycles,AC Range,AC Measure Type,AC Signal' (V),AC Signal'' (V),AC Trim Coil Ratio,AC Trim Coil Phase,Min. Temperature (K),Max. Temperature (K),Min. Field (Oe),Max. Field (Oe),Mass (grams),Motor Lag (deg),Pressure (Torr),Measure Count,Measurement Number,SQUID Status (code),Motor Status (code),Measure Status (code),Motor Current (amps),Motor Temp. (C),Temp. Status (code),Field Status (code),Chamber Status (code),Chamber Temp (K),Redirection State,Evercool Status,Average Temp (K),Rotation Angle (deg),Rotator state,DC Moment Fixed Ctr (emu),DC Moment Err Fixed Ctr (emu),DC Moment Free Ctr (emu),DC Moment Err Free Ctr (emu),DC Fixed Fit,DC Free Fit,DC Calculated Center (mm),DC Calculated Center Err (mm),DC Scan Length (mm),DC Scan Time (s),DC Number of Points,DC Squid Drift,DC Min V (V),DC Max V (V),DC Scans per Measure,Map 01,Map 02,Map 03,Map 04,Map 05,Map 06,Map 07,Map 08,Map 09,Map 10,Map 11,Map 12,Map 13,Map 14,Map 15,Map 16
,3869736811.33274,299.781173706055,0,,,6,,,,32.2510204688741,,,1,,,,,,,,,,,,,,,,,,,,,,299.701721191406,299.876068115234,0,0,,,11.5996150970459,,1,0,0,0,0,32.2580642700195,6,1,1,299.68994140625,0,2085105664,299.825736999512,,,0.000162790569747152,5.63760863283807E-6,0.000163319848216999,5.63849331652191E-6,0.914176344871521,0.965157151222229,32.5514984130859,0,30,2,200,-0.000468491925857961,-0.222683191299438,0.480081886053085,2,,,,,,,,,,,,,,,,
,3869737063.92649,219.400123596191,0,,,6,,,,31.9032724180828,,,1,,,,,,,,,,,,,,,,,,,,,,217.743209838867,221.372741699219,0,0,,,11.1249170303345,,1,0,0,0,0,31.7693061828613,2,1,1,217.427505493164,0,2085105664,219.61301352761,,,0.000169727361908775,5.86493717172189E-6,0.000169880948128618,5.86522363256994E-6,0.945279479026794,0.964129328727722,32.0615997314453,0,30,2,200,-0.00118181714788079,-0.251439809799194,0.481345683336258,2,,,,,,,,,,,,,,,,
,3869737330.21413,130.54411315918,0,,,6,,,,31.6121974588068,,,1,,,,,,,,,,,,,,,,,,,,,,128.479400634766,132.608825683594,0,0,,,10.6144142150879,,1,0,0,0,0.01861572265625,31.7693061828613,2,1,1,128.479400634766,0,2085105664,130.583282470703,,,0.000178719752560226,6.1705650992471E-6,0.000178722523312518,6.17057269325607E-6,0.963348627090454,0.963739633560181,31.5917472839355,0.130684807896614,30,2,200,-0.000598806655034423,-0.27514311671257,0.494747430086136,2,,,,,,,,,,,,,,,,
,3869737605.55009,35.900182723999,0,,,6,,,,31.3952713430772,,,1,,,,,,,,,,,,,,,,,,,,,,34.0931282043457,37.9304809570313,0,0,,,8.99700927734375,,1,0,0,0,0,31.2805480957031,2,1,1,33.7382965087891,0,2085105664,36.0248854955037,,,0.000184044572463285,6.36536267485599E-6,0.00018437258402993,6.36585559229975E-6,0.930883705615997,0.962836623191833,31.1719398498535,,30,2,200,-0.00164453778415918,-0.286563605070114,0.506052136421204,2,,,,,,,,,,,,,,,,
,3869737848.79226,9.93997240066528,0,,,6,,,,31.3193598857831,,,1,,,,,,,,,,,,,,,,,,,,,,9.89690494537353,9.9801607131958,0,0,,,5.64580488204956,,1,0,0,0,0.0138092041015625,30.7917900085449,6,1,1,9.98303985595703,0,2085105664,9.9468100865682,,,0.000186698575031435,6.45688483056802E-6,0.000187022541744117,6.45738988424892E-6,0.931487858295441,0.962677717208862,31.0992050170898,7.6418776512146,30,2,200,-0.00124612729996443,-0.294124156236649,0.509786486625671,2,,,,,,,,,,,,,,,,
,3869738022.93297,10.001238822937,0,,,6,,,,31.3193598857831,,,1,,,,,,,,,,,,,,,,,,,,,,9.9981164932251,10.0020036697388,0,0,,,5.40628242492676,,1,0,0,0,0.0138092041015625,31.2805480957031,1,1,1,10.0008277893066,0,2085105664,9.99994087219238,,,0.000186698633974212,6.45674159708417E-6,0.000187015875293263,6.45714535984502E-6,0.93181300163269,0.962732672691345,31.1005325317383,0,30,2,200,-0.000458579655969515,-0.296859174966812,0.506593823432922,2,,,,,,,,,,,,,,,,
,3869738194.90678,10.0017614364624,0,,,6,,,,31.3193598857831,,,1,,,,,,,,,,,,,,,,,,,,,,9.99810314178467,10.0022478103638,0,0,,,5.28986930847168,,1,0,0,0,0,30.7917900085449,1,1,1,10.0014171600342,0,2085105664,9.99996503194173,,,0.000186696707512755,6.45663345651133E-6,0.000187015780942424,6.45715237825924E-6,0.931909620761871,0.962694883346558,31.1010475158691,0,30,2,200,-0.00116226763930172,-0.299293458461761,0.504558682441711,2,,,,,,,,,,,,,,,,
,3869738367.14884,10.0011348724365,0,,,6,,,,31.3193598857831,,,1,,,,,,,,,,,,,,,,,,,,,,9.99759769439697,10.0019969940186,0,0,,,4.99257707595825,,1,0,0,0,0,31.2805480957031,1,1,1,10.001410484314,0,2085105664,9.99978335698446,,,0.000186694950949488,6.45654447974337E-6,0.000187011390743077,6.45700156577725E-6,0.931971371173859,0.96268767118454,31.1013488769531,3.39512298523914E-5,30,2,200,-0.00135456444695592,-0.30385634303093,0.499784737825394,2,,,,,,,,,,,,,,,,
,3869738552.37918,10.0008463859558,23366.5771484375,,,6,,,,31.3193598857831,,,1000,,,,,,,,,,,,,,,,,,,,,,9.9961519241333,10.0015478134155,21852.751953125,25002.912109375,,,4.94530200958252,,1,0,0,0,0,31.2805480957031,1,6,1,10.0004253387451,0,2085105664,9.99844487508138,,,0.0644736759369043,0.00227981615105152,0.0656453670901177,0.00228168470969483,0.781156718730926,0.879218101501465,30.6091785430908,0,30,2,200,0.226700738072395,-0.266139835119247,1.04116559028625,2,,,,,,,,,,,,,,,,
,3869741477.986,15.002772808075,0,,,6,,,,31.3127771022179,,,10,,,,,,,,,,,,,,,,,,,,,,14.9998216629028,15.0047740936279,0,0,,,5.37865591049194,,1,0,0,0,0,31.2805480957031,5,1,1,15.0013456344604,0,2085105664,15.0021122296651,,,0.000499794450776373,1.73785106442928E-5,0.000503463421166606,1.73839974908617E-5,0.876072824001312,0.961541414260864,30.8607368469238,0,30,2,200,0.000503390619996935,-0.241622358560562,-0.0193806979805231,2,,,,,,,,,,,,,,,,
,3869741681.26946,20.8925437927246,0,,,6,,,,31.3127771022179,,,10,,,,,,,,,,,,,,,,,,,,,,20.0165386199951,21.7208099365234,0,0,,,5.74713087081909,,1,0,0,0,0,31.2805480957031,6,1,1,21.7685489654541,0,2085105664,20.7860139211019,,,0.000465762250508984,1.61845937349559E-5,0.000468891687313612,1.61892360570195E-5,0.881378531455994,0.963248312473297,30.8799743652344,0,30,2,200,-0.000371494155842811,-0.223494052886963,-0.02205347456038,2,,,,,,,,,,,,,,,,
,3869741877.175,26.843017578125,0,,,6,,,,31.318251295659,,,10,,,,,,,,,,,,,,,,,,,,,,26.4964485168457,27.1748123168945,0,0,,,5.94279336929321,,1,0,0,0,0,31.7693061828613,2,1,1,27.1895866394043,0,2085105664,26.8947854042053,,,0.000441849349529722,1.53474002598794E-5,0.000444639138166455,1.53516127360928E-5,0.884817123413086,0.963725805282593,30.8988914489746,0,30,2,200,-0.000318598322337493,-0.215268403291702,-0.0240869745612144,2,,,,,,,,,,,,,,,,
,3869742073.91447,31.6607751846313,0,,,6,,,,31.3233083896862,,,10,,,,,,,,,,,,,,,,,,,,,,31.3163394927978,31.9943141937256,0,0,,,6.09033584594727,,1,0,0,0,0,31.2805480957031,2,1,1,32.0052108764648,0,2085105664,31.6974102656047,,,0.00042365659608496,1.47093188164838E-5,0.000426139980269013,1.47127696268606E-5,0.888466715812683,0.963990986347198,30.9184722900391,0,30,2,200,-0.000340251834131777,-0.210349857807159,-0.0272234417498112,2,,,,,,,,,,,,,,,,
,3869742271.11771,35.4867610931396,0,,,6,,,,31.3233083896862,,,10,,,,,,,,,,,,,,,,,,,,,,35.0003814697266,35.9731407165527,0,0,,,6.19261598587036,,1,0,0,0,0,31.2805480957031,6,1,1,35.9731407165527,0,2085105664,35.3724711491511,,,0.000408890665374523,1.41893157274839E-5,0.000411070450913651,1.41923843392355E-5,0.893141150474548,0.964187443256378,30.9372749328613,0,30,2,200,-0.000344380328897387,-0.206073716282845,-0.0295202899724245,2,,,,,,,,,,,,,,,,
,3869742466.23266,39.9860725402832,0,,,6,,,,31.3285110502165,,,10,,,,,,,,,,,,,,,,,,,,,,39.9807357788086,39.9904365539551,0,0,,,6.28114318847656,,1,0,0,0,0,32.7468223571777,5,1,1,39.9914093017578,0,2085105664,39.9862632751465,,,0.00039622264622108,1.374370643151E-5,0.000398154043328996,1.37463771021448E-5,0.897258162498474,0.964300990104675,30.9591293334961,0,30,2,200,-0.000374935858417302,-0.202827110886574,-0.0319089293479919,2,,,,,,,,,,,,,,,,
,3869742668.68524,44.5446548461914,0,,,6,,,,31.3336556676511,,,10,,,,,,,,,,,,,,,,,,,,,,44.410228729248,44.6565132141113,0,0,,,6.39729881286621,,1,0,0,0,0,31.2805480957031,6,1,1,44.6790809631348,0,2085105664,44.5348946253459,,,0.000387262339544239,1.34271684459145E-5,0.000388974056149682,1.34293850321652E-5,0.901464641094208,0.964427709579468,30.9813919067383,0,30,2,200,-0.00029367787647061,-0.200716450810432,-0.0336805544793606,2,,,,,,,,,,,,,,,,
,3869742858.78514,47.4868907928467,0,,,6,,,,31.3388419429559,,,10,,,,,,,,,,,,,,,,,,,,,,47.4823722839355,47.4904479980469,0,0,,,6.54025506973267,,1,0,0,0,0.0138092041015625,31.2805480957031,5,1,1,47.4914093017578,0,2085105664,47.4873895645142,,,0.00038062058337222,1.31930576545571E-5,0.000382193516440351,1.31952754135823E-5,0.904421210289001,0.964438915252686,30.9987964630127,0,30,2,200,-0.000341623555868864,-0.199042826890945,-0.0349511839449406,2,,,,,,,,,,,,,,,,
,3869743060.09304,52.4140491485596,0,,,6,,,,31.344232283183,,,10,,,,,,,,,,,,,,,,,,,,,,52.3883323669434,52.4376258850098,0,0,,,6.98337459564209,,1,0,0,0,0,31.2805480957031,5,1,1,52.4397659301758,0,2085105664,52.4153772989909,,,0.000373741450572573,1.29491401975287E-5,0.000375121348573064,1.29510626364033E-5,0.908907234668732,0.964532017707825,31.0226707458496,0.000196947046788409,30,2,200,-0.000278921128483489,-0.197362467646599,-0.0362927466630936,2,,,,,,,,,,,,,,,,
,3869743257.51953,56.8041305541992,0,,,6,,,,31.3497486721935,,,10,,,,,,,,,,,,,,,,,,,,,,56.6221580505371,56.9701385498047,0,0,,,7.7726902961731,,1,0,0,0,0,32.2580642700195,6,1,1,56.9861030578613,0,2085105664,56.8079891204834,,,0.000368897748573961,1.2777602048354E-5,0.000370143033777197,1.27791935511824E-5,0.91213446855545,0.964523434638977,31.0417251586914,0,30,2,200,-0.0003306778089609,-0.196328356862068,-0.0373650342226028,2,,,,,,,,,,,,,,,,
,3869743445.79945,59.9541282653809,0,,,6,,,,31.3497486721935,,,1,,,,,,,,,,,,,,,,,,,,,,59.9436645507812,59.9640922546387,0,0,,,8.01992225646973,,1,0,0,0,0,31.2805480957031,5,1,1,59.9645919799805,0,2085105664,59.9550663630168,,,0.000364044012102398,1.26049138577528E-5,0.000365139951928249,1.2606425240165E-5,0.916318893432617,0.964584052562714,31.0592575073242,,30,2,200,-0.00286399992182851,-1.95014798641205,0.7020383477211,2,,,,,,,,,,,,,,,,
,3869743644.74169,64.5621948242188,0,,,6,,,,31.3550306480822,,,1,,,,,,,,,,,,,,,,,,,,,,64.4570541381836,64.6597213745117,0,0,,,8.05906677246094,,1,0,0,0,0.0138092041015625,31.7693061828613,6,1,1,64.6673355102539,0,2085105664,64.5694618225098,,,0.000359304632433809,1.24369329167128E-5,0.000360271620988153,1.24383385632787E-5,0.920112431049347,0.964610755443573,31.0806198120117,0,30,2,200,-0.0027299290522933,-1.93555736541748,0.696255147457123,2,,,,,,,,,,,,,,,,
,3869743833.38948,67.4499397277832,0,,,6,,,,31.3600870210985,,,1,,,,,,,,,,,,,,,,,,,,,,67.4394607543945,67.4592056274414,0,0,,,8.0842170715332,,1,0,0,0,0,31.2805480957031,5,1,1,67.4604187011719,0,2085105664,67.4503790537516,,,0.000355213785052514,1.22929399536325E-5,0.000356094325460383,1.22941294874333E-5,0.922577857971191,0.964598178863525,31.0962982177734,0,30,2,200,-0.00326312007382512,-0.840497255325317,0.688693583011627,2,,,,,,,,,,,,,,,,
,3869744040.49674,72.0488815307617,0,,,6,,,,31.3704149244823,,,1,,,,,,,,,,,,,,,,,,,,,,71.9553833007812,72.1335830688477,0,0,,,8.12175369262695,,1,0,0,0,0,31.2805480957031,6,1,1,72.1423797607422,0,2085105664,72.0513165791829,,,0.000350724979623548,1.21351901763039E-5,0.000351521444113017,1.21362186311259E-5,0.925160646438599,0.964662849903107,31.1176452636719,0,30,2,200,-0.00258278544060886,-0.82315319776535,0.6870157122612,2,,,,,,,,,,,,,,,,
,3869744252.09355,75.0798377990723,0,,,6,,,,31.3755033985157,,,1,,,,,,,,,,,,,,,,,,,,,,74.9574432373047,75.1725234985352,0,0,,,8.15658092498779,,1,0,0,0,0,31.7693061828613,6,1,1,75.2022323608398,0,2085105664,75.0200635469877,,,0.000346586156300649,1.19897438166088E-5,0.000347304896805337,1.19906306811452E-5,0.927690267562866,0.964696705341339,31.1337585449219,0,30,2,200,-0.00267010414972901,-1.88026535511017,0.696035623550415,2,,,,,,,,,,,,,,,,
,3869744443.87951,79.4684600830078,0,,,6,,,,31.3809961126197,,,1,,,,,,,,,,,,,,,,,,,,,,79.3567123413086,79.5500564575195,0,0,,,8.19717121124268,,1,0,0,0,0.0138092041015625,31.7693061828613,6,1,1,79.580207824707,0,2085105664,79.4600205854936,,,0.000342103762499345,1.18316937545E-5,0.000342727595467828,1.18325988304196E-5,0.931255757808685,0.964708864688873,31.1550579071045,0,30,2,200,-0.00290754204615951,-1.84835934638977,0.708285868167877,2,,,,,,,,,,,,,,,,
,3869744630.24702,82.3805198669434,0,,,6,,,,31.3861249932217,,,1,,,,,,,,,,,,,,,,,,,,,,82.3586654663086,82.4001770019531,0,0,,,8.22274494171143,,1,0,0,0,0,31.7693061828613,5,1,1,82.4023742675781,0,2085105664,82.3812758127848,,,0.000338070880965567,1.16902605203733E-5,0.000338629625215035,1.16910935542697E-5,0.933715403079987,0.964753568172455,31.1711521148682,0,30,2,200,-0.00283729797229171,-1.83780479431152,0.700990676879883,2,,,,,,,,,,,,,,,,
,3869744822.43244,85.9212379455566,0,,,6,,,,31.39121913739,,,1,,,,,,,,,,,,,,,,,,,,,,85.6662139892578,86.1361770629883,0,0,,,8.24733924865723,,1,0,0,0,0,31.7693061828613,6,1,1,86.1762619018555,0,2085105664,85.9140535990397,,,0.000333901830520887,1.15436213495506E-5,0.000334382743303143,1.15444243844491E-5,0.937022149562836,0.964872062206268,31.1910495758057,0,30,2,200,-0.00217852066271007,-1.82855319976807,0.692328870296478,2,,,,,,,,,,,,,,,,
,3869745011.88349,89.6375846862793,0,,,6,,,,31.3965150397874,,,1,,,,,,,,,,,,,,,,,,,,,,89.5709991455078,89.6973114013672,0,0,,,8.261643409729,,1,0,0,0,0.0138092041015625,32.2580642700195,6,1,1,89.7041702270508,0,2085105664,89.6391531626383,,,0.000328694027450985,1.13611867568783E-5,0.00032909331433071,1.13617776346244E-5,0.940442264080048,0.964948177337646,31.2121601104736,0.200806766748428,30,2,200,-0.00267414539121091,-1.81330811977386,0.685050964355469,2,,,,,,,,,,,,,,,,
,3869745211.99762,92.5260734558105,0,,,6,,,,31.4067764241706,,,1,,,,,,,,,,,,,,,,,,,,,,92.4251174926758,92.5964736938477,0,0,,,8.2848014831543,,1,0,0,0,0.0138092041015625,31.2805480957031,6,1,1,92.6270294189453,0,2085105664,92.4813181559245,,,0.000323927318232895,1.1195110020128E-5,0.000324282714549534,1.11956258493626E-5,0.942442655563354,0.965119302272797,31.2314987182617,0.278753966093063,30,2,200,-0.00247103977017105,-0.716181397438049,0.677810609340668,2,,,,,,,,,,,,,,,,
,3869745401.83607,96.6612434387207,0,,,6,,,,31.4118623975919,,,1,,,,,,,,,,,,,,,,,,,,,,96.5256652832031,96.7870864868164,0,0,,,8.30174922943115,,1,0,0,0,0,31.2805480957031,6,1,1,96.7968215942383,0,2085105664,96.6605167388916,,,0.000318040967227641,1.09889528385207E-5,0.000318309622255218,1.09893160631117E-5,0.946910381317139,0.965371191501617,31.2578048706055,2.34240578720346E-5,30,2,200,-0.00240101525560021,-0.701998472213745,0.666471600532532,2,,,,,,,,,,,,,,,,
,3869745590.8153,99.7895927429199,0,,,6,,,,31.4169616336139,,,1,,,,,,,,,,,,,,,,,,,,,,99.7548980712891,99.8219985961914,0,0,,,8.31522178649902,,1,0,0,0,0.0138092041015625,31.7693061828613,5,1,1,99.8242874145508,0,2085105664,99.7894469041091,,,0.000312224111870449,1.0786054051024E-5,0.000312431297692735,1.07862985939127E-5,0.950354158878326,0.965566396713257,31.2800617218018,,30,2,200,-0.0026171188801527,-0.667114794254303,0.67585825920105,2,,,,,,,,,,,,,,,,
,3869745797.99,103.375797271729,0,,,6,,,,31.4270610249483,,,1,,,,,,,,,,,,,,,,,,,,,,103.148635864258,103.587348937988,0,0,,,8.3312349319458,,1,0,0,0,0,31.2805480957031,6,1,1,103.602958679199,0,2085105664,103.378705978394,,,0.000305716838305342,1.05596226785211E-5,0.000305873595426993,1.05597998583925E-5,0.953563868999481,0.965849220752716,31.3066482543945,7.6505880355835,30,2,200,-0.00250737182796001,-0.65095865726471,0.664587020874023,2,,,,,,,,,,,,,,,,
,3869745995.20966,107.137969970703,0,,,6,,,,31.4375498659704,,,1,,,,,,,,,,,,,,,,,,,,,,107.079956054688,107.192413330078,0,0,,,8.34745979309082,,1,0,0,0,0.0138092041015625,31.7693061828613,5,1,1,107.195983886719,0,2085105664,107.139839808146,,,0.000297304716374595,1.02674871573574E-5,0.000297411443027598,1.02675643445142E-5,0.956992983818054,0.966119945049286,31.3361797332764,,30,2,200,-0.00258963066153228,-0.625789701938629,0.653356909751892,2,,,,,,,,,,,,,,,,
,3869746197.43469,110.027359008789,0,,,6,,,,31.4427341172194,,,1,,,,,,,,,,,,,,,,,,,,,,109.91072845459,110.113586425781,0,0,,,8.36743068695068,,1,0,0,0,0.0138092041015625,31.2805480957031,6,1,1,110.143989562988,0,2085105664,109.975655873617,,,0.000289814991242162,1.00075487630301E-5,0.000289882359856298,1.00075739343877E-5,0.960068464279175,0.966305315494537,31.3607311248779,,30,2,200,-0.0025622732937336,-0.603613138198852,0.642991840839386,2,,,,,,,,,,,,,,,,
,3869746397.59371,114.230205535889,0,,,6,,,,31.4530043083231,,,1,,,,,,,,,,,,,,,,,,,,,,114.113967895508,114.338134765625,0,0,,,8.38145351409912,,1,0,0,0,0,31.2805480957031,6,1,1,114.34644317627,0,2085105664,114.231143951416,,,0.000278212992660934,9.60632970624742E-6,0.000278257954233894,9.60633966689088E-6,0.961634278297424,0.966070175170898,31.3844776153564,4.06556558609009,30,2,200,-0.00235054106451571,-0.571679890155792,0.625940501689911,2,,,,,,,,,,,,,,,,
,3869746590.24774,117.282764434814,0,,,6,,,,31.459038125299,,,1,,,,,,,,,,,,,,,,,,,,,,117.248657226563,117.314781188965,0,0,,,8.39091110229492,,1,0,0,0,0.015411376953125,31.2805480957031,5,1,1,117.316871643066,0,2085105664,117.285159428914,,,0.000265517543080381,9.16854994912258E-6,0.000265568223451286,9.16855655749067E-6,0.960041105747223,0.965114772319794,31.384449005127,1.25424872581581E-38,30,2,200,-0.00244525284506381,-0.532512366771698,0.609618067741394,2,,,,,,,,,,,,,,,,
,3869746808.17876,121.025524139404,0,,,6,,,,31.4702838756641,,,1,,,,,,,,,,,,,,,,,,,,,,120.82250213623,121.217300415039,0,0,,,8.40700435638428,,1,0,0,0,0,32.2580642700195,6,1,1,121.228546142578,0,2085105664,121.020590464274,,,0.000243167435742447,8.40025626323248E-6,0.000243296782885401,8.40036081045278E-6,0.950775802135468,0.962766647338867,31.3469314575195,,30,2,200,-0.00216927332803607,-0.466611295938492,0.579595327377319,2,,,,,,,,,,,,,,,,
,3869747004.10448,124.566131591797,0,,,6,,,,31.476744438452,,,1,,,,,,,,,,,,,,,,,,,,,,124.498817443848,124.629379272461,0,0,,,8.418532371521,,1,0,0,0,0,31.2805480957031,6,1,1,124.633445739746,0,2085105664,124.568639755249,,,0.000237345776605289,8.19889164205158E-6,0.000237463148523336,8.19902092828588E-6,0.951402246952057,0.962499499320984,31.3583011627197,0.171309575438499,30,2,200,-0.0019499936606735,-0.447890013456345,0.571833193302155,2,,,,,,,,,,,,,,,,
,3869747188.20566,127.333999633789,0,,,6,,,,31.4872143520266,,,1,,,,,,,,,,,,,,,,,,,,,,127.310241699219,127.356018066406,0,0,,,8.43518161773682,,1,0,0,0,0,32.7468223571777,5,1,1,127.357757568359,0,2085105664,127.335189819336,,,0.000234920915533584,8.11495470330531E-6,0.000235031281941611,8.1150735409874E-6,0.951845347881317,0.962443768978119,31.3717212677002,0.000199428293853998,30,2,200,-0.00195544958114624,-0.442054003477097,0.567362487316132,2,,,,,,,,,,,,,,,,
,3869747397.65239,131.047996520996,0,,,6,,,,31.498163237911,,,1,,,,,,,,,,,,,,,,,,,,,,130.854598999023,131.221496582031,0,0,,,8.43771266937256,,1,0,0,0,0,31.7693061828613,6,1,1,131.241394042969,0,2085105664,131.044848124186,,,0.00023277946326133,8.04050886403897E-6,0.000232875198041133,8.04063310438986E-6,0.95307594537735,0.962425649166107,31.390474319458,0,30,2,200,-0.0022556409239769,-0.438495278358459,0.561577558517456,2,,,,,,,,,,,,,,,,
,3869747593.41642,134.522422790527,0,,,6,,,,31.5036081255947,,,1,,,,,,,,,,,,,,,,,,,,,,134.450698852539,134.580017089844,0,0,,,8.43219089508057,,1,0,0,0,0,31.2805480957031,6,1,1,134.594146728516,0,2085105664,134.519399469549,,,0.000230940802823182,7.97634202469456E-6,0.000231017122041187,7.97645381452844E-6,0.954864144325256,0.962509632110596,31.4073085784912,4.07152891159058,30,2,200,-0.00198578019626439,-0.433322131633759,0.558759868144989,2,,,,,,,,,,,,,,,,
,3869747794.26479,137.359001159668,0,,,6,,,,31.5139419050629,,,1,,,,,,,,,,,,,,,,,,,,,,137.340042114258,137.37678527832,0,0,,,8.41079139709473,,1,0,0,0,0,31.2805480957031,6,1,1,137.377960205078,0,2085105664,137.360012054443,,,0.000229396159488709,7.92282270213518E-6,0.00022946624376399,7.92290809307148E-6,0.955344617366791,0.96250706911087,31.4209938049316,0,30,2,200,-0.00197458383627236,-0.430146664381027,0.555278420448303,2,,,,,,,,,,,,,,,,
,3869747995.7295,141.017311096191,0,,,6,,,,31.525473993804,,,1,,,,,,,,,,,,,,,,,,,,,,140.825744628906,141.189270019531,0,0,,,8.39985466003418,,1,0,0,0,0,32.2580642700195,6,1,1,141.208877563477,0,2085105664,141.01548131307,,,0.000227870803010123,7.86978644325704E-6,0.000227930195488126,7.869862205939E-6,0.956365466117859,0.962545454502106,31.4397048950195,5.60711193084717,30,2,200,-0.00195390824228525,-0.428425401449204,0.550369679927826,2,,,,,,,,,,,,,,,,
,3869748193.29284,144.507736206055,0,,,6,,,,31.5359686851218,,,1,,,,,,,,,,,,,,,,,,,,,,144.43342590332,144.576766967773,0,0,,,8.38286781311035,,1,0,0,0,0.0156402587890625,30.7917900085449,6,1,1,144.582046508789,0,2085105664,144.507556915283,,,0.000226369037787453,7.81764871513396E-6,0.000226419694485497,7.8177006214286E-6,0.957177221775055,0.962579905986786,31.4561977386475,1.18238775835784E-38,30,2,200,-0.00185250898357481,-0.424527138471603,0.548139154911041,2,,,,,,,,,,,,,,,,
,3869748382.88511,147.297348022461,0,,,6,,,,31.5417044802324,,,1,,,,,,,,,,,,,,,,,,,,,,147.267776489258,147.322326660156,0,0,,,8.33787155151367,,1,0,0,0,0,31.7693061828613,5,1,1,147.326919555664,0,2085105664,147.298161824544,,,0.000225072728740071,7.77252415148862E-6,0.000225113481712195,7.77258213672679E-6,0.958247780799866,0.962628662586212,31.4703712463379,7.65122556686401,30,2,200,-0.00213555688969791,-0.420109272003174,0.546794831752777,2,,,,,,,,,,,,,,,,
,3869748593.90419,150.745002746582,0,,,6,,,,31.5531072157107,,,1,,,,,,,,,,,,,,,,,,,,,,150.542999267578,150.933395385742,0,0,,,8.36678695678711,,1,0,0,0,0,31.7693061828613,6,1,1,150.95654296875,0,2085105664,150.749813079834,,,0.000223734205038776,7.72603858497558E-6,0.000223767128042246,7.72607812853499E-6,0.959064185619354,0.962688744068146,31.4885883331299,0,30,2,200,-0.00185719900764525,-0.418752104043961,0.542353928089142,2,,,,,,,,,,,,,,,,
,3869748790.14107,154.332527160645,0,,,6,,,,31.5638159758483,,,1,,,,,,,,,,,,,,,,,,,,,,154.237152099609,154.415542602539,0,0,,,8.43539142608643,,1,0,0,0,0,31.7693061828613,6,1,1,154.42790222168,0,2085105664,154.330060323079,,,0.000222348334582026,7.67795944685224E-6,0.000222374786482742,7.67799218235183E-6,0.959773063659668,0.962728559970856,31.5058326721191,0,30,2,200,-0.00179838563781232,-0.415377467870712,0.539661884307861,2,,,,,,,,,,,,,,,,
,3869748993.42927,157.300956726074,0,,,6,,,,31.5746332785778,,,1,,,,,,,,,,,,,,,,,,,,,,157.273452758789,157.327453613281,0,0,,,8.45391178131103,,1,0,0,0,0,31.7693061828613,5,1,1,157.330017089844,0,2085105664,157.303933461507,,,0.000221076811001741,7.6339093419188E-6,0.00022109964140712,7.63394373683071E-6,0.960244834423065,0.962807893753052,31.520824432373,0.00013801918248646,30,2,200,-0.00174963450990617,-0.412776589393616,0.536925494670868,2,,,,,,,,,,,,,,,,
,3869749202.33083,160.725677490234,0,,,6,,,,31.5852346206956,,,1,,,,,,,,,,,,,,,,,,,,,,160.511535644531,160.92219543457,0,0,,,8.44833850860596,,1,0,0,0,0.0138092041015625,32.2580642700195,6,1,1,160.939819335938,0,2085105664,160.720595041911,,,0.000219854260617106,7.59148832447542E-6,0.0002198703067067,7.59149406402241E-6,0.9609215259552,0.962812840938568,31.5392246246338,0,30,2,200,-0.00186135247349739,-0.412420213222504,0.531970739364624,2,,,,,,,,,,,,,,,,
,3869749398.84396,164.320533752441,0,,,6,,,,31.5970030773199,,,1,,,,,,,,,,,,,,,,,,,,,,164.230682373047,164.404525756836,0,0,,,8.43572425842285,,1,0,0,0,0,30.7917900085449,6,1,1,164.410385131836,0,2085105664,164.319666544596,,,0.000218538126826952,7.54587548325824E-6,0.000218550615835947,7.54589406287518E-6,0.961491048336029,0.962936162948608,31.5569667816162,0,30,2,200,-0.00176727504003793,-0.408908575773239,0.52975869178772,2,,,,,,,,,,,,,,,,
,3869749602.58791,167.29248046875,0,,,6,,,,31.6073417621049,,,1,,,,,,,,,,,,,,,,,,,,,,167.262649536133,167.322311401367,0,0,,,8.42801952362061,,1,0,0,0,0,31.2805480957031,5,1,1,167.322311401367,0,2085105664,167.295628474309,,,0.000217429446309443,7.50757187136032E-6,0.000217439418656176,7.50758431946258E-6,0.961580514907837,0.96274721622467,31.571346282959,0,30,2,200,-0.00212494004517794,-0.445876032114029,0.490635633468628,2,,,,,,,,,,,,,,,,
,3869749823.14595,170.93724822998,0,,,6,,,,31.6246398920441,,,1,,,,,,,,,,,,,,,,,,,,,,170.752426147461,171.108871459961,0,0,,,8.41655445098877,,1,0,0,0,0.0138092041015625,30.7917900085449,6,1,1,171.1220703125,0,2085105664,170.932516733805,,,0.000216131445693385,7.46263896018005E-6,0.000216139828639262,7.46265043190959E-6,0.961980700492859,0.962971925735474,31.5916023254395,0.000107598832983058,30,2,200,-0.00177078414708376,-0.446403533220291,0.482017397880554,2,,,,,,,,,,,,,,,,
,3869750029.36859,174.48624420166,0,,,6,,,,31.6348864785538,,,1,,,,,,,,,,,,,,,,,,,,,,174.417510986328,174.54621887207,0,0,,,8.39007091522217,,1,0,0,0,0.0138092041015625,31.2805480957031,6,1,1,174.554977416992,0,2085105664,174.485173543294,,,0.000214831715758049,7.41765645759581E-6,0.000214836737833637,7.41765908486969E-6,0.96235978603363,0.962975561618805,31.6089115142822,5.62218046188354,30,2,200,-0.00176609121263027,-0.442442983388901,0.48053577542305,2,,,,,,,,,,,,,,,,
,3869750228.97476,177.317016601562,0,,,6,,,,31.6461978454868,,,1,,,,,,,,,,,,,,,,,,,,,,177.293182373047,177.338241577148,0,0,,,8.39936828613281,,1,0,0,0,0,31.2805480957031,5,1,1,177.340850830078,0,2085105664,177.31878789266,,,0.00021374324671512,7.37999310258597E-6,0.000213746950106602,7.37999503793874E-6,0.962641179561615,0.963100135326386,31.623836517334,0,30,2,200,-0.00169898488093168,-0.439974367618561,0.478312999010086,2,,,,,,,,,,,,,,,,
,3869750456.7249,181.30884552002,0,,,6,,,,31.6626662128185,,,1,,,,,,,,,,,,,,,,,,,,,,181.157470703125,181.432189941406,0,0,,,8.40419292449951,,1,0,0,0,0,32.7468223571777,6,1,1,181.460220336914,0,2085105664,181.296221415202,,,0.000212468502344611,7.33594726844713E-6,0.000212471026434624,7.33595063899371E-6,0.962762057781219,0.96306961774826,31.6443729400635,1.18238775835784E-38,30,2,200,-0.0015781179536134,-0.451336890459061,0.461492329835892,2,,,,,,,,,,,,,,,,
,3869750658.32106,184.565872192383,0,,,6,,,,31.6743731530663,,,1,,,,,,,,,,,,,,,,,,,,,,184.504806518555,184.619354248047,0,0,,,8.41327095031738,,1,0,0,0,0,31.7693061828613,6,1,1,184.626937866211,0,2085105664,184.563866933187,,,0.000211328059884787,7.29652518710568E-6,0.000211329305140915,7.29652598747442E-6,0.962930262088776,0.963086366653442,31.66135597229,0,30,2,200,-0.00165406090673059,-0.45236924290657,0.455459624528885,2,,,,,,,,,,,,,,,,
,3869750880.21521,187.467208862305,0,,,6,,,,31.6856718707476,,,1,,,,,,,,,,,,,,,,,,,,,,187.387390136719,187.535125732422,0,0,,,8.42537879943848,,1,0,0,0,0,32.2580642700195,6,1,1,187.547027587891,0,2085105664,187.428892869216,,,0.000210223403246128,7.25834735401109E-6,0.000210223975911144,7.25834694212718E-6,0.963080048561096,0.963155329227448,31.6766452789307,,30,2,200,-0.00182160176336765,-0.449972152709961,0.45315432548523,2,,,,,,,,,,,,,,,,
,3869751083.33182,191.269554138184,0,,,6,,,,31.698114644034,,,1,,,,,,,,,,,,,,,,,,,,,,191.113723754883,191.420501708984,0,0,,,8.44448757171631,,1,0,0,0,0,29.8142719268799,6,1,1,191.425384521484,0,2085105664,191.278729756673,,,0.000209091401173226,7.21924037870012E-6,0.000209091409611179,7.219240180235E-6,0.963162064552307,0.963163912296295,31.696704864502,,30,2,200,-0.00173126382287592,-0.449549525976181,0.448501229286194,2,,,,,,,,,,,,,,,,
,3869751290.05357,194.587623596191,0,,,6,,,,31.7098571740165,,,1,,,,,,,,,,,,,,,,,,,,,,194.530029296875,194.641632080078,0,0,,,8.47275257110596,,1,0,0,0,0,31.2805480957031,6,1,1,194.645217895508,0,2085105664,194.592425028483,,,0.000207990023970777,7.18116081984703E-6,0.000207990150099997,7.18116232635322E-6,0.963344991207123,0.963355779647827,31.7132663726807,0.435273110866547,30,2,200,-0.0016790785593912,-0.44565948843956,0.448141664266586,2,,,,,,,,,,,,,,,,
,3869751506.95595,197.46541595459,0,,,6,,,,31.7213921919452,,,1,,,,,,,,,,,,,,,,,,,,,,197.381713867187,197.522933959961,0,0,,,8.50529003143311,,1,0,0,0,0,31.7693061828613,6,1,1,197.549118041992,0,2085105664,197.424889197716,,,0.000206977792152548,7.14622906888295E-6,0.000206978323574779,7.14623415428771E-6,0.963277578353882,0.963328063488007,31.7287654876709,,30,2,200,-0.00194457278121263,-0.444431096315384,0.444775968790054,2,,,,,,,,,,,,,,,,
,3869751721.17616,201.572547912598,0,,,6,,,,31.740550454353,,,1,,,,,,,,,,,,,,,,,,,,,,201.451782226562,201.67805480957,0,0,,,8.53948879241943,,1,0,0,0,0.017852783203125,31.7693061828613,6,1,1,201.693313598633,0,2085105664,201.57080968221,,,0.000205779091290853,7.10485433219642E-6,0.000205779893078859,7.10486035056036E-6,0.963241815567017,0.963324785232544,31.7500019073486,7.65369272232056,30,2,200,-0.0016379012959078,-0.44272717833519,0.441437751054764,2,,,,,,,,,,,,,,,,
,3869751927.57964,204.677093505859,0,,,6,,,,31.7522836550127,,,1,,,,,,,,,,,,,,,,,,,,,,204.634078979492,204.714782714844,0,0,,,8.54971885681152,,1,0,0,0,0,31.7693061828613,5,1,1,204.720108032227,0,2085105664,204.677625020345,,,0.000204671703889717,7.06664438894774E-6,0.000204673544302313,7.06665383661812E-6,0.963149905204773,0.963357925415039,31.7672595977783,0,30,2,200,-0.001789994770661,-0.439298123121262,0.440074175596237,2,,,,,,,,,,,,,,,,
,3869752138.06083,207.45027923584,0,,,6,,,,31.7629137827803,,,1,,,,,,,,,,,,,,,,,,,,,,207.375823974609,207.508117675781,0,0,,,8.55707740783691,,1,0,0,0,0.0138092041015625,31.7693061828613,6,1,1,207.52473449707,0,2085105664,207.417545025165,,,0.000203754519970876,7.03500834209496E-6,0.000203757777988895,7.03502287299809E-6,0.963028430938721,0.963406443595886,31.7831115722656,0,30,2,200,-0.00185911101289094,-0.439314514398575,0.436268925666809,2,,,,,,,,,,,,,,,,
,3869752342.67294,211.269035339355,0,,,6,,,,31.7810530351532,,,1,,,,,,,,,,,,,,,,,,,,,,211.122131347656,211.400619506836,0,0,,,8.56779766082764,,1,0,0,0,0,31.7693061828613,6,1,1,211.415939331055,0,2085105664,211.26859664917,,,0.000202718291705521,6.99923654359682E-6,0.000202722672729478,6.99925391535423E-6,0.963004231452942,0.963524222373962,31.8047256469727,0.130665466189384,30,2,200,-0.00183037563692778,-0.438791185617447,0.432179987430572,2,,,,,,,,,,,,,,,,
,3869752545.51038,214.530670166016,0,,,6,,,,31.797064212777,,,1,,,,,,,,,,,,,,,,,,,,,,214.468948364258,214.585433959961,0,0,,,8.58509731292725,,1,0,0,0,0,30.7917900085449,6,1,1,214.592391967773,0,2085105664,214.530874888102,,,0.000201725867468769,6.96500975243194E-6,0.000201730754260986,6.96503249899086E-6,0.962854087352753,0.963421881198883,31.8218402862549,0,30,2,200,-0.00165367324370891,-0.435258507728577,0.431714981794357,2,,,,,,,,,,,,,,,,
,3869752741.63073,217.288558959961,0,,,6,,,,31.8079562741669,,,1,,,,,,,,,,,,,,,,,,,,,,217.262588500977,217.311767578125,0,0,,,8.59644508361816,,1,0,0,0,0,30.3030319213867,5,1,1,217.314529418945,0,2085105664,217.290985107422,,,0.000200853874747741,6.93494410029018E-6,0.000200860132239233,6.93496036809864E-6,0.962687194347382,0.963466346263885,31.8370056152344,0,30,2,200,-0.00175629451405257,-0.433239042758942,0.430233865976334,2,,,,,,,,,,,,,,,,
,3869752962.39086,220.856658935547,0,,,6,,,,31.8248145187976,,,1,,,,,,,,,,,,,,,,,,,,,,220.665512084961,221.015655517578,0,0,,,8.61209583282471,,1,0,0,0,0,31.7693061828613,6,1,1,221.047805786133,0,2085105664,220.844223022461,,,0.000199871887787599,6.9010962797139E-6,0.000199880405143827,6.9011143233051E-6,0.962479472160339,0.963559627532959,31.8590469360352,0,30,2,200,-0.00169731874484569,-0.427589863538742,0.431284844875336,2,,,,,,,,,,,,,,,,
,3869753166.90237,224.376129150391,0,,,6,,,,31.8416890722448,,,1,,,,,,,,,,,,,,,,,,,,,,224.300216674805,224.447280883789,0,0,,,8.61952209472656,,1,0,0,0,0,32.7468223571777,6,1,1,224.457412719727,0,2085105664,224.378110249837,,,0.000198844247069057,6.86562632916093E-6,0.000198853877017961,6.86564701649535E-6,0.962435781955719,0.963663220405579,31.8781642913818,0,30,2,200,-0.00143446633592248,-0.424204051494598,0.430374383926392,2,,,,,,,,,,,,,,,,
,3869753365.37889,227.235862731934,0,,,6,,,,31.8531125887638,,,1,,,,,,,,,,,,,,,,,,,,,,227.200164794922,227.268524169922,0,0,,,8.6336841583252,,1,0,0,0,0,31.7693061828613,5,1,1,227.271560668945,0,2085105664,227.237937927246,,,0.00019795006589206,6.8348258736534E-6,0.000197962220748698,6.8348469292535E-6,0.962133407592773,0.96370404958725,31.8944454193115,0,30,2,200,-0.00152928102761507,-0.396800339221954,0.453985393047333,2,,,,,,,,,,,,,,,,
,3869753585.20442,230.493461608887,0,,,6,,,,31.8705264001606,,,1,,,,,,,,,,,,,,,,,,,,,,230.299514770508,230.671264648438,0,0,,,8.64815330505371,,1,0,0,0,0.0006866455078125,31.2805480957031,6,1,1,230.687408447266,0,2085105664,230.483378092448,,,0.000197059020919905,6.80411957026259E-6,0.000197072477299879,6.80414332977157E-6,0.96190881729126,0.963647067546845,31.9140968322754,0,30,2,200,-0.00134807976428419,-0.419423192739487,0.427574425935745,2,,,,,,,,,,,,,,,,
,3869753800.61173,234.358932495117,0,,,6,,,,31.8875169435682,,,1,,,,,,,,,,,,,,,,,,,,,,234.276885986328,234.427368164062,0,0,,,8.66871929168701,,1,0,0,0,0,31.7693061828613,6,1,1,234.440979003906,0,2085105664,234.357171376546,,,0.000196021999063371,6.7683897729606E-6,0.000196038454492486,6.76841201379908E-6,0.96161675453186,0.963775932788849,31.936128616333,0,30,2,200,-0.00137944717425853,-0.415795624256134,0.426545679569244,2,,,,,,,,,,,,,,,,
,3869753997.77851,237.211845397949,0,,,6,,,,31.8993233219229,,,1,,,,,,,,,,,,,,,,,,,,,,237.174026489258,237.245178222656,0,0,,,8.68701267242432,,1,0,0,0,0,31.7693061828613,5,1,1,237.249664306641,0,2085105664,237.212631225586,,,0.000195156746814394,6.73862156373489E-6,0.000195176081106523,6.73864769378304E-6,0.96119350194931,0.963725566864014,31.9521331787109,0.216425880789757,30,2,200,-0.0014666827628389,-0.412963539361954,0.425687551498413,2,,,,,,,,,,,,,,,,
,3869754204.50901,239.963287353516,0,,,6,,,,31.9111851804198,,,1,,,,,,,,,,,,,,,,,,,,,,239.883605957031,240.04296875,0,0,,,8.70873641967773,,1,0,0,0,0.0138092041015625,31.7693061828613,6,1,1,240.04296875,0,2085105664,239.932351919321,,,0.000194381852270206,6.71197845252353E-6,0.000194404697373795,6.71201570059436E-6,0.960756421089172,0.96371728181839,31.9684619903564,0,30,2,200,-0.00165615731384605,-0.413948595523834,0.421411961317062,2,,,,,,,,,,,,,,,,
,3869754408.71792,243.738723754883,0,,,6,,,,31.929825312692,,,1,,,,,,,,,,,,,,,,,,,,,,243.588119506836,243.868286132813,0,0,,,8.73533725738525,,1,0,0,0,0,31.7693061828613,6,1,1,243.88932800293,0,2085105664,243.739351908366,,,0.000193446424100841,6.67979701665196E-6,0.000193473060899078,6.67983828403778E-6,0.960331320762634,0.963792741298676,31.9918937683105,0,30,2,200,-0.00167964946012944,-0.428947687149048,0.417571723461151,2,,,,,,,,,,,,,,,,
,3869754613.30782,247.012214660645,0,,,6,,,,31.9478121204701,,,1,,,,,,,,,,,,,,,,,,,,,,246.946426391602,247.078002929687,0,0,,,8.75971221923828,,1,0,0,0,0,31.7693061828613,6,1,1,247.078002929687,0,2085105664,247.015278742864,,,0.000192498778778255,6.64709124194781E-6,0.000192526604156943,6.64713297147235E-6,0.960250377655029,0.963890254497528,32.0114593505859,0.000138455026899464,30,2,200,-0.00167604931630194,-0.427753865718842,0.39975643157959,2,,,,,,,,,,,,,,,,
,3869754809.49196,249.771324157715,0,,,6,,,,31.9593774299838,,,1,,,,,,,,,,,,,,,,,,,,,,249.742263793945,249.798461914062,0,0,,,8.77982044219971,,1,0,0,0,0,31.7693061828613,5,1,1,249.800384521484,0,2085105664,249.773742675781,,,0.000191657134257022,6.61819817249212E-6,0.000191689940128338,6.61824456598459E-6,0.95961594581604,0.963902056217194,32.0287170410156,0,30,2,200,-0.00150261435192078,-0.425355583429337,0.398296922445297,2,,,,,,,,,,,,,,,,
,3869755036.94703,253.350112915039,0,,,6,,,,31.982735899376,,,1,,,,,,,,,,,,,,,,,,,,,,253.167343139648,253.507049560547,0,0,,,8.82098007202148,,1,0,0,0,0,30.7917900085449,6,1,1,253.53288269043,0,2085105664,253.338499704997,,,0.000190734273493151,6.58632801201378E-6,0.000190767407011562,6.5863785366069E-6,0.95962518453598,0.963964581489563,32.0524749755859,0.155256479978561,30,2,200,-0.00152959860861301,-0.436948835849762,0.38293981552124,2,,,,,,,,,,,,,,,,
,3869755242.38005,256.837310791016,0,,,6,,,,31.9991213117691,,,1,,,,,,,,,,,,,,,,,,,,,,256.754028320313,256.914154052734,0,0,,,8.89083385467529,,1,0,0,0,0,31.2805480957031,6,1,1,256.920593261719,0,2085105664,256.838442484538,,,0.000189788740612813,6.55385048494634E-6,0.000189827279230441,6.55392409062021E-6,0.958985030651092,0.963955819606781,32.0740737915039,,30,2,200,-0.00162314914632589,-0.425514787435532,0.390208333730698,2,,,,,,,,,,,,,,,,
,3869755452.88965,259.77587890625,0,,,6,,,,32.0150575691418,,,1,,,,,,,,,,,,,,,,,,,,,,259.749267578125,259.799346923828,0,0,,,8.96947288513184,,1,0,0,0,0,31.7693061828613,5,1,1,259.802490234375,0,2085105664,259.776382446289,,,0.000188838874138343,6.5211336584702E-6,0.00018888071476961,6.52120087789427E-6,0.958674550056457,0.964139819145203,32.0937194824219,,30,2,200,-0.00148690084461123,-0.422797620296478,0.389214426279068,2,,,,,,,,,,,,,,,,
,3869755658.46137,262.707992553711,0,,,6,,,,32.0317052404736,,,1,,,,,,,,,,,,,,,,,,,,,,262.520843505859,262.874969482422,0,0,,,9.09356784820557,,1,0,0,0,0.0138092041015625,31.7693061828613,6,1,1,262.895141601562,0,2085105664,262.695411682129,,,0.000187919457949317,6.48957162697367E-6,0.000187967061365453,6.48965320150132E-6,0.957976937294006,0.96414977312088,32.1156768798828,0,30,2,200,-0.00163592747412622,-0.422964751720428,0.384964883327484,2,,,,,,,,,,,,,,,,
,3869755874.341,266.648544311523,0,,,6,,,,32.0538897170948,,,1,,,,,,,,,,,,,,,,,,,,,,266.547454833984,266.731872558594,0,0,,,9.26316738128662,,1,0,0,0,0,31.7693061828613,6,1,1,266.749633789062,0,2085105664,266.644643147786,,,0.000186691057928157,6.44733994045725E-6,0.000186745502625676,6.4474377101311E-6,0.957280278205872,0.964321076869965,32.1438636779785,0.130715161561966,30,2,200,-0.00135382357984781,-0.419829607009888,0.383231073617935,2,,,,,,,,,,,,,,,,
,3869756084.5549,269.700103759766,0,,,6,,,,32.0701585755041,,,1,,,,,,,,,,,,,,,,,,,,,,269.662292480469,269.733673095703,0,0,,,9.45877361297607,,1,0,0,0,0,31.7693061828613,5,1,1,269.739715576172,0,2085105664,269.701855977376,,,0.000185323686102681,6.40036762763425E-6,0.000185385492537686,6.40046816616237E-6,0.95637321472168,0.964379489421844,32.1666564941406,0.000161838048370555,30,2,200,-0.0013398602604866,-0.415281236171722,0.381990283727646,2,,,,,,,,,,,,,,,,
,3869756308.95527,272.718811035156,0,,,6,,,,32.0872812003716,,,1,,,,,,,,,,,,,,,,,,,,,,272.534332275391,272.889099121094,0,0,,,9.72403907775879,,1,0,0,0,0.0138092041015625,31.7693061828613,6,1,1,272.903289794922,0,2085105664,272.710934956868,,,0.000183680399869817,6.34407433807554E-6,0.000183756523526505,6.34424900574892E-6,0.954755425453186,0.964296758174896,32.1937065124512,0,30,2,200,-0.00135485827922821,-0.41225591301918,0.377839207649231,2,,,,,,,,,,,,,,,,
,3869756524.01403,276.631942749023,0,,,6,,,,32.1106892620977,,,1,,,,,,,,,,,,,,,,,,,,,,276.528015136719,276.725189208984,0,0,,,10.07763671875,,1,0,0,0,0,31.7693061828613,6,1,1,276.739624023438,0,2085105664,276.634023030599,,,0.000182415182063903,6.30083708189201E-6,0.000182505481104149,6.30103763437842E-6,0.953153252601624,0.964361727237701,32.2271270751953,7.64984083175659,30,2,200,-0.000394995819078758,-0.408634722232819,0.376154333353043,2,,,,,,,,,,,,,,,,
,3869756737.85553,279.697677612305,0,,,6,,,,32.127738598312,,,1,,,,,,,,,,,,,,,,,,,,,,279.658386230469,279.734283447266,0,0,,,10.4765176773071,,1,0,0,0,0.0138092041015625,31.7693061828613,5,1,1,279.736968994141,0,2085105664,279.701156616211,,,0.000181289231100373,6.26257204205767E-6,0.000181397577665309,6.26272923252388E-6,0.951078236103058,0.964634835720062,32.257194519043,0,30,2,200,-0.000871252967044711,-0.404197782278061,0.375875174999237,2,,,,,,,,,,,,,,,,
,3869756959.74372,282.73405456543,0,,,6,,,,32.1449175885498,,,1,,,,,,,,,,,,,,,,,,,,,,282.542327880859,282.898986816406,0,0,,,10.8888673782349,,1,0,0,0,0.0138092041015625,32.2580642700195,6,1,1,282.92578125,0,2085105664,282.725962320964,,,0.000180282230750477,6.22850862667106E-6,0.000180412418209178,6.22870487692649E-6,0.948770344257355,0.964695274829864,32.2870826721191,0,30,2,200,-0.00134779792279005,-0.403242975473404,0.372528880834579,2,,,,,,,,,,,,,,,,
,3869757174.42894,286.63493347168,0,,,6,,,,32.1695078088349,,,1,,,,,,,,,,,,,,,,,,,,,,286.525115966797,286.731048583984,0,0,,,11.2272529602051,,1,0,0,0,0.0138092041015625,30.7917900085449,6,1,1,286.749237060547,0,2085105664,286.630666097005,,,0.000179088086233934,6.18794540667015E-6,0.00017923843639564,6.18818370018025E-6,0.94663006067276,0.964640498161316,32.3226013183594,7.64658737182617,30,2,200,-0.00128101499285549,-0.400965988636017,0.370169788599014,2,,,,,,,,,,,,,,,,
,3869757385.52354,289.688293457031,0,,,6,,,,32.1859842535479,,,1,,,,,,,,,,,,,,,,,,,,,,289.649566650391,289.723266601562,0,0,,,11.0772180557251,,1,0,0,0,0,31.7693061828613,5,1,1,289.727020263672,0,2085105664,289.690190633138,,,0.000177870275890904,6.14677051358839E-6,0.000178048914220503,6.14707818031843E-6,0.943949580192566,0.964810431003571,32.3530540466309,0,30,2,200,-0.00124811858404428,-0.396616756916046,0.368952333927155,2,,,,,,,,,,,,,,,,
,3869757610.93762,292.726119995117,0,,,6,,,,32.205136717157,,,1,,,,,,,,,,,,,,,,,,,,,,292.542907714844,292.89306640625,0,0,,,11.0419120788574,,1,0,0,0,0.0138092041015625,32.2580642700195,6,1,1,292.909332275391,0,2085105664,292.712773640951,,,0.000176545577581898,6.10206716692417E-6,0.000176754214567336,6.10239297558867E-6,0.940903067588806,0.964752078056335,32.3868064880371,0,30,2,200,-0.00122858001850545,-0.394792944192886,0.36530539393425,2,,,,,,,,,,,,,,,,
,3869757826.97119,296.640731811523,0,,,6,,,,32.2306132596343,,,1,,,,,,,,,,,,,,,,,,,,,,296.538391113281,296.73291015625,0,0,,,11.1243276596069,,1,0,0,0,0.0138092041015625,31.7693061828613,6,1,1,296.743072509766,0,2084573184,296.639213562012,,,0.000174921620158582,6.04763065267203E-6,0.00017518083698933,6.04805390360959E-6,0.936360001564026,0.96484512090683,32.4337921142578,0,30,2,200,-0.00134477007668465,-0.391083329916,0.362627893686295,2,,,,,,,,,,,,,,,,
,3869758037.38715,299.689376831055,0,,,6,,,,32.2475167652862,,,1,,,,,,,,,,,,,,,,,,,,,,299.653961181641,299.723876953125,0,0,,,11.3217153549194,,1,0,0,0,0.0138092041015625,31.7693061828613,5,1,1,299.727844238281,0,2085105664,299.693491617839,,,0.000173105139277451,5.98692834469681E-6,0.00017342595155047,5.98745647597487E-6,0.931084215641022,0.964882671833038,32.4746398925781,0,30,2,200,-0.00101496244315058,-0.384673267602921,0.361730098724365,2,,,,,,,,,,,,,,,,
,3869758235.4152,299.990371704102,25000.2421875,,,6,,,,32.252551471328,,,100,,,,,,,,,,,,,,,,,,,,,,299.989929199219,299.996398925781,25000.2421875,25000.2421875,,,11.4638118743896,,1,0,0,0,0.0138092041015625,31.7693061828613,1,1,1,299.990814208984,0,2085105664,299.993222554525,,,0.0045982819213255,0.000158926147448104,0.00459839722771938,0.000158926422743012,0.941694259643555,0.942094624042511,32.2784996032715,,30,2,200,0.00483628502115607,-0.177523016929626,0.0538276955485344,2,,,,,,,,,,,,,,,,
,3869758472.6387,299.995315551758,0,,,6,,,,32.252551471328,,,1,,,,,,,,,,,,,,,,,,,,,,299.99609375,300.002563476562,0,0,,,11.5474128723145,,1,0,0,0,0.0138092041015625,32.2580642700195,1,1,1,299.994476318359,0,2085105664,299.998918013139,,,0.000268098688106532,9.26616097939686E-6,0.000268414229285214,9.26665138276975E-6,0.941484212875366,0.965611219406128,32.4338035583496,2.43671693169745E-5,30,2,200,-0.0203541032969952,-1.17683684825897,0.152350187301636,2,,,,,,,,,,,,,,,,
,3869758648.61023,299.996841430664,0,,,6,,,,32.252551471328,,,1,,,,,,,,,,,,,,,,,,,,,,299.995880126953,300.004669189453,0,0,,,11.5998477935791,,1,0,0,0,0,32.2580642700195,1,1,1,299.99560546875,0,2085105664,300.000091552734,,,0.000264875414831087,9.15529249671606E-6,0.000265205670164115,9.15581419807806E-6,0.940497875213623,0.965824604034424,32.4390525817871,0,30,2,200,-0.00614567985758185,-0.638411045074463,0.539829969406128,2,,,,,,,,,,,,,,,,
,3869758824.00528,299.999008178711,0,,,6,,,,32.252551471328,,,1,,,,,,,,,,,,,,,,,,,,,,299.998352050781,300.004760742188,0,0,,,11.643238067627,,1,0,0,0,7.62939453125E-5,32.7468223571777,1,1,1,299.998138427734,0,2085105664,300.001569112142,,,0.000261384686497973,9.03691156203727E-6,0.000261783802833726,9.03753864272036E-6,0.936418235301971,0.966274201869965,32.4589195251465,,30,2,200,-0.00290015805512667,-1.04021203517914,0.0946474820375443,2,,,,,,,,,,,,,,,,
,3869758998.7784,299.999908447266,0,,,6,,,,32.252551471328,,,1,,,,,,,,,,,,,,,,,,,,,,299.999359130859,300.005035400391,0,0,,,11.6763143539429,,1,0,0,0,0.0138092041015625,31.7693061828613,1,1,1,299.999389648438,0,2085105664,300.002184549967,,,0.000257510006151157,8.9037113884469E-6,0.000257926252777123,8.9043589796245E-6,0.93510490655899,0.966312706470489,32.4649276733398,,30,2,200,-0.00204105954617262,-1.14526462554932,-0.0340920016169548,2,,,,,,,,,,,,,,,,
,3869759173.28161,299.998733520508,0,,,6,,,,32.252551471328,,,1,,,,,,,,,,,,,,,,,,,,,,299.998504638672,300.002563476562,0,0,,,11.7034311294556,,1,0,0,0,0.0119781494140625,32.7468223571777,1,1,1,299.998687744141,0,2085105664,300.000666300456,,,0.000255633605598171,8.83997123377199E-6,0.000256082453761956,8.84067274225643E-6,0.933153867721558,0.966415464878082,32.4738464355469,0,30,2,200,-0.00176473276223987,-1.18600308895111,-0.0688897594809532,2,,,,,,,,,,,,,,,,
,3869759348.13381,299.997848510742,0,,,6,,,,32.252551471328,,,1,,,,,,,,,,,,,,,,,,,,,,299.997528076172,300.002166748047,0,0,,,11.7364778518677,,1,0,0,0,0.0138092041015625,32.2580642700195,1,1,1,299.997650146484,0,2085105664,299.999626159668,,,0.000254712221778037,8.80905253243417E-6,0.000255188582459996,8.80978342651324E-6,0.931573331356049,0.966509461402893,32.4810104370117,0,30,2,200,-0.00165405694860965,-1.18347835540771,-0.0864989310503006,2,,,,,,,,,,,,,,,,
,3869759523.38668,299.998565673828,0,,,6,,,,32.252551471328,,,1,,,,,,,,,,,,,,,,,,,,,,299.998443603516,300.00341796875,0,0,,,11.7673864364624,,1,0,0,0,0.0138092041015625,32.7468223571777,1,1,1,299.998352050781,0,2085105664,300.000966389974,,,0.000254207109817684,8.7922880405472E-6,0.000254704079599153,8.79307107679443E-6,0.9304159283638,0.966458439826965,32.4859886169434,0,30,2,200,-0.00159023492597044,-1.19245660305023,-0.0976901948451996,2,,,,,,,,,,,,,,,,
,3869759722.20344,299.996948242188,0,,,6,,,,32.252551471328,,,10,,,,,,,,,,,,,,,,,,,,,,299.995758056641,300.001800537109,0,0,,,11.7922267913818,,1,0,0,0,0.0138092041015625,31.7693061828613,1,1,1,299.99609375,0,2085105664,299.998537699382,,,0.000251749341690204,8.70958019683406E-6,0.000252311454563737,8.71044667772505E-6,0.926745116710663,0.966557741165161,32.502067565918,0.130926415324211,30,2,200,-0.000156926340423524,-0.135836854577065,-0.0273647401481867,2,,,,,,,,,,,,,,,,
,3869759897.8845,299.998016357422,0,,,6,,,,32.252551471328,,,10,,,,,,,,,,,,,,,,,,,,,,299.997863769531,300.003295898438,0,0,,,11.8007736206055,,1,0,0,0,0,31.7693061828613,1,1,1,299.997680664063,0,2085105664,300.000465393066,,,0.000251655022186151,8.70619745350006E-6,0.000252213437471803,8.70704972758461E-6,0.926925718784332,0.966589152812958,32.501407623291,5.7010006904602,30,2,200,-0.000160009120008908,-0.136673390865326,-0.0282741338014603,2,,,,,,,,,,,,,,,,
,3869760073.01143,299.998809814453,0,,,6,,,,32.252551471328,,,10,,,,,,,,,,,,,,,,,,,,,,299.998779296875,300.003784179687,0,0,,,11.8174438476563,,1,0,0,0,0,29.3255138397217,1,1,1,299.998840332031,0,2085105664,300.001235961914,,,0.000251522167546819,8.70175392616983E-6,0.000252086839308565,8.70264865260501E-6,0.926688611507416,0.96669739484787,32.5026092529297,0.130947604775429,30,2,200,-0.000164885554113425,-0.137170031666756,-0.0288220401853323,2,,,,,,,,,,,,,,,,
,3869760248.53263,299.997100830078,0,,,6,,,,32.252551471328,,,10,,,,,,,,,,,,,,,,,,,,,,299.996765136719,300.002319335937,0,0,,,11.8312740325928,,1,0,0,0,0,31.7693061828613,1,1,1,299.996612548828,0,2085105664,299.999450683594,,,0.000251457189801667,8.6996060157345E-6,0.000252024700930281,8.70049842041154E-6,0.926529407501221,0.966707468032837,32.503303527832,0,30,2,200,-0.000152510372572578,-0.137381672859192,-0.029037106782198,2,,,,,,,,,,,,,,,,
,3869760424.32177,299.998657226562,0,,,6,,,,32.252551471328,,,10,,,,,,,,,,,,,,,,,,,,,,299.997589111328,300.003662109375,0,0,,,11.8378353118896,,1,0,0,0,0,32.2580642700195,1,1,1,299.997772216797,0,2085105664,300.000452677409,,,0.000251348157117043,8.69608258961595E-6,0.000251921841408129,8.69696198939163E-6,0.926146388053894,0.966664552688599,32.5048789978027,0,30,2,200,-0.000160254538059235,-0.13782112300396,-0.0295304227620363,2,,,,,,,,,,,,,,,,
,3869760607.18138,299.997619628906,0,,,6,,,,32.2575646006414,,,1,,,,,,,,,,,,,,,,,,,,,,299.996826171875,300.002868652344,0,0,,,11.8432016372681,,1,0,0,0,0,30.7917900085449,1,1,1,299.996551513672,0,2085105664,299.999425252279,,,0.000251274624985182,8.69288225154478E-6,0.00025183000183724,8.69376751450739E-6,0.927172601222992,0.966752409934998,32.5056304931641,0,30,2,200,-0.00138881825841963,-1.38210010528564,-0.299826115369797,2,,,,,,,,,,,,,,,,
,3869760781.44473,299.997573852539,0,,,6,,,,32.2575646006414,,,1,,,,,,,,,,,,,,,,,,,,,,299.996917724609,300.002258300781,0,0,,,11.8611793518066,,1,0,0,0,0.0138092041015625,30.3030319213867,1,1,1,299.997100830078,0,2085105664,299.999603271484,,,0.000251193828055678,8.69023982534458E-6,0.000251752145970705,8.69107988153002E-6,0.926932215690613,0.96675044298172,32.5066795349121,0,30,2,200,-0.00127560761757195,-1.38543796539307,-0.303475081920624,2,,,,,,,,,,,,,,,,
,3869760962.33457,299.997741699219,0,,,6,,,,32.2575646006414,,,10,,,,,,,,,,,,,,,,,,,,,,299.996917724609,300.003540039063,0,0,,,11.8831472396851,,1,0,0,0,0.0138092041015625,31.7693061828613,1,1,1,299.996948242188,0,2085105664,300.00010172526,,,0.000250765070277549,8.67703803820477E-6,0.000251371912250044,8.67794972675664E-6,0.924419820308685,0.966770768165588,32.5174713134766,0,30,2,200,-0.000141758864629082,-0.133270412683487,-0.0252029486000538,2,,,,,,,,,,,,,,,,