File: Chapter5/lowT/LG12_HYS_4K.dat
[Header]
; MPMS3 Data File (default extension .dat)
; Copyright (c) 2007, Quantum Design, Inc. All rights reserved.
TITLE,
FILEOPENTIME,3886905226.6192,03/02/2023,7:53 am
BYAPP,MPMS3 w/ AC,1.0,1.1
INFO,MPMS3 Measurement Release 1.1.16 Build 424, MultiVu Release 2.3.4.26,APPNAME
INFO,Linear Motor Servo Controller,MOTOR_MODULE_NAME
INFO,3101-100 N0,MOTOR_HW_VERSION
INFO,MMC1047,MOTOR_SERIAL_NUMBER
INFO,01.04.28,MOTOR_SOFTWARE_VERSION
INFO,Quantum Design Squid Module,SQUID_MODULE_NAME
INFO,3101-501 B0,SQUID_HW_VERSION
INFO,SQM278,SQUID_SERIAL_NUMBER
INFO,01.03.04,SQUID_SOFTWARE_VERSION
INFO,Quantum Design VSM Oven,OVEN_MODULE_NAME
INFO,3101-201 A3,OVEN_HW_VERSION
INFO,OVB323,OVEN_SERIAL_NUMBER
INFO,01.07.07,OVEN_SOFTWARE_VERSION
INFO,SQUID AC,AC_MODULE_NAME
INFO,3101-401 G0,AC_HW_VERSION
INFO,SAC258,AC_SERIAL_NUMBER
INFO,SQUID AC 00.95.07,AC_SOFTWARE_VERSION
INFO,TCI408,COIL_SERIAL_NUMBER
INFO,0,MOMENT_UNITS
INFO,C3,SAMPLE_MATERIAL
INFO,,SAMPLE_COMMENT
INFO,,SAMPLE_MASS
INFO,,SAMPLE_VOLUME
INFO,,SAMPLE_MOLECULAR_WEIGHT
INFO,,SAMPLE_SIZE
INFO,,SAMPLE_SHAPE
INFO,Straw,SAMPLE_HOLDER
INFO,Standard,SAMPLE_HOLDER_DETAIL
INFO,66.62,SAMPLE_OFFSET
DATATYPE,COMMENT,1
DATATYPE,TIME,2
STARTUPAXIS,X,2
STARTUPAXIS,Y1,5
FIELDGROUP, VSM,2,3,4,5,6,8,9,10,11,14,15
FIELDGROUP, DC, 2,3,4,14,56,57,58,59,60,61,62,63,64,65,66,67,68,69
FIELDGROUP, AC, 2,3,4,11,16,17,18,19,20,21,22,23,24,25,26,27,28,29,30
STARTUPGROUP, All
[Data]
Comment,Time Stamp (sec),Temperature (K),Magnetic Field (Oe),Moment (emu),M. Std. Err. (emu),Transport Action,Averaging Time (sec),Frequency (Hz),Peak Amplitude (mm),Center Position (mm),Lockin Signal' (V),Lockin Signal (V),Range,M. Quad. Signal (emu),AC Moment (emu),AC M. Std Err. (emu),AC Phase (deg),AC Phase Std. Err. (deg),AC Susceptibility (emu/Oe),AC Suscept. Std Err. (emu/Oe),AC X' (emu/Oe),AC X' Std Err. (emu/Oe),AC X'' (emu/Oe),AC X'' Std Err. (emu/Oe),AC Drive (Oe),AC Frequency (Hz),AC Averaging Time (sec),AC Cycles,AC Range,AC Measure Type,AC Signal' (V),AC Signal'' (V),AC Trim Coil Ratio,AC Trim Coil Phase,Min. Temperature (K),Max. Temperature (K),Min. Field (Oe),Max. Field (Oe),Mass (grams),Motor Lag (deg),Pressure (Torr),Measure Count,Measurement Number,SQUID Status (code),Motor Status (code),Measure Status (code),Motor Current (amps),Motor Temp. (C),Temp. Status (code),Field Status (code),Chamber Status (code),Chamber Temp (K),Redirection State,Evercool Status,Average Temp (K),Rotation Angle (deg),Rotator state,DC Moment Fixed Ctr (emu),DC Moment Err Fixed Ctr (emu),DC Moment Free Ctr (emu),DC Moment Err Free Ctr (emu),DC Fixed Fit,DC Free Fit,DC Calculated Center (mm),DC Calculated Center Err (mm),DC Scan Length (mm),DC Scan Time (s),DC Number of Points,DC Squid Drift,DC Min V (V),DC Max V (V),DC Scans per Measure,Map 01,Map 02,Map 03,Map 04,Map 05,Map 06,Map 07,Map 08,Map 09,Map 10,Map 11,Map 12,Map 13,Map 14,Map 15,Map 16
,3886905234.95183,299.778259277344,0.00121735187713057,,,6,,,,34.5993407385358,,,10,,,,,,,,,,,,,,,,,,,,,,299.685333251953,299.891296386719,0.00121735187713057,0.00121735187713057,,,9.83629322052002,,1,0,0,0,0.013885498046875,29.3255138397217,6,1,1,299.676483154297,0,4232056832,299.834392841046,,,0.000318510958074181,1.12314171097256E-5,0.000318627070113751,1.12316610903141E-5,0.931684255599976,0.936877191066742,34.7003479003906,8.67290291353129E-5,30,2,200,-2.36306004808284E-6,-0.148820206522942,-0.011359334923327,2,,,,,,,,,,,,,,,,
,3886905404.46438,248.376472473145,0.00121735187713057,,,6,,,,34.3632171254504,,,10,,,,,,,,,,,,,,,,,,,,,,246.045883178711,250.707061767578,0.00121735187713057,0.00121735187713057,,,9.77821636199951,,1,0,0,0,0.013885498046875,29.3255138397217,2,1,1,246.045883178711,0,4232056832,248.291180928548,,,0.000330206116424115,1.16405159516124E-5,0.00033022771793403,1.1640570199775E-5,0.935949325561523,0.936901092529297,34.4057426452637,7.49648427963257,30,2,200,-0.000262921646935865,-0.152473658323288,-0.0107560567557812,2,,,,,,,,,,,,,,,,
,3886905581.86747,187.599479675293,0.00121735187713057,,,6,,,,34.1328316134939,,,10,,,,,,,,,,,,,,,,,,,,,,185.878189086914,189.554046630859,0.00121735187713057,0.00121735187713057,,,9.51321411132813,,1,0,0,0,0.013885498046875,28.8367557525635,2,1,1,185.644912719727,0,4232056832,187.721070607503,,,0.000335728736426013,1.18356789477349E-5,0.000335780226040425,1.18357392911056E-5,0.935320317745209,0.937645018100739,34.0664100646973,0,30,2,200,-0.000292802549665794,-0.153413385152817,-0.00930468365550041,2,,,,,,,,,,,,,,,,
,3886905758.51066,128.608139038086,0.00121735187713057,,,6,,,,33.9520943431569,,,10,,,,,,,,,,,,,,,,,,,,,,126.953979492187,130.512420654297,0.00121735187713057,0.00121735187713057,,,9.19063472747803,,1,0,0,0,0.013885498046875,29.3255138397217,2,1,1,126.703857421875,0,4232056832,128.768848419189,,,0.000320346468053766,1.13053489320975E-5,0.000320782040373604,1.13059181784601E-5,0.920705199241638,0.939305007457733,33.7549591064453,,30,2,200,2.70935488515534E-5,-0.148561730980873,-0.0105415591970086,2,,,,,,,,,,,,,,,,
,3886905935.48372,68.5038261413574,0.00121735187713057,,,6,,,,33.8040680838051,,,10,,,,,,,,,,,,,,,,,,,,,,66.6276397705078,70.592643737793,0.00121735187713057,0.00121735187713057,,,8.73876571655273,,1,0,0,0,0.013885498046875,28.8367557525635,2,1,1,66.4150085449219,0,4232056832,68.5857944488525,,,0.000259939366193672,9.19142816044957E-6,0.000260862187408945,9.19289202692919E-6,0.899224698543549,0.941412687301636,33.4873046875,0,30,2,200,-0.000211407837923616,-0.129732698202133,-0.0178051013499498,2,,,,,,,,,,,,,,,,
,3886906113.24861,10.0431714057922,0.00121735187713057,,,6,,,,33.696271135026,,,10,,,,,,,,,,,,,,,,,,,,,,9.92768001556397,10.0960111618042,0.00121735187713057,0.00121735187713057,,,6.59873628616333,,1,0,0,0,0,28.8367557525635,6,1,1,9.9904146194458,0,4232056832,9.98228136698405,,,0.000260957049327032,9.2398766094877E-6,0.00026227278958354,9.24191923105215E-6,0.886751353740692,0.942674100399017,33.3189849853516,1.61226598720532E-5,30,2,200,-0.000196129738469608,-0.129997745156288,-0.0174333266913891,2,,,,,,,,,,,,,,,,
,3886906259.7363,9.94138479232788,0.00121735187713057,,,6,,,,33.6636719639605,,,10,,,,,,,,,,,,,,,,,,,,,,9.89643955230713,9.98434162139893,0.00121735187713057,0.00121735187713057,,,5.4864821434021,,1,0,0,0,0,28.8367557525635,6,1,1,9.98633003234863,0,4232056832,9.94931085904439,,,0.000261023252576943,9.23968287863075E-6,0.00026226914670465,9.24171325679187E-6,0.889173746109009,0.942824125289917,33.2969284057617,0,30,2,200,-0.000179605121957138,-0.129822388291359,-0.0173336286097765,2,,,,,,,,,,,,,,,,
,3886906368.51904,10.0002479553223,0.00121735187713057,,,6,,,,33.6636719639605,,,10,,,,,,,,,,,,,,,,,,,,,,9.99813652038574,10.0023374557495,0.00121735187713057,0.00121735187713057,,,5.41125679016113,,1,0,0,0,0,29.3255138397217,1,1,1,10.0000944137573,0,4232056832,10.0000843207041,,,0.000261024221675496,9.23952108058451E-6,0.000262263564270052,9.2415292497746E-6,0.889367580413818,0.942809045314789,33.2978401184082,0,30,2,200,-0.00015638506738469,-0.129825562238693,-0.0173025950789452,2,,,,,,,,,,,,,,,,
,3886906476.74512,3.10168933868408,0.00121735187713057,,,6,,,,33.6636719639605,,,10,,,,,,,,,,,,,,,,,,,,,,2.996248960495,3.20096731185913,0.00121735187713057,0.00121735187713057,,,3.44862651824951,,1,0,0,0,0,28.8367557525635,2,1,1,3.00156688690186,0,4232056832,3.02847093343735,,,0.000257969931276126,9.13239672839211E-6,0.000259226955579226,9.13445013260552E-6,0.888401746749878,0.942948639392853,33.2931861877441,0,30,2,200,-0.000163727818289772,-0.128824293613434,-0.0175711736083031,2,,,,,,,,,,,,,,,,
,3886906586.15779,3.00189101696014,0.00121735187713057,,,6,,,,33.6636719639605,,,10,,,,,,,,,,,,,,,,,,,,,,2.9952666759491,3.00370478630066,0.00121735187713057,0.00121735187713057,,,3.35775828361511,,1,0,0,0,0,30.3030319213867,1,1,1,3.00239729881287,0,4232056832,3.00007190306981,,,0.000257981555959996,9.1327708236243E-6,0.000259234479278769,9.13476181262741E-6,0.888434886932373,0.942853450775146,33.2935485839844,0,30,2,200,-0.000196937922737561,-0.128733932971954,-0.0175096616148949,2,,,,,,,,,,,,,,,,
,3886906694.59392,3.00204420089722,0.00121735187713057,,,6,,,,33.6636719639605,,,10,,,,,,,,,,,,,,,,,,,,,,2.99529600143433,3.00378918647766,0.00121735187713057,0.00121735187713057,,,3.32344675064087,,1,0,0,0,0,28.8367557525635,1,1,1,3.00159811973572,0,4232056832,3.00000923871994,,,0.000257964032160908,9.13212319776552E-6,0.000259222039707165,9.13426635033343E-6,0.888461649417877,0.942963242530823,33.2933692932129,0,30,2,200,-0.000176485787960701,-0.128772631287575,-0.0175588149577379,2,,,,,,,,,,,,,,,,
,3886906803.32444,3.00089848041534,0.00121735187713057,,,6,,,,33.6636719639605,,,10,,,,,,,,,,,,,,,,,,,,,,2.99512505531311,3.00342082977295,0.00121735187713057,0.00121735187713057,,,3.29916191101074,,1,0,0,0,0,28.8367557525635,1,1,1,3.00218749046326,0,4232057536,2.99961372216543,,,0.000257962443744487,9.1321798664843E-6,0.000259222237713324,9.1343089260206E-6,0.88835883140564,0.94290816783905,33.2930564880371,0,30,2,200,-0.000189660378964618,-0.128753438591957,-0.017493050545454,2,,,,,,,,,,,,,,,,
,3886906912.59222,3.00250363349915,0.00121735187713057,,,6,,,,33.6636719639605,,,10,,,,,,,,,,,,,,,,,,,,,,2.99355053901672,3.00734853744507,0.00121735187713057,0.00121735187713057,,,3.27588367462158,,1,0,0,0,0,29.3255138397217,1,1,1,3.00338435173035,0,4232057696,3.00149416923523,,,0.00025795610004566,9.13188172890276E-6,0.000259212989628044,9.13397450131323E-6,0.888426661491394,0.94291764497757,33.2933235168457,0,30,2,200,-0.000171498773852363,-0.128781974315643,-0.0175511464476585,2,,,,,,,,,,,,,,,,
,3886907020.84938,3.00221621990204,0.00121735187713057,,,6,,,,33.6636719639605,,,10,,,,,,,,,,,,,,,,,,,,,,2.99426341056824,3.0041298866272,0.00121735187713057,0.00121735187713057,,,3.25187802314758,,1,0,0,0,0,28.8367557525635,5,1,1,3.00368452072144,0,4232057664,2.99947357177734,,,0.000257967624897433,9.13229188183865E-6,0.000259224305317545,9.13438247468657E-6,0.888424754142761,0.942900478839874,33.2933769226074,,30,2,200,-0.00019827474898193,-0.128809824585915,-0.0175841264426708,2,,,,,,,,,,,,,,,,
,3886907182.04306,3.00375604629517,15000.43359375,,,6,,,,33.6636719639605,,,100,,,,,,,,,,,,,,,,,,,,,,2.99349641799927,3.00479006767273,15000.43359375,15000.43359375,,,3.20379137992859,,1,0,0,0,0,28.8367557525635,1,1,1,3.00409078598022,0,4232056832,3.00029477808211,,,0.0915762773812569,0.00322819200154343,0.0915787350894483,0.00322819575147467,0.936334788799286,0.936737716197967,33.6360092163086,0,30,2,200,-0.00639241049066186,-4.72541952133179,4.52725172042847,2,,,,,,,,,,,,,,,,
,3886907398.3891,3.00407767295837,14226.671875,,,6,,,,33.6636719639605,,,1000,,,,,,,,,,,,,,,,,,,,,,2.9937732219696,3.00463891029358,14226.671875,14226.671875,,,3.15726280212402,,1,0,0,0,0,28.8367557525635,1,1,1,3.00461888313293,0,4232057568,3.00035212437312,,,0.0888272305862706,0.00313129124705583,0.0888300270607189,0.00313129644660867,0.936297595500946,0.936765551567078,33.633861541748,7.49602651596069,30,2,200,-0.000329020345816389,-0.336512595415115,0.0451123341917992,2,,,,,,,,,,,,,,,,
,3886907610.34942,3.0034556388855,13453.0576171875,,,6,,,,33.6636719639605,,,1000,,,,,,,,,,,,,,,,,,,,,,2.9945170879364,3.00491309165955,13453.0576171875,13453.0576171875,,,3.12422370910645,,1,0,0,0,0,27.8592376708984,1,1,1,3.00366044044495,0,4232057920,3.00041337807973,,,0.0859535780644858,0.00303001094189648,0.0859565438477556,0.0030300159165445,0.936188161373138,0.936703145503998,33.6323776245117,5.21676847711206E-5,30,2,200,-0.00044641163549386,-0.325647085905075,0.0438649281859398,2,,,,,,,,,,,,,,,,
,3886907826.60863,3.00377440452576,12679.41796875,,,6,,,,33.6636719639605,,,1000,,,,,,,,,,,,,,,,,,,,,,2.99490022659302,3.00480341911316,12679.41796875,12679.41796875,,,3.09922623634338,,1,0,0,0,0,28.8367557525635,1,1,1,3.00386929512024,0,4232057600,3.00030263264974,,,0.0829844845104834,0.00292536371878196,0.0829876341647691,0.00292536841852575,0.936098158359528,0.936667144298553,33.6307601928711,,30,2,200,-0.000412462337408215,-0.314513832330704,0.0421605557203293,2,,,,,,,,,,,,,,,,
,3886908040.91492,3.00391161441803,11905.7421875,,,6,,,,33.6636719639605,,,1000,,,,,,,,,,,,,,,,,,,,,,2.99500465393066,3.00454115867615,11905.7421875,11905.7421875,,,3.08196878433228,,1,0,0,0,0,29.8142719268799,1,1,1,3.00418281555176,0,4232057920,3.00068120161692,,,0.079915688862707,0.00281719066959662,0.0799189819854239,0.00281719467651028,0.93604850769043,0.936671137809753,33.6292419433594,0,30,2,200,-0.000372372916899622,-0.302897602319717,0.0406619347631931,2,,,,,,,,,,,,,,,,
,3886908257.32139,3.00376880168915,11132.1533203125,,,6,,,,33.6636719639605,,,1000,,,,,,,,,,,,,,,,,,,,,,2.99431562423706,3.00459432601929,11132.1533203125,11132.1533203125,,,3.07018208503723,,1,0,0,0,0,28.8367557525635,1,1,1,3.0041983127594,0,4232058048,3.00033100446065,,,0.0767376317120073,0.00270517369986322,0.0767410803870806,0.00270517787129787,0.935963273048401,0.936641871929169,33.6277122497559,0,30,2,200,-0.00042262562783435,-0.290579378604889,0.0386238545179367,2,,,,,,,,,,,,,,,,
,3886908473.77534,3.00286424160004,10358.4033203125,,,6,,,,33.6636719639605,,,1000,,,,,,,,,,,,,,,,,,,,,,2.99472498893738,3.00437116622925,10358.4033203125,10358.4033203125,,,3.05923676490784,,1,0,0,0,0,29.3255138397217,1,1,1,3.00278735160828,0,4232057888,3.00041327873866,,,0.0734448989885056,0.00258910850765647,0.0734484964327646,0.00258911292134414,0.935891687870026,0.936630368232727,33.6261405944824,5.79880523681641,30,2,200,-0.000334477779688314,-0.27800926566124,0.0372567214071751,2,,,,,,,,,,,,,,,,
,3886908688.91696,3.00392532348633,9584.703125,,,6,,,,33.6636719639605,,,1000,,,,,,,,,,,,,,,,,,,,,,2.99412083625793,3.004230260849,9584.703125,9584.703125,,,3.05315065383911,,1,0,0,0,0,28.8367557525635,1,1,1,3.00384926795959,0,4232057696,3.00004024939104,,,0.070034902259905,0.00246891273772748,0.0700387136657063,0.00246891903056702,0.935803711414337,0.936613500118256,33.6243553161621,0,30,2,200,-0.000363177445251495,-0.265522181987762,0.0358576811850071,2,,,,,,,,,,,,,,,,
,3886908903.11199,3.00330018997192,8811.1259765625,,,6,,,,33.6636719639605,,,1000,,,,,,,,,,,,,,,,,,,,,,2.99413847923279,3.0043797492981,8811.1259765625,8811.1259765625,,,3.04660606384277,,1,0,0,0,0,28.8367557525635,1,1,1,3.00343894958496,0,4232057856,3.00051208337148,,,0.0664899438200508,0.00234395685576371,0.0664938828211037,0.00234396206543571,0.935704052448273,0.936593353748322,33.6224517822266,0,30,2,200,-0.000304646557196975,-0.251842856407166,0.0338749513030052,2,,,,,,,,,,,,,,,,
,3886909116.42235,3.00366997718811,8037.4384765625,,,6,,,,33.6636719639605,,,1000,,,,,,,,,,,,,,,,,,,,,,2.99463295936584,3.00456666946411,8037.4384765625,8037.4384765625,,,3.04357147216797,,1,0,0,0,0,28.8367557525635,1,1,1,3.00470948219299,0,4232057728,3.00042341152827,,,0.0628028556059318,0.0022139920975442,0.0628070138710609,0.00221399866799981,0.935604631900787,0.936590254306793,33.6202583312988,0,30,2,200,-0.000222579968976788,-0.238233789801598,0.0323314294219017,2,,,,,,,,,,,,,,,,
,3886909332.66965,3.00358188152313,7264.05859375,,,6,,,,33.6636719639605,,,1000,,,,,,,,,,,,,,,,,,,,,,2.99384903907776,3.00408411026001,7264.05859375,7264.05859375,,,3.04001665115356,,1,0,0,0,0,28.8367557525635,1,1,1,3.00344443321228,0,4232057728,3.00031208992004,,,0.0589627775528363,0.00207863669920666,0.0589671910756815,0.00207864468707247,0.935459196567535,0.936564326286316,33.6176719665527,0,30,2,200,-0.000212306855246425,-0.223509967327118,0.0297313146293163,2,,,,,,,,,,,,,,,,
,3886909543.37175,3.00317549705505,6490.21044921875,,,6,,,,33.6636719639605,,,1000,,,,,,,,,,,,,,,,,,,,,,2.9947874546051,3.00440073013306,6490.21044921875,6490.21044921875,,,3.03554177284241,,1,0,0,0,0,28.8367557525635,1,1,1,3.00312423706055,0,4232057568,3.00055247545242,,,0.0549474448729977,0.00193710760385077,0.0549520235225894,0.0019371141505844,0.935263156890869,0.936504900455475,33.6148643493652,0,30,2,200,-0.000201880888198502,-0.208720192313194,0.028344314545393,2,,,,,,,,,,,,,,,,
,3886909755.25147,3.00262463092804,5716.5341796875,,,6,,,,33.6636719639605,,,1000,,,,,,,,,,,,,,,,,,,,,,2.99569249153137,3.00435948371887,5716.5341796875,5716.5341796875,,,3.03533434867859,,1,0,0,0,0,28.8367557525635,1,1,1,3.00220942497253,0,4232057760,3.0003316005071,,,0.0507410624882742,0.00178884356072414,0.0507459237913612,0.00178885204251414,0.935033917427063,0.936445116996765,33.6115798950195,0.000506214331835508,30,2,200,-0.000255832361290231,-0.192966371774673,0.0252276677638292,2,,,,,,,,,,,,,,,,
,3886909965.25845,3.0027734041214,4942.9453125,,,6,,,,33.6636719639605,,,1000,,,,,,,,,,,,,,,,,,,,,,2.99490809440613,3.00415539741516,4942.9453125,4942.9453125,,,3.03216195106506,,1,0,0,0,0,28.8367557525635,1,1,1,3.00301051139832,0,4232057792,3.00027718146642,,,0.0463108864171197,0.00163269503610309,0.0463160969410011,0.0016327039206816,0.934711456298828,0.9363654255867,33.6071853637695,0,30,2,200,-0.000207796911126934,-0.176013797521591,0.0232647676020861,2,,,,,,,,,,,,,,,,
,3886910178.47618,3.00299513339996,4169.4052734375,,,6,,,,33.6636719639605,,,1000,,,,,,,,,,,,,,,,,,,,,,2.99422836303711,3.00396823883057,4169.4052734375,4169.4052734375,,,3.03013682365417,,1,0,0,0,0,28.8367557525635,1,1,1,3.00355219841003,0,4232057952,3.00037298599879,,,0.0416172691170639,0.00146725519650038,0.0416228282542384,0.00146726420272846,0.934354662895203,0.936317086219788,33.6020469665527,0,30,2,200,-0.000199299829546362,-0.158478632569313,0.0206523351371288,2,,,,,,,,,,,,,,,,
,3886910390.46546,3.00328814983368,3395.705078125,,,6,,,,33.6636719639605,,,1000,,,,,,,,,,,,,,,,,,,,,,2.994136095047,3.0040717124939,3395.705078125,3395.705078125,,,3.03028273582458,,1,0,0,0,0,29.3255138397217,1,1,1,3.00312995910645,0,4232057888,3.00033561388652,,,0.036596812283655,0.00129030238666791,0.036602827352521,0.00129031226213261,0.933792293071747,0.936192452907562,33.5953330993652,0,30,2,200,-0.000145950689329766,-0.139956325292587,0.0187008008360863,2,,,,,,,,,,,,,,,,
,3886910598.90449,3.00268840789795,2622.17749023438,,,6,,,,33.6636719639605,,,1000,,,,,,,,,,,,,,,,,,,,,,2.99450325965881,3.00367999076843,2622.17749023438,2622.17749023438,,,3.02837705612183,,1,0,0,0,0,28.3479976654053,1,1,1,3.00191378593445,0,4232057856,3.00036054849625,,,0.0311428171485543,0.00109805988529687,0.0311494603396078,0.00109807094143839,0.933103621006012,0.936200201511383,33.5858421325684,INF,30,2,200,1.39672124532808E-6,-0.118868917226791,0.0160659961402416,2,,,,,,,,,,,,,,,,
,3886910811.48146,3.00333249568939,1848.353515625,,,6,,,,33.6636719639605,,,100,,,,,,,,,,,,,,,,,,,,,,2.99422740936279,3.00408601760864,1848.353515625,1848.353515625,,,3.02932333946228,,1,0,0,0,0,29.3255138397217,1,1,1,3.00335025787354,0,4232057920,3.00035951534907,,,0.0250735963062233,0.000884136667470781,0.0250807059346726,0.000884147541756207,0.931932032108307,0.93602192401886,33.5737648010254,0,30,2,200,0.000591829011682421,-0.947843313217163,0.13786643743515,2,,,,,,,,,,,,,,,,
,3886911019.63568,3.00367641448975,1074.82604980469,,,6,,,,33.6636719639605,,,100,,,,,,,,,,,,,,,,,,,,,,2.99496245384216,3.00404715538025,1074.82604980469,1074.82604980469,,,3.02873659133911,,1,0,0,0,0,28.8367557525635,1,1,1,3.00387191772461,0,4232057632,3.00040318568548,,,0.0179787566860412,0.000634046076175676,0.0179858657056909,0.000634057084314084,0.929987967014313,0.935585975646973,33.5575256347656,0,30,2,200,0.00132356805261224,-0.679301202297211,0.0972974374890327,2,,,,,,,,,,,,,,,,
,3886911227.19933,3.00380086898804,301.187377929687,,,6,,,,33.6636719639605,,,100,,,,,,,,,,,,,,,,,,,,,,2.99470901489258,3.00393199920654,301.187377929687,301.187377929687,,,3.02725076675415,,1,0,0,0,0,28.8367557525635,1,1,1,3.00418281555176,0,4232057536,3.00047947963079,,,0.00889987306606281,0.000313945644343919,0.0089050000887377,0.000313954377526405,0.926494598388672,0.934332847595215,33.5358009338379,0.000165656689205207,30,2,200,0.00178600614890456,-0.337582588195801,0.0505930632352829,2,,,,,,,,,,,,,,,,
,3886911438.60732,3.00362062454224,-473.031921386719,,,6,,,,33.6636719639605,,,10,,,,,,,,,,,,,,,,,,,,,,2.99516224861145,3.00429177284241,-473.031921386719,-473.031921386719,,,3.0278844833374,,1,0,0,0,0,28.8367557525635,1,1,1,3.00402188301086,0,4232057888,3.00044010082881,,,-0.00301986876737868,0.000106429033872568,-0.00302007768856124,0.000106429381908077,0.940205156803131,0.941313862800598,33.6194267272949,0,30,2,200,0.0234970804303885,-0.160953611135483,1.30755078792572,2,,,,,,,,,,,,,,,,
,3886911653.1554,3.00379240512848,-1246.74475097656,,,6,,,,33.6636719639605,,,100,,,,,,,,,,,,,,,,,,,,,,2.99437165260315,3.00465321540833,-1246.74475097656,-1246.74475097656,,,3.02645611763001,,1,0,0,0,0,28.8367557525635,1,1,1,3.00459575653076,0,4232057920,3.00051776568095,,,-0.0134083120013748,0.0004727897107767,-0.0134133018654945,0.000472798266349541,0.932230949401855,0.937648713588715,33.5610084533691,7.49413251876831,30,2,200,0.00223674299195409,-0.0712293460965157,0.525522470474243,2,,,,,,,,,,,,,,,,
,3886911861.07456,3.00307285785675,-2020.32165527344,,,6,,,,33.6636719639605,,,100,,,,,,,,,,,,,,,,,,,,,,2.99418878555298,3.00394701957703,-2020.32165527344,-2020.32165527344,,,3.02499651908874,,1,0,0,0,0,28.8367557525635,1,1,1,3.00319528579712,0,4232057792,3.00051629543304,,,-0.0212210780489444,0.000748199966853336,-0.0212258304469489,0.000748208521920324,0.933723092079163,0.936996579170227,33.5841102600098,0,30,2,200,0.00186793273314834,-0.116589434444904,0.800689458847046,2,,,,,,,,,,,,,,,,
,3886912069.0436,3.00335955619812,-2793.81201171875,,,6,,,,33.6636719639605,,,100,,,,,,,,,,,,,,,,,,,,,,2.99487900733948,3.00409984588623,-2793.81201171875,-2793.81201171875,,,3.02261018753052,,1,0,0,0,0,29.3255138397217,1,1,1,3.00382661819458,0,4232058080,3.00051693121592,,,-0.0277593959470796,0.000978664360698451,-0.0277635447495135,0.000978671422977218,0.93464595079422,0.936850428581238,33.598575592041,0,30,2,200,0.00175940408371389,-0.147599950432777,1.04948127269745,2,,,,,,,,,,,,,,,,
,3886912275.85783,3.00325286388397,-3567.84619140625,,,6,,,,33.6636719639605,,,100,,,,,,,,,,,,,,,,,,,,,,2.99483966827393,3.00435924530029,-3567.84619140625,-3567.84619140625,,,3.02134418487549,,1,0,0,0,0,28.8367557525635,1,1,1,3.0035924911499,0,4232057920,3.00044053792953,,,-0.0336304021001709,0.00118561176457051,-0.0336342775886395,0.00118561879738538,0.935116112232208,0.936816036701202,33.6066093444824,0,30,2,200,0.00300516723655164,-0.177045598626137,1.30472207069397,2,,,,,,,,,,,,,,,,
,3886912484.81675,3.00337815284729,-4341.17626953125,,,6,,,,33.6636719639605,,,100,,,,,,,,,,,,,,,,,,,,,,2.99443459510803,3.00429606437683,-4341.17626953125,-4341.17626953125,,,3.02154135704041,,1,0,0,0,0,28.8367557525635,1,1,1,3.00409245491028,0,4232057728,3.00049030780792,,,-0.0390534970585547,0.00137677584903741,-0.0390571448499268,0.00137678237449999,0.935365200042725,0.936746060848236,33.6122741699219,0,30,2,200,0.00446821982041001,-0.199011787772179,1.47459030151367,2,,,,,,,,,,,,,,,,
,3886912695.91012,3.00381517410278,-5115.0126953125,,,6,,,,33.6636719639605,,,100,,,,,,,,,,,,,,,,,,,,,,2.99505805969238,3.00385808944702,-5115.0126953125,-5115.0126953125,,,3.02054595947266,,1,0,0,0,0,28.8367557525635,1,1,1,3.00398921966553,0,4232057728,3.00031328201294,,,-0.0441394240989311,0.00155605264964815,-0.0441429746423934,0.00155605925877356,0.935568153858185,0.936756789684296,33.6160278320313,7.49625873565674,30,2,200,0.00509669026359916,-0.223801761865616,1.66607856750488,2,,,,,,,,,,,,,,,,
,3886912906.77692,3.00261962413788,-5888.40380859375,,,6,,,,33.6636719639605,,,100,,,,,,,,,,,,,,,,,,,,,,2.99488139152527,3.00417280197144,-5888.40380859375,-5888.40380859375,,,3.0194034576416,,1,0,0,0,0,28.8367557525635,1,1,1,3.00213742256165,0,4232057664,3.0005019903183,,,-0.0489417765148445,0.00172533691514969,-0.0489452222598509,0.00172534305987825,0.935695886611938,0.936739563941956,33.6190414428711,0,30,2,200,0.0053981700912118,-0.248254284262657,1.8446102142334,2,,,,,,,,,,,,,,,,
,3886913116.60482,3.00322663784027,-6662.21533203125,,,6,,,,33.6636719639605,,,100,,,,,,,,,,,,,,,,,,,,,,2.99440288543701,3.00409173965454,-6662.21533203125,-6662.21533203125,,,3.01671624183655,,1,0,0,0,0,28.8367557525635,1,1,1,3.00353980064392,0,4232058112,3.00029271841049,,,-0.0535008093943923,0.00188604787162236,-0.0535042243418989,0.0018860542856052,0.935764729976654,0.936708569526672,33.6212387084961,0,30,2,200,0.00600266456604004,-0.273974478244782,2.02359366416931,2,,,,,,,,,,,,,,,,
,3886913329.42385,3.00289797782898,-7436.0146484375,,,6,,,,33.6636719639605,,,100,,,,,,,,,,,,,,,,,,,,,,2.99438405036926,3.00451111793518,-7436.0146484375,-7436.0146484375,,,3.01662278175354,,1,0,0,0,0,27.3704795837402,1,1,1,3.00381851196289,0,4232057664,3.00043642520905,,,-0.0578407710409937,0.00203903320788873,-0.0578441365774406,0.00203903941079162,0.935834169387817,0.93669581413269,33.6231384277344,7.49611043930054,30,2,200,0.00597282079979777,-0.293590724468231,2.18887972831726,2,,,,,,,,,,,,,,,,
,3886913544.61295,3.00374090671539,-8209.3203125,,,6,,,,33.6636719639605,,,1000,,,,,,,,,,,,,,,,,,,,,,2.99365091323853,3.00420331954956,-8209.3203125,-8209.3203125,,,3.01646065711975,,1,0,0,0,0,29.3255138397217,1,1,1,3.0031795501709,0,4232057824,3.00047159194946,,,-0.0619725424086687,0.00218467579732315,-0.061975906843543,0.00218468180747713,0.935930728912354,0.936736881732941,33.6244850158691,0,30,2,200,0.000502054928801954,-0.0329521931707859,0.233654245734215,2,,,,,,,,,,,,,,,,
,3886913754.1796,3.00355386734009,-8983.119140625,,,6,,,,33.6636719639605,,,1000,,,,,,,,,,,,,,,,,,,,,,2.99555397033691,3.0042610168457,-8983.119140625,-8983.119140625,,,3.01623153686523,,1,0,0,0,0,28.8367557525635,1,1,1,3.00296950340271,0,4232057632,3.00051973263423,,,-0.0659157062680019,0.00232368196380203,-0.0659190182291884,0.00232368789423633,0.93592232465744,0.936667919158936,33.6259765625,0,30,2,200,0.000697132141795009,-0.0345512665808201,0.248181194067001,2,,,,,,,,,,,,,,,,
,3886913964.60098,3.00332808494568,-9756.8076171875,,,6,,,,33.6636719639605,,,1000,,,,,,,,,,,,,,,,,,,,,,2.99538350105286,3.00430488586426,-9756.8076171875,-9756.8076171875,,,3.01698660850525,,1,0,0,0,0,29.8142719268799,1,1,1,3.00347709655762,0,4232058016,3.00031773249308,,,-0.0696870294824202,0.00245662211044287,-0.0696903460868597,0.00245662840616805,0.935969173908234,0.936673402786255,33.6270408630371,0,30,2,200,0.000721802352927625,-0.0361052379012108,0.262699782848358,2,,,,,,,,,,,,,,,,
,3886914174.0624,3.00294828414917,-10530.384765625,,,6,,,,33.6636719639605,,,1000,,,,,,,,,,,,,,,,,,,,,,2.99426436424255,3.00435876846313,-10530.384765625,-10530.384765625,,,3.01462864875793,,1,0,0,0,0,30.3030319213867,1,1,1,3.00270771980286,0,4232057824,3.00044216712316,,,-0.0732986155504502,0.00258393245782172,-0.0733019034388181,0.002583939142855,0.936002194881439,0.936663389205933,33.6281852722168,0.132864892482758,30,2,200,0.000716117909178138,-0.0381449908018112,0.276112109422684,2,,,,,,,,,,,,,,,,
,3886914384.54185,3.00370800495148,-11304.18359375,,,6,,,,33.6636719639605,,,1000,,,,,,,,,,,,,,,,,,,,,,2.99401926994324,3.00430035591126,-11304.18359375,-11304.18359375,,,3.01400113105774,,1,0,0,0,0,28.8367557525635,1,1,1,3.00355815887451,0,4232057824,3.00068553288778,,,-0.0767622854307372,0.00270602898429233,-0.0767655221332252,0.00270603453875783,0.936038553714752,0.936666190624237,33.6291007995605,7.49628686904907,30,2,200,0.000762273732107133,-0.0398027524352074,0.289279848337173,2,,,,,,,,,,,,,,,,
,3886914595.5318,3.00344812870026,-12077.7119140625,,,6,,,,33.6636719639605,,,1000,,,,,,,,,,,,,,,,,,,,,,2.99405407905579,3.00424981117249,-12077.7119140625,-12077.7119140625,,,3.01469302177429,,1,0,0,0,0,28.8367557525635,1,1,1,3.0041515827179,0,4232057664,3.00042353073756,,,-0.0800821619891867,0.00282305276522204,-0.0800853756325461,0.00282305779974532,0.936083912849426,0.936684250831604,33.6298713684082,0.000406305451178923,30,2,200,0.0007437834283337,-0.0416417568922043,0.30163511633873,2,,,,,,,,,,,,,,,,
,3886914806.48353,3.00326657295227,-12851.412109375,,,6,,,,33.6636719639605,,,1000,,,,,,,,,,,,,,,,,,,,,,2.99422144889832,3.00426006317139,-12851.412109375,-12851.412109375,,,3.01175832748413,,1,0,0,0,0,29.3255138397217,1,1,1,3.00320935249329,0,4232057600,3.00009894371033,,,-0.0832732758718038,0.00293554446810342,-0.0832764601570463,0.00293554946430911,0.936093926429748,0.936665892601013,33.6306762695313,4.33324289321899,30,2,200,0.000791831698734313,-0.0438441075384617,0.314086854457855,2,,,,,,,,,,,,,,,,
,3886915016.96658,3.00355958938599,-13625.0869140625,,,6,,,,33.6636719639605,,,1000,,,,,,,,,,,,,,,,,,,,,,2.99379110336304,3.00446224212646,-13625.0869140625,-13625.0869140625,,,3.0125777721405,,1,0,0,0,0,28.8367557525635,1,1,1,3.00402498245239,0,4232057728,3.0004633863767,,,-0.0863456445085544,0.00304384364087934,-0.0863488060867353,0.00304384853149805,0.936132311820984,0.936680555343628,33.6313743591309,,30,2,200,0.00078367063542828,-0.0451482571661472,0.324932128190994,2,,,,,,,,,,,,,,,,
,3886915226.287,3.00355505943298,-14398.6396484375,,,6,,,,33.6636719639605,,,1000,,,,,,,,,,,,,,,,,,,,,,2.9942455291748,3.00468039512634,-14398.6396484375,-14398.6396484375,,,3.01230812072754,,1,0,0,0,0,29.3255138397217,1,1,1,3.00361227989197,0,4232057856,3.0001473903656,,,-0.0893063439039769,0.00314820660670319,-0.0893094719523158,0.0031482111274287,0.936164438724518,0.936690628528595,33.6320343017578,0.133341088891029,30,2,200,0.000821940542664379,-0.046614333987236,0.336976230144501,2,,,,,,,,,,,,,,,,
,3886915436.8661,3.00382721424103,-14828.44921875,,,6,,,,33.6636719639605,,,1000,,,,,,,,,,,,,,,,,,,,,,2.99399733543396,3.00456309318542,-14828.44921875,-14828.44921875,,,3.01247572898865,,1,0,0,0,0,29.3255138397217,1,1,1,3.00414252281189,0,4232057952,3.0005181034406,,,-0.090925666049687,0.00320527542654643,-0.0909288571154528,0.00320528055214056,0.936244428157806,0.936769843101501,33.632080078125,,30,2,200,0.000529018463566899,-0.0478413142263889,0.342550933361053,2,,,,,,,,,,,,,,,,
,3886915644.77674,3.00347542762756,-14054.7734375,,,6,,,,33.6636719639605,,,1000,,,,,,,,,,,,,,,,,,,,,,2.99411749839783,3.00443315505981,-14054.7734375,-14054.7734375,,,3.00985312461853,,1,0,0,0,0,29.8142719268799,1,1,1,3.00388646125793,0,4232057824,3.00033656756083,,,-0.0881137494778281,0.0031061695025241,-0.0881170493170899,0.00310617535352179,0.936152338981628,0.936709582805634,33.6311149597168,7.49595499038696,30,2,200,0.000561082328204066,-0.0465997904539108,0.331577867269516,2,,,,,,,,,,,,,,,,
,3886915852.02988,3.00347065925598,-13281.3203125,,,6,,,,33.6636719639605,,,1000,,,,,,,,,,,,,,,,,,,,,,2.99402689933777,3.00439286231995,-13281.3203125,-13281.3203125,,,3.00902223587036,,1,0,0,0,0.013885498046875,29.3255138397217,1,1,1,3.00377702713013,0,4232057888,3.0003783305486,,,-0.0852158408562678,0.00300402400963025,-0.0852191789662282,0.00300402841281877,0.936087667942047,0.936677992343903,33.6301574707031,0,30,2,200,0.000568095303606242,-0.0448524579405785,0.320387214422226,2,,,,,,,,,,,,,,,,
,3886916062.51214,3.00284647941589,-12507.4580078125,,,6,,,,33.6636719639605,,,1000,,,,,,,,,,,,,,,,,,,,,,2.99384450912476,3.00457429885864,-12507.4580078125,-12507.4580078125,,,3.01010584831238,,1,0,0,0,0,28.8367557525635,1,1,1,3.00302672386169,0,4232057920,3.00047950311141,,,-0.0822201655460306,0.00289843193143221,-0.0822236390931338,0.00289843817279488,0.936036050319672,0.936663389205933,33.6291084289551,0,30,2,200,0.000523516326211393,-0.0431802719831467,0.309351980686188,2,,,,,,,,,,,,,,,,
,3886916275.54253,3.00343251228333,-11733.8076171875,,,6,,,,33.6636719639605,,,1000,,,,,,,,,,,,,,,,,,,,,,2.99415850639343,3.00444483757019,-11733.8076171875,-11733.8076171875,,,3.01061964035034,,1,0,0,0,0,29.3255138397217,1,1,1,3.00343942642212,0,4232057696,3.00058321519332,,,-0.0791256182466995,0.00278934966694737,-0.0791291800541838,0.00278935504030867,0.935991704463959,0.936665713787079,33.6278381347656,5.58479950996116E-5,30,2,200,0.000387578969821334,-0.0418413914740086,0.297632396221161,2,,,,,,,,,,,,,,,,
,3886916484.87975,3.00332391262054,-10960.0947265625,,,6,,,,33.6636719639605,,,1000,,,,,,,,,,,,,,,,,,,,,,2.99451112747192,3.00417280197144,-10960.0947265625,-10960.0947265625,,,3.01036787033081,,1,0,0,0,0,28.8367557525635,1,1,1,3.00311851501465,0,4232057984,3.00048369169235,,,-0.0759246732633003,0.00267652630248601,-0.0759283815792823,0.00267653241319457,0.935893714427948,0.936621189117432,33.6264228820801,7.49600839614868,30,2,200,0.000400220596930012,-0.0406210459768772,0.285943239927292,2,,,,,,,,,,,,,,,,
,3886916690.98589,3.0037579536438,-10186.5673828125,,,6,,,,33.6636719639605,,,1000,,,,,,,,,,,,,,,,,,,,,,2.99417638778687,3.00424695014954,-10186.5673828125,-10186.5673828125,,,3.01072835922241,,1,0,0,0,0,28.8367557525635,1,1,1,3.00424695014954,0,4232058016,3.00032683213552,,,-0.0726084249793441,0.00255963215068036,-0.0726122774263071,0.00255963901262128,0.935825169086456,0.936611771583557,33.624927520752,5.81240528845228E-5,30,2,200,0.000375616655219346,-0.0390012711286545,0.273455560207367,2,,,,,,,,,,,,,,,,
,3886916895.93472,3.00362920761108,-9413.0029296875,,,6,,,,33.6636719639605,,,1000,,,,,,,,,,,,,,,,,,,,,,2.99415493011475,3.00440049171448,-9413.0029296875,-9413.0029296875,,,3.00998163223267,,1,0,0,0,0,28.8367557525635,1,1,1,3.00428485870361,0,4232057952,3.00041105349859,,,-0.0691697411488193,0.00243841819248326,-0.06917370646598,0.0024384245857356,0.935765743255615,0.936619579792023,33.6233024597168,0,30,2,200,0.000325712549965829,-0.0368241108953953,0.259972244501114,2,,,,,,,,,,,,,,,,
,3886917102.1924,3.00348615646362,-8639.302734375,,,6,,,,33.6636719639605,,,1000,,,,,,,,,,,,,,,,,,,,,,2.9953887462616,3.00429344177246,-8639.302734375,-8639.302734375,,,3.00549101829529,,1,0,0,0,0,28.8367557525635,1,1,1,3.0036096572876,0,4232057696,3.00015985965729,,,-0.0655963533582895,0.0023124599835858,-0.0656005005472673,0.0023124665440171,0.935678601264954,0.93662041425705,33.6212539672852,0.000455561763374135,30,2,200,0.000234904582612216,-0.0356499403715134,0.24676313996315,2,,,,,,,,,,,,,,,,
,3886917309.46217,3.00339472293854,-7865.55224609375,,,6,,,,33.6636719639605,,,1000,,,,,,,,,,,,,,,,,,,,,,2.99376487731934,3.00432276725769,-7865.55224609375,-7865.55224609375,,,3.00698065757751,,1,0,0,0,0,29.8142719268799,1,1,1,3.00365352630615,0,4232057728,2.99999263069846,,,-0.0618736272079624,0.00218124101828036,-0.0618779549488538,0.00218124753763375,0.935551941394806,0.936595022678375,33.6190032958984,6.24233798589557E-5,30,2,200,0.000187245226697996,-0.0333437547087669,0.232372373342514,2,,,,,,,,,,,,,,,,
,3886917515.45424,3.00285923480988,-7092.08642578125,,,6,,,,33.6636719639605,,,1000,,,,,,,,,,,,,,,,,,,,,,2.99455642700195,3.00428080558777,-7092.08642578125,-7092.08642578125,,,3.00913500785828,,1,0,0,0,0,28.8367557525635,1,1,1,3.00345063209534,0,4232057696,3.00041298071543,,,-0.057997868063902,0.00204463001074129,-0.0580024155534839,0.00204463660209377,0.93539023399353,0.936559677124023,33.616340637207,5.79796028137207,30,2,200,0.000180449787876569,-0.0311849936842918,0.217987388372421,2,,,,,,,,,,,,,,,,
,3886917720.29671,3.0034646987915,-6318.31201171875,,,6,,,,33.6636719639605,,,1000,,,,,,,,,,,,,,,,,,,,,,2.99422669410706,3.00397729873657,-6318.31201171875,-6318.31201171875,,,3.01133131980896,,1,0,0,0,0,29.3255138397217,1,1,1,3.00342917442322,0,4232057728,3.00027080376943,,,-0.0539438221500391,0.00190173242168926,-0.0539486055238182,0.00190173880553842,0.935213088989258,0.93653804063797,33.6132545471191,0,30,2,200,0.000157618298544548,-0.0291467532515526,0.202747121453285,2,,,,,,,,,,,,,,,,
,3886917923.42188,3.00363397598267,-5544.8212890625,,,6,,,,33.6636719639605,,,1000,,,,,,,,,,,,,,,,,,,,,,2.99461936950684,3.00415301322937,-5544.8212890625,-5544.8212890625,,,3.01143097877502,,1,0,0,0,0,28.8367557525635,1,1,1,3.00403785705566,0,4232057760,3.00058597326279,,,-0.049691886650852,0.0017518631467827,-0.049697094546265,0.00175187338079401,0.934965789318085,0.936499178409576,33.6093673706055,0,30,2,200,0.00016270880587399,-0.0268040522933006,0.186967596411705,2,,,,,,,,,,,,,,,,
,3886918127.81471,3.0035640001297,-4771.046875,,,6,,,,33.6636719639605,,,1000,,,,,,,,,,,,,,,,,,,,,,2.99553823471069,3.00441145896912,-4771.046875,-4771.046875,,,3.01109623908997,,1,0,0,0,0,30.7917900085449,1,1,1,3.0039541721344,0,4232057824,3.00061949094137,,,-0.0452041759834619,0.00159368032653412,-0.0452097194947909,0.0015936901310027,0.934682607650757,0.936483204364777,33.6047554016113,0,30,2,200,4.7887340770103E-5,-0.0247104186564684,0.17000874876976,2,,,,,,,,,,,,,,,,
,3886918330.53444,3.00368273258209,-3997.568359375,,,6,,,,33.6636719639605,,,1000,,,,,,,,,,,,,,,,,,,,,,2.99507546424866,3.00446319580078,-3997.568359375,-3997.568359375,,,3.00895643234253,,1,0,0,0,0,27.8592376708984,1,1,1,3.00443720817566,0,4232057536,3.00032039483388,,,-0.040447315103783,0.0014260161501573,-0.0404532503042644,0.00142602610895509,0.934259176254273,0.936411201953888,33.5991363525391,0,30,2,200,4.76397917736904E-6,-0.0225008353590965,0.151945322751999,2,,,,,,,,,,,,,,,,
,3886918537.2976,3.00356340408325,-3223.74462890625,,,6,,,,33.6636719639605,,,1000,,,,,,,,,,,,,,,,,,,,,,2.99497413635254,3.00419330596924,-3223.74462890625,-3223.74462890625,,,3.01027274131775,,1,0,0,0,0,29.3255138397217,1,1,1,3.0037248134613,0,4232057856,3.00023537874222,,,-0.0353418377599397,0.00124606559739944,-0.0353482679574999,0.00124607622810086,0.933671236038208,0.936327576637268,33.5917778015137,0,30,2,200,-1.50007499541971E-5,-0.0197752732783556,0.132937848567963,2,,,,,,,,,,,,,,,,
,3886918742.88287,3.0034111738205,-2450.2294921875,,,6,,,,33.6636719639605,,,1000,,,,,,,,,,,,,,,,,,,,,,2.99413537979126,3.00400519371033,-2450.2294921875,-2450.2294921875,,,3.0113787651062,,1,0,0,0,0,27.8592376708984,1,1,1,3.00369763374329,0,4232057728,3.0002818107605,,,-0.0297733740247972,0.00104979701137905,-0.0297804098113941,0.00104980997866902,0.932796120643616,0.936200141906738,33.581974029541,0,30,2,200,-4.99460220453329E-5,-0.0172873754054308,0.111688263714314,2,,,,,,,,,,,,,,,,
,3886918958.15626,3.00331628322601,-1676.57836914062,,,6,,,,33.6636719639605,,,1000,,,,,,,,,,,,,,,,,,,,,,2.99439597129822,3.00414729118347,-1676.57836914062,-1676.57836914062,,,3.01406717300415,,1,0,0,0,0,29.3255138397217,1,1,1,3.00362491607666,0,4232057728,3.00028512057136,,,-0.0235273569202012,0.000829640114447041,-0.023534753566106,0.000829652275441009,0.931464552879334,0.935965716838837,33.5691566467285,0,30,2,200,-5.11910475324839E-5,-0.11544681340456,0.909264624118805,2,,,,,,,,,,,,,,,,
,3886919171.99344,3.00316643714905,-902.976684570312,,,6,,,,33.6636719639605,,,100,,,,,,,,,,,,,,,,,,,,,,2.99654936790466,3.00380969047546,-902.976684570312,-902.976684570312,,,3.01146531105041,,1,0,0,0,0,29.3255138397217,1,1,1,3.00305914878845,0,4232057760,3.00056459506353,,,-0.016101152128071,0.000567859267114215,-0.0161082578604061,0.000567871016262416,0.929259479045868,0.935447573661804,33.5516967773438,0.196910187602043,30,2,200,-0.00140267983078957,-0.0934157446026802,0.608659386634827,2,,,,,,,,,,,,,,,,
,3886919378.6538,3.00389194488525,-129.090911865234,,,6,,,,33.6636719639605,,,100,,,,,,,,,,,,,,,,,,,,,,2.99445629119873,3.00420451164246,-129.090911865234,-129.090911865234,,,3.01306962966919,,1,0,0,0,0,28.8367557525635,1,1,1,3.00448679924011,0,4232057760,3.00021678751165,,,-0.00633982191509809,0.000223681297865202,-0.00634450094720397,0.00022368900086633,0.923985660076141,0.93382853269577,33.518798828125,0.133510917425156,30,2,200,-0.00211211130954325,-0.0439986027777195,0.23809427022934,2,,,,,,,,,,,,,,,,
,3886919588.7746,3.00295627117157,645.09130859375,,,6,,,,33.6636719639605,,,10,,,,,,,,,,,,,,,,,,,,,,2.99488425254822,3.00415420532227,645.09130859375,645.09130859375,,,3.01096725463867,,1,0,0,0,0,29.3255138397217,1,1,1,3.00267457962036,0,4232057728,3.00048492352168,,,0.00568453194260335,0.000200399666385834,0.00568593220086001,0.000200402083051398,0.935400664806366,0.939119398593903,33.5802001953125,0.133404821157455,30,2,200,-0.0199401583522558,-2.18913435935974,0.298248797655106,2,,,,,,,,,,,,,,,,
,3886919801.36936,3.00389397144318,1418.76708984375,,,6,,,,33.6636719639605,,,100,,,,,,,,,,,,,,,,,,,,,,2.9945502281189,3.00398015975952,1418.76708984375,1418.76708984375,,,3.01029777526855,,1,0,0,0,0,29.3255138397217,1,1,1,3.00397038459778,0,4232057792,3.00049616893133,,,0.0154362595550059,0.000544285111825298,0.0154413862087727,0.000544294091513093,0.932556271553039,0.93738853931427,33.5667381286621,0,30,2,200,-0.0021663794759661,-0.593382239341736,0.0786558836698532,2,,,,,,,,,,,,,,,,
,3886920007.6498,3.00336384773254,2192.35620117187,,,6,,,,33.6636719639605,,,100,,,,,,,,,,,,,,,,,,,,,,2.99436926841736,3.00425362586975,2192.35620117187,2192.35620117187,,,3.0111403465271,,1,0,0,0,0,29.3255138397217,1,1,1,3.00399971008301,0,4232058016,3.00045305490494,,,0.0228573884164057,0.000805875056267447,0.0228618811553207,0.000805882751219985,0.934037148952484,0.936923205852509,33.5890350341797,4.33301258087158,30,2,200,-0.00195576343685389,-0.867666006088257,0.119305893778801,2,,,,,,,,,,,,,,,,
,3886920217.47529,3.00358271598816,2965.98266601562,,,6,,,,33.6636719639605,,,100,,,,,,,,,,,,,,,,,,,,,,2.99408555030823,3.0042781829834,2965.98266601562,2965.98266601562,,,3.00976419448853,,1,0,0,0,0,27.8592376708984,1,1,1,3.00369119644165,0,4232057792,3.00038633743922,,,0.0292198053932691,0.00103014185831277,0.0292238505944671,0.00103014848535292,0.934790968894958,0.936839044094086,33.600959777832,,30,2,200,-0.00163079786580056,-1.10501754283905,0.153807371854782,2,,,,,,,,,,,,,,,,
,3886920426.74937,3.00320470333099,3739.53491210937,,,6,,,,33.6636719639605,,,100,,,,,,,,,,,,,,,,,,,,,,2.99479675292969,3.00418186187744,3739.53491210937,3739.53491210937,,,3.01013040542603,,1,0,0,0,0,28.8367557525635,1,1,1,3.00338697433472,0,4232057920,3.00032780567805,,,0.0349755343859659,0.00123302821953989,0.0349793516418964,0.00123303534125994,0.935180127620697,0.936788082122803,33.6081771850586,,30,2,200,-0.00337255652993917,-1.32830727100372,0.182241857051849,2,,,,,,,,,,,,,,,,
,3886920636.6321,3.00328743457794,4513.0498046875,,,6,,,,33.6636719639605,,,100,,,,,,,,,,,,,,,,,,,,,,2.99397730827332,3.00421142578125,4513.0498046875,4513.0498046875,,,3.00895476341248,,1,0,0,0,0,27.8592376708984,1,1,1,3.00360608100891,0,4232057728,3.00014861424764,,,0.0403194692785454,0.00142140110723406,0.0403231195316338,0.00142140787917228,0.935418844223022,0.936755239963532,33.6131210327148,0,30,2,200,-0.00448299944400787,-1.52612614631653,0.200669825077057,2,,,,,,,,,,,,,,,,
,3886920847.32861,3.00326240062714,5286.8984375,,,6,,,,33.6636719639605,,,100,,,,,,,,,,,,,,,,,,,,,,2.99382138252258,3.00415015220642,5286.8984375,5286.8984375,,,3.00962972640991,,1,0,0,0,0,28.8367557525635,1,1,1,3.00304698944092,0,4232057984,2.99999558925629,,,0.0453424759128329,0.00159846076865437,0.0453460047030352,0.00159846655677462,0.935606360435486,0.936764419078827,33.6166534423828,,30,2,200,-0.00503815896809101,-1.717977643013,0.232291236519814,2,,,,,,,,,,,,,,,,
,3886921055.83292,3.00309205055237,6060.46337890625,,,6,,,,33.6636719639605,,,100,,,,,,,,,,,,,,,,,,,,,,2.99453783035278,3.00421786308289,6060.46337890625,6060.46337890625,,,3.00796246528625,,1,0,0,0,0,29.3255138397217,1,1,1,3.0027437210083,0,4232057600,3.00042504072189,,,0.0500853596051091,0.00176565146918464,0.0500887920151037,0.00176565687836228,0.935688436031342,0.936710357666016,33.6195030212402,,30,2,200,-0.00559411011636257,-1.89706265926361,0.255540817975998,2,,,,,,,,,,,,,,,,
,3886921265.93547,3.00329864025116,6834.2744140625,,,6,,,,33.6636719639605,,,100,,,,,,,,,,,,,,,,,,,,,,2.99423456192017,3.00414419174194,6834.2744140625,6834.2744140625,,,3.00724315643311,,1,0,0,0,0,29.3255138397217,1,1,1,3.00333786010742,0,4232057664,3.00080714623133,,,0.0545962088850738,0.00192466146809269,0.0545996335491797,0.00192466767366378,0.935773253440857,0.93670266866684,33.6215667724609,,30,2,200,-0.00604256242513657,-2.06731510162354,0.276760578155518,2,,,,,,,,,,,,,,,,
,3886921476.04937,3.00292432308197,7607.8642578125,,,6,,,,33.6636719639605,,,100,,,,,,,,,,,,,,,,,,,,,,2.99421286582947,3.00413680076599,7607.8642578125,7607.8642578125,,,3.00986289978027,,1,0,0,0,0,28.8367557525635,1,1,1,3.00268626213074,0,4232057920,3.00038806597392,,,0.0588857926593434,0.00207587210764587,0.0588891531040203,0.00207587748691316,0.935833156108856,0.936684310436249,33.6233787536621,,30,2,200,-0.00627447757869959,-2.2234377861023,0.29378142952919,2,,,,,,,,,,,,,,,,
,3886921692.55856,3.0035240650177,8381.52734375,,,6,,,,33.6636719639605,,,1000,,,,,,,,,,,,,,,,,,,,,,2.99454832077026,3.00444483757019,8381.52734375,8381.52734375,,,3.00808644294739,,1,0,0,0,0,29.3255138397217,1,1,1,3.00354480743408,0,4232057952,3.00026081005732,,,0.0629783690087069,0.00222013829535396,0.0629817119282743,0.00222014379483086,0.935888051986694,0.936679005622864,33.6248397827148,0,30,2,200,-0.000641780148725957,-0.238711535930634,0.031480435281992,2,,,,,,,,,,,,,,,,
,3886921903.63693,3.00382268428802,9155.0546875,,,6,,,,33.6636719639605,,,1000,,,,,,,,,,,,,,,,,,,,,,2.99404263496399,3.00435590744019,9155.0546875,9155.0546875,,,3.00924754142761,,1,0,0,0,0,28.8367557525635,1,1,1,3.00440096855164,0,4232057728,3.00038409233093,,,0.0668815932543718,0.00235772553987671,0.0668848884049511,0.00235773059585032,0.93595564365387,0.936692714691162,33.6261978149414,5.69841395190451E-5,30,2,200,-0.000661501719150692,-0.253348290920258,0.0335039347410202,2,,,,,,,,,,,,,,,,
,3886922113.55934,3.00335621833801,9928.7431640625,,,6,,,,33.6636719639605,,,1000,,,,,,,,,,,,,,,,,,,,,,2.99404716491699,3.00403881072998,9928.7431640625,9928.7431640625,,,3.00972318649292,,1,0,0,0,0,28.8367557525635,1,1,1,3.00311613082886,0,4232058016,3.00035083293915,,,0.0706142559288,0.00248930788892061,0.0706175747846582,0.00248931407819433,0.935975790023804,0.936672031879425,33.6272506713867,0,30,2,200,-0.000747295562177896,-0.267635554075241,0.0351593941450119,2,,,,,,,,,,,,,,,,
,3886922325.05414,3.003298163414,10702.48046875,,,6,,,,33.6636719639605,,,1000,,,,,,,,,,,,,,,,,,,,,,2.99415349960327,3.00456595420837,10702.48046875,10702.48046875,,,3.00561022758484,,1,0,0,0,0,29.3255138397217,1,1,1,3.00310254096985,0,4232057728,3.00031886498133,,,0.0741896847813717,0.00261534337844943,0.074192962599064,0.00261534887135194,0.936016738414764,0.936675131320953,33.6282615661621,5.54734760953579E-5,30,2,200,-0.000697207113262266,-0.280783981084824,0.0373350419104099,2,,,,,,,,,,,,,,,,
,3886922539.88965,3.00381505489349,11475.9091796875,,,6,,,,33.6636719639605,,,1000,,,,,,,,,,,,,,,,,,,,,,2.99464917182922,3.0043158531189,11475.9091796875,11475.9091796875,,,3.00705909729004,,1,0,0,0,0,29.3255138397217,1,1,1,3.00397610664368,0,4232057888,3.00042674938838,,,0.0776154197937317,0.00273610032236572,0.0776186791376399,0.00273610641115662,0.936055421829224,0.936677813529968,33.6292495727539,0,30,2,200,-0.000691978202667087,-0.294399350881577,0.0384399928152561,2,,,,,,,,,,,,,,,,
,3886922754.50286,3.00351929664612,12249.5107421875,,,6,,,,33.6636719639605,,,1000,,,,,,,,,,,,,,,,,,,,,,2.99401450157166,3.00452566146851,12249.5107421875,12249.5107421875,,,3.00685596466064,,1,0,0,0,0,28.3479976654053,1,1,1,3.00367379188538,0,4232057664,3.00023905436198,,,0.0809046724806029,0.00285204753161514,0.0809078999887445,0.00285205266959442,0.93608570098877,0.936681985855103,33.6299781799316,5.41429544682615E-5,30,2,200,-0.000645370048005134,-0.306228995323181,0.0406033247709274,2,,,,,,,,,,,,,,,,
,3886922967.95323,3.00371718406677,13023.4462890625,,,6,,,,33.6636719639605,,,1000,,,,,,,,,,,,,,,,,,,,,,2.9948410987854,3.00415301322937,13023.4462890625,13023.4462890625,,,3.00629734992981,,1,0,0,0,0,29.3255138397217,1,1,1,3.00401926040649,0,4232057952,3.00058428446452,,,0.0840660096834646,0.00296348788956634,0.0840692395717748,0.00296349374555318,0.936096251010895,0.936666786670685,33.6307182312012,0,30,2,200,-0.000801401271019131,-0.318176656961441,0.0420700758695602,2,,,,,,,,,,,,,,,,
,3886923181.72895,3.00372564792633,13797.060546875,,,6,,,,33.6636719639605,,,1000,,,,,,,,,,,,,,,,,,,,,,2.99487662315369,3.00426411628723,13797.060546875,13797.060546875,,,3.00625610351562,,1,0,0,0,0,29.3255138397217,1,1,1,3.00421166419983,0,4232057824,3.00033597512679,,,0.0871089639123435,0.00307075127259799,0.087112124778849,0.0030707562756595,0.936129987239838,0.936672687530518,33.6315383911133,0,30,2,200,-0.000876286532729864,-0.329935818910599,0.0433323830366135,2,,,,,,,,,,,,,,,,
,3886923394.879,3.00260782241821,14570.5751953125,,,6,,,,33.6636719639605,,,1000,,,,,,,,,,,,,,,,,,,,,,2.99459958076477,3.00449848175049,14570.5751953125,14570.5751953125,,,3.00620698928833,,1,0,0,0,0,28.3479976654053,1,1,1,3.00381755828857,0,4232057888,3.00021276871363,,,0.0900393890617811,0.00317405055937344,0.0900425768012062,0.00317405651142057,0.93615460395813,0.936679780483246,33.6320648193359,0,30,2,200,-0.000848101917654276,-0.341207087039948,0.0454247035086155,2,,,,,,,,,,,,,,,,
,3886923512.09614,3.00402295589447,15000.43359375,,,6,,,,33.6636719639605,,,1000,,,,,,,,,,,,,,,,,,,,,,2.99426412582397,3.00477123260498,15000.43359375,15000.43359375,,,3.00545883178711,,1,0,0,0,0,29.3255138397217,1,1,1,3.00460290908814,0,4232058112,3.00028266509374,,,0.0916199149463953,0.00322976321941527,0.0916230866355272,0.0032297687459767,0.936171352863312,0.936686933040619,33.6323623657227,0,30,2,200,-0.000923256622627378,-0.347208708524704,0.0462407693266869,2,,,,,,,,,,,,,,,,