File: Chapter5/lowT/LG12_ZFC.dat
[Header]
; MPMS3 Data File (default extension .dat)
; Copyright (c) 2007, Quantum Design, Inc. All rights reserved.
TITLE,
FILEOPENTIME,3886853094.31266,03/01/2023,5:24 pm
BYAPP,MPMS3 w/ AC,1.0,1.1
INFO,MPMS3 Measurement Release 1.1.16 Build 424, MultiVu Release 2.3.4.26,APPNAME
INFO,Linear Motor Servo Controller,MOTOR_MODULE_NAME
INFO,3101-100 N0,MOTOR_HW_VERSION
INFO,MMC1047,MOTOR_SERIAL_NUMBER
INFO,01.04.28,MOTOR_SOFTWARE_VERSION
INFO,Quantum Design Squid Module,SQUID_MODULE_NAME
INFO,3101-501 B0,SQUID_HW_VERSION
INFO,SQM278,SQUID_SERIAL_NUMBER
INFO,01.03.04,SQUID_SOFTWARE_VERSION
INFO,Quantum Design VSM Oven,OVEN_MODULE_NAME
INFO,3101-201 A3,OVEN_HW_VERSION
INFO,OVB323,OVEN_SERIAL_NUMBER
INFO,01.07.07,OVEN_SOFTWARE_VERSION
INFO,SQUID AC,AC_MODULE_NAME
INFO,3101-401 G0,AC_HW_VERSION
INFO,SAC258,AC_SERIAL_NUMBER
INFO,SQUID AC 00.95.07,AC_SOFTWARE_VERSION
INFO,TCI408,COIL_SERIAL_NUMBER
INFO,0,MOMENT_UNITS
INFO,C3,SAMPLE_MATERIAL
INFO,,SAMPLE_COMMENT
INFO,,SAMPLE_MASS
INFO,,SAMPLE_VOLUME
INFO,,SAMPLE_MOLECULAR_WEIGHT
INFO,,SAMPLE_SIZE
INFO,,SAMPLE_SHAPE
INFO,Straw,SAMPLE_HOLDER
INFO,Standard,SAMPLE_HOLDER_DETAIL
INFO,66.62,SAMPLE_OFFSET
DATATYPE,COMMENT,1
DATATYPE,TIME,2
STARTUPAXIS,X,2
STARTUPAXIS,Y1,5
FIELDGROUP, VSM,2,3,4,5,6,8,9,10,11,14,15
FIELDGROUP, DC, 2,3,4,14,56,57,58,59,60,61,62,63,64,65,66,67,68,69
FIELDGROUP, AC, 2,3,4,11,16,17,18,19,20,21,22,23,24,25,26,27,28,29,30
STARTUPGROUP, All
[Data]
Comment,Time Stamp (sec),Temperature (K),Magnetic Field (Oe),Moment (emu),M. Std. Err. (emu),Transport Action,Averaging Time (sec),Frequency (Hz),Peak Amplitude (mm),Center Position (mm),Lockin Signal' (V),Lockin Signal (V),Range,M. Quad. Signal (emu),AC Moment (emu),AC M. Std Err. (emu),AC Phase (deg),AC Phase Std. Err. (deg),AC Susceptibility (emu/Oe),AC Suscept. Std Err. (emu/Oe),AC X' (emu/Oe),AC X' Std Err. (emu/Oe),AC X'' (emu/Oe),AC X'' Std Err. (emu/Oe),AC Drive (Oe),AC Frequency (Hz),AC Averaging Time (sec),AC Cycles,AC Range,AC Measure Type,AC Signal' (V),AC Signal'' (V),AC Trim Coil Ratio,AC Trim Coil Phase,Min. Temperature (K),Max. Temperature (K),Min. Field (Oe),Max. Field (Oe),Mass (grams),Motor Lag (deg),Pressure (Torr),Measure Count,Measurement Number,SQUID Status (code),Motor Status (code),Measure Status (code),Motor Current (amps),Motor Temp. (C),Temp. Status (code),Field Status (code),Chamber Status (code),Chamber Temp (K),Redirection State,Evercool Status,Average Temp (K),Rotation Angle (deg),Rotator state,DC Moment Fixed Ctr (emu),DC Moment Err Fixed Ctr (emu),DC Moment Free Ctr (emu),DC Moment Err Free Ctr (emu),DC Fixed Fit,DC Free Fit,DC Calculated Center (mm),DC Calculated Center Err (mm),DC Scan Length (mm),DC Scan Time (s),DC Number of Points,DC Squid Drift,DC Min V (V),DC Max V (V),DC Scans per Measure,Map 01,Map 02,Map 03,Map 04,Map 05,Map 06,Map 07,Map 08,Map 09,Map 10,Map 11,Map 12,Map 13,Map 14,Map 15,Map 16
,3886853102.77528,299.741470336914,0.00121735187713057,,,6,,,,34.59929676886,,,1,,,,,,,,,,,,,,,,,,,,,,299.629791259766,299.878356933594,0.00121735187713057,0.00121735187713057,,,9.8785457611084,,1,0,0,0,0.013885498046875,29.8142719268799,6,1,1,299.612609863281,0,4232056832,299.793713887533,,,0.00019884538876589,7.00866045632483E-6,0.000198887082265893,7.00874377057424E-6,0.938415586948395,0.941703140735626,34.6759147644043,0.158496305346489,30,2,200,0.000321415951475501,-0.90828412771225,-0.0538436993956566,2,,,,,,,,,,,,,,,,
,3886853407.58255,201.787902832031,0.00121735187713057,,,6,,,,34.1832626479959,,,1,,,,,,,,,,,,,,,,,,,,,,200.087432861328,203.71337890625,0.00121735187713057,0.00121735187713057,,,9.59790134429932,,1,0,0,0,0.014801025390625,29.8142719268799,2,1,1,199.862426757813,0,4232056832,201.901172637939,,,0.000218821893541885,7.71149422720677E-6,0.000218830234659936,7.71149832120235E-6,0.94114226102829,0.941782176494598,34.1498641967773,,30,2,200,-0.00196325080469251,-0.973223388195038,-0.0332454890012741,2,,,,,,,,,,,,,,,,
,3886853717.82538,98.3854141235352,0.00121735187713057,,,6,,,,33.8723340589437,,,1,,,,,,,,,,,,,,,,,,,,,,96.4301147460937,100.459396362305,0.00121735187713057,0.00121735187713057,,,8.98365592956543,,1,0,0,0,0,28.3479976654053,2,1,1,96.3114318847656,0,4232056832,98.4750487009684,,,0.000253899793071961,8.96248932099285E-6,0.000254396682100787,8.96323369774369E-6,0.917806446552277,0.944954752922058,33.6369323730469,1.49449024320347E-5,30,2,200,0.000263439142145216,-1.08052110671997,0.0137745151296258,2,,,,,,,,,,,,,,,,
,3886854021.30218,10.002311706543,0.00121735187713057,,,6,,,,33.6875005483344,,,1,,,,,,,,,,,,,,,,,,,,,,9.99709224700928,10.003059387207,0.00121735187713057,0.00121735187713057,,,6.04794359207153,,1,0,0,0,0,29.8142719268799,6,1,1,10.0027742385864,0,4232056832,10.0000685850779,,,0.000260142536584711,9.20782579013788E-6,0.000261436351599843,9.20996578912588E-6,0.889838695526123,0.94757467508316,33.313892364502,5.77181911468506,30,2,200,0.000193915329873562,-1.10318613052368,0.0188178233802319,2,,,,,,,,,,,,,,,,
,3886854233.31193,10.0003261566162,0.00121735187713057,,,6,,,,33.6649567101744,,,1,,,,,,,,,,,,,,,,,,,,,,9.99810600280762,10.0021181106567,0.00121735187713057,0.00121735187713057,,,5.39746904373169,,1,0,0,0,0,28.3479976654053,1,1,1,10.0001354217529,0,4232056832,9.99999618530273,,,0.000260203590492759,9.20746256922458E-6,0.000261422238939461,9.20952413535924E-6,0.892322659492493,0.94745409488678,33.3025016784668,,30,2,200,-0.00213118642568588,-1.1028265953064,0.0194110497832298,2,,,,,,,,,,,,,,,,
,3886854422.73495,10.0003399848938,0.00121735187713057,,,6,,,,33.6649567101744,,,1,,,,,,,,,,,,,,,,,,,,,,9.99808120727539,10.0021419525146,0.00121735187713057,0.00121735187713057,,,5.30086803436279,,1,0,0,0,0,29.8142719268799,1,1,1,10.0001430511475,0,4232056832,9.99991679191589,,,0.000260161081586157,9.20582584188189E-6,0.000261370982250414,9.20776595435029E-6,0.892457008361816,0.947360694408417,33.303337097168,7.41493058740161E-5,30,2,200,-0.00202610739506781,-1.10282707214355,0.019387923181057,2,,,,,,,,,,,,,,,,
,3886854611.62644,10.0002489089966,0.00121735187713057,,,6,,,,33.6649567101744,,,1,,,,,,,,,,,,,,,,,,,,,,9.997878074646,10.0019464492798,0.00121735187713057,0.00121735187713057,,,5.23980665206909,,1,0,0,0,0,29.3255138397217,1,1,1,10.0002136230469,0,4232057696,9.99993125597636,,,0.000260157017668142,9.20563072358989E-6,0.000261365705625184,9.20761662878483E-6,0.892505586147308,0.947280049324036,33.3037185668945,,30,2,200,-0.002044094260782,-1.10390865802765,0.0179440192878246,2,,,,,,,,,,,,,,,,
,3886854808.11321,9.99920129776001,15521.4536132812,,,6,,,,33.6649567101744,,,1000,,,,,,,,,,,,,,,,,,,,,,9.99603271484375,10.0002851486206,11950.9560546875,18732.384765625,,,5.19388055801392,,1,0,0,0,0,29.3255138397217,1,6,1,9.99940776824951,0,4232056832,9.99826343854268,,,0.066783223251901,0.00245338903792021,0.0671305513163455,0.00245397492373387,0.711980700492859,0.728276014328003,33.2808685302734,7.19304800033569,30,2,200,0.572204768657684,0.0986623838543892,1.67358243465424,2,,,,,,,,,,,,,,,,
,3886857745.17684,15.0160713195801,0.00121735187713057,,,6,,,,33.6649567101744,,,10,,,,,,,,,,,,,,,,,,,,,,15.0059432983398,15.0260496139526,0.00121735187713057,0.00121735187713057,,,5.32541847229004,,1,0,0,0,0,29.3255138397217,5,1,1,15.0060930252075,0,4232056832,15.0141663551331,,,0.00128321491865032,4.54388094040088E-5,0.00128925185623111,4.54488173742766E-5,0.886147320270538,0.936029553413391,33.300235748291,0,30,2,200,-0.00104865757748485,-0.54604560136795,0.111778981983662,2,,,,,,,,,,,,,,,,
,3886857981.0283,21.9580602645874,0.00121735187713057,,,6,,,,33.6649567101744,,,10,,,,,,,,,,,,,,,,,,,,,,21.5169105529785,22.3890628814697,0.00121735187713057,0.00121735187713057,,,5.72689533233643,,1,0,0,0,0,29.3255138397217,2,1,1,22.3992099761963,0,4232056832,22.0650536219279,,,0.00110690970228148,3.91868679833277E-5,0.00111189916878827,3.91952546981445E-5,0.888144552707672,0.936631202697754,33.30810546875,0,30,2,200,-0.000806788739282638,-0.391680747270584,0.0881375148892403,2,,,,,,,,,,,,,,,,
,3886858195.36169,27.4945192337036,0.00121735187713057,,,6,,,,33.6649567101744,,,10,,,,,,,,,,,,,,,,,,,,,,27.4885177612305,27.5000553131104,0.00121735187713057,0.00121735187713057,,,5.93707323074341,,1,0,0,0,0,29.3255138397217,5,1,1,27.5005207061768,0,4232056832,27.4950218200684,,,0.0010282232741862,3.63904651222554E-5,0.00103255826970343,3.63976884611361E-5,0.890778422355652,0.936945915222168,33.3197288513184,2.2645426724921E-5,30,2,200,-0.000650698493700474,-0.366471916437149,0.0769999474287033,2,,,,,,,,,,,,,,,,
,3886858410.08085,32.5003032684326,0.00121735187713057,,,6,,,,33.6701742202978,,,10,,,,,,,,,,,,,,,,,,,,,,32.4977760314941,32.5023078918457,0.00121735187713057,0.00121735187713057,,,6.09256649017334,,1,0,0,0,0,29.3255138397217,5,1,1,32.5026512145996,0,4232056832,32.5008204778036,,,0.00097452034195334,3.44801371799813E-5,0.00097835337765505,3.44866095161561E-5,0.893357515335083,0.937117099761963,33.3368225097656,5.77380514144897,30,2,200,-1.68134265550179E-5,-0.350007683038712,0.0700638368725777,2,,,,,,,,,,,,,,,,
,3886858653.06993,37.8250141143799,0.00121735187713057,,,6,,,,33.6757040628415,,,10,,,,,,,,,,,,,,,,,,,,,,37.5015068054199,38.1275329589844,0.00121735187713057,0.00121735187713057,,,6.22864532470703,,1,0,0,0,0,28.8367557525635,6,1,1,38.1485214233398,0,4232056832,37.6951434795673,,,0.000924080315294956,3.26822781220905E-5,0.000927315040232413,3.26877256435866E-5,0.897170066833496,0.937015831470489,33.361141204834,0,30,2,200,-0.000605579698458314,-0.334598422050476,0.0634495466947556,2,,,,,,,,,,,,,,,,
,3886858859.45431,42.486967086792,0.00121735187713057,,,6,,,,33.6808414082837,,,10,,,,,,,,,,,,,,,,,,,,,,42.4814949035645,42.4922142028809,0.00121735187713057,0.00121735187713057,,,6.31141662597656,,1,0,0,0,0,28.8367557525635,5,1,1,42.4924392700195,0,4232057600,42.4876197179159,,,0.000885092871344048,3.12922621199919E-5,0.000887854810019022,3.12968292805112E-5,0.900654792785645,0.936982750892639,33.3836708068848,0,30,2,200,-2.31146386795444E-5,-0.322611808776855,0.0584242790937424,2,,,,,,,,,,,,,,,,
,3886859079.30885,47.2829723358154,0.00121735187713057,,,6,,,,33.6860226052187,,,10,,,,,,,,,,,,,,,,,,,,,,47.2046928405762,47.3592338562012,0.00121735187713057,0.00121735187713057,,,6.39148092269897,,1,0,0,0,0,30.3030319213867,6,1,1,47.3612518310547,0,4232057568,47.2926540374756,,,0.000854925751114334,3.02167502105735E-5,0.000857321821313052,3.02205707903464E-5,0.903653979301453,0.936965346336365,33.4041061401367,0.000172760235727765,30,2,200,-0.0006290742312558,-0.31351026892662,0.054521206766367,2,,,,,,,,,,,,,,,,
,3886859293.05712,51.8789119720459,0.00121735187713057,,,6,,,,33.6914097795692,,,10,,,,,,,,,,,,,,,,,,,,,,51.6823921203613,52.0555992126465,0.00121735187713057,0.00121735187713057,,,6.45724630355835,,1,0,0,0,0,28.8367557525635,6,1,1,52.0754318237305,0,4232057696,51.8851976394653,,,0.00082746547870815,2.92381743368949E-5,0.000829557941401116,2.92416170851752E-5,0.906514108181,0.937114894390106,33.4237899780273,0,30,2,200,-2.58257387031335E-5,-0.305328100919724,0.0508443564176559,2,,,,,,,,,,,,,,,,
,3886859515.51841,56.2471141815186,0.00121735187713057,,,6,,,,33.6965755724015,,,10,,,,,,,,,,,,,,,,,,,,,,55.9406089782715,56.5428657531738,0.00121735187713057,0.00121735187713057,,,6.50896072387695,,1,0,0,0,0,29.3255138397217,6,1,1,56.5536193847656,0,4232057792,56.2500511805216,,,0.000802489269802756,2.83483207537302E-5,0.000804305241146753,2.83513324766221E-5,0.909298598766327,0.937193155288696,33.4434547424316,0,30,2,200,-0.000533586309757084,-0.297789663076401,0.047478161752224,2,,,,,,,,,,,,,,,,
,3886859720.14695,59.9697170257568,0.00121735187713057,,,6,,,,33.7016061125515,,,10,,,,,,,,,,,,,,,,,,,,,,59.9635276794434,59.975513458252,0.00121735187713057,0.00121735187713057,,,6.54481744766235,,1,0,0,0,0,28.8367557525635,5,1,1,59.9764060974121,0,4232057728,59.9701223373413,,,0.000780571072249155,2.7568532016189E-5,0.000782173280361209,2.75711345888232E-5,0.91151636838913,0.93722927570343,33.4603729248047,5.78449392318726,30,2,200,-2.95034205919364E-5,-0.290914684534073,0.0446697100996971,2,,,,,,,,,,,,,,,,
,3886859942.11759,64.8814353942871,0.00121735187713057,,,6,,,,33.7072011200181,,,10,,,,,,,,,,,,,,,,,,,,,,64.8512268066406,64.910774230957,0.00121735187713057,0.00121735187713057,,,6.58788919448852,,1,0,0,0,0,29.3255138397217,5,1,1,64.9116439819336,0,4232057728,64.8837998708089,,,0.000758060035143168,2.67662230667626E-5,0.000759405862291947,2.67684078705786E-5,0.914607346057892,0.937337636947632,33.4828262329102,0,30,2,200,-0.000464207725599408,-0.284073531627655,0.0417180880904198,2,,,,,,,,,,,,,,,,
,3886860164.11395,69.4467239379883,0.00121735187713057,,,6,,,,33.7122700272318,,,10,,,,,,,,,,,,,,,,,,,,,,69.3279495239258,69.554084777832,0.00121735187713057,0.00121735187713057,,,6.6234130859375,,1,0,0,0,0,29.3255138397217,6,1,1,69.5654983520508,0,4232057952,69.449317296346,,,0.000737511509830099,2.60338022335213E-5,0.000738614185747962,2.60354957085229E-5,0.917734086513519,0.9373499751091,33.5060729980469,5.78844308853149,30,2,200,-3.32891031575855E-5,-0.277974992990494,0.038894459605217,2,,,,,,,,,,,,,,,,
,3886860376.92045,72.5731201171875,0.00121735187713057,,,6,,,,33.717346777881,,,10,,,,,,,,,,,,,,,,,,,,,,72.4676742553711,72.642463684082,0.00121735187713057,0.00121735187713057,,,6.64916372299194,,1,0,0,0,0,29.3255138397217,6,1,1,72.6785659790039,0,4232057888,72.5163281758626,,,0.000719436392784988,2.53910526003829E-5,0.000720380315319142,2.53926033346523E-5,0.920005738735199,0.937455832958221,33.5244903564453,5.79003381729126,30,2,200,-0.000460551760625094,-0.272524058818817,0.0364896878600121,2,,,,,,,,,,,,,,,,
,3886860583.50735,77.204532623291,0.00121735187713057,,,6,,,,33.7227990730998,,,10,,,,,,,,,,,,,,,,,,,,,,77.1458740234375,77.2613830566406,0.00121735187713057,0.00121735187713057,,,6.67482423782349,,1,0,0,0,0,28.8367557525635,6,1,1,77.2631912231445,0,4232057856,77.2085431416829,,,0.000698129514691623,2.46328950354199E-5,0.000698862635088414,2.46341865808092E-5,0.923184037208557,0.937420427799225,33.5505447387695,0,30,2,200,-0.000565302616450936,-0.265987753868103,0.0337485894560814,2,,,,,,,,,,,,,,,,
,3886860813.15917,81.2434844970703,0.00121735187713057,,,6,,,,33.7337788349322,,,10,,,,,,,,,,,,,,,,,,,,,,81.0229034423828,81.4346084594727,0.00121735187713057,0.00121735187713057,,,6.69985246658325,,1,0,0,0,0,27.3704795837402,6,1,1,81.4640655517578,0,4232057760,81.2380466461182,,,0.000676926813968948,2.38809162670651E-5,0.000677524615412789,2.38818747504401E-5,0.925302863121033,0.937530159950256,33.575439453125,0,30,2,200,-0.000492101709824055,-0.259795814752579,0.0309711322188377,2,,,,,,,,,,,,,,,,
,3886861023.6601,84.8762397766113,0.00121735187713057,,,6,,,,33.7391762668719,,,10,,,,,,,,,,,,,,,,,,,,,,84.8512496948242,84.899055480957,0.00121735187713057,0.00121735187713057,,,6.71593284606934,,1,0,0,0,0,29.8142719268799,5,1,1,84.9012298583984,0,4232058048,84.8768965403239,,,0.000654449234467926,2.30838763428497E-5,0.000654913956470868,2.3084604333127E-5,0.927684128284454,0.937717199325561,33.5971221923828,0,30,2,200,-1.48548160723294E-5,-0.252788037061691,0.0280307549983263,2,,,,,,,,,,,,,,,,
,3886861252.91668,89.3232269287109,0.00121735187713057,,,6,,,,33.7496051521622,,,10,,,,,,,,,,,,,,,,,,,,,,89.2077560424805,89.4306945800781,0.00121735187713057,0.00121735187713057,,,6.73847961425781,,1,0,0,0,0,29.3255138397217,6,1,1,89.4386978149414,0,4232057760,89.3217868804932,,,0.000627649544338541,2.21352501880514E-5,0.00062800489913817,2.21358056278576E-5,0.92979496717453,0.937938153743744,33.6227569580078,0,30,2,200,-3.12832708004862E-5,-0.244797646999359,0.0246152505278587,2,,,,,,,,,,,,,,,,
,3886861474.99678,92.5256843566895,0.00121735187713057,,,6,,,,33.7547843046586,,,10,,,,,,,,,,,,,,,,,,,,,,92.4372634887695,92.5661697387695,0.00121735187713057,0.00121735187713057,,,6.75438737869263,,1,0,0,0,0,29.3255138397217,6,1,1,92.6141052246094,0,4232057792,92.4730987548828,,,0.000604482808542921,2.13162798214711E-5,0.000604776116576629,2.13166957638085E-5,0.931098699569702,0.938192307949066,33.6371040344238,0,30,2,200,-0.000422441284172237,-0.237857565283775,0.021559439599514,2,,,,,,,,,,,,,,,,
,3886861692.9346,97.1439514160156,0.00121735187713057,,,6,,,,33.765087774429,,,10,,,,,,,,,,,,,,,,,,,,,,97.0827789306641,97.1990280151367,0.00121735187713057,0.00121735187713057,,,6.77172088623047,,1,0,0,0,0.013885498046875,29.3255138397217,6,1,1,97.2051239013672,0,4232057856,97.1466096242269,,,0.000570236759606609,2.01076870530688E-5,0.000570505618709536,2.01081268704355E-5,0.931788682937622,0.938701033592224,33.649471282959,0,30,2,200,-0.000429416249971837,-0.227414309978485,0.0172901563346386,2,,,,,,,,,,,,,,,,
,3886861914.97463,100.799564361572,0.00121735187713057,,,6,,,,33.7703087979655,,,10,,,,,,,,,,,,,,,,,,,,,,100.576873779297,100.999183654785,0.00121735187713057,0.00121735187713057,,,6.78490018844605,,1,0,0,0,0,28.8367557525635,6,1,1,101.022254943848,0,4232057920,100.792850494385,,,0.000534506993227877,1.88495008299006E-5,0.000534823773206115,1.88500003499155E-5,0.930476486682892,0.939119935035706,33.6405944824219,0,30,2,200,-4.75966626254376E-5,-0.217081367969513,0.0129483547061682,2,,,,,,,,,,,,,,,,
,3886862135.83389,104.816070556641,0.00121735187713057,,,6,,,,33.7806928585744,,,10,,,,,,,,,,,,,,,,,,,,,,104.783714294434,104.848426818848,0.00121735187713057,0.00121735187713057,,,6.79938840866089,,1,0,0,0,0,28.8367557525635,5,1,1,104.850448608398,0,4232057600,104.818092981974,,,0.000488743946008741,1.72394702864584E-5,0.000489187169632221,1.72401898057278E-5,0.92737877368927,0.940401017665863,33.620433807373,0,30,2,200,-1.37949598411069E-6,-0.202584967017174,0.00723497103899717,2,,,,,,,,,,,,,,,,
,3886862367.97877,109.226623535156,0.00121735187713057,,,6,,,,33.7908907414803,,,10,,,,,,,,,,,,,,,,,,,,,,109.106513977051,109.342811584473,0.00121735187713057,0.00121735187713057,,,6.81333255767822,,1,0,0,0,0.013885498046875,29.3255138397217,6,1,1,109.358367919922,0,4232057824,109.231824874878,,,0.000445728785255064,1.57251870862908E-5,0.000446239674633008,1.57259584328561E-5,0.924818634986877,0.941099464893341,33.6104736328125,0,30,2,200,-1.23945455925423E-5,-0.189684331417084,0.0018500885926187,2,,,,,,,,,,,,,,,,
,3886862596.0828,112.498783111572,0.00121735187713057,,,6,,,,33.7966024432395,,,10,,,,,,,,,,,,,,,,,,,,,,112.416229248047,112.567100524902,0.00121735187713057,0.00121735187713057,,,6.82560300827026,,1,0,0,0,0,29.3255138397217,6,1,1,112.581336975098,0,4232057792,112.46503384908,,,0.000420484146607147,1.48357788515853E-5,0.000421008964265044,1.48365654335238E-5,0.923745393753052,0.941372752189636,33.608325958252,1.73050157172838E-5,30,2,200,-0.000304789195070043,-0.18212041258812,-0.00145157193765044,2,,,,,,,,,,,,,,,,
,3886862820.35545,117.087448120117,0.00121735187713057,,,6,,,,33.8077206052055,,,10,,,,,,,,,,,,,,,,,,,,,,117.019645690918,117.146980285645,0.00121735187713057,0.00121735187713057,,,6.83715343475342,,1,0,0,0,0.013885498046875,29.3255138397217,6,1,1,117.15779876709,0,4232057792,117.085868199666,,,0.000386801760347138,1.3645883110557E-5,0.000387261788562888,1.36466455777824E-5,0.92518013715744,0.942184090614319,33.624397277832,,30,2,200,-1.31236565721338E-5,-0.171833530068398,-0.00560224102810025,2,,,,,,,,,,,,,,,,
,3886863041.40945,120.28324508667,0.00121735187713057,,,6,,,,33.8137902495623,,,10,,,,,,,,,,,,,,,,,,,,,,120.066566467285,120.479591369629,0.00121735187713057,0.00121735187713057,,,6.84776020050049,,1,0,0,0,0.013885498046875,29.3255138397217,6,1,1,120.499923706055,0,4232057696,120.26350402832,,,0.000366989131199647,1.29461783969424E-5,0.000367417859157556,1.29469020367855E-5,0.925948441028595,0.942815542221069,33.6322288513184,0,30,2,200,-0.000264246773440391,-0.166152685880661,-0.00821058079600334,2,,,,,,,,,,,,,,,,
,3886863256.21227,124.563636779785,0.00121735187713057,,,6,,,,33.8252853579366,,,10,,,,,,,,,,,,,,,,,,,,,,124.49227142334,124.62865447998,0.00121735187713057,0.00121735187713057,,,6.85921430587769,,1,0,0,0,0.013885498046875,29.3255138397217,6,1,1,124.63500213623,0,4232058080,124.564926147461,,,0.000350970009737,1.23827226075151E-5,0.000351421890648171,1.23834453841843E-5,0.924189507961273,0.942539572715759,33.6344413757324,0,30,2,200,-0.000230397781706415,-0.160990610718727,-0.010211587883532,2,,,,,,,,,,,,,,,,
,3886863469.28333,127.483604431152,0.00121735187713057,,,6,,,,33.8356895965781,,,10,,,,,,,,,,,,,,,,,,,,,,127.409973144531,127.550819396973,0.00121735187713057,0.00121735187713057,,,6.8681697845459,,1,0,0,0,0.013885498046875,27.8592376708984,6,1,1,127.557235717773,0,4232057664,127.450544504019,,,0.000344133327801025,1.21416450920609E-5,0.00034457767604447,1.21423636384365E-5,0.92404305934906,0.942395746707916,33.6445999145508,0,30,2,200,-0.000256740080658346,-0.159168139100075,-0.0112894382327795,2,,,,,,,,,,,,,,,,
,3886863685.90844,131.874252319336,0.00121735187713057,,,6,,,,33.846573181674,,,10,,,,,,,,,,,,,,,,,,,,,,131.780136108398,131.959060668945,0.00121735187713057,0.00121735187713057,,,6.87752771377564,,1,0,0,0,0,28.8367557525635,6,1,1,131.968368530273,0,4232057728,131.872689565023,,,0.000336712656601009,1.1878910248079E-5,0.000337113085211807,1.18795408505277E-5,0.925066351890564,0.942083179950714,33.6630401611328,5.80198574066162,30,2,200,-0.000167323945788667,-0.156905740499496,-0.0123051814734936,2,,,,,,,,,,,,,,,,
,3886863912.24667,134.985191345215,0.00121735187713057,,,6,,,,33.8571521230046,,,10,,,,,,,,,,,,,,,,,,,,,,134.905029296875,135.046539306641,0.00121735187713057,0.00121735187713057,,,6.88602352142334,,1,0,0,0,0.013885498046875,29.3255138397217,6,1,1,135.065353393555,0,4232057856,134.951496124268,,,0.000332086979668074,1.17154298429111E-5,0.0003324688594852,1.17160399674679E-5,0.925390124320984,0.941844582557678,33.6767234802246,0.0894389301538467,30,2,200,-0.000186863137059845,-0.155712217092514,-0.0129923038184643,2,,,,,,,,,,,,,,,,
,3886864127.41407,139.34268951416,0.00121735187713057,,,6,,,,33.8675584135402,,,10,,,,,,,,,,,,,,,,,,,,,,139.246917724609,139.428939819336,0.00121735187713057,0.00121735187713057,,,6.89498090744019,,1,0,0,0,0.013885498046875,28.8367557525635,6,1,1,139.438461303711,0,4232057760,139.346332550049,,,0.000326986763423116,1.15345331097627E-5,0.000327331500721687,1.15350828720726E-5,0.926522970199585,0.941728353500366,33.6947898864746,0,30,2,200,-1.22417068268987E-5,-0.154143542051315,-0.0137554816901684,2,,,,,,,,,,,,,,,,
,3886864360.10844,142.478622436523,0.00121735187713057,,,6,,,,33.8785498504932,,,10,,,,,,,,,,,,,,,,,,,,,,142.406677246094,142.538238525391,0.00121735187713057,0.00121735187713057,,,6.90148115158081,,1,0,0,0,0.013885498046875,29.3255138397217,6,1,1,142.550567626953,0,4232057728,142.450138092041,,,0.000323395547143552,1.14076064651578E-5,0.000323725822527537,1.14081361726075E-5,0.926816523075104,0.941555738449097,33.7085189819336,0,30,2,200,-2.70961354544852E-5,-0.153289884328842,-0.014404178597033,2,,,,,,,,,,,,,,,,
,3886864578.42477,146.834983825684,0.00121735187713057,,,6,,,,33.8898442297573,,,10,,,,,,,,,,,,,,,,,,,,,,146.73860168457,146.928436279297,0.00121735187713057,0.00121735187713057,,,6.91015100479126,,1,0,0,0,0.013885498046875,29.8142719268799,6,1,1,146.931365966797,0,4232057824,146.839019775391,,,0.000319149229741537,1.12570775794145E-5,0.000319450029145713,1.1257569246991E-5,0.92771989107132,0.941387474536896,33.7265777587891,1.62806682055816E-5,30,2,200,-5.01125532537117E-6,-0.151990622282028,-0.0149215068668127,2,,,,,,,,,,,,,,,,
,3886864808.92297,149.960357666016,0.00121735187713057,,,6,,,,33.901097969639,,,10,,,,,,,,,,,,,,,,,,,,,,149.893859863281,150.017318725586,0.00121735187713057,0.00121735187713057,,,6.91769933700562,,1,0,0,0,0,29.3255138397217,6,1,1,150.02685546875,0,4232057952,149.930287679036,,,0.000316147191761981,1.11508395972937E-5,0.000316432217584259,1.11513257863906E-5,0.928147852420807,0.941220641136169,33.7415618896484,4.35889911651611,30,2,200,-2.87402726826258E-5,-0.151324167847633,-0.0154838571324944,2,,,,,,,,,,,,,,,,
,3886865029.26754,154.300025939941,0.00121735187713057,,,6,,,,33.9115333115298,,,10,,,,,,,,,,,,,,,,,,,,,,154.197967529297,154.392547607422,0.00121735187713057,0.00121735187713057,,,6.92567873001099,,1,0,0,0,0.014801025390625,29.3255138397217,6,1,1,154.402084350586,0,4232057536,154.299849192301,,,0.00031261058067135,1.10251251370588E-5,0.000312861975602994,1.10255025594224E-5,0.929387152194977,0.941234171390534,33.7603950500488,5.81036949157715,30,2,200,-2.51118240157666E-6,-0.150275319814682,-0.0160443000495434,2,,,,,,,,,,,,,,,,
,3886865265.06276,157.457794189453,0.00121735187713057,,,6,,,,33.9222601542359,,,10,,,,,,,,,,,,,,,,,,,,,,157.399017333984,157.500869750977,0.00121735187713057,0.00121735187713057,,,6.93304347991943,,1,0,0,0,0.013885498046875,30.7917900085449,6,1,1,157.516571044922,0,4232058016,157.433232625326,,,0.000309892177575982,1.09288792581192E-5,0.000310128370716876,1.09292352768708E-5,0.929864704608917,0.941123425960541,33.7751274108887,1.61107891472057E-5,30,2,200,-4.98674398841104E-6,-0.149666592478752,-0.0165837220847607,2,,,,,,,,,,,,,,,,
,3886865487.25815,161.789596557617,0.00121735187713057,,,6,,,,33.9387956709867,,,10,,,,,,,,,,,,,,,,,,,,,,161.695053100586,161.874282836914,0.00121735187713057,0.00121735187713057,,,6.94017314910889,,1,0,0,0,0.013885498046875,29.8142719268799,6,1,1,161.884140014648,0,4232058144,161.786996205648,,,0.000306737604497017,1.08173828544524E-5,0.000306962274855133,1.08177293032062E-5,0.930188298225403,0.941015124320984,33.7946166992188,0.133450657129288,30,2,200,-1.43775423566694E-5,-0.148695006966591,-0.0170652884989977,2,,,,,,,,,,,,,,,,
,3886865722.9975,164.944580078125,0.00121735187713057,,,6,,,,33.9496471201971,,,10,,,,,,,,,,,,,,,,,,,,,,164.891235351562,164.982681274414,0.00121735187713057,0.00121735187713057,,,6.94665145874023,,1,0,0,0,0.013885498046875,29.3255138397217,6,1,1,164.997924804687,0,4232057792,164.921137491862,,,0.000304313400795162,1.07315707251641E-5,0.000304524771370626,1.07319015979911E-5,0.930615901947021,0.940901398658752,33.8092880249023,0.133443847298622,30,2,200,-4.59880902781151E-5,-0.14819797873497,-0.0174578446894884,2,,,,,,,,,,,,,,,,
,3886865945.64566,169.289054870605,0.00121735187713057,,,6,,,,33.9616353844434,,,10,,,,,,,,,,,,,,,,,,,,,,169.192245483398,169.376846313477,0.00121735187713057,0.00121735187713057,,,6.95363235473633,,1,0,0,0,0.0139617919921875,29.8142719268799,6,1,1,169.385864257813,0,4232057888,169.285818735758,,,0.000301406583348999,1.06283219792532E-5,0.000301592461643751,1.06286086360184E-5,0.931624054908752,0.940830707550049,33.8293228149414,,30,2,200,-1.90895189007279E-5,-0.147327750921249,-0.0179484710097313,2,,,,,,,,,,,,,,,,
,3886866161.06207,172.332893371582,0.00121735187713057,,,6,,,,33.9720361823104,,,10,,,,,,,,,,,,,,,,,,,,,,172.309906005859,172.354827880859,0.00121735187713057,0.00121735187713057,,,6.95869874954224,,1,0,0,0,0.013885498046875,29.3255138397217,5,1,1,172.355880737305,0,4232057696,172.334729512533,,,0.00029918127803346,1.0549603625321E-5,0.000299355733494813,1.05498610116949E-5,0.931966245174408,0.940703630447388,33.8432388305664,0,30,2,200,-1.23094823720749E-5,-0.14673587679863,-0.0183082837611437,2,,,,,,,,,,,,,,,,
,3886866396.15159,176.576057434082,0.00121735187713057,,,6,,,,33.9882005341907,,,10,,,,,,,,,,,,,,,,,,,,,,176.452499389648,176.688278198242,0.00121735187713057,0.00121735187713057,,,6.96626329421997,,1,0,0,0,0.0006103515625,29.3255138397217,6,1,1,176.699615478516,0,4232057824,176.573095957438,,,0.000296497393977036,1.04545880020097E-5,0.000296658333800109,1.04548332167634E-5,0.932488679885864,0.940640330314636,33.8640327453613,,30,2,200,-1.76738612935878E-5,-0.14608670771122,-0.018855731934309,2,,,,,,,,,,,,,,,,
,3886866610.6243,179.766036987305,0.00121735187713057,,,6,,,,33.9990583369387,,,10,,,,,,,,,,,,,,,,,,,,,,179.73420715332,179.796340942383,0.00121735187713057,0.00121735187713057,,,6.97239208221436,,1,0,0,0,0,30.7917900085449,5,1,1,179.797866821289,0,4232057664,179.767555236816,,,0.000294324697005503,1.03777126048938E-5,0.000294474976715796,1.03779482742564E-5,0.932878851890564,0.940555334091187,33.8787002563477,5.82054138183594,30,2,200,-2.13619423448108E-5,-0.145475164055824,-0.0191672667860985,2,,,,,,,,,,,,,,,,
,3886866847.03116,183.726409912109,0.00121735187713057,,,6,,,,34.0156153231199,,,10,,,,,,,,,,,,,,,,,,,,,,183.573577880859,183.867141723633,0.00121735187713057,0.00121735187713057,,,6.97928333282471,,1,0,0,0,0.013885498046875,29.3255138397217,6,1,1,183.879241943359,0,4232057984,183.725336710612,,,0.000291898594729245,1.02919288472393E-5,0.000292039610727857,1.02921527366712E-5,0.933228611946106,0.940505027770996,33.8985824584961,0,30,2,200,-0.000283970613963902,-0.144976183772087,-0.0197471790015697,2,,,,,,,,,,,,,,,,
,3886867063.28846,187.191093444824,0.00121735187713057,,,6,,,,34.0270968836932,,,10,,,,,,,,,,,,,,,,,,,,,,187.150848388672,187.224853515625,0.00121735187713057,0.00121735187713057,,,6.98428058624268,,1,0,0,0,0.013885498046875,29.8142719268799,5,1,1,187.231338500977,0,4232057376,187.189486416903,,,0.000289657307441559,1.02125406770015E-5,0.000289785245398697,1.02127399149637E-5,0.933755159378052,0.940438568592072,33.9151229858398,0.133426159620285,30,2,200,-0.000279365514870733,-0.144281476736069,-0.0200152415782213,2,,,,,,,,,,,,,,,,
,3886867302.78027,190.933723449707,0.00121735187713057,,,6,,,,34.0446267196168,,,10,,,,,,,,,,,,,,,,,,,,,,190.752868652344,191.096389770508,0.00121735187713057,0.00121735187713057,,,6.99096345901489,,1,0,0,0,0,28.8367557525635,6,1,1,191.11457824707,0,4232057984,190.928396860758,,,0.000287534109229243,1.01375012596901E-5,0.000287657715576583,1.01376913770555E-5,0.934024751186371,0.940553426742554,33.9341354370117,7.84067087806761E-5,30,2,200,-0.000282444671029225,-0.143858134746552,-0.0204908065497875,2,,,,,,,,,,,,,,,,
,3886867517.95427,194.570709228516,0.00121735187713057,,,6,,,,34.056028306267,,,10,,,,,,,,,,,,,,,,,,,,,,194.509674072266,194.628036499023,0.00121735187713057,0.00121735187713057,,,6.99580764770508,,1,0,0,0,0.013885498046875,29.3255138397217,6,1,1,194.631744384766,0,4232057920,194.574131011963,,,0.000285328650921435,1.00594474119158E-5,0.000285438947149123,1.0059594847395E-5,0.934469759464264,0.940388977527618,33.9509315490723,5.82674264907837,30,2,200,-0.000280337641015649,-0.143250957131386,-0.0208440646529198,2,,,,,,,,,,,,,,,,
,3886867758.76611,197.946464538574,0.00121735187713057,,,6,,,,34.0738874333024,,,10,,,,,,,,,,,,,,,,,,,,,,197.728256225586,198.142639160156,0.00121735187713057,0.00121735187713057,,,7.00252103805542,,1,0,0,0,0.012969970703125,29.3255138397217,6,1,1,198.164672851562,0,4232057920,197.94854482015,,,0.000283224942674725,9.98539628301194E-6,0.000283335273492463,9.98556078224946E-6,0.934301137924194,0.940223097801208,33.968620300293,0.0592150762677193,30,2,200,-0.000278926017927006,-0.142768710851669,-0.0212538260966539,2,,,,,,,,,,,,,,,,
,3886867976.25214,201.92586517334,0.00121735187713057,,,6,,,,34.0860861513478,,,10,,,,,,,,,,,,,,,,,,,,,,201.851425170898,201.995666503906,0.00121735187713057,0.00121735187713057,,,7.00819444656372,,1,0,0,0,0.013885498046875,29.8142719268799,6,1,1,202.002899169922,0,4232057760,201.927040100098,,,0.000280993519147909,9.90625440527979E-6,0.000281091276144645,9.90637280901087E-6,0.935013353824615,0.940383672714233,33.986198425293,0.185487017035484,30,2,200,-0.000256166938925162,-0.142151400446892,-0.0216242894530296,2,,,,,,,,,,,,,,,,
,3886868213.37245,204.987174987793,0.00121735187713057,,,6,,,,34.1014924967434,,,10,,,,,,,,,,,,,,,,,,,,,,204.921264648438,205.022262573242,0.00121735187713057,0.00121735187713057,,,7.01288223266602,,1,0,0,0,0.013885498046875,29.3255138397217,6,1,1,205.053085327148,0,4232057856,204.953970591227,,,0.000279297194143614,9.84617994297396E-6,0.000279387993699225,9.84630264087484E-6,0.935437798500061,0.940455734729767,34.0051383972168,0.000554554280824959,30,2,200,-1.96031051018508E-5,-0.142215386033058,-0.022228442132473,2,,,,,,,,,,,,,,,,
,3886868426.70845,209.017799377441,0.00121735187713057,,,6,,,,34.1181645500515,,,10,,,,,,,,,,,,,,,,,,,,,,208.895172119141,209.135711669922,0.00121735187713057,0.00121735187713057,,,7.01900100708008,,1,0,0,0,0.0139617919921875,29.3255138397217,6,1,1,209.140426635742,0,4232057728,209.018232981364,,,0.000277329557318126,9.77669148879537E-6,0.000277416532795576,9.77681979619886E-6,0.935640454292297,0.940472066402435,34.0236892700195,0,30,2,200,-1.89392139873235E-5,-0.141545102000237,-0.0225907582789659,2,,,,,,,,,,,,,,,,
,3886868643.34579,212.247001647949,0.00121735187713057,,,6,,,,34.1287513171379,,,10,,,,,,,,,,,,,,,,,,,,,,212.212493896484,212.277923583984,0.00121735187713057,0.00121735187713057,,,7.02570390701294,,1,0,0,0,0.013885498046875,30.7917900085449,5,1,1,212.281509399414,0,4232057760,212.247393290202,,,0.000275652508292852,9.71732490392244E-6,0.000275729510835526,9.71742838964341E-6,0.936032891273498,0.940363347530365,34.0394134521484,0,30,2,200,-1.59521041496191E-5,-0.141144648194313,-0.0228854045271873,2,,,,,,,,,,,,,,,,
,3886868884.91076,216.187294006348,0.00121735187713057,,,6,,,,34.1503488552742,,,10,,,,,,,,,,,,,,,,,,,,,,216.041198730469,216.310729980469,0.00121735187713057,0.00121735187713057,,,7.03395318984985,,1,0,0,0,0,29.8142719268799,6,1,1,216.333389282227,0,4232057536,216.179017384847,,,0.000273605553538893,9.64518832252383E-6,0.000273682372067228,9.64527595048823E-6,0.935990869998932,0.940368056297302,34.0605201721191,0,30,2,200,-3.86328019885696E-6,-0.140677705407143,-0.0233391150832176,2,,,,,,,,,,,,,,,,
,3886869092.59179,219.555572509766,0.00121735187713057,,,6,,,,34.1613894975354,,,10,,,,,,,,,,,,,,,,,,,,,,219.49772644043,219.609802246094,0.00121735187713057,0.00121735187713057,,,7.04158163070679,,1,0,0,0,0.013885498046875,29.8142719268799,6,1,1,219.613418579102,0,4232057792,219.557936350505,,,0.00027190145840903,9.58488112176939E-6,0.000271969746148592,9.58497778950707E-6,0.936376392841339,0.940269470214844,34.0767707824707,7.01350072631612E-5,30,2,200,-2.15724976442289E-5,-0.140208810567856,-0.0235488042235374,2,,,,,,,,,,,,,,,,
,3886869328.78869,222.749160766602,0.00121735187713057,,,6,,,,34.1773053982188,,,10,,,,,,,,,,,,,,,,,,,,,,222.553726196289,222.916244506836,0.00121735187713057,0.00121735187713057,,,7.05042362213135,,1,0,0,0,0.013885498046875,29.8142719268799,6,1,1,222.944595336914,0,4232057888,222.727616628011,,,0.00027000052881348,9.51781768727494E-6,0.000270064704738871,9.51788353566954E-6,0.936458468437195,0.940185308456421,34.0945014953613,0,30,2,200,-0.000235233092098497,-0.139875590801239,-0.0241018943488598,2,,,,,,,,,,,,,,,,
,3886869552.44656,226.909378051758,0.00121735187713057,,,6,,,,34.1948899093663,,,10,,,,,,,,,,,,,,,,,,,,,,226.832046508789,226.98176574707,0.00121735187713057,0.00121735187713057,,,7.06027460098267,,1,0,0,0,0.013885498046875,29.3255138397217,6,1,1,226.986709594727,0,4232058112,226.910279591878,,,0.000267898580707386,9.44356125172951E-6,0.000267956460646435,9.44361938600434E-6,0.936732590198517,0.94012838602066,34.1159324645996,6.81343663018197E-5,30,2,200,-0.000246092793531716,-0.139291182160378,-0.0243837460875511,2,,,,,,,,,,,,,,,,
,3886869788.17209,229.953926086426,0.00121735187713057,,,6,,,,34.210569836085,,,10,,,,,,,,,,,,,,,,,,,,,,229.880004882813,230.01139831543,0.00121735187713057,0.00121735187713057,,,7.07410955429077,,1,0,0,0,0.013885498046875,29.3255138397217,6,1,1,230.027847290039,0,4232057856,229.924462636312,,,0.000266240186652929,9.38502215173697E-6,0.000266297222698415,9.38509187691993E-6,0.936863005161285,0.94021463394165,34.1321983337402,0,30,2,200,-1.36715316330083E-5,-0.139051720499992,-0.0247443541884422,2,,,,,,,,,,,,,,,,
,3886870013.76702,234.224166870117,0.00121735187713057,,,6,,,,34.22915000977,,,10,,,,,,,,,,,,,,,,,,,,,,234.124984741211,234.317901611328,0.00121735187713057,0.00121735187713057,,,7.09353494644165,,1,0,0,0,0.013885498046875,29.8142719268799,6,1,1,234.323348999023,0,4232057824,234.223089853923,,,0.000264429289975814,9.32088310715064E-6,0.000264477888835901,9.32094170322841E-6,0.937386155128479,0.940276861190796,34.1565361022949,0,30,2,200,-3.68526198144536E-5,-0.138438001275063,-0.0249639768153429,2,,,,,,,,,,,,,,,,
,3886870239.92642,237.323402404785,0.00121735187713057,,,6,,,,34.2470981688754,,,10,,,,,,,,,,,,,,,,,,,,,,237.3017578125,237.344482421875,0.00121735187713057,0.00121735187713057,,,7.1158561706543,,1,0,0,0,0.013885498046875,29.3255138397217,5,1,1,237.346160888672,0,4232057824,237.325108846029,,,0.000263016892333469,9.27121232307637E-6,0.00026306726961841,9.27126194294506E-6,0.937183499336243,0.940208852291107,34.1727333068848,0,30,2,200,-0.000268869684077799,-0.138106480240822,-0.0252845697104931,2,,,,,,,,,,,,,,,,
,3886870479.67607,241.486953735352,0.00121735187713057,,,6,,,,34.2663063913721,,,10,,,,,,,,,,,,,,,,,,,,,,241.3603515625,241.609436035156,0.00121735187713057,0.00121735187713057,,,7.14984607696533,,1,0,0,0,0.013885498046875,30.7917900085449,6,1,1,241.613555908203,0,4232058240,241.481808980306,,,0.000261359375846219,9.21265652303429E-6,0.000261404548771286,9.21270277088756E-6,0.937399685382843,0.940129697322845,34.1956977844238,5.8477087020874,30,2,200,-0.00027529353974387,-0.137827575206757,-0.0256218537688255,2,,,,,,,,,,,,,,,,
,3886870707.06005,244.768753051758,0.00121735187713057,,,6,,,,34.2818546252497,,,10,,,,,,,,,,,,,,,,,,,,,,244.739242553711,244.79460144043,0.00121735187713057,0.00121735187713057,,,7.19134616851807,,1,0,0,0,0,29.3255138397217,5,1,1,244.798263549805,0,4232058304,244.768919626872,,,0.000259918821810062,9.16171808287807E-6,0.000259960731303458,9.16175670500485E-6,0.937691330909729,0.94025456905365,34.2135543823242,0,30,2,200,-7.39456982046249E-6,-0.137338921427727,-0.0258428268134594,2,,,,,,,,,,,,,,,,
,3886870944.1575,248.70809173584,0.00121735187713057,,,6,,,,34.3047135539688,,,10,,,,,,,,,,,,,,,,,,,,,,248.549758911133,248.847106933594,0.00121735187713057,0.00121735187713057,,,7.25237226486206,,1,0,0,0,0.013885498046875,29.3255138397217,6,1,1,248.866424560547,0,4232058112,248.704181671143,,,0.000258348513214552,9.10637915766294E-6,0.000258389459023312,9.10641676041763E-6,0.937664926052094,0.940182626247406,34.2369995117188,6.31431830697693E-5,30,2,200,-0.000269187556114048,-0.137069672346115,-0.0262688416987658,2,,,,,,,,,,,,,,,,
,3886871172.7422,252.202751159668,0.00121735187713057,,,6,,,,34.3207824194694,,,10,,,,,,,,,,,,,,,,,,,,,,252.161056518555,252.241577148438,0.00121735187713057,0.00121735187713057,,,7.33000802993774,,1,0,0,0,0,29.8142719268799,5,1,1,252.244445800781,0,4232057824,252.204077402751,,,0.000256760412196343,9.05025604864552E-6,0.000256797312546867,9.05029773817617E-6,0.937923789024353,0.940197885036468,34.2564964294434,,30,2,200,-7.24134770280216E-6,-0.136621758341789,-0.0264292974025011,2,,,,,,,,,,,,,,,,
,3886871409.58793,255.829483032227,0.00121735187713057,,,6,,,,34.344182437351,,,10,,,,,,,,,,,,,,,,,,,,,,255.652893066406,255.972702026367,0.00121735187713057,0.00121735187713057,,,7.43754148483276,,1,0,0,0,0,30.7917900085449,6,1,1,256.006072998047,0,4232057824,255.813952128092,,,0.000255286764533358,8.99824906140654E-6,0.000255323553628275,8.99829378979463E-6,0.938034355640411,0.940313160419464,34.2798957824707,7.49742603302002,30,2,200,-0.000252245081355795,-0.136432111263275,-0.0268245954066515,2,,,,,,,,,,,,,,,,
,3886871637.90071,259.6015625,0.00121735187713057,,,6,,,,34.3607452230717,,,10,,,,,,,,,,,,,,,,,,,,,,259.549926757813,259.648010253906,0.00121735187713057,0.00121735187713057,,,7.5807056427002,,1,0,0,0,0,29.3255138397217,6,1,1,259.653198242187,0,4232057760,259.603233337402,,,0.000253705636587908,8.94242134549189E-6,0.000253737419761027,8.94245384093689E-6,0.938209295272827,0.940202653408051,34.3006324768066,,30,2,200,-3.82263388019055E-5,-0.13593415915966,-0.0270313043147326,2,,,,,,,,,,,,,,,,
,3886871889.08928,263.320205688477,0.00121735187713057,,,6,,,,34.3821202367407,,,10,,,,,,,,,,,,,,,,,,,,,,263.143585205078,263.483184814453,0.00121735187713057,0.00121735187713057,,,7.7721152305603,,1,0,0,0,0.013885498046875,29.3255138397217,6,1,1,263.496826171875,0,4232057824,263.314239501953,,,0.00025215045418557,8.88741947531652E-6,0.000252178247696049,8.88744450120446E-6,0.938543677330017,0.940310299396515,34.3256378173828,,30,2,200,-3.86596730095334E-5,-0.135629862546921,-0.0274795703589916,2,,,,,,,,,,,,,,,,
,3886872118.6519,267.085037231445,0.00121735187713057,,,6,,,,34.4042565263314,,,10,,,,,,,,,,,,,,,,,,,,,,267.029632568359,267.135986328125,0.00121735187713057,0.00121735187713057,,,7.99371242523193,,1,0,0,0,0.013885498046875,29.8142719268799,6,1,1,267.140441894531,0,4232057792,267.08605448405,,,0.000250472657797979,8.82824368845776E-6,0.000250498475335459,8.82826223846352E-6,0.93862396478653,0.940285563468933,34.3494873046875,7.49705505371094,30,2,200,-0.000258674321230501,-0.135173976421356,-0.0276993922889233,2,,,,,,,,,,,,,,,,
,3886872354.9909,270.171279907227,0.00121735187713057,,,6,,,,34.4209285504874,,,10,,,,,,,,,,,,,,,,,,,,,,270.003173828125,270.324127197266,0.00121735187713057,0.00121735187713057,,,8.24258613586426,,1,0,0,0,0.0232696533203125,28.8367557525635,6,1,1,270.339385986328,0,4232057728,270.158953348796,,,0.00024874829310154,8.76716304106683E-6,0.000248767235130849,8.76717409555256E-6,0.939185321331024,0.940424859523773,34.3737640380859,,30,2,200,-2.4605078579043E-5,-0.134882628917694,-0.0281186122447252,2,,,,,,,,,,,,,,,,
,3886872591.93355,274.473510742187,0.00121735187713057,,,6,,,,34.4442564497354,,,10,,,,,,,,,,,,,,,,,,,,,,274.407379150391,274.535552978516,0.00121735187713057,0.00121735187713057,,,8.46345329284668,,1,0,0,0,0.013885498046875,29.3255138397217,6,1,1,274.539642333984,0,4232057728,274.472989400228,,,0.000246764884801254,8.69714637869587E-6,0.000246779137632554,8.69715202892568E-6,0.939389288425446,0.940335512161255,34.4030685424805,,30,2,200,-0.000257353036431596,-0.13426861166954,-0.0282693319022655,2,,,,,,,,,,,,,,,,
,3886872826.09726,277.446151733398,0.00121735187713057,,,6,,,,34.4612939565169,,,10,,,,,,,,,,,,,,,,,,,,,,277.376770019531,277.515533447266,0.00121735187713057,0.00121735187713057,,,8.5956449508667,,1,0,0,0,0.013885498046875,29.3255138397217,6,1,1,277.521636962891,0,4232057952,277.421818659856,,,0.00024539018441378,8.64856920702307E-6,0.00024540013638823,8.64856974845297E-6,0.939629256725311,0.940301299095154,34.4266090393066,0,30,2,200,-3.57563949364703E-5,-0.134106203913689,-0.0287335738539696,2,,,,,,,,,,,,,,,,
,3886873064.10046,281.820907592773,0.00121735187713057,,,6,,,,34.4904804290067,,,10,,,,,,,,,,,,,,,,,,,,,,281.735504150391,281.900634765625,0.00121735187713057,0.00121735187713057,,,8.82454204559326,,1,0,0,0,0.013885498046875,29.8142719268799,6,1,1,281.906311035156,0,4232057824,281.827435811361,,,0.000243653346024089,8.58711771389334E-6,0.00024365910051155,8.5871152851934E-6,0.940091609954834,0.940490484237671,34.4638328552246,3.93972695746925E-5,30,2,200,-3.30400689563248E-5,-0.133571356534958,-0.0289483889937401,2,,,,,,,,,,,,,,,,
,3886873293.31873,284.838882446289,0.00121735187713057,,,6,,,,34.5079916163311,,,10,,,,,,,,,,,,,,,,,,,,,,284.8203125,284.855743408203,0.00121735187713057,0.00121735187713057,,,9.07441806793213,,1,0,0,0,0.014801025390625,29.8142719268799,5,1,1,284.857452392578,0,4232057792,284.840558369954,,,0.000242097182202508,8.53219161736655E-6,0.000242099442242137,8.53218919164875E-6,0.940249145030975,0.94040983915329,34.4910850524902,,30,2,200,-3.41878258041106E-5,-0.133111208677292,-0.0291719455271959,2,,,,,,,,,,,,,,,,
,3886873536.22891,289.062316894531,0.00121735187713057,,,6,,,,34.5324564684091,,,10,,,,,,,,,,,,,,,,,,,,,,288.939971923828,289.1708984375,0.00121735187713057,0.00121735187713057,,,9.33920955657959,,1,0,0,0,0.013885498046875,30.7917900085449,6,1,1,289.184661865234,0,4232057792,289.062271118164,,,0.000240346840939097,8.47039037381207E-6,0.000240346890371282,8.47038909016718E-6,0.940474271774292,0.94048023223877,34.5291976928711,0,30,2,200,-3.5991699405713E-5,-0.132723063230515,-0.0295563954859972,2,,,,,,,,,,,,,,,,
,3886873760.02656,292.252502441406,0.00121735187713057,,,6,,,,34.5493110318966,,,10,,,,,,,,,,,,,,,,,,,,,,292.219299316406,292.283538818359,0.00121735187713057,0.00121735187713057,,,9.35360050201416,,1,0,0,0,0.013885498046875,29.8142719268799,5,1,1,292.285705566406,0,4232057696,292.254572550456,,,0.000238732110764044,8.41349554263756E-6,0.000238732733636508,8.41349837316436E-6,0.940459728240967,0.940497756004333,34.5575256347656,0,30,2,200,-2.37967651628423E-5,-0.132227122783661,-0.029773436486721,2,,,,,,,,,,,,,,,,
,3886874005.24924,296.142349243164,0.00121735187713057,,,6,,,,34.5748658740778,,,10,,,,,,,,,,,,,,,,,,,,,,295.984313964844,296.28955078125,0.00121735187713057,0.00121735187713057,,,9.4834451675415,,1,0,0,0,0.013885498046875,29.3255138397217,6,1,1,296.300384521484,0,4232057824,296.146893819173,,,0.000236948792919967,8.35082639889812E-6,0.000236953139678413,8.35084246844496E-6,0.94010055065155,0.940374314785004,34.5969505310059,0,30,2,200,-0.000219689856749028,-0.131914228200912,-0.0302128810435534,2,,,,,,,,,,,,,,,,
,3886874244.70184,299.743103027344,0.00121735187713057,,,6,,,,34.5994640599913,,,10,,,,,,,,,,,,,,,,,,,,,,299.710815429687,299.773529052734,0.00121735187713057,0.00121735187713057,,,9.5614013671875,,1,0,0,0,0.013885498046875,29.8142719268799,5,1,1,299.775390625,0,4232056832,299.743166605632,,,0.000235226941832966,8.29026830092978E-6,0.000235236849876877,8.29029393149893E-6,0.939846277236938,0.940496265888214,34.6335105895996,4.41903903265484E-5,30,2,200,-2.27933869609842E-5,-0.131357610225677,-0.0301795415580273,2,,,,,,,,,,,,,,,,
,3886874471.32154,299.987030029297,12151.234375,,,6,,,,34.5994640599913,,,1000,,,,,,,,,,,,,,,,,,,,,,299.979949951172,299.996704101562,9091.287109375,15870.6630859375,,,10.0501680374146,,1,0,0,0,0.013885498046875,29.3255138397217,1,6,1,299.994110107422,0,4232056832,299.991251627604,,,0.00596818042389864,0.000778158933622196,0.0118431177347564,0.000840594411843176,0.0370881445705891,0.131476834416389,43.5093765258789,0.0176265891641378,30,2,200,-1.3176007270813,-3.30401396751404,-0.235314831137657,2,,,,,,,,,,,,,,,,
,3886874670.32172,300.003234863281,0.00121735187713057,,,6,,,,34.5994640599913,,,10,,,,,,,,,,,,,,,,,,,,,,300.003021240234,300.006286621094,0.00121735187713057,0.00121735187713057,,,10.0870332717896,,1,0,0,0,0.013885498046875,29.8142719268799,1,1,1,300.00244140625,0,4232056832,300.00498453776,,,0.000513467021404808,1.80958721208274E-5,0.000513473457509868,1.80958986559383E-5,0.940401256084442,0.940586566925049,34.6175918579102,3.20257022394799E-5,30,2,200,-0.000255318358540535,-0.205881983041763,0.0162897929549217,2,,,,,,,,,,,,,,,,
,3886874863.53723,300,0.00121735187713057,,,6,,,,34.5994640599913,,,10,,,,,,,,,,,,,,,,,,,,,,299.999755859375,300.002899169922,0.00121735187713057,0.00121735187713057,,,10.1797962188721,,1,0,0,0,0.013885498046875,29.3255138397217,1,1,1,299.999572753906,0,4232056832,300.001681009928,,,0.000510175383994791,1.79798710876433E-5,0.00051018073394074,1.79798939286148E-5,0.940404534339905,0.940558791160584,34.6160087585449,3.06801339320373E-5,30,2,200,-7.47644371585921E-5,-0.215104728937149,0.00400900887325406,2,,,,,,,,,,,,,,,,
,3886875056.41931,300.004165649414,0.00121735187713057,,,6,,,,34.5994640599913,,,10,,,,,,,,,,,,,,,,,,,,,,300.003112792969,300.007080078125,0.00121735187713057,0.00121735187713057,,,10.2215490341187,,1,0,0,0,0.014801025390625,28.3479976654053,1,1,1,300.005218505859,0,4232056832,300.005592346191,,,0.000506556980274561,1.78524504997043E-5,0.000506566933299582,1.78524922192203E-5,0.94030100107193,0.940590620040894,34.6221389770508,0,30,2,200,-7.74616273702122E-5,-0.216329798102379,0.0011164746247232,2,,,,,,,,,,,,,,,,
,3886875249.48888,299.999114990234,0.00121735187713057,,,6,,,,34.5994640599913,,,10,,,,,,,,,,,,,,,,,,,,,,299.998718261719,300.001892089844,0.00121735187713057,0.00121735187713057,,,10.2895526885986,,1,0,0,0,0.013885498046875,28.8367557525635,1,1,1,299.998626708984,0,4232056832,300.000467936198,,,0.000502443750485283,1.77076577625615E-5,0.000502457984468658,1.77077014477463E-5,0.940140128135681,0.940572202205658,34.6271781921387,0,30,2,200,-5.22023547091521E-5,-0.216735035181046,-0.000987529871053994,2,,,,,,,,,,,,,,,,
,3886875443.31435,300.000244140625,0.00121735187713057,,,6,,,,34.5994640599913,,,10,,,,,,,,,,,,,,,,,,,,,,299.999450683594,300.002288818359,0.00121735187713057,0.00121735187713057,,,10.3344297409058,,1,0,0,0,0.013885498046875,29.8142719268799,1,1,1,300.001037597656,0,4232056832,300.001373291016,,,0.000496519655874989,1.74997136321841E-5,0.000496561245891626,1.74998231318605E-5,0.939348101615906,0.940634965896606,34.6474380493164,,30,2,200,-8.26418327051215E-5,-0.216157048940659,-0.00298420619219542,2,,,,,,,,,,,,,,,,
,3886875635.607,300.001449584961,0.00121735187713057,,,6,,,,34.5994640599913,,,10,,,,,,,,,,,,,,,,,,,,,,300.001251220703,300.003631591797,0.00121735187713057,0.00121735187713057,,,10.3626041412354,,1,0,0,0,0.013885498046875,29.3255138397217,1,1,1,300.000915527344,0,4232056832,300.002632141113,,,0.000487260001902874,1.71749687399706E-5,0.0004873305562874,1.71751343395286E-5,0.937827467918396,0.940032124519348,34.6628189086914,4.438316822052,30,2,200,-8.01837086328305E-5,-0.21435858309269,-0.00509742926806211,2,,,,,,,,,,,,,,,,
,3886875835.92697,299.996765136719,-0.079079195857048,,,6,,,,34.5994640599913,,,1000,,,,,,,,,,,,,,,,,,,,,,299.995788574219,300.000457763672,-0.097609169781208,-0.0358425937592983,,,10.394434928894,,1,0,0,0,0.013885498046875,29.8142719268799,1,8,1,299.995269775391,0,4232056832,299.999102274577,,,0.858589042601755,0.0852934089999572,0.93673480625521,0.0858387770338775,0.0805206745862961,0.0921464636921883,36.5296440124512,0,30,2,200,-0.21493324637413,-0.340744972229004,2.16512537002563,2,,,,,,,,,,,,,,,,
,3886876035.70195,300.001724243164,0.00121735187713057,,,6,,,,34.5994640599913,,,10,,,,,,,,,,,,,,,,,,,,,,300.000885009766,300.005279541016,0.00121735187713057,0.00121735187713057,,,10.4092082977295,,1,0,0,0,0.013885498046875,28.8367557525635,1,1,1,300.002899169922,0,4232056832,300.003969828288,,,0.00047012684093322,1.65714064050293E-5,0.000470229612161398,1.65716227817603E-5,0.93749725818634,0.940863966941833,34.6775741577148,0,30,2,200,-7.65811564633623E-5,-0.15440508723259,0.0474395006895065,2,,,,,,,,,,,,,,,,
,3886876240.35294,299.994094848633,0.00121735187713057,,,6,,,,34.5994640599913,,,10,,,,,,,,,,,,,,,,,,,,,,299.992309570313,299.996398925781,0.00121735187713057,0.00121735187713057,,,10.4341125488281,,1,0,0,0,0.013885498046875,29.8142719268799,1,1,1,299.992156982422,0,4232056832,299.994626363118,,,0.000466869699115448,1.64571523728101E-5,0.000466986867124093,1.6457426961018E-5,0.936957895755768,0.940775275230408,34.682861328125,0,30,2,200,-5.59600412088912E-5,-0.153592839837074,0.0468630827963352,2,,,,,,,,,,,,,,,,
,3886876433.86388,300.009841918945,0.00121735187713057,,,6,,,,34.5994640599913,,,10,,,,,,,,,,,,,,,,,,,,,,300.009429931641,300.011047363281,0.00121735187713057,0.00121735187713057,,,10.4096336364746,,1,0,0,0,0.013885498046875,29.3255138397217,1,1,1,300.010192871094,0,4232056832,300.010274251302,,,0.000464317170046009,1.63678449927484E-5,0.000464452292380901,1.6368141785566E-5,0.936321973800659,0.940743982791901,34.6894683837891,0.0766617357730866,30,2,200,-6.08513073530048E-5,-0.152955144643784,0.046324297785759,2,,,,,,,,,,,,,,,,
,3886876627.55085,299.998962402344,0.00121735187713057,,,6,,,,34.5994640599913,,,10,,,,,,,,,,,,,,,,,,,,,,299.997528076172,300.002380371094,0.00121735187713057,0.00121735187713057,,,10.4364709854126,,1,0,0,0,0.013885498046875,30.3030319213867,1,1,1,300.000579833984,0,4232056832,300.000183105469,,,0.000463564367233519,1.63412346546025E-5,0.000463699526737735,1.63415306894319E-5,0.936384618282318,0.940820872783661,34.6895599365234,0,30,2,200,-4.40758522017859E-5,-0.152892962098122,0.0460714139044285,2,,,,,,,,,,,,,,,,
,3886876821.12352,300.000091552734,0.00121735187713057,,,6,,,,34.5994640599913,,,10,,,,,,,,,,,,,,,,,,,,,,299.998962402344,300.002716064453,0.00121735187713057,0.00121735187713057,,,10.4509840011597,,1,0,0,0,0.013885498046875,29.3255138397217,1,1,1,300.0009765625,0,4232056832,300.000722249349,,,0.000463253596417218,1.63303554178192E-5,0.000463389974961197,1.63306508801568E-5,0.936314344406128,0.940793216228485,34.6900253295898,0,30,2,200,-5.6217879318865E-5,-0.152956530451775,0.0458413399755955,2,,,,,,,,,,,,,,,,
,3886877014.60243,300.000778198242,0.00121735187713057,,,6,,,,34.5994640599913,,,10,,,,,,,,,,,,,,,,,,,,,,300.000610351562,300.003326416016,0.00121735187713057,0.00121735187713057,,,10.4727230072021,,1,0,0,0,0.013885498046875,30.3030319213867,1,1,1,300.000946044922,0,4232057376,300.001848856608,,,0.000462659958082699,1.63096977676628E-5,0.000462802753550511,1.63100172468327E-5,0.936051964759827,0.940724909305572,34.6920890808105,0,30,2,200,-4.90245220134966E-5,-0.152998104691505,0.045597318559885,2,,,,,,,,,,,,,,,,
,3886877158.93558,299.995330810547,0.00121735187713057,,,6,,,,34.5994640599913,,,10,,,,,,,,,,,,,,,,,,,,,,299.995361328125,299.999725341797,0.00121735187713057,0.00121735187713057,,,10.4855518341064,,1,0,0,0,0.013885498046875,28.3479976654053,1,1,1,299.992156982422,0,4232056832,299.998392740885,,,0.000463080514499322,1.63250184423785E-5,0.000463239315347231,1.63253806238845E-5,0.935583114624023,0.94074934720993,34.6970367431641,0,30,2,200,-8.20118366391398E-5,-0.180955320596695,0.0178531818091869,2,,,,,,,,,,,,,,,,