File: Chapter5/lowT/LG12_FC.dat
[Header]
; MPMS3 Data File (default extension .dat)
; Copyright (c) 2007, Quantum Design, Inc. All rights reserved.
TITLE,
FILEOPENTIME,3886831993.16468,03/01/2023,11:32 am
BYAPP,MPMS3 w/ AC,1.0,1.1
INFO,MPMS3 Measurement Release 1.1.16 Build 424, MultiVu Release 2.3.4.26,APPNAME
INFO,Linear Motor Servo Controller,MOTOR_MODULE_NAME
INFO,3101-100 N0,MOTOR_HW_VERSION
INFO,MMC1047,MOTOR_SERIAL_NUMBER
INFO,01.04.28,MOTOR_SOFTWARE_VERSION
INFO,Quantum Design Squid Module,SQUID_MODULE_NAME
INFO,3101-501 B0,SQUID_HW_VERSION
INFO,SQM278,SQUID_SERIAL_NUMBER
INFO,01.03.04,SQUID_SOFTWARE_VERSION
INFO,Quantum Design VSM Oven,OVEN_MODULE_NAME
INFO,3101-201 A3,OVEN_HW_VERSION
INFO,OVB323,OVEN_SERIAL_NUMBER
INFO,01.07.07,OVEN_SOFTWARE_VERSION
INFO,SQUID AC,AC_MODULE_NAME
INFO,3101-401 G0,AC_HW_VERSION
INFO,SAC258,AC_SERIAL_NUMBER
INFO,SQUID AC 00.95.07,AC_SOFTWARE_VERSION
INFO,TCI408,COIL_SERIAL_NUMBER
INFO,0,MOMENT_UNITS
INFO,C3,SAMPLE_MATERIAL
INFO,,SAMPLE_COMMENT
INFO,,SAMPLE_MASS
INFO,,SAMPLE_VOLUME
INFO,,SAMPLE_MOLECULAR_WEIGHT
INFO,,SAMPLE_SIZE
INFO,,SAMPLE_SHAPE
INFO,Straw,SAMPLE_HOLDER
INFO,Standard,SAMPLE_HOLDER_DETAIL
INFO,66.62,SAMPLE_OFFSET
DATATYPE,COMMENT,1
DATATYPE,TIME,2
STARTUPAXIS,X,2
STARTUPAXIS,Y1,5
FIELDGROUP, VSM,2,3,4,5,6,8,9,10,11,14,15
FIELDGROUP, DC, 2,3,4,14,56,57,58,59,60,61,62,63,64,65,66,67,68,69
FIELDGROUP, AC, 2,3,4,11,16,17,18,19,20,21,22,23,24,25,26,27,28,29,30
STARTUPGROUP, All
[Data]
Comment,Time Stamp (sec),Temperature (K),Magnetic Field (Oe),Moment (emu),M. Std. Err. (emu),Transport Action,Averaging Time (sec),Frequency (Hz),Peak Amplitude (mm),Center Position (mm),Lockin Signal' (V),Lockin Signal (V),Range,M. Quad. Signal (emu),AC Moment (emu),AC M. Std Err. (emu),AC Phase (deg),AC Phase Std. Err. (deg),AC Susceptibility (emu/Oe),AC Suscept. Std Err. (emu/Oe),AC X' (emu/Oe),AC X' Std Err. (emu/Oe),AC X'' (emu/Oe),AC X'' Std Err. (emu/Oe),AC Drive (Oe),AC Frequency (Hz),AC Averaging Time (sec),AC Cycles,AC Range,AC Measure Type,AC Signal' (V),AC Signal'' (V),AC Trim Coil Ratio,AC Trim Coil Phase,Min. Temperature (K),Max. Temperature (K),Min. Field (Oe),Max. Field (Oe),Mass (grams),Motor Lag (deg),Pressure (Torr),Measure Count,Measurement Number,SQUID Status (code),Motor Status (code),Measure Status (code),Motor Current (amps),Motor Temp. (C),Temp. Status (code),Field Status (code),Chamber Status (code),Chamber Temp (K),Redirection State,Evercool Status,Average Temp (K),Rotation Angle (deg),Rotator state,DC Moment Fixed Ctr (emu),DC Moment Err Fixed Ctr (emu),DC Moment Free Ctr (emu),DC Moment Err Free Ctr (emu),DC Fixed Fit,DC Free Fit,DC Calculated Center (mm),DC Calculated Center Err (mm),DC Scan Length (mm),DC Scan Time (s),DC Number of Points,DC Squid Drift,DC Min V (V),DC Max V (V),DC Scans per Measure,Map 01,Map 02,Map 03,Map 04,Map 05,Map 06,Map 07,Map 08,Map 09,Map 10,Map 11,Map 12,Map 13,Map 14,Map 15,Map 16
,3886836443.74043,11.1246104240417,0.00121735187713057,,,6,,,,33.6606185752668,,,10,,,,,,,,,,,,,,,,,,,,,,10.0409126281738,12.0761966705322,0.00121735187713057,0.00121735187713057,,,4.99613475799561,,1,0,0,0,0,29.3255138397217,6,1,1,12.2083082199097,0,4232056832,10.9770883719126,,,0.00187168228116055,6.60837949389024E-5,0.00187537134608877,6.60901562789867E-5,0.915166139602661,0.941083252429962,33.4248313903809,0,30,2,200,-0.000219334178837016,-0.692190587520599,0.216908678412437,2,,,,,,,,,,,,,,,,
,3886836619.78168,15.9540677070618,0.00121735187713057,,,6,,,,33.6606185752668,,,10,,,,,,,,,,,,,,,,,,,,,,15.0146074295044,16.8549385070801,0.00121735187713057,0.00121735187713057,,,5.4620509147644,,1,0,0,0,0,29.3255138397217,6,1,1,16.8935279846191,0,4232056832,15.7547383308411,,,0.00153763663799993,5.42755123432082E-5,0.00154041656923351,5.42801330938732E-5,0.918253660202026,0.942927598953247,33.434741973877,0,30,2,200,-0.000265563372522593,-0.590871036052704,0.0728153437376022,2,,,,,,,,,,,,,,,,
,3886836801.00608,21.9841070175171,0.00121735187713057,,,6,,,,33.6606185752668,,,10,,,,,,,,,,,,,,,,,,,,,,21.57590675354,22.3873767852783,0.00121735187713057,0.00121735187713057,,,5.72324275970459,,1,0,0,0,0,28.8367557525635,2,1,1,22.3923072814941,0,4232056832,22.08877770106,,,0.00132511641497343,4.67576849767998E-5,0.00132710298788656,4.67610466782373E-5,0.92260479927063,0.943868517875671,33.4550437927246,0,30,2,200,-0.000201932052732445,-0.528830587863922,0.0438727587461472,2,,,,,,,,,,,,,,,,
,3886836980.86719,26.6648502349854,0.00121735187713057,,,6,,,,33.6657833378005,,,10,,,,,,,,,,,,,,,,,,,,,,26.1483154296875,27.1558895111084,0.00121735187713057,0.00121735187713057,,,5.9152684211731,,1,0,0,0,0,29.3255138397217,2,1,1,27.1813850402832,0,4232056832,26.7564878463745,,,0.00121636031927683,4.29148178156979E-5,0.00121804531088447,4.29175688757252E-5,0.924219489097595,0.944197177886963,33.4680061340332,0,30,2,200,-0.000853808596730232,-0.494901299476624,0.0293310899287462,2,,,,,,,,,,,,,,,,
,3886837158.80312,30.474326133728,0.00121735187713057,,,6,,,,33.6657833378005,,,10,,,,,,,,,,,,,,,,,,,,,,29.9997100830078,30.9159755706787,0.00121735187713057,0.00121735187713057,,,6.05200910568237,,1,0,0,0,0,28.8367557525635,6,1,1,30.9489421844482,0,4232056832,30.3007154464722,,,0.00113869158143889,4.01680294621278E-5,0.00114009526150405,4.01702777439131E-5,0.926377594470978,0.94451767206192,33.4791221618652,0,30,2,200,-0.00062736525433138,-0.470122188329697,0.0189055614173412,2,,,,,,,,,,,,,,,,
,3886837330.37872,34.9931392669678,0.00121735187713057,,,6,,,,33.6717644851398,,,10,,,,,,,,,,,,,,,,,,,,,,34.9884605407715,34.9973983764648,0.00121735187713057,0.00121735187713057,,,6.14811182022095,,1,0,0,0,0,28.8367557525635,5,1,1,34.9978179931641,0,4232056832,34.9936151504517,,,0.00107350898661857,3.78652282586301E-5,0.00107474620293098,3.78672408390269E-5,0.927617073059082,0.944763839244842,33.4913635253906,0,30,2,200,-1.34441024783882E-5,-0.450197368860245,0.0105131082236767,2,,,,,,,,,,,,,,,,
,3886837518.19785,39.7460117340088,0.00121735187713057,,,6,,,,33.6776570857072,,,10,,,,,,,,,,,,,,,,,,,,,,39.6480102539063,39.8411521911621,0.00121735187713057,0.00121735187713057,,,6.2504301071167,,1,0,0,0,0,29.3255138397217,6,1,1,39.8440132141113,0,4232056832,39.7559938430786,,,0.00102639363557436,3.61991383355977E-5,0.00102746292831109,3.62009187229318E-5,0.929241955280304,0.944949746131897,33.5062446594238,0,30,2,200,-4.70683989988174E-5,-0.436340302228928,0.00431474111974239,2,,,,,,,,,,,,,,,,
,3886837687.38998,42.4907779693604,0.00121735187713057,,,6,,,,33.6776570857072,,,10,,,,,,,,,,,,,,,,,,,,,,42.4864959716797,42.4948616027832,0.00121735187713057,0.00121735187713057,,,6.30917739868164,,1,0,0,0,0,28.8367557525635,5,1,1,42.495059967041,0,4232057312,42.4912618001302,,,0.000995431072016016,3.51024783564974E-5,0.000996337763960243,3.5103958015534E-5,0.931135952472687,0.945114493370056,33.5172805786133,0,30,2,200,-3.11091425828636E-5,-0.426834613084793,0.00013804437185172,2,,,,,,,,,,,,,,,,
,3886837882.6584,46.7532272338867,0.00121735187713057,,,6,,,,33.6829597263667,,,10,,,,,,,,,,,,,,,,,,,,,,46.5119705200195,46.9728851318359,0.00121735187713057,0.00121735187713057,,,6.37802410125732,,1,0,0,0,0,29.3255138397217,6,1,1,46.9944839477539,0,4232057664,46.7625919977824,,,0.000967858651234949,3.41268973194861E-5,0.000968651624828159,3.41281005499126E-5,0.932541489601135,0.945327043533325,33.5306243896484,0.133422538638115,30,2,200,-0.000816694227978587,-0.418982923030853,-0.00358458375558257,2,,,,,,,,,,,,,,,,
,3886838061.24627,49.9815273284912,0.00121735187713057,,,6,,,,33.688511340155,,,10,,,,,,,,,,,,,,,,,,,,,,49.9765892028809,49.9859619140625,0.00121735187713057,0.00121735187713057,,,6.42379856109619,,1,0,0,0,0,27.3704795837402,5,1,1,49.9864654541016,0,4232057952,49.9819984436035,,,0.000942026131959714,3.32140435675209E-5,0.000942756158471624,3.32152468511324E-5,0.93342399597168,0.945585191249847,33.5406379699707,,30,2,200,-2.14173796848627E-5,-0.411035865545273,0.0965515822172165,2,,,,,,,,,,,,,,,,
,3886838239.09865,54.6368923187256,0.00121735187713057,,,6,,,,33.6941152197366,,,10,,,,,,,,,,,,,,,,,,,,,,54.5281524658203,54.7303085327148,0.00121735187713057,0.00121735187713057,,,6.47613573074341,,1,0,0,0,0,29.8142719268799,6,1,1,54.7456321716309,0,4232057248,54.6397835413615,,,0.000918162871409953,3.23695126804847E-5,0.000918790052279639,3.2370544723054E-5,0.934902548789978,0.945774376392365,33.5552864074707,0.133409351110458,30,2,200,-0.000414535374147817,-0.40404748916626,0.0935412347316742,2,,,,,,,,,,,,,,,,
,3886838397.72013,57.4443168640137,0.00121735187713057,,,6,,,,33.6941152197366,,,10,,,,,,,,,,,,,,,,,,,,,,57.4298324584961,57.4573364257812,0.00121735187713057,0.00121735187713057,,,6.50889921188354,,1,0,0,0,0,28.8367557525635,5,1,1,57.4588012695313,0,4232057696,57.4453220367432,,,0.000900078649406111,3.17287947540119E-5,0.00090060888074673,3.17296008145596E-5,0.936452269554138,0.946007430553436,33.5649452209473,0.133403688669205,30,2,200,-0.00052616698667407,-0.39863583445549,0.090901181101799,2,,,,,,,,,,,,,,,,
,3886838580.80875,61.3159084320068,0.00121735187713057,,,6,,,,33.6995664475668,,,10,,,,,,,,,,,,,,,,,,,,,,61.0547256469727,61.5678596496582,0.00121735187713057,0.00121735187713057,,,6.54871082305908,,1,0,0,0,0,29.8142719268799,6,1,1,61.577091217041,0,4232057760,61.3286778132121,,,0.000881711973055072,3.10787937017043E-5,0.000882164615452855,3.10794907747225E-5,0.937751054763794,0.946179568767548,33.5790176391602,0.000486947334138677,30,2,200,-5.37611631443724E-5,-0.289803683757782,0.0884091556072235,2,,,,,,,,,,,,,,,,
,3886838753.64296,64.8308029174805,0.00121735187713057,,,6,,,,33.7046370069409,,,10,,,,,,,,,,,,,,,,,,,,,,64.7885894775391,64.8691253662109,0.00121735187713057,0.00121735187713057,,,6.576584815979,,1,0,0,0,0,31.7693061828613,5,1,1,64.8730163574219,0,4232057888,64.8319047292073,,,0.000863054478518829,3.04192387601552E-5,0.000863450599917572,3.04199012718221E-5,0.938761591911316,0.946345031261444,33.5908813476562,5.79576396942139,30,2,200,-0.000614080287050456,-0.284132391214371,0.085863396525383,2,,,,,,,,,,,,,,,,
,3886838934.77989,67.5860176086426,0.00121735187713057,,,6,,,,33.7098997467188,,,10,,,,,,,,,,,,,,,,,,,,,,67.4714584350586,67.6695861816406,0.00121735187713057,0.00121735187713057,,,6.60354328155518,,1,0,0,0,0,28.8367557525635,6,1,1,67.7005767822266,0,4232057920,67.5293534596761,,,0.000847503554098023,2.98695500308727E-5,0.0008478525468291,2.98701279467104E-5,0.939630746841431,0.946499645709991,33.6021308898926,,30,2,200,-7.53424828872085E-5,-0.27968043088913,0.0836773812770844,2,,,,,,,,,,,,,,,,
,3886839135.80045,72.258846282959,0.00121735187713057,,,6,,,,33.7151228329086,,,10,,,,,,,,,,,,,,,,,,,,,,72.2080459594727,72.3076095581055,0.00121735187713057,0.00121735187713057,,,6.63404750823975,,1,0,0,0,0,29.3255138397217,5,1,1,72.3096466064453,0,4232057888,72.2607123057048,,,0.000826095256456697,2.91123916133291E-5,0.000826362108064367,2.91128608989782E-5,0.941143870353699,0.946593344211578,33.619815826416,,30,2,200,-0.000577441533096135,-0.273245126008987,0.0808541029691696,2,,,,,,,,,,,,,,,,
,3886839310.00401,74.9439163208008,0.00121735187713057,,,6,,,,33.7212268660007,,,10,,,,,,,,,,,,,,,,,,,,,,74.933349609375,74.9540939331055,0.00121735187713057,0.00121735187713057,,,6.6523814201355,,1,0,0,0,0,29.3255138397217,5,1,1,74.9544830322266,0,4232057664,74.9447625478109,,,0.000810726713023757,2.85697284387226E-5,0.000810960713440057,2.85701185237362E-5,0.941772103309631,0.946686506271362,33.6310195922852,,30,2,200,-8.08329496067017E-5,-0.268675327301025,0.182329118251801,2,,,,,,,,,,,,,,,,
,3886839484.51427,78.4378128051758,0.00121735187713057,,,6,,,,33.7262384772551,,,10,,,,,,,,,,,,,,,,,,,,,,78.1868667602539,78.6789855957031,0.00121735187713057,0.00121735187713057,,,6.6755428314209,,1,0,0,0,0,30.7917900085449,6,1,1,78.6887588500977,0,4232057696,78.4372946421305,,,0.000793821492754282,2.7972126731565E-5,0.000793999411270354,2.79724182357244E-5,0.942930221557617,0.946793854236603,33.6467132568359,0,30,2,200,-0.000558922532945871,-0.263917803764343,0.17981193959713,2,,,,,,,,,,,,,,,,
,3886839656.1631,81.9821586608887,0.00121735187713057,,,6,,,,33.7314042686831,,,10,,,,,,,,,,,,,,,,,,,,,,81.8849716186523,82.0697479248047,0.00121735187713057,0.00121735187713057,,,6.69364833831787,,1,0,0,0,0,31.7693061828613,6,1,1,82.079345703125,0,4232057632,81.9828484853109,,,0.000774102829566921,2.72759124903325E-5,0.000774237624195511,2.72761357959265E-5,0.943828999996185,0.946855664253235,33.6613273620605,4.89337435283233E-5,30,2,200,-7.57093148422428E-5,-0.25786492228508,0.177479803562164,2,,,,,,,,,,,,,,,,
,3886839831.27642,84.8341217041016,0.00121735187713057,,,6,,,,33.7364693918818,,,10,,,,,,,,,,,,,,,,,,,,,,84.8031311035156,84.8631057739258,0.00121735187713057,0.00121735187713057,,,6.70811939239502,,1,0,0,0,0,29.3255138397217,5,1,1,84.8651123046875,0,4232057824,84.8349774678548,,,0.000755806095891359,2.66303016223262E-5,0.000755911881354482,2.66304479070133E-5,0.944441914558411,0.946909725666046,33.6733856201172,4.63870346720796E-5,30,2,200,-0.000464742362964898,-0.252375096082687,0.0714631527662277,2,,,,,,,,,,,,,,,,
,3886839990.25355,87.4172515869141,0.00121735187713057,,,6,,,,33.7414996260074,,,10,,,,,,,,,,,,,,,,,,,,,,87.4021453857422,87.4308471679688,0.00121735187713057,0.00121735187713057,,,6.72014808654785,,1,0,0,0,0,28.8367557525635,6,1,1,87.4323577880859,0,4232057920,87.418675104777,,,0.00073864445297284,2.60249319380228E-5,0.000738728639505996,2.60250572751502E-5,0.944915413856506,0.946927905082703,33.6846618652344,0,30,2,200,-6.05175482633058E-5,-0.247262865304947,0.276443868875504,2,,,,,,,,,,,,,,,,
,3886840181.47137,91.180347442627,0.00121735187713057,,,6,,,,33.7531441735224,,,10,,,,,,,,,,,,,,,,,,,,,,90.9733047485352,91.3733596801758,0.00121735187713057,0.00121735187713057,,,6.73870325088501,,1,0,0,0,0,29.8142719268799,6,1,1,91.3873901367187,0,4232057856,91.1812636057536,,,0.000714431164160402,2.51712578605062E-5,0.000714497530568106,2.51713925548975E-5,0.945322573184967,0.946942925453186,33.7022438049316,,30,2,200,-0.000504025665577501,-0.240364223718643,0.0660706833004951,2,,,,,,,,,,,,,,,,
,3886840355.60061,94.5286102294922,0.00121735187713057,,,6,,,,33.7587772344322,,,10,,,,,,,,,,,,,,,,,,,,,,94.4452743530273,94.5990982055664,0.00121735187713057,0.00121735187713057,,,6.7521014213562,,1,0,0,0,0,29.3255138397217,6,1,1,94.611946105957,0,4232058016,94.5267902721058,,,0.000688898768316734,2.42715087911776E-5,0.000688947706576915,2.42715881103899E-5,0.945451259613037,0.946704387664795,33.7139892578125,0,30,2,200,-5.54064972675405E-5,-0.232445329427719,0.0628096759319305,2,,,,,,,,,,,,,,,,
,3886840528.08994,97.3246116638184,0.00121735187713057,,,6,,,,33.7642196802904,,,10,,,,,,,,,,,,,,,,,,,,,,97.2941818237305,97.3510437011719,0.00121735187713057,0.00121735187713057,,,6.76407241821289,,1,0,0,0,0.013885498046875,29.3255138397217,5,1,1,97.3550415039063,0,4232057792,97.3234911831943,,,0.000661988019699016,2.33245785743988E-5,0.000662037378406616,2.3324648702909E-5,0.944523215293884,0.945824384689331,33.7181854248047,,30,2,200,-0.000468887417810038,-0.224171862006187,0.059441689401865,2,,,,,,,,,,,,,,,,
,3886840715.78802,100.357688903809,0.00121735187713057,,,6,,,,33.7694571419643,,,10,,,,,,,,,,,,,,,,,,,,,,100.130676269531,100.555000305176,0.00121735187713057,0.00121735187713057,,,6.77802181243896,,1,0,0,0,0.013885498046875,29.3255138397217,6,1,1,100.584701538086,0,4232058048,100.336626688639,,,0.000628983401764246,2.21631952040838E-5,0.000629033970514046,2.21632699826574E-5,0.943314850330353,0.944685935974121,33.7216796875,0.000336764176608995,30,2,200,-9.31470058276318E-5,-0.214765608310699,0.0553227290511131,2,,,,,,,,,,,,,,,,
,3886840904.49869,104.363414764404,0.00121735187713057,,,6,,,,33.7803650094031,,,10,,,,,,,,,,,,,,,,,,,,,,104.253875732422,104.450019836426,0.00121735187713057,0.00121735187713057,,,6.79027843475342,,1,0,0,0,0,29.3255138397217,6,1,1,104.472953796387,0,4232057696,104.36036491394,,,0.000577086402581577,2.03380247187196E-5,0.000577175490603494,2.03381630455119E-5,0.940366566181183,0.94288581609726,33.7141914367676,0,30,2,200,-6.247829151107E-5,-0.198487371206284,0.0489620007574558,2,,,,,,,,,,,,,,,,
,3886841077.01121,107.220062255859,0.00121735187713057,,,6,,,,33.7857136135702,,,10,,,,,,,,,,,,,,,,,,,,,,107.174613952637,107.262390136719,0.00121735187713057,0.00121735187713057,,,6.8007493019104,,1,0,0,0,0,28.8367557525635,5,1,1,107.265510559082,0,4232057728,107.220988591512,,,0.000542985532429631,1.91382274726684E-5,0.000543092315846116,1.91383874448788E-5,0.938639461994171,0.941777110099793,33.7109413146973,0,30,2,200,-0.000368986773537472,-0.187863916158676,0.0446636714041233,2,,,,,,,,,,,,,,,,
,3886841269.97539,110.010185241699,0.00121735187713057,,,6,,,,33.7907538416225,,,10,,,,,,,,,,,,,,,,,,,,,,109.921867370605,110.070304870605,0.00121735187713057,0.00121735187713057,,,6.81163311004639,,1,0,0,0,0,29.3255138397217,6,1,1,110.098503112793,0,4232057952,109.970324834188,,,0.000517229490668129,1.82311891583535E-5,0.000517341862879832,1.82313598768793E-5,0.937961041927338,0.941394507884979,33.7121772766113,0,30,2,200,-5.5175660236273E-5,-0.180194914340973,0.0412788428366184,2,,,,,,,,,,,,,,,,
,3886841455.24732,113.926044464111,0.00121735187713057,,,6,,,,33.8015729916671,,,10,,,,,,,,,,,,,,,,,,,,,,113.775749206543,114.065612792969,0.00121735187713057,0.00121735187713057,,,6.82272720336914,,1,0,0,0,0.001373291015625,29.3255138397217,6,1,1,114.07633972168,0,4232057824,113.924573262533,,,0.000485051343775266,1.70972256297417E-5,0.000485160530844091,1.70974079275814E-5,0.937732338905335,0.941263318061829,33.7217826843262,0.0776239559054375,30,2,200,-6.09181624895427E-5,-0.170667394995689,0.0373983010649681,2,,,,,,,,,,,,,,,,
,3886841633.24123,117.077003479004,0.00121735187713057,,,6,,,,33.8076418574347,,,10,,,,,,,,,,,,,,,,,,,,,,117.012237548828,117.139686584473,0.00121735187713057,0.00121735187713057,,,6.83164787292481,,1,0,0,0,0,29.3255138397217,6,1,1,117.14176940918,0,4232056832,117.0773340861,,,0.000461367839894873,1.62619379974907E-5,0.000461462734246844,1.62620962012144E-5,0.938211262226105,0.941455900669098,33.7313613891602,6.97710704803467,30,2,200,-4.62723037344404E-5,-0.163294449448586,0.0343006476759911,2,,,,,,,,,,,,,,,,
,3886841811.04798,119.833808898926,0.00121735187713057,,,6,,,,33.8137262784418,,,10,,,,,,,,,,,,,,,,,,,,,,119.807731628418,119.855865478516,0.00121735187713057,0.00121735187713057,,,6.83995723724365,,1,0,0,0,0,28.8367557525635,5,1,1,119.859886169434,0,4232057760,119.832558371804,,,0.000443247004652232,1.56229633820624E-5,0.000443338157473087,1.56231126334888E-5,0.938488185405731,0.941750884056091,33.7374267578125,4.35009479522705,30,2,200,-0.000300364830764011,-0.157876461744308,0.0319697484374046,2,,,,,,,,,,,,,,,,
,3886841985.75513,122.486408233643,0.00121735187713057,,,6,,,,33.8199710375167,,,10,,,,,,,,,,,,,,,,,,,,,,122.408699035645,122.545913696289,0.00121735187713057,0.00121735187713057,,,6.84754419326782,,1,0,0,0,0.013885498046875,28.8367557525635,6,1,1,122.564117431641,0,4232057632,122.453473409017,,,0.000429814761445945,1.51496477267658E-5,0.00042990921003326,1.51498085766022E-5,0.9383465051651,0.941823959350586,33.7411842346191,0,30,2,200,-5.20280518685468E-5,-0.154102295637131,0.0300314836204052,2,,,,,,,,,,,,,,,,
,3886842162.16317,125.952301025391,0.00121735187713057,,,6,,,,33.8314634596904,,,10,,,,,,,,,,,,,,,,,,,,,,125.759735107422,126.144866943359,0.00121735187713057,0.00121735187713057,,,6.85590362548828,,1,0,0,0,0.013885498046875,28.8367557525635,6,1,1,126.151847839355,0,4232057888,125.951134999593,,,0.00041833634033994,1.47452459696389E-5,0.000418425345424275,1.47453756290279E-5,0.938158392906189,0.941536545753479,33.7536430358887,6.51920563541353E-5,30,2,200,-3.7697722291341E-5,-0.150710999965668,0.0286105889827013,2,,,,,,,,,,,,,,,,
,3886842347.48793,129.369911193848,0.00121735187713057,,,6,,,,33.841800417593,,,10,,,,,,,,,,,,,,,,,,,,,,129.2783203125,129.451553344727,0.00121735187713057,0.00121735187713057,,,6.86407470703125,,1,0,0,0,0.013885498046875,29.3255138397217,6,1,1,129.461502075195,0,4232057888,129.36794350364,,,0.0004096917697567,1.44405828581206E-5,0.000409773734686617,1.44407104885086E-5,0.938120484352112,0.941279828548431,33.7664413452148,0,30,2,200,-3.04272325593047E-5,-0.148147284984589,0.0273084659129381,2,,,,,,,,,,,,,,,,
,3886842519.26692,132.150657653809,0.00121735187713057,,,6,,,,33.8473598915824,,,10,,,,,,,,,,,,,,,,,,,,,,132.101623535156,132.19775390625,0.00121735187713057,0.00121735187713057,,,6.87103223800659,,1,0,0,0,0.013885498046875,29.3255138397217,5,1,1,132.199691772461,0,4232057888,132.152216593424,,,0.00040337557589211,1.42176892626385E-5,0.000403442675615509,1.42177962449035E-5,0.938423931598663,0.941049575805664,33.778678894043,0.133381485939026,30,2,200,-0.000310541421640664,-0.146301239728928,0.0264658555388451,2,,,,,,,,,,,,,,,,
,3886842690.85935,134.808738708496,0.00121735187713057,,,6,,,,33.8532436943918,,,10,,,,,,,,,,,,,,,,,,,,,,134.780197143555,134.835357666016,0.00121735187713057,0.00121735187713057,,,6.87720108032227,,1,0,0,0,0.013885498046875,29.3255138397217,5,1,1,134.837280273438,0,4232057856,134.809074401855,,,0.000397847121017001,1.40225079908463E-5,0.000397903299653025,1.40226036448899E-5,0.938784062862396,0.941011786460876,33.7900657653809,7.4973201751709,30,2,200,-0.000301267602480948,-0.144734278321266,0.0256082639098167,2,,,,,,,,,,,,,,,,
,3886842884.68542,137.74015045166,0.00121735187713057,,,6,,,,33.8640664185712,,,10,,,,,,,,,,,,,,,,,,,,,,137.535461425781,137.919570922852,0.00121735187713057,0.00121735187713057,,,6.88459300994873,,1,0,0,0,0.013885498046875,28.8367557525635,6,1,1,137.944839477539,0,4232057664,137.721243540446,,,0.000392168278665754,1.38222604268219E-5,0.000392218488336171,1.38223419527533E-5,0.938895761966705,0.94092071056366,33.8038330078125,5.91788157180417E-5,30,2,200,-0.000309462833683938,-0.143418401479721,0.0245614871382713,2,,,,,,,,,,,,,,,,
,3886843066.56436,141.295234680176,0.00121735187713057,,,6,,,,33.8747291267177,,,10,,,,,,,,,,,,,,,,,,,,,,141.133926391602,141.445861816406,0.00121735187713057,0.00121735187713057,,,6.89124488830566,,1,0,0,0,0.013885498046875,28.3479976654053,6,1,1,141.45654296875,0,4232057888,141.302937825521,,,0.000386084566645192,1.36077514194163E-5,0.000386126654469274,1.36078110605988E-5,0.938999176025391,0.940732717514038,33.818977355957,0,30,2,200,-0.000313125230604783,-0.141613528132439,0.0237414855509996,2,,,,,,,,,,,,,,,,
,3886843239.90599,144.342391967773,0.00121735187713057,,,6,,,,33.8807771138558,,,10,,,,,,,,,,,,,,,,,,,,,,144.249649047852,144.435134887695,0.00121735187713057,0.00121735187713057,,,6.89747905731201,,1,0,0,0,0.013885498046875,29.3255138397217,6,1,1,144.437866210938,0,4232057824,144.345617930094,,,0.000380977887687359,1.34275389198809E-5,0.000381010421116508,1.34275813714916E-5,0.939270079135895,0.940634548664093,33.8313484191895,0,30,2,200,-2.34445051319199E-5,-0.140136569738388,0.0229726247489452,2,,,,,,,,,,,,,,,,
,3886843425.34454,147.219879150391,0.00121735187713057,,,6,,,,33.8914630719565,,,10,,,,,,,,,,,,,,,,,,,,,,147.180328369141,147.256927490234,0.00121735187713057,0.00121735187713057,,,6.90369558334351,,1,0,0,0,0,29.3255138397217,5,1,1,147.259429931641,0,4232057760,147.219992319743,,,0.000376145157173392,1.32572189129599E-5,0.000376175808525301,1.32572661818529E-5,0.939257085323334,0.940548956394196,33.8433456420898,0,30,2,200,-2.27983200602466E-5,-0.138809144496918,0.0222387332469225,2,,,,,,,,,,,,,,,,
,3886843601.02343,149.845771789551,0.00121735187713057,,,6,,,,33.8973538269421,,,10,,,,,,,,,,,,,,,,,,,,,,149.824066162109,149.866088867187,0.00121735187713057,0.00121735187713057,,,6.90854549407959,,1,0,0,0,0,28.3479976654053,5,1,1,149.867477416992,0,4232058016,149.846300760905,,,0.00037190471029386,1.3107614225479E-5,0.000371928697036587,1.31076439618823E-5,0.939447700977325,0.940480470657349,33.8543510437012,0,30,2,200,-0.000245392671786249,-0.137609899044037,0.0215967111289501,2,,,,,,,,,,,,,,,,
,3886843790.13194,152.773994445801,0.00121735187713057,,,6,,,,33.9087898116868,,,10,,,,,,,,,,,,,,,,,,,,,,152.566925048828,152.963226318359,0.00121735187713057,0.00121735187713057,,,6.91562414169311,,1,0,0,0,0,29.3255138397217,6,1,1,152.981063842773,0,4232057760,152.764469146729,,,0.000367399039716346,1.2948696428312E-5,0.000367420383080637,1.29487277792467E-5,0.939592838287353,0.940518200397491,33.8681182861328,0,30,2,200,-2.15647269214969E-5,-0.136576429009438,0.0207270793616772,2,,,,,,,,,,,,,,,,
,3886843972.49652,156.262298583984,0.00121735187713057,,,6,,,,33.9193603388414,,,10,,,,,,,,,,,,,,,,,,,,,,156.108489990234,156.408142089844,0.00121735187713057,0.00121735187713057,,,6.92126941680908,,1,0,0,0,0.013885498046875,29.3255138397217,6,1,1,156.416107177734,0,4232057952,156.262086232503,,,0.000362485225251526,1.27754426931783E-5,0.000362502321284665,1.27754652761458E-5,0.939694046974182,0.940448820590973,33.8826293945313,0,30,2,200,-2.73975219897693E-5,-0.135151997208595,0.0200160760432482,2,,,,,,,,,,,,,,,,
,3886844148.42965,159.277282714844,0.00121735187713057,,,6,,,,33.9302613196725,,,10,,,,,,,,,,,,,,,,,,,,,,159.175964355469,159.371932983398,0.00121735187713057,0.00121735187713057,,,6.92689990997314,,1,0,0,0,0.013885498046875,29.3255138397217,6,1,1,159.378601074219,0,4232057728,159.279396057129,,,0.000358094652582206,1.26206288758086E-5,0.000358110014459703,1.26206482829432E-5,0.939779043197632,0.940467298030853,33.895206451416,0,30,2,200,-1.71771844179602E-5,-0.133956640958786,0.0193941220641136,2,,,,,,,,,,,,,,,,
,3886844333.4471,162.155158996582,0.00121735187713057,,,6,,,,33.9409116930559,,,10,,,,,,,,,,,,,,,,,,,,,,162.105651855469,162.200408935547,0.00121735187713057,0.00121735187713057,,,6.93215370178223,,1,0,0,0,0.013885498046875,27.8592376708984,5,1,1,162.204666137695,0,4232057760,162.156656901042,,,0.000353906644652481,1.24730417030752E-5,0.000353920910419086,1.24730596274569E-5,0.939768433570862,0.94041496515274,33.906925201416,,30,2,200,-4.17137089243624E-5,-0.13276594877243,0.0186966676265001,2,,,,,,,,,,,,,,,,
,3886844502.37493,164.769454956055,0.00121735187713057,,,6,,,,33.9469589722341,,,10,,,,,,,,,,,,,,,,,,,,,,164.737030029297,164.800735473633,0.00121735187713057,0.00121735187713057,,,6.93642711639404,,1,0,0,0,0.013885498046875,29.3255138397217,5,1,1,164.801879882813,0,4232057888,164.770853678385,,,0.000350110194555498,1.23391888022219E-5,0.000350119913230943,1.2339190352256E-5,0.939832210540771,0.940291583538055,33.9183006286621,0,30,2,200,-0.000287794217001647,-0.131766214966774,0.0181162767112255,2,,,,,,,,,,,,,,,,
,3886844693.72747,167.464149475098,0.00121735187713057,,,6,,,,33.9579021233632,,,10,,,,,,,,,,,,,,,,,,,,,,167.389312744141,167.526504516602,0.00121735187713057,0.00121735187713057,,,6.94216108322144,,1,0,0,0,0,29.8142719268799,6,1,1,167.538986206055,0,4232057888,167.435407002767,,,0.000346219729266089,1.22020627692847E-5,0.00034622858999006,1.22020728244778E-5,0.939854323863983,0.940266072750092,33.9307708740234,4.10907559853513E-5,30,2,200,-4.84489355585538E-5,-0.130899369716644,0.0174194984138012,2,,,,,,,,,,,,,,,,
,3886844872.69034,170.628784179687,0.00121735187713057,,,6,,,,33.9680093280297,,,10,,,,,,,,,,,,,,,,,,,,,,170.417434692383,170.818222045898,0.00121735187713057,0.00121735187713057,,,6.94733428955078,,1,0,0,0,0.013885498046875,29.8142719268799,6,1,1,170.840133666992,0,4232057664,170.620889027913,,,0.000342047522836167,1.20549463301173E-5,0.000342053416069087,1.20549502100358E-5,0.939943253993988,0.940224409103394,33.9455909729004,,30,2,200,-2.25173644139431E-5,-0.129696741700172,0.0167592391371727,2,,,,,,,,,,,,,,,,
,3886845057.92664,174.010787963867,0.00121735187713057,,,6,,,,33.9803886802731,,,10,,,,,,,,,,,,,,,,,,,,,,173.878433227539,174.116729736328,0.00121735187713057,0.00121735187713057,,,6.95294332504273,,1,0,0,0,0.013885498046875,29.3255138397217,6,1,1,174.143142700195,0,4232057824,174.00009432706,,,0.000337590966852857,1.18979161011492E-5,0.000337595719081962,1.18979162234106E-5,0.939897060394287,0.940130770206451,33.9599418640137,0.1400036662817,30,2,200,-2.75561724265572E-5,-0.128400176763535,0.0161540918052197,2,,,,,,,,,,,,,,,,
,3886845237.29758,176.944435119629,0.00121735187713057,,,6,,,,33.990711950063,,,10,,,,,,,,,,,,,,,,,,,,,,176.873245239258,177.01350402832,0.00121735187713057,0.00121735187713057,,,6.95734834671021,,1,0,0,0,0,28.8367557525635,6,1,1,177.015625,0,4232056832,176.948954264323,,,0.000333561307525959,1.17558285736511E-5,0.00033356505062171,1.17558266134656E-5,0.939994990825653,0.940184414386749,33.9723167419434,,30,2,200,-1.3309960195329E-5,-0.127312317490578,0.0155581245198846,2,,,,,,,,,,,,,,,,
,3886845422.84239,179.736221313477,0.00121735187713057,,,6,,,,34.0019788821693,,,10,,,,,,,,,,,,,,,,,,,,,,179.701477050781,179.76985168457,0.00121735187713057,0.00121735187713057,,,6.96303844451904,,1,0,0,0,0,28.8367557525635,5,1,1,179.770965576172,0,4232057888,179.737143198649,,,0.000329604153278297,1.16164464672056E-5,0.00032960750765494,1.16164484033609E-5,0.939881920814514,0.940048038959503,33.9847297668457,,30,2,200,-3.28017631545663E-5,-0.126235857605934,0.0149017181247473,2,,,,,,,,,,,,,,,,
,3886845600.29469,182.345161437988,0.00121735187713057,,,6,,,,34.01284942564,,,10,,,,,,,,,,,,,,,,,,,,,,182.324691772461,182.364318847656,0.00121735187713057,0.00121735187713057,,,6.96703195571899,,1,0,0,0,0,29.8142719268799,5,1,1,182.365631103516,0,4232057920,182.346673329671,,,0.000326011434815133,1.14898813572295E-5,0.000326014426078408,1.14898794885816E-5,0.939800977706909,0.939955711364746,33.9961891174316,0.133374899625778,30,2,200,-0.000289509276626632,-0.125325500965118,0.0142841748893261,2,,,,,,,,,,,,,,,,
,3886845777.8328,184.963363647461,0.00121735187713057,,,6,,,,34.0183177322986,,,10,,,,,,,,,,,,,,,,,,,,,,184.892425537109,185.034301757813,0.00121735187713057,0.00121735187713057,,,6.9719672203064,,1,0,0,0,0,29.8142719268799,6,1,1,185.034301757813,0,4232057792,184.937235905574,,,0.00032246898452164,1.13649089255567E-5,0.000322470049254974,1.1364907183387E-5,0.939974904060364,0.940032303333282,34.0081825256348,2.53663802141091E-5,30,2,200,-4.5675078581553E-5,-0.124537631869316,0.0136211719363928,2,,,,,,,,,,,,,,,,
,3886845962.91002,188.375541687012,0.00121735187713057,,,6,,,,34.0360575553418,,,10,,,,,,,,,,,,,,,,,,,,,,188.194610595703,188.55647277832,0.00121735187713057,0.00121735187713057,,,6.9765305519104,,1,0,0,0,0,28.8367557525635,6,1,1,188.563720703125,0,4232057824,188.37331644694,,,0.00031836023969588,1.12201588049489E-5,0.000318361664022709,1.1220156846483E-5,0.939894378185272,0.939971446990967,34.0243034362793,0.000204860989470035,30,2,200,-0.000237343192566186,-0.123376972973347,0.0129975490272045,2,,,,,,,,,,,,,,,,
,3886846142.19028,191.491500854492,0.00121735187713057,,,6,,,,34.0470187365205,,,10,,,,,,,,,,,,,,,,,,,,,,191.361434936523,191.595520019531,0.00121735187713057,0.00121735187713057,,,6.98191070556641,,1,0,0,0,0,29.3255138397217,6,1,1,191.621566772461,0,4232057792,191.48446932706,,,0.000314492983150507,1.10837902410913E-5,0.000314493942366002,1.10837880500242E-5,0.94000369310379,0.940057635307312,34.0371932983398,0,30,2,200,-0.000225453317398205,-0.122340530157089,0.0124148540198803,2,,,,,,,,,,,,,,,,
,3886846318.87577,194.36499786377,0.00121735187713057,,,6,,,,34.059170113799,,,10,,,,,,,,,,,,,,,,,,,,,,194.284210205078,194.437835693359,0.00121735187713057,0.00121735187713057,,,6.98615646362305,,1,0,0,0,0,29.3255138397217,6,1,1,194.445785522461,0,4232057696,194.36387125651,,,0.000310932004709824,1.09582976207478E-5,0.000310932962661613,1.09582977344224E-5,0.939988315105438,0.940039336681366,34.049617767334,0,30,2,200,-4.65238445030991E-5,-0.121300786733627,0.0118634710088372,2,,,,,,,,,,,,,,,,
,3886846490.87454,197.057456970215,0.00121735187713057,,,6,,,,34.0654637257141,,,10,,,,,,,,,,,,,,,,,,,,,,196.999206542969,197.108917236328,0.00121735187713057,0.00121735187713057,,,6.99010133743286,,1,0,0,0,0,29.3255138397217,6,1,1,197.115707397461,0,4232057760,197.056730906169,,,0.000307454603506864,1.08357284526517E-5,0.000307454723945001,1.08357275348439E-5,0.940013587474823,0.940021514892578,34.0617027282715,5.83624029159546,30,2,200,-0.00027206662343815,-0.120378144085407,0.0112958364188671,2,,,,,,,,,,,,,,,,
,3886846670.47997,199.747657775879,0.00121735187713057,,,6,,,,34.076882927922,,,10,,,,,,,,,,,,,,,,,,,,,,199.712463378906,199.779357910156,0.00121735187713057,0.00121735187713057,,,6.99430322647095,,1,0,0,0,0.013885498046875,29.3255138397217,5,1,1,199.782852172852,0,4232057792,199.74818166097,,,0.000303988226890727,1.07135004602102E-5,0.000303988276891468,1.0713499356621E-5,0.940109312534332,0.940113723278046,34.0740623474121,0,30,2,200,-0.000288048322545365,-0.1194222047925,0.0107450895011425,2,,,,,,,,,,,,,,,,
,3886846846.77039,202.33325958252,0.00121735187713057,,,6,,,,34.0893785283829,,,10,,,,,,,,,,,,,,,,,,,,,,202.311309814453,202.353790283203,0.00121735187713057,0.00121735187713057,,,6.9991865158081,,1,0,0,0,7.62939453125E-5,28.3479976654053,5,1,1,202.355209350586,0,4232057856,202.334875742594,,,0.000300698105765949,1.05975187330902E-5,0.00030069820813421,1.05975178264401E-5,0.940152049064636,0.940159142017364,34.0858192443848,0,30,2,200,-3.73228031094186E-5,-0.118489630520344,0.0102540664374828,2,,,,,,,,,,,,,,,,
,3886847035.87196,205.1953125,0.00121735187713057,,,6,,,,34.1011698031311,,,10,,,,,,,,,,,,,,,,,,,,,,205.016571044922,205.366897583008,0.00121735187713057,0.00121735187713057,,,7.00486373901367,,1,0,0,0,0.013885498046875,29.3255138397217,6,1,1,205.374053955078,0,4232057888,205.183636983236,,,0.000297346483302335,1.04793959213936E-5,0.000297346482284723,1.04793956972267E-5,0.940150260925293,0.940150558948517,34.1004409790039,5.83955812454224,30,2,200,-4.12514091294724E-5,-0.117783635854721,0.00957787130028009,2,,,,,,,,,,,,,,,,
,3886847205.85669,208.10570526123,0.00121735187713057,,,6,,,,34.1127105555588,,,10,,,,,,,,,,,,,,,,,,,,,,207.909240722656,208.302169799805,0.00121735187713057,0.00121735187713057,,,7.01031351089478,,1,0,0,0,0.013885498046875,28.8367557525635,6,1,1,208.302169799805,0,4232058016,208.10764948527,,,0.000293988847659169,1.03611167214954E-5,0.000293988868288807,1.03611170383691E-5,0.940071165561676,0.940071821212769,34.1137962341309,0,30,2,200,-0.000225851195864379,-0.1168462485075,0.00906372163444758,2,,,,,,,,,,,,,,,,
,3886847382.67448,211.196174621582,0.00121735187713057,,,6,,,,34.1287726407441,,,10,,,,,,,,,,,,,,,,,,,,,,211.045104980469,211.336349487305,0.00121735187713057,0.00121735187713057,,,7.01492357254028,,1,0,0,0,0.013885498046875,29.3255138397217,6,1,1,211.347244262695,0,4232057760,211.196091969808,,,0.000290566729222277,1.02404613915904E-5,0.00029056672827586,1.02404613476862E-5,0.940147757530212,0.940147757530212,34.1285972595215,0,30,2,200,-3.0773582693655E-5,-0.115960843861103,0.00851607415825129,2,,,,,,,,,,,,,,,,
,3886847550.0831,213.97444152832,0.00121735187713057,,,6,,,,34.1393773296386,,,10,,,,,,,,,,,,,,,,,,,,,,213.849319458008,214.094924926758,0.00121735187713057,0.00121735187713057,,,7.01994895935059,,1,0,0,0,0.013885498046875,28.8367557525635,6,1,1,214.099563598633,0,4232057792,213.972902933757,,,0.000287409179599134,1.01291821370591E-5,0.000287409205773248,1.01291824932528E-5,0.940145313739777,0.940146207809448,34.1406669616699,4.71189414383844E-5,30,2,200,-1.76016692421399E-5,-0.115064308047295,0.00805242918431759,2,,,,,,,,,,,,,,,,
,3886847732.19691,216.886947631836,0.00121735187713057,,,6,,,,34.1501352595562,,,10,,,,,,,,,,,,,,,,,,,,,,216.804916381836,216.961547851562,0.00121735187713057,0.00121735187713057,,,7.02543783187866,,1,0,0,0,0.013885498046875,29.8142719268799,6,1,1,216.968978881836,0,4232057632,216.888066609701,,,0.000284003011681785,1.00091468500158E-5,0.000284003186659566,1.00091483074987E-5,0.940128266811371,0.940136134624481,34.1538734436035,0.133370757102966,30,2,200,-3.18917263939511E-5,-0.114128597080708,0.00750005291774869,2,,,,,,,,,,,,,,,,
,3886847915.05894,219.645851135254,0.00121735187713057,,,6,,,,34.1611064744362,,,10,,,,,,,,,,,,,,,,,,,,,,219.599746704102,219.687377929687,0.00121735187713057,0.00121735187713057,,,7.0312614440918,,1,0,0,0,0.013885498046875,29.3255138397217,5,1,1,219.691955566406,0,4232057792,219.646902720133,,,0.000280696237631883,9.89260357308429E-6,0.00028069662830674,9.89260631489708E-6,0.940136313438415,0.940154910087585,34.166862487793,0,30,2,200,-3.22411069646478E-5,-0.113223560154438,0.00698407553136349,2,,,,,,,,,,,,,,,,
,3886848097.20829,222.294105529785,0.00121735187713057,,,6,,,,34.172089393482,,,10,,,,,,,,,,,,,,,,,,,,,,222.267333984375,222.319107055664,0.00121735187713057,0.00121735187713057,,,7.03899002075195,,1,0,0,0,0.014801025390625,29.3255138397217,5,1,1,222.320877075195,0,4232057888,222.295675913493,,,0.000277497198416781,9.77989742868301E-6,0.000277497744560904,9.77990034626289E-6,0.940064430236816,0.940092206001282,34.1791343688965,0,30,2,200,-3.5606342862593E-5,-0.112357348203659,0.0065214242786169,2,,,,,,,,,,,,,,,,
,3886848297.89586,225.197196960449,0.00121735187713057,,,6,,,,34.1883873945431,,,10,,,,,,,,,,,,,,,,,,,,,,225.020156860352,225.374237060547,0.00121735187713057,0.00121735187713057,,,7.04750776290894,,1,0,0,0,0.014801025390625,30.7917900085449,6,1,1,225.374237060547,0,4232057888,225.189895629883,,,0.000274027389588667,9.65748394846946E-6,0.00027402784427357,9.6574872276882E-6,0.940286993980408,0.94030898809433,34.1946487426758,0,30,2,200,-2.2254751456785E-5,-0.111570283770561,0.00582695053890348,2,,,,,,,,,,,,,,,,
,3886848488.51141,228.663047790527,0.00121735187713057,,,6,,,,34.2049089313256,,,10,,,,,,,,,,,,,,,,,,,,,,228.497695922852,228.799728393555,0.00121735187713057,0.00121735187713057,,,7.05780410766602,,1,0,0,0,0.013885498046875,28.3479976654053,6,1,1,228.828399658203,0,4232057696,228.658922831217,,,0.000270421034669402,9.53051684769771E-6,0.000270421482108477,9.53051932637986E-6,0.940063178539276,0.940086364746094,34.2113456726074,0,30,2,200,-0.000277307786745951,-0.110568732023239,0.00530286692082882,2,,,,,,,,,,,,,,,,
,3886848671.10928,231.712364196777,0.00121735187713057,,,6,,,,34.2169610671594,,,10,,,,,,,,,,,,,,,,,,,,,,231.618911743164,231.788986206055,0.00121735187713057,0.00121735187713057,,,7.07098054885864,,1,0,0,0,0.013885498046875,29.3255138397217,6,1,1,231.805816650391,0,4232057792,231.709014892578,,,0.00026706176232512,9.41207398504403E-6,0.000267062593766327,9.41207883291694E-6,0.940146625041962,0.940189838409424,34.2257461547852,0,30,2,200,-0.000271905853878707,-0.109656065702438,0.0048131151124835,2,,,,,,,,,,,,,,,,
,3886848860.50216,234.603981018066,0.00121735187713057,,,6,,,,34.234694641514,,,10,,,,,,,,,,,,,,,,,,,,,,234.554611206055,234.650848388672,0.00121735187713057,0.00121735187713057,,,7.08738088607788,,1,0,0,0,0.0139617919921875,27.8592376708984,5,1,1,234.653350830078,0,4232057952,234.604015350342,,,0.000263829127812116,9.29816184957898E-6,0.000263829472951829,9.29816431285449E-6,0.940124809741974,0.940142214298248,34.2402610778809,1.85142944246763E-5,30,2,200,-0.000271781900664791,-0.108747132122517,0.00434458302333951,2,,,,,,,,,,,,,,,,
,3886849043.33458,237.270446777344,0.00121735187713057,,,6,,,,34.247092092185,,,10,,,,,,,,,,,,,,,,,,,,,,237.240524291992,237.297119140625,0.00121735187713057,0.00121735187713057,,,7.10620927810669,,1,0,0,0,0.013885498046875,29.3255138397217,5,1,1,237.300369262695,0,4232056832,237.27140045166,,,0.00026079369329479,9.19109060546657E-6,0.000260793823456538,9.19109197223753E-6,0.940284430980682,0.94029027223587,34.2503204345703,0,30,2,200,-0.000312863645376638,-0.107629582285881,0.00409368705004454,2,,,,,,,,,,,,,,,,
,3886849241.1554,239.942420959473,0.00121735187713057,,,6,,,,34.258745357583,,,10,,,,,,,,,,,,,,,,,,,,,,239.887222290039,239.98698425293,0.00121735187713057,0.00121735187713057,,,7.13201999664307,,1,0,0,0,0.013885498046875,28.8367557525635,6,1,1,239.997619628906,0,4232057888,239.919616699219,,,0.000257895379812363,9.08896909437659E-6,0.00025789590724976,9.08897213336915E-6,0.940246403217316,0.940274953842163,34.2658767700195,7.49855899810791,30,2,200,-4.91741375299171E-5,-0.107323929667473,0.00329200457781553,2,,,,,,,,,,,,,,,,
,3886849423.86689,243.096664428711,0.00121735187713057,,,6,,,,34.2741551472691,,,10,,,,,,,,,,,,,,,,,,,,,,242.888580322266,243.287857055664,0.00121735187713057,0.00121735187713057,,,7.16396713256836,,1,0,0,0,0,28.8367557525635,6,1,1,243.304748535156,0,4232057792,243.098286946615,,,0.000254732531084915,8.97745505667667E-6,0.000254733212220785,8.9774580530757E-6,0.940337836742401,0.940376937389374,34.2824935913086,2.24541654461063E-5,30,2,200,-0.000264273781795055,-0.106415994465351,0.00274650286883116,2,,,,,,,,,,,,,,,,
,3886849614.61885,246.461128234863,0.00121735187713057,,,6,,,,34.2915146655658,,,10,,,,,,,,,,,,,,,,,,,,,,246.322402954102,246.591903686523,0.00121735187713057,0.00121735187713057,,,7.20742082595825,,1,0,0,0,0,29.3255138397217,6,1,1,246.599853515625,0,4232057792,246.467674255371,,,0.000251290460766527,8.85617090088537E-6,0.000251291022448998,8.85617387820289E-6,0.940284669399261,0.940316379070282,34.2990264892578,,30,2,200,-3.75179915863555E-5,-0.105463154613972,0.00227872561663389,2,,,,,,,,,,,,,,,,
,3886849805.90884,249.468994140625,0.00121735187713057,,,6,,,,34.307521148631,,,10,,,,,,,,,,,,,,,,,,,,,,249.397232055664,249.540756225586,0.00121735187713057,0.00121735187713057,,,7.26225566864014,,1,0,0,0,0,29.8142719268799,6,1,1,249.540756225586,0,4232057760,249.470504760742,,,0.000248002417985372,8.74022814174012E-6,0.000248002892617451,8.74023117786082E-6,0.94040858745575,0.940434753894806,34.3143424987793,0,30,2,200,-1.8459535567672E-5,-0.104606792330742,0.00171581911854446,2,,,,,,,,,,,,,,,,
,3886849989.62945,252.179702758789,0.00121735187713057,,,6,,,,34.3247887894229,,,10,,,,,,,,,,,,,,,,,,,,,,252.139343261719,252.211898803711,0.00121735187713057,0.00121735187713057,,,7.32583713531494,,1,0,0,0,0,29.3255138397217,5,1,1,252.220062255859,0,4232057888,252.178164395419,,,0.00024492074777869,8.63165431745285E-6,0.00024492110047327,8.63165702666916E-6,0.940342307090759,0.940361142158508,34.3305740356445,7.49813556671143,30,2,200,-0.000256901315879077,-0.103747293353081,0.00126405572518706,2,,,,,,,,,,,,,,,,
,3886850175.6779,254.816223144531,0.00121735187713057,,,6,,,,34.3361964879452,,,10,,,,,,,,,,,,,,,,,,,,,,254.794525146484,254.834381103516,0.00121735187713057,0.00121735187713057,,,7.40756559371948,,1,0,0,0,0.0144195556640625,28.8367557525635,5,1,1,254.837921142578,0,4232057984,254.816224531694,,,0.000241921506946226,8.52595293356385E-6,0.000241921917006833,8.52595604106523E-6,0.940349221229553,0.940371453762054,34.3424835205078,5.86024618148804,30,2,200,-0.000245790608460084,-0.102920144796371,0.000802278576884419,2,,,,,,,,,,,,,,,,
,3886850373.04748,257.68766784668,0.00121735187713057,,,6,,,,34.3524059586974,,,10,,,,,,,,,,,,,,,,,,,,,,257.499420166016,257.847839355469,0.00121735187713057,0.00121735187713057,,,7.5186595916748,,1,0,0,0,0.013885498046875,29.3255138397217,6,1,1,257.875915527344,0,4232057824,257.667289733887,,,0.000238813169048349,8.41631382158197E-6,0.000238813744911289,8.41631779094229E-6,0.940521776676178,0.940554261207581,34.3599967956543,2.1261997972033E-5,30,2,200,-3.84843442589045E-5,-0.102275379002094,0.00013506413961295,2,,,,,,,,,,,,,,,,
,3886850572.91281,261.364761352539,0.00121735187713057,,,6,,,,34.3742949297621,,,10,,,,,,,,,,,,,,,,,,,,,,261.234039306641,261.485900878906,0.00121735187713057,0.00121735187713057,,,7.6662278175354,,1,0,0,0,0.013885498046875,29.8142719268799,6,1,1,261.495483398438,0,4232057888,261.360117594401,,,0.000235396127011615,8.29597455049011E-6,0.000235396569355989,8.29597734775707E-6,0.940361320972443,0.940387070178986,34.3810615539551,0,30,2,200,-0.000248077471042052,-0.101310774683952,-0.000406583189032972,2,,,,,,,,,,,,,,,,
,3886850758.50895,264.306243896484,0.00121735187713057,,,6,,,,34.3904864354041,,,10,,,,,,,,,,,,,,,,,,,,,,264.222778320313,264.386962890625,0.00121735187713057,0.00121735187713057,,,7.82878637313843,,1,0,0,0,0.013885498046875,29.3255138397217,6,1,1,264.389709472656,0,4232057728,264.307945251465,,,0.000232305119386501,8.18697025125533E-6,0.000232305592033588,8.18697253939144E-6,0.940496861934662,0.940526247024536,34.3977088928223,2.0745233996422E-5,30,2,200,-2.01236725843046E-5,-0.100456640124321,-0.000861843465827405,2,,,,,,,,,,,,,,,,
,3886850956.2775,267.177978515625,0.00121735187713057,,,6,,,,34.4024976630812,,,1,,,,,,,,,,,,,,,,,,,,,,267.135437011719,267.218719482422,0.00121735187713057,0.00121735187713057,,,8.01329898834228,,1,0,0,0,0.013885498046875,29.3255138397217,5,1,1,267.220520019531,0,4232057888,267.178682963053,,,0.000229028405674491,8.0714814234441E-6,0.000229029982337114,8.07148905630449E-6,0.940526247024536,0.940625846385956,34.4157791137695,2.79219711956102E-5,30,2,200,-0.000526674615684897,-0.995479166507721,-0.0131134996190667,2,,,,,,,,,,,,,,,,
,3886851148.83439,269.83219909668,0.00121735187713057,,,6,,,,34.4209358681658,,,1,,,,,,,,,,,,,,,,,,,,,,269.808776855469,269.85498046875,0.00121735187713057,0.00121735187713057,,,8.22553825378418,,1,0,0,0,0,29.3255138397217,5,1,1,269.855621337891,0,4232057792,269.835283915202,,,0.000226000102566733,7.96473982688761E-6,0.000226001317329289,7.96474602723812E-6,0.940555214881897,0.940632283687592,34.4326210021973,0,30,2,200,-0.00035870837746188,-0.987050890922546,-0.0172736663371325,2,,,,,,,,,,,,,,,,
,3886851347.46322,272.926208496094,0.00121735187713057,,,6,,,,34.4382849281497,,,1,,,,,,,,,,,,,,,,,,,,,,272.742340087891,273.110076904297,0.00121735187713057,0.00121735187713057,,,8.4637336730957,,1,0,0,0,0.013885498046875,28.8367557525635,6,1,1,273.110076904297,0,4232057920,272.92699432373,,,0.000222895828336175,7.85528195760407E-6,0.000222898056244163,7.85529119857277E-6,0.940676510334015,0.940824806690216,34.4544715881348,0,30,2,200,-0.000459121860330924,-0.980403304100037,-0.0243773087859154,2,,,,,,,,,,,,,,,,
,3886851532.11623,276.111740112305,0.00121735187713057,,,6,,,,34.4552267916258,,,1,,,,,,,,,,,,,,,,,,,,,,275.956573486328,276.232116699219,0.00121735187713057,0.00121735187713057,,,8.58752918243408,,1,0,0,0,0.013885498046875,29.8142719268799,6,1,1,276.266906738281,0,4232057728,276.10688273112,,,0.000218995573819506,7.71797120408004E-6,0.000218999465967942,7.7179819687789E-6,0.940369784832001,0.940644085407257,34.4772834777832,0,30,2,200,-0.00202988786622882,-0.969049632549286,-0.0292664784938097,2,,,,,,,,,,,,,,,,
,3886851724.91223,279.298843383789,0.00121735187713057,,,6,,,,34.4731531828119,,,1,,,,,,,,,,,,,,,,,,,,,,279.207427978516,279.383605957031,0.00121735187713057,0.00121735187713057,,,8.70846939086914,,1,0,0,0,0.013885498046875,28.3479976654053,6,1,1,279.390258789062,0,4232057760,279.303487141927,,,0.000215789975975427,7.60491658901574E-6,0.000215795439307294,7.60493771575475E-6,0.940550208091736,0.940929234027863,34.4990272521973,0,30,2,200,-0.00178427225910127,-0.959648728370666,-0.033791147172451,2,,,,,,,,,,,,,,,,
,3886851909.37338,282.08659362793,0.00121735187713057,,,6,,,,34.490484742705,,,1,,,,,,,,,,,,,,,,,,,,,,282.034423828125,282.136871337891,0.00121735187713057,0.00121735187713057,,,8.88361358642578,,1,0,0,0,0.013885498046875,29.3255138397217,6,1,1,282.138763427734,0,4232057632,282.089279174805,,,0.000213076490033098,7.50931080035623E-6,0.000213084180100689,7.5093391401437E-6,0.940492689609528,0.941036343574524,34.5214653015137,0.000312601216137409,30,2,200,-0.00042820384260267,-0.952407121658325,-0.0378652848303318,2,,,,,,,,,,,,,,,,
,3886852102.5132,284.791320800781,0.00121735187713057,,,6,,,,34.5079756977521,,,1,,,,,,,,,,,,,,,,,,,,,,284.765716552734,284.814971923828,0.00121735187713057,0.00121735187713057,,,9.07839012145996,,1,0,0,0,0.013885498046875,27.3704795837402,5,1,1,284.816925048828,0,4232057856,284.792249043783,,,0.000210569922413656,7.42116940767485E-6,0.000210580291853708,7.42119527937121E-6,0.940048694610596,0.940814137458801,34.5448379516602,,30,2,200,-0.00046269063022919,-0.945719480514526,-0.041743878275156,2,,,,,,,,,,,,,,,,
,3886852295.74652,287.443572998047,0.00121735187713057,,,6,,,,34.5201228650788,,,1,,,,,,,,,,,,,,,,,,,,,,287.380493164062,287.490905761719,0.00121735187713057,0.00121735187713057,,,9.27367687225342,,1,0,0,0,0,29.3255138397217,6,1,1,287.506652832031,0,4232057920,287.417623666617,,,0.000208085963633318,7.33376940674014E-6,0.000208101231370442,7.33381213976319E-6,0.939733505249023,0.94086080789566,34.5649108886719,,30,2,200,-0.000434061861597002,-0.941246628761292,-0.0473676957190037,2,,,,,,,,,,,,,,,,
,3886852488.04156,290.77799987793,0.00121735187713057,,,6,,,,34.5440636639354,,,1,,,,,,,,,,,,,,,,,,,,,,290.590606689453,290.95361328125,0.00121735187713057,0.00121735187713057,,,9.26849174499512,,1,0,0,0,0.013885498046875,29.3255138397217,6,1,1,290.965393066406,0,4232057984,290.782287597656,,,0.000205650627289742,7.24800253897032E-6,0.000205668625553694,7.2480389059462E-6,0.939588367938995,0.940964758396149,34.5935554504395,0,30,2,200,-0.00216374616138637,-0.933963358402252,-0.0515838116407394,2,,,,,,,,,,,,,,,,
,3886852681.24047,294.093185424805,0.00121735187713057,,,6,,,,34.563120984865,,,1,,,,,,,,,,,,,,,,,,,,,,293.988861083984,294.192443847656,0.00121735187713057,0.00121735187713057,,,9.34757995605469,,1,0,0,0,0.013885498046875,29.8142719268799,6,1,1,294.197509765625,0,4232057600,294.092620849609,,,0.000203258292951538,7.16388385584393E-6,0.000203283043907115,7.1639329738541E-6,0.939135432243347,0.941046595573425,34.6215324401855,,30,2,200,-0.00193475210107863,-0.926988244056702,-0.0549289025366306,2,,,,,,,,,,,,,,,,
,3886852867.59282,296.942687988281,0.00121735187713057,,,6,,,,34.5810270074642,,,1,,,,,,,,,,,,,,,,,,,,,,296.875366210937,297.0078125,0.00121735187713057,0.00121735187713057,,,9.48169136047363,,1,0,0,0,0.013885498046875,29.8142719268799,6,1,1,297.010009765625,0,4232057856,296.94659169515,,,0.000201145208518084,7.08959201025496E-6,0.000201176640849565,7.08965806214374E-6,0.938704073429108,0.941141068935394,34.6470794677734,0,30,2,200,-0.000191213461221196,-0.922217309474945,-0.0585329569876194,2,,,,,,,,,,,,,,,,
,3886853060.13491,299.716094970703,0.00121735187713057,,,6,,,,34.59929676886,,,1,,,,,,,,,,,,,,,,,,,,,,299.679290771484,299.749237060547,0.00121735187713057,0.00121735187713057,,,9.65995407104492,,1,0,0,0,0.013885498046875,29.3255138397217,5,1,1,299.752899169922,0,4232057824,299.71662902832,,,0.000199342491912432,7.0263815341055E-6,0.000199381597994892,7.02646282093202E-6,0.937957227230072,0.940995931625366,34.6733322143555,6.33633462712169E-5,30,2,200,-0.00034317685640417,-0.917032897472382,-0.0616203583776951,2,,,,,,,,,,,,,,,,
,3886853084.25117,299.827163696289,0.00121735187713057,,,6,,,,34.59929676886,,,1,,,,,,,,,,,,,,,,,,,,,,299.808410644531,299.845397949219,0.00121735187713057,0.00121735187713057,,,9.70506477355957,,1,0,0,0,0.0006103515625,29.3255138397217,5,1,1,299.845916748047,0,4232057728,299.829612731934,,,0.000199115205313088,7.01842713060116E-6,0.000199156367841738,7.01850655236957E-6,0.937826454639435,0.941040635108948,34.675464630127,0.000481063732877374,30,2,200,-0.000337991659762338,-0.916778266429901,-0.0616007670760155,2,,,,,,,,,,,,,,,,