File: Chapter5/lowT/LG12_HYS_300K.dat
[Header]
; MPMS3 Data File (default extension .dat)
; Copyright (c) 2007, Quantum Design, Inc. All rights reserved.
TITLE,
FILEOPENTIME,3886925430.35798,03/02/2023,1:30 pm
BYAPP,MPMS3 w/ AC,1.0,1.1
INFO,MPMS3 Measurement Release 1.1.16 Build 424, MultiVu Release 2.3.4.26,APPNAME
INFO,Linear Motor Servo Controller,MOTOR_MODULE_NAME
INFO,3101-100 N0,MOTOR_HW_VERSION
INFO,MMC1047,MOTOR_SERIAL_NUMBER
INFO,01.04.28,MOTOR_SOFTWARE_VERSION
INFO,Quantum Design Squid Module,SQUID_MODULE_NAME
INFO,3101-501 B0,SQUID_HW_VERSION
INFO,SQM278,SQUID_SERIAL_NUMBER
INFO,01.03.04,SQUID_SOFTWARE_VERSION
INFO,Quantum Design VSM Oven,OVEN_MODULE_NAME
INFO,3101-201 A3,OVEN_HW_VERSION
INFO,OVB323,OVEN_SERIAL_NUMBER
INFO,01.07.07,OVEN_SOFTWARE_VERSION
INFO,SQUID AC,AC_MODULE_NAME
INFO,3101-401 G0,AC_HW_VERSION
INFO,SAC258,AC_SERIAL_NUMBER
INFO,SQUID AC 00.95.07,AC_SOFTWARE_VERSION
INFO,TCI408,COIL_SERIAL_NUMBER
INFO,0,MOMENT_UNITS
INFO,C3,SAMPLE_MATERIAL
INFO,,SAMPLE_COMMENT
INFO,,SAMPLE_MASS
INFO,,SAMPLE_VOLUME
INFO,,SAMPLE_MOLECULAR_WEIGHT
INFO,,SAMPLE_SIZE
INFO,,SAMPLE_SHAPE
INFO,Straw,SAMPLE_HOLDER
INFO,Standard,SAMPLE_HOLDER_DETAIL
INFO,66.62,SAMPLE_OFFSET
DATATYPE,COMMENT,1
DATATYPE,TIME,2
STARTUPAXIS,X,2
STARTUPAXIS,Y1,5
FIELDGROUP, VSM,2,3,4,5,6,8,9,10,11,14,15
FIELDGROUP, DC, 2,3,4,14,56,57,58,59,60,61,62,63,64,65,66,67,68,69
FIELDGROUP, AC, 2,3,4,11,16,17,18,19,20,21,22,23,24,25,26,27,28,29,30
STARTUPGROUP, All
[Data]
Comment,Time Stamp (sec),Temperature (K),Magnetic Field (Oe),Moment (emu),M. Std. Err. (emu),Transport Action,Averaging Time (sec),Frequency (Hz),Peak Amplitude (mm),Center Position (mm),Lockin Signal' (V),Lockin Signal (V),Range,M. Quad. Signal (emu),AC Moment (emu),AC M. Std Err. (emu),AC Phase (deg),AC Phase Std. Err. (deg),AC Susceptibility (emu/Oe),AC Suscept. Std Err. (emu/Oe),AC X' (emu/Oe),AC X' Std Err. (emu/Oe),AC X'' (emu/Oe),AC X'' Std Err. (emu/Oe),AC Drive (Oe),AC Frequency (Hz),AC Averaging Time (sec),AC Cycles,AC Range,AC Measure Type,AC Signal' (V),AC Signal'' (V),AC Trim Coil Ratio,AC Trim Coil Phase,Min. Temperature (K),Max. Temperature (K),Min. Field (Oe),Max. Field (Oe),Mass (grams),Motor Lag (deg),Pressure (Torr),Measure Count,Measurement Number,SQUID Status (code),Motor Status (code),Measure Status (code),Motor Current (amps),Motor Temp. (C),Temp. Status (code),Field Status (code),Chamber Status (code),Chamber Temp (K),Redirection State,Evercool Status,Average Temp (K),Rotation Angle (deg),Rotator state,DC Moment Fixed Ctr (emu),DC Moment Err Fixed Ctr (emu),DC Moment Free Ctr (emu),DC Moment Err Free Ctr (emu),DC Fixed Fit,DC Free Fit,DC Calculated Center (mm),DC Calculated Center Err (mm),DC Scan Length (mm),DC Scan Time (s),DC Number of Points,DC Squid Drift,DC Min V (V),DC Max V (V),DC Scans per Measure,Map 01,Map 02,Map 03,Map 04,Map 05,Map 06,Map 07,Map 08,Map 09,Map 10,Map 11,Map 12,Map 13,Map 14,Map 15,Map 16
,3886925476.28755,300.002792358398,15000.322265625,,,6,,,,34.6006521713563,,,100,,,,,,,,,,,,,,,,,,,,,,300.001434326172,300.00537109375,15000.322265625,15000.322265625,,,8.38742065429688,,1,0,0,0,0,29.3255138397217,1,1,1,300.001281738281,0,4232056832,300.003687241498,,,0.00665927124751132,0.000234912427147048,0.00666794692924627,0.000234928095501166,0.926226317882538,0.945388078689575,34.7919044494629,0.000614243908785284,30,2,200,0.000760461669415235,-0.253170311450958,0.0386060103774071,2,,,,,,,,,,,,,,,,
,3886925665.53491,300.000289916992,14312.5771484375,,,6,,,,34.6006521713563,,,100,,,,,,,,,,,,,,,,,,,,,,299.999084472656,300.002593994141,14312.5771484375,14312.5771484375,,,8.59011650085449,,1,0,0,0,0.013885498046875,28.3479976654053,1,1,1,299.998870849609,0,4232057728,300.00122833252,,,0.00655682048707739,0.000231309816733914,0.00656564036533243,0.000231326538829393,0.925564229488373,0.945157885551453,34.7947463989258,5.89870738983154,30,2,200,0.000130962827824987,-0.252225935459137,0.0300964936614037,2,,,,,,,,,,,,,,,,
,3886925854.99287,300.001770019531,13624.94140625,,,6,,,,34.6006521713563,,,100,,,,,,,,,,,,,,,,,,,,,,299.998474121094,300.004791259766,13624.94140625,13624.94140625,,,8.91268444061279,,1,0,0,0,0.013885498046875,29.3255138397217,1,1,1,299.999572753906,0,4232057792,300.001592000326,,,0.0064531883466824,0.000227658295734916,0.00646191209883444,0.000227673878775287,0.92530483007431,0.944996118545532,34.7955474853516,5.89877510070801,30,2,200,0.000772281840909272,-0.247766956686974,0.0358271226286888,2,,,,,,,,,,,,,,,,
,3886926044.33168,299.997253417969,12937.1953125,,,6,,,,34.6006521713563,,,100,,,,,,,,,,,,,,,,,,,,,,299.997314453125,299.998443603516,12937.1953125,12937.1953125,,,9.28892707824707,,1,0,0,0,0.013885498046875,29.3255138397217,1,1,1,299.997192382812,0,4232057952,299.99774424235,,,0.00635008080466973,0.000224008640623514,0.00635823872914167,0.000224023592095385,0.926039338111878,0.944806814193726,34.7905464172363,,30,2,200,0.00133995560463518,-0.241132318973541,0.0386392697691917,2,,,,,,,,,,,,,,,,
,3886926233.49932,299.999816894531,12249.7080078125,,,6,,,,34.6006521713563,,,100,,,,,,,,,,,,,,,,,,,,,,299.998260498047,300.001953125,12249.7080078125,12249.7080078125,,,9.67123317718506,,1,0,0,0,0.013885498046875,29.8142719268799,1,1,1,299.998077392578,0,4232057728,300.000391642253,,,0.00624902573774278,0.000220413932357618,0.00625606901551935,0.000220426701283226,0.92787778377533,0.944561898708344,34.7785987854004,0.0893581435084343,30,2,200,0.00175938103348017,-0.240811973810196,0.0320038050413132,2,,,,,,,,,,,,,,,,
,3886926422.12562,300.001892089844,11562.01171875,,,6,,,,34.6006521713563,,,100,,,,,,,,,,,,,,,,,,,,,,300.001800537109,300.003173828125,11562.01171875,11562.01171875,,,9.96108531951904,,1,0,0,0,0,29.8142719268799,1,1,1,300.001983642578,0,4232057728,300.002471923828,,,0.00615171359734145,0.000216953111984245,0.00615770754742302,0.000216964449496849,0.929716229438782,0.944286704063416,34.7659454345703,,30,2,200,0.00189734995365143,-0.236013427376747,0.0325301922857761,2,,,,,,,,,,,,,,,,
,3886926623.41607,299.998352050781,10874.3896484375,,,6,,,,34.6006521713563,,,100,,,,,,,,,,,,,,,,,,,,,,299.998107910156,299.999572753906,10874.3896484375,10874.3896484375,,,10.0938749313354,,1,0,0,0,0.013885498046875,29.8142719268799,1,1,1,299.998046875,0,4232057856,299.998769124349,,,0.00605388166309162,0.0002134773034161,0.00605896906221967,0.000213487251430034,0.931426584720612,0.944127678871155,34.7540168762207,,30,2,200,0.00197683740407228,-0.231545940041542,0.0340001210570335,2,,,,,,,,,,,,,,,,
,3886926814.08911,299.999038696289,10186.408203125,,,6,,,,34.6006521713563,,,100,,,,,,,,,,,,,,,,,,,,,,299.998504638672,300.000518798828,10186.408203125,10186.408203125,,,10.3360195159912,,1,0,0,0,0.013885498046875,29.8142719268799,1,1,1,299.998504638672,0,4232057824,299.999725341797,,,0.00595392394799765,0.000209931382160787,0.00595821063422012,0.000209940064876445,0.932903647422791,0.9438716173172,34.7424774169922,0.0870624333620071,30,2,200,0.00203795684501529,-0.226421818137169,0.035993579775095,2,,,,,,,,,,,,,,,,
,3886927001.94727,300.001495361328,9499.0703125,,,6,,,,34.6006521713563,,,100,,,,,,,,,,,,,,,,,,,,,,300.001129150391,300.003265380859,9499.0703125,9499.0703125,,,10.4286336898804,,1,0,0,0,0.013885498046875,29.3255138397217,1,1,1,300.001129150391,0,4232057792,300.002136230469,,,0.0058525084015869,0.000206340875355615,0.00585617899399737,0.000206347873546136,0.933966219425201,0.943619251251221,34.7332725524902,0.133355483412743,30,2,200,0.00209734099917114,-0.225134387612343,0.0359445437788963,2,,,,,,,,,,,,,,,,
,3886927197.78552,300.000549316406,8811.2001953125,,,6,,,,34.6006521713563,,,100,,,,,,,,,,,,,,,,,,,,,,300.000549316406,300.002746582031,8811.2001953125,8811.2001953125,,,10.6144180297852,,1,0,0,0,0.013885498046875,28.3479976654053,1,1,1,300.000549316406,0,4232057728,300.001637776693,,,0.00575098325567655,0.000202751894513272,0.0057541938099769,0.000202758267824752,0.934682250022888,0.943281352519989,34.725643157959,1.41125010486576E-5,30,2,200,0.00208238000050187,-0.220517307519913,0.0312247294932604,2,,,,,,,,,,,,,,,,
,3886927387.7589,299.999908447266,8123.50390625,,,6,,,,34.6006521713563,,,100,,,,,,,,,,,,,,,,,,,,,,299.99951171875,300.002014160156,8123.50390625,8123.50390625,,,10.6082382202148,,1,0,0,0,0.013885498046875,29.8142719268799,1,1,1,299.998992919922,0,4232057760,300.001040140788,,,0.00564556739483925,0.000199026299568357,0.00564838636056481,0.000199032239625979,0.935384035110474,0.943079054355621,34.7186622619629,0.133415475487709,30,2,200,0.00211441074497998,-0.216253027319908,0.0322095192968845,2,,,,,,,,,,,,,,,,
,3886927576.22722,300.001510620117,7435.9052734375,,,6,,,,34.6006521713563,,,100,,,,,,,,,,,,,,,,,,,,,,300.001129150391,300.003692626953,7435.9052734375,7435.9052734375,,,10.6110973358154,,1,0,0,0,0.013885498046875,29.8142719268799,1,1,1,300.001007080078,0,4232057888,300.002555847168,,,0.00553994664348061,0.000195296114877647,0.0055424314489453,0.000195301211884718,0.935907304286957,0.942848145961762,34.7125968933105,0,30,2,200,0.00216156616806984,-0.210972055792809,0.031915508210659,2,,,,,,,,,,,,,,,,
,3886927764.63592,299.998168945313,6748.2587890625,,,6,,,,34.6006521713563,,,100,,,,,,,,,,,,,,,,,,,,,,299.996246337891,300.002105712891,6748.2587890625,6748.2587890625,,,10.6129627227783,,1,0,0,0,0.013885498046875,29.3255138397217,1,1,1,299.996215820313,0,4232057728,299.999598185221,,,0.00543231432274463,0.000191494950378824,0.00543443433511612,0.00019149943553636,0.936475217342377,0.942514598369598,34.7049865722656,0.133403822779655,30,2,200,0.00215738825500011,-0.208492770791054,0.0296697244048119,2,,,,,,,,,,,,,,,,
,3886927952.49151,299.998016357422,6060.66064453125,,,6,,,,34.6006521713563,,,100,,,,,,,,,,,,,,,,,,,,,,299.997711181641,299.999755859375,6060.66064453125,6060.66064453125,,,10.618088722229,,1,0,0,0,0.013885498046875,28.8367557525635,1,1,1,299.998321533203,0,4232058144,299.998809814453,,,0.00532256534791324,0.000187619965910414,0.00532434277127188,0.000187623858321804,0.936994969844818,0.942158401012421,34.6970672607422,0,30,2,200,0.00221358868293464,-0.201810777187347,0.0321461781859398,2,,,,,,,,,,,,,,,,
,3886928138.39212,300.001541137695,5372.865234375,,,6,,,,34.6006521713563,,,100,,,,,,,,,,,,,,,,,,,,,,300.000610351562,300.003936767578,5372.865234375,5372.865234375,,,10.603874206543,,1,0,0,0,0.013885498046875,27.8592376708984,1,1,1,300.000244140625,0,4232057952,300.002461751302,,,0.00520865037955816,0.000183596952347924,0.00521007519252187,0.000183599947932235,0.937653541564941,0.941909074783325,34.6880340576172,0.0812029018998146,30,2,200,0.00253759720362723,-0.198616415262222,0.0319621190428734,2,,,,,,,,,,,,,,,,
,3886928325.36913,299.999740600586,4685.09423828125,,,6,,,,34.6006521713563,,,100,,,,,,,,,,,,,,,,,,,,,,299.999877929687,300.002075195313,4685.09423828125,4685.09423828125,,,10.6029176712036,,1,0,0,0,0.013885498046875,29.3255138397217,1,1,1,299.999359130859,0,4232057984,300.000926624645,,,0.00508885178414522,0.000179369321510931,0.00508998465982885,0.000179371834948316,0.938088059425354,0.941541135311127,34.6793556213379,0.000493943691253662,30,2,200,0.00226498278789222,-0.19471763074398,0.0644831359386444,2,,,,,,,,,,,,,,,,
,3886928513.17315,299.997161865234,3997.47216796875,,,6,,,,34.6006521713563,,,100,,,,,,,,,,,,,,,,,,,,,,299.996795654297,299.998443603516,3997.47216796875,3997.47216796875,,,10.6283445358276,,1,0,0,0,0.013885498046875,28.8367557525635,1,1,1,299.997314453125,0,4232057728,299.997596740723,,,0.00496099610560026,0.000174858979153679,0.00496186755705353,0.000174860683990586,0.938432037830353,0.941178023815155,34.670841217041,0.00047403053031303,30,2,200,0.00237882579676807,-0.189798295497894,0.029607655480504,2,,,,,,,,,,,,,,,,
,3886928699.14745,299.995819091797,3309.66430664063,,,6,,,,34.6006521713563,,,100,,,,,,,,,,,,,,,,,,,,,,299.994689941406,299.998779296875,3309.66430664063,3309.66430664063,,,10.6139345169067,,1,0,0,0,0.0016021728515625,28.3479976654053,1,1,1,299.994689941406,0,4232057856,299.996663411458,,,0.00481491277690181,0.000169704888826424,0.00481551645463131,0.00016970642880587,0.938918590545654,0.940846025943756,34.6594314575195,,30,2,200,0.00244943401776254,-0.182405695319176,0.0312072448432446,2,,,,,,,,,,,,,,,,
,3886928883.57898,299.996643066406,2622.14038085938,,,6,,,,34.6006521713563,,,100,,,,,,,,,,,,,,,,,,,,,,299.996215820313,299.9990234375,2622.14038085938,2622.14038085938,,,10.6187496185303,,1,0,0,0,0,29.3255138397217,1,1,1,299.995727539063,0,4232057888,299.997489929199,,,0.00463415440037771,0.000163329881048226,0.00463452048010214,0.000163330767927283,0.939327955245972,0.940548360347748,34.647403717041,0.133306249976158,30,2,200,0.00243463600054383,-0.17706173658371,0.0286728553473949,2,,,,,,,,,,,,,,,,
,3886929069.54134,300.005737304687,1934.44396972656,,,6,,,,34.6006521713563,,,100,,,,,,,,,,,,,,,,,,,,,,300.004486083984,300.007751464844,1934.44396972656,1934.44396972656,,,10.5936098098755,,1,0,0,0,0.013885498046875,28.8367557525635,1,1,1,300.004272460937,0,4232057696,300.005967573686,,,0.00435994421287187,0.000153663223639454,0.00436010877382228,0.000153663738926806,0.939562320709229,0.940131962299347,34.632625579834,,30,2,200,0.00250231334939599,-0.167301952838898,0.0282572526484728,2,,,,,,,,,,,,,,,,
,3886929255.85469,300.000915527344,1246.69775390625,,,6,,,,34.6006521713563,,,100,,,,,,,,,,,,,,,,,,,,,,300.000427246094,300.003326416016,1246.69775390625,1246.69775390625,,,10.610951423645,,1,0,0,0,0.013885498046875,29.8142719268799,1,1,1,300.000427246094,0,4232057760,300.001879374186,,,0.00380100837563275,0.000133965901184309,0.00380102433577007,0.000133965984472652,0.939311981201172,0.93937075138092,34.6109657287598,0,30,2,200,0.00263413973152637,-0.147142350673676,0.0239656791090965,2,,,,,,,,,,,,,,,,
,3886929439.54192,299.998641967773,559.112243652344,,,6,,,,34.6006521713563,,,10,,,,,,,,,,,,,,,,,,,,,,299.997711181641,300.001434326172,559.112243652344,559.112243652344,,,10.6095705032349,,1,0,0,0,0.013885498046875,29.3255138397217,1,1,1,299.997711181641,0,4232058016,299.999127556296,,,0.00251217686172632,8.85423887380349E-5,0.00251217710220777,8.85423935245823E-5,0.939109623432159,0.939110338687897,34.6017646789551,5.88232660293579,30,2,200,0.0205260626971722,-0.983222663402557,0.220515191555023,2,,,,,,,,,,,,,,,,
,3886929628.01771,299.993591308594,-128.967376708984,,,6,,,,34.6006521713563,,,1,,,,,,,,,,,,,,,,,,,,,,299.992797851562,299.995666503906,-128.967376708984,-128.967376708984,,,10.6198263168335,,1,0,0,0,0.013885498046875,29.8142719268799,1,1,1,299.994384765625,0,4232057792,299.994450887044,,,-0.000289416530637659,1.02147713932359E-5,-0.000289708406919095,1.02151736944313E-5,0.919523000717163,0.932546257972717,34.4308319091797,4.43846797943115,30,2,200,0.229041993618011,-0.532555401325226,1.63635885715485,2,,,,,,,,,,,,,,,,
,3886929816.47709,299.997894287109,-816.861755371094,,,6,,,,34.6006521713563,,,10,,,,,,,,,,,,,,,,,,,,,,299.997589111328,300.000885009766,-816.861755371094,-816.861755371094,,,10.6042613983154,,1,0,0,0,0.0139617919921875,28.8367557525635,1,1,1,299.998199462891,0,4232057664,299.999458312988,,,-0.00300252228809707,0.000105824328840675,-0.00300256397300853,0.000105824292277852,0.939174234867096,0.939407765865326,34.5800857543945,0,30,2,200,0.0135700851678848,-0.187900632619858,1.16971325874329,2,,,,,,,,,,,,,,,,
,3886929998.52342,299.999221801758,-1504.58312988281,,,6,,,,34.6006521713563,,,10,,,,,,,,,,,,,,,,,,,,,,299.998504638672,300.000701904297,-1504.58312988281,-1504.58312988281,,,10.5940933227539,,1,0,0,0,0.013885498046875,29.8142719268799,1,1,1,299.999725341797,0,4232057856,299.999450683594,,,-0.00401441041938009,0.000141480619430313,-0.00401442132434977,0.000141480691191189,0.940079689025879,0.940116465091705,34.6087532043457,0.646353602409363,30,2,200,0.00589423114433885,-0.248437017202377,1.55816292762756,2,,,,,,,,,,,,,,,,
,3886930180.84285,300.001953125,-2191.9091796875,,,6,,,,34.6006521713563,,,10,,,,,,,,,,,,,,,,,,,,,,300.001647949219,300.004791259766,-2191.9091796875,-2191.9091796875,,,10.5873289108276,,1,0,0,0,0.0018310546875,29.3255138397217,1,1,1,300.001647949219,0,4232057696,300.0033009847,,,-0.00442614131390551,0.000155990942423228,-0.00442628834486035,0.000155991362434114,0.940134227275848,0.94064450263977,34.6307678222656,0,30,2,200,-0.00124913360923529,-0.281412601470947,1.90781271457672,2,,,,,,,,,,,,,,,,
,3886930364.94229,299.998870849609,-2879.87768554687,,,6,,,,34.6006521713563,,,10,,,,,,,,,,,,,,,,,,,,,,299.997680664063,300.001190185547,-2879.87768554687,-2879.87768554687,,,10.5787210464478,,1,0,0,0,0.013885498046875,28.3479976654053,1,1,1,299.997314453125,0,4232057728,299.999712626139,,,-0.00465476462494477,0.000164052548313241,-0.00465513027262208,0.000164053442368635,0.939701437950134,0.940921783447266,34.6472511291504,0,30,2,200,-0.00576312886551023,-0.289263248443604,1.77199018001556,2,,,,,,,,,,,,,,,,
,3886930548.44023,299.993469238281,-3567.5,,,6,,,,34.6006521713563,,,10,,,,,,,,,,,,,,,,,,,,,,299.990417480469,300.000640869141,-3567.5,-3567.5,,,10.5816516876221,,1,0,0,0,0.013885498046875,29.3255138397217,1,1,1,299.98828125,0,4232056832,299.998715718587,,,-0.00482241334715823,0.000169967560356142,-0.00482306951167658,0.000169969217600325,0.939080655574799,0.941182851791382,34.6619033813477,0,30,2,200,0.00444769626483321,-0.293434292078018,1.80418181419373,2,,,,,,,,,,,,,,,,
,3886930732.10585,300.001770019531,-4255.46875,,,6,,,,34.6006521713563,,,10,,,,,,,,,,,,,,,,,,,,,,300.000579833984,300.005554199219,-4255.46875,-4255.46875,,,10.5611257553101,,1,0,0,0,0.013885498046875,29.3255138397217,1,1,1,300.002960205078,0,4232057984,300.004320780436,,,-0.00496596708011943,0.000175033499601689,-0.0049669199175401,0.000175035827497925,0.938491642475128,0.941455543041229,34.673469543457,,30,2,200,0.0116828950121999,-0.291439592838287,1.91043663024902,2,,,,,,,,,,,,,,,,
,3886930917.08844,299.999465942383,-4942.9677734375,,,6,,,,34.6006521713563,,,10,,,,,,,,,,,,,,,,,,,,,,299.987365722656,300.001251220703,-4942.9677734375,-4942.9677734375,,,10.5687475204468,,1,0,0,0,0.013885498046875,29.3255138397217,1,1,1,299.997680664063,0,4232057472,299.993639628092,,,-0.00509697830641035,0.000179664913092033,-0.00509831790656005,0.000179667726939729,0.937267243862152,0.941323161125183,34.6863174438477,0.133392944931984,30,2,200,0.0170037336647511,-0.277737975120544,1.9790974855423,2,,,,,,,,,,,,,,,,
,3886931102.89023,300.002288818359,-5630.77587890625,,,6,,,,34.6006521713563,,,10,,,,,,,,,,,,,,,,,,,,,,300.001556396484,300.004333496094,-5630.77587890625,-5630.77587890625,,,10.562801361084,,1,0,0,0,0,27.8592376708984,1,1,1,300.000915527344,0,4232057408,300.003555297852,,,-0.00521673318086604,0.000183894346797606,-0.00521845892655745,0.000183897988380041,0.936574101448059,0.941662609577179,34.6967353820801,5.89039325714111,30,2,200,0.0177555922418833,-0.310236036777496,1.99812507629395,2,,,,,,,,,,,,,,,,
,3886931289.84606,300.000381469727,-6318.23779296875,,,6,,,,34.6006521713563,,,10,,,,,,,,,,,,,,,,,,,,,,299.996948242188,300.002319335937,-6318.23779296875,-6318.23779296875,,,10.5704593658447,,1,0,0,0,0.013885498046875,29.3255138397217,1,1,1,299.999359130859,0,4232057632,299.999736439098,,,-0.00533272927437214,0.000187994203466557,-0.00533493732883442,0.000187998662543234,0.935664296150207,0.942021548748016,34.7082748413086,,30,2,200,0.0186258256435394,-0.321459352970123,2.06929492950439,2,,,,,,,,,,,,,,,,
,3886931474.85495,299.999282836914,-7005.958984375,,,6,,,,34.6006521713563,,,10,,,,,,,,,,,,,,,,,,,,,,299.998718261719,300.002166748047,-7005.958984375,-7005.958984375,,,10.5788669586182,,1,0,0,0,0.013885498046875,29.3255138397217,1,1,1,299.998504638672,0,4232057888,300.000834147135,,,-0.00544488956518006,0.000191957643293198,-0.00544755019924916,0.000191963185780081,0.934907913208008,0.942370653152466,34.7174453735352,0,30,2,200,0.0191604141145945,-0.302674680948257,2.72000503540039,2,,,,,,,,,,,,,,,,
,3886931662.45518,299.997985839844,-7693.6064453125,,,6,,,,34.6006521713563,,,10,,,,,,,,,,,,,,,,,,,,,,299.9970703125,299.999847412109,-7693.6064453125,-7693.6064453125,,,10.5908174514771,,1,0,0,0,0.013885498046875,29.8142719268799,1,1,1,299.997955322266,0,4232058112,299.998458862305,,,-0.00555388239163293,0.000195814537006972,-0.00555712218490737,0.000195820853990248,0.93379133939743,0.942676424980164,34.7284965515137,5.89308881759644,30,2,200,0.020754124969244,-0.327606528997421,2.12875819206238,2,,,,,,,,,,,,,,,,
,3886931850.24628,300.000213623047,-8381.3642578125,,,6,,,,34.6006521713563,,,10,,,,,,,,,,,,,,,,,,,,,,299.999755859375,300.002380371094,-8381.3642578125,-8381.3642578125,,,10.5913047790527,,1,0,0,0,0.013885498046875,29.8142719268799,1,1,1,299.999603271484,0,4232057312,300.0009765625,,,-0.00566200880900907,0.000199642550594558,-0.0056658615292762,0.000199650050258205,0.932616293430328,0.942901253700256,34.7387275695801,1.48302378875087E-5,30,2,200,0.0213042180985212,-0.296524852514267,2.18122529983521,2,,,,,,,,,,,,,,,,
,3886932037.45214,299.999923706055,-9069.0126953125,,,6,,,,34.6006521713563,,,10,,,,,,,,,,,,,,,,,,,,,,299.999176025391,300.003845214844,-9069.0126953125,-9069.0126953125,,,10.5878076553345,,1,0,0,0,0.013885498046875,29.8142719268799,1,1,1,299.99853515625,0,4232057920,300.001612345378,,,-0.00576840584839011,0.000203410296723675,-0.00577290331302443,0.000203419116071067,0.93144553899765,0.943135857582092,34.7483978271484,5.89477729797363,30,2,200,0.0194199755787849,-0.32511442899704,2.21795034408569,2,,,,,,,,,,,,,,,,
,3886932224.83779,299.9990234375,-9756.8447265625,,,6,,,,34.6006521713563,,,10,,,,,,,,,,,,,,,,,,,,,,299.998046875,300.001708984375,-9756.8447265625,-9756.8447265625,,,10.5870809555054,,1,0,0,0,0,29.8142719268799,1,1,1,299.998107910156,0,4232057920,299.999855041504,,,-0.00587336066557515,0.000207129076338682,-0.00587855184675915,0.000207138870392018,0.930217623710632,0.943396329879761,34.7581176757812,,30,2,200,0.0198459513485432,-0.349117010831833,2.23827385902405,2,,,,,,,,,,,,,,,,
,3886932411.60479,299.997711181641,-10444.4306640625,,,6,,,,34.6006521713563,,,10,,,,,,,,,,,,,,,,,,,,,,299.996307373047,300.001922607422,-10444.4306640625,-10444.4306640625,,,10.5977563858032,,1,0,0,0,0.013885498046875,29.3255138397217,1,1,1,299.995483398438,0,4232057440,299.999738057454,,,-0.00597743654060362,0.000210816715952648,-0.00598333009638376,0.000210828072043885,0.929053246974945,0.9436274766922,34.766845703125,8.38326450320892E-5,30,2,200,0.0192498154938221,-0.35456457734108,2.30828762054443,2,,,,,,,,,,,,,,,,
,3886932599.65925,299.999099731445,-11132.1640625,,,6,,,,34.6006521713563,,,10,,,,,,,,,,,,,,,,,,,,,,299.998229980469,300.0009765625,-11132.1640625,-11132.1640625,,,10.5969514846802,,1,0,0,0,0,28.8367557525635,1,1,1,299.999572753906,0,4232057920,299.999465942383,,,-0.00608115366098904,0.000214494211999227,-0.00608779836077738,0.000214506303410336,0.927791893482208,0.943863868713379,34.7758712768555,7.49197244644165,30,2,200,0.0197718888521194,-0.336518168449402,2.31613063812256,2,,,,,,,,,,,,,,,,
,3886932788.2775,299.999237060547,-11819.935546875,,,6,,,,34.6006521713563,,,10,,,,,,,,,,,,,,,,,,,,,,299.998931884766,300.001373291016,-11819.935546875,-11819.935546875,,,10.6002540588379,,1,0,0,0,0.013885498046875,29.3255138397217,1,1,1,299.998901367188,0,4232057664,300.000089009603,,,-0.0061839078793509,0.000218137086045735,-0.00619133237948065,0.000218151153038984,0.926628410816193,0.944123089313507,34.7840957641602,0.000115813003503717,30,2,200,0.0192417744547129,-0.355398505926132,2.35985946655273,2,,,,,,,,,,,,,,,,
,3886932977.22524,299.998504638672,-12507.65625,,,6,,,,34.6006521713563,,,10,,,,,,,,,,,,,,,,,,,,,,299.998931884766,300.001647949219,-12507.65625,-12507.65625,,,10.5908842086792,,1,0,0,0,0,29.3255138397217,1,1,1,299.998077392578,0,4232057696,300.000263560902,,,-0.0062859754473629,0.000221757018205317,-0.00629419216332745,0.000221772623237536,0.925448417663574,0.944351255893707,34.7920188903809,0,30,2,200,0.0180353689938784,-0.349290400743484,2.39747476577759,2,,,,,,,,,,,,,,,,
,3886933166.37534,299.995147705078,-13195.044921875,,,6,,,,34.6006521713563,,,10,,,,,,,,,,,,,,,,,,,,,,299.994964599609,299.997772216797,-13195.044921875,-13195.044921875,,,10.580415725708,,1,0,0,0,0.013885498046875,28.8367557525635,1,1,1,299.995300292969,0,4232057888,299.996513366699,,,-0.00638810095554356,0.000225380967235805,-0.00639716048927089,0.000225397452643134,0.924205839633942,0.944605827331543,34.8002128601074,1.54624285642058E-5,30,2,200,0.0181129015982151,-0.356624454259872,2.44345021247864,2,,,,,,,,,,,,,,,,
,3886933355.85926,300.001647949219,-13882.8154296875,,,6,,,,34.6006521713563,,,10,,,,,,,,,,,,,,,,,,,,,,300.001129150391,300.004241943359,-13882.8154296875,-13882.8154296875,,,10.5702466964722,,1,0,0,0,0,29.3255138397217,1,1,1,300.000823974609,0,4232057728,300.002754211426,,,-0.00648946582942178,0.000228977884024389,-0.00649939397661592,0.000228996786632266,0.923025369644165,0.944811820983887,34.8076248168945,0,30,2,200,0.0176908355206251,-0.344643115997314,2.49592924118042,2,,,,,,,,,,,,,,,,
,3886933547.35366,299.998519897461,-14570.5,,,6,,,,34.6006521713563,,,10,,,,,,,,,,,,,,,,,,,,,,299.998504638672,300.000579833984,-14570.5,-14570.5,,,10.5616579055786,,1,0,0,0,0.013885498046875,29.8142719268799,1,1,1,299.99853515625,0,4232057664,299.999397277832,,,-0.00659042585811358,0.000232561540348353,-0.00660123097826087,0.000232581920160992,0.921859383583069,0.945054471492767,34.8149566650391,7.48830842971802,30,2,200,0.0168740842491388,-0.353803277015686,2.53048372268677,2,,,,,,,,,,,,,,,,
,3886933735.46818,300.000381469727,-14742.4697265625,,,6,,,,34.6006521713563,,,10,,,,,,,,,,,,,,,,,,,,,,300.000213623047,300.002380371094,-14742.4697265625,-14742.4697265625,,,10.5527496337891,,1,0,0,0,0.013885498046875,29.3255138397217,1,1,1,300.000213623047,0,4232057856,300.001121520996,,,-0.00661517305821709,0.000233438966511968,-0.00662618892784391,0.000233459384059759,0.921626806259155,0.945191383361816,34.8167266845703,0,30,2,200,0.00250869407318532,-0.324646830558777,2.51479649543762,2,,,,,,,,,,,,,,,,
,3886933924.18104,300.00032043457,-14054.833984375,,,6,,,,34.6006521713563,,,10,,,,,,,,,,,,,,,,,,,,,,299.999908447266,300.003479003906,-14054.833984375,-14054.833984375,,,10.5437116622925,,1,0,0,0,0.013885498046875,29.3255138397217,1,1,1,299.999664306641,0,4232057760,300.001787821452,,,-0.00651388048816642,0.000229844790298933,-0.00652408643219806,0.000229863806271436,0.92272824048996,0.945058524608612,34.8102264404297,0,30,2,200,-0.00169667019508779,-0.352013140916824,2.45675349235535,2,,,,,,,,,,,,,,,,
,3886934112.72047,300.000518798828,-13367.02734375,,,6,,,,34.6006521713563,,,10,,,,,,,,,,,,,,,,,,,,,,300.000061035156,300.003570556641,-13367.02734375,-13367.02734375,,,10.5352478027344,,1,0,0,0,0.013885498046875,28.8367557525635,1,1,1,299.999755859375,0,4232057728,300.001960754395,,,-0.00641233331834068,0.000226240129805247,-0.00642169352699073,0.000226257611380505,0.923959136009216,0.944939851760864,34.8029479980469,1.53117416630266E-5,30,2,200,-0.00839451141655445,-0.363350540399551,2.44535875320435,2,,,,,,,,,,,,,,,,
,3886934297.69714,299.998626708984,-12679.4658203125,,,6,,,,34.6006521713563,,,10,,,,,,,,,,,,,,,,,,,,,,299.998748779297,300.001647949219,-12679.4658203125,-12679.4658203125,,,10.52783203125,,1,0,0,0,0.013885498046875,29.3255138397217,1,1,1,299.998016357422,0,4232057696,300.000413374467,,,-0.00631132877195652,0.000222657072829783,-0.0063198747253678,0.000222672515261116,0.925107836723328,0.944751799106598,34.7956924438477,0,30,2,200,-0.014028737321496,-0.376378446817398,2.39831280708313,2,,,,,,,,,,,,,,,,
,3886934486.87118,299.994125366211,-11991.6455078125,,,6,,,,34.6006521713563,,,10,,,,,,,,,,,,,,,,,,,,,,299.993103027344,299.997039794922,-11991.6455078125,-11991.6455078125,,,10.5196294784546,,1,0,0,0,0.013885498046875,28.8367557525635,1,1,1,299.992889404297,0,4232057824,299.995134989421,,,-0.00621004108913226,0.000219067807228961,-0.00621791007454274,0.000219082595413027,0.926078140735626,0.944529175758362,34.7891273498535,INF,30,2,200,-0.0166636016219854,-0.369545578956604,2.34444260597229,2,,,,,,,,,,,,,,,,
,3886934677.1057,300.001449584961,-11304.1337890625,,,6,,,,34.6006521713563,,,10,,,,,,,,,,,,,,,,,,,,,,299.999633789063,300.005737304687,-11304.1337890625,-11304.1337890625,,,10.5120878219604,,1,0,0,0,0.013885498046875,28.8367557525635,1,1,1,300.003265380859,0,4232057696,300.003362019857,,,-0.00610860020148819,0.000215472631092758,-0.006115761485414,0.00021548631271705,0.927130818367004,0.944295942783356,34.7818870544434,7.49124097824097,30,2,200,-0.018238253891468,-0.391904711723328,2.29786920547485,2,,,,,,,,,,,,,,,,
,3886934864.30408,299.997421264648,-10616.51171875,,,6,,,,34.6006521713563,,,10,,,,,,,,,,,,,,,,,,,,,,299.9970703125,300.000274658203,-10616.51171875,-10616.51171875,,,10.505220413208,,1,0,0,0,0.013885498046875,28.3479976654053,1,1,1,299.996734619141,0,4232057568,299.998565673828,,,-0.00600696804689242,0.000211872783594791,-0.00601347555215647,0.000211885376594541,0.928099095821381,0.944039046764374,34.7748184204102,7.49203681945801,30,2,200,-0.0194683466106653,-0.408905386924744,2.24300217628479,2,,,,,,,,,,,,,,,,
,3886935050.82399,300.000671386719,-9928.802734375,,,6,,,,34.6006521713563,,,10,,,,,,,,,,,,,,,,,,,,,,299.999847412109,300.004943847656,-9928.802734375,-9928.802734375,,,10.4975519180298,,1,0,0,0,0.013885498046875,29.3255138397217,1,1,1,299.999481201172,0,4232057792,300.002721150716,,,-0.00590484004713271,0.000208254185969624,-0.00591065434947016,0.000208265190830835,0.929194748401642,0.943801164627075,34.7668190002441,0,30,2,200,-0.0205300729721785,-0.379888504743576,2.2053861618042,2,,,,,,,,,,,,,,,,
,3886935236.87377,299.998931884766,-9241.15625,,,6,,,,34.6006521713563,,,10,,,,,,,,,,,,,,,,,,,,,,299.998260498047,300.002044677734,-9241.15625,-9241.15625,,,10.4914360046387,,1,0,0,0,0.013885498046875,29.8142719268799,1,1,1,299.998107910156,0,4232056832,300.000132242839,,,-0.00580196132606731,0.000204610971812075,-0.00580714977921615,0.000204621031101579,0.930224001407623,0.943554401397705,34.7589263916016,0,30,2,200,-0.0199726205319166,-0.395245552062988,2.16525793075562,2,,,,,,,,,,,,,,,,
,3886935422.37722,299.997634887695,-8553.396484375,,,6,,,,34.6006521713563,,,10,,,,,,,,,,,,,,,,,,,,,,299.996307373047,300.0009765625,-8553.396484375,-8553.396484375,,,10.4840688705444,,1,0,0,0,0.013885498046875,29.3255138397217,1,1,1,299.998962402344,0,4232057664,299.999610900879,,,-0.00569816679720196,0.000200937590280273,-0.00570275744234973,0.000200945924065708,0.931152939796448,0.943269729614258,34.7511672973633,0,30,2,200,-0.02093162573874,-0.386456996202469,2.12429976463318,2,,,,,,,,,,,,,,,,
,3886935610.69435,299.996215820313,-7865.68798828125,,,6,,,,34.6006521713563,,,10,,,,,,,,,,,,,,,,,,,,,,299.994934082031,300.000213623047,-7865.68798828125,-7865.68798828125,,,10.4779624938965,,1,0,0,0,0.013885498046875,29.3255138397217,1,1,1,299.997497558594,0,4232057696,299.998471577962,,,-0.00559339238836056,0.000197230976518582,-0.00559746824706615,0.000197239431081458,0.932031571865082,0.942956328392029,34.7432594299316,0,30,2,200,-0.0209687538444996,-0.346607089042664,2.1163227558136,2,,,,,,,,,,,,,,,,
,3886935797.78877,300.001113891602,-7178.00341796875,,,6,,,,34.6006521713563,,,10,,,,,,,,,,,,,,,,,,,,,,300.000823974609,300.003753662109,-7178.00341796875,-7178.00341796875,,,10.4717226028442,,1,0,0,0,0.013885498046875,29.3255138397217,1,1,1,300.000549316406,0,4232057792,300.002484639486,,,-0.00548712452436645,0.000193470115651085,-0.00549061301721772,0.000193476677576904,0.933075428009033,0.942726194858551,34.734260559082,0,30,2,200,-0.0212403163313866,-0.344615012407303,2.06129240989685,2,,,,,,,,,,,,,,,,
,3886935982.40673,299.998016357422,-6490.45556640625,,,6,,,,34.6006521713563,,,10,,,,,,,,,,,,,,,,,,,,,,299.997375488281,300.000885009766,-6490.45556640625,-6490.45556640625,,,10.4652280807495,,1,0,0,0,0.013885498046875,29.3255138397217,1,1,1,299.996826171875,0,4232057664,299.999356356534,,,-0.00537923886583219,0.000189654671255878,-0.00538224814305046,0.000189660917391327,0.933985710144043,0.942473888397217,34.7256278991699,0,30,2,200,-0.0211004093289375,-0.364890068769455,2.00858569145203,2,,,,,,,,,,,,,,,,
,3886936168.55245,299.998336791992,-5802.73388671875,,,6,,,,34.6006521713563,,,10,,,,,,,,,,,,,,,,,,,,,,299.997711181641,300.000732421875,-5802.73388671875,-5802.73388671875,,,10.4595155715942,,1,0,0,0,0.013885498046875,29.3255138397217,1,1,1,299.997436523438,0,4232058112,299.999226888021,,,-0.00526807850069582,0.000185726373751399,-0.00527059518350407,0.000185731233690704,0.934732556343079,0.94203108549118,34.7164115905762,0,30,2,200,-0.021676629781723,-0.344821274280548,1.97215127944946,2,,,,,,,,,,,,,,,,
,3886936353.05677,299.999816894531,-5114.77783203125,,,6,,,,34.6006521713563,,,10,,,,,,,,,,,,,,,,,,,,,,299.999786376953,300.001739501953,-5114.77783203125,-5114.77783203125,,,10.453314781189,,1,0,0,0,0,29.8142719268799,1,1,1,299.999389648438,0,4232057760,300.000718550249,,,-0.00515301861605602,0.000181657815864518,-0.00515506439222814,0.000181662157250129,0.935761153697967,0.941833198070526,34.7058868408203,0.133402615785599,30,2,200,-0.0230870991945267,-0.362373560667038,1.94086492061615,2,,,,,,,,,,,,,,,,
,3886936539.61148,299.996963500977,-4427.40234375,,,6,,,,34.6006521713563,,,10,,,,,,,,,,,,,,,,,,,,,,299.996215820313,299.999298095703,-4427.40234375,-4427.40234375,,,10.4478206634521,,1,0,0,0,0.013885498046875,29.3255138397217,1,1,1,299.996215820313,0,4232057696,299.997792561849,,,-0.00503245680148992,0.000177401653719841,-0.00503410193891434,0.000177405097530803,0.936284601688385,0.9412881731987,34.6962013244629,0.252519428730011,30,2,200,-0.0226489435881376,-0.320912033319473,1.89816677570343,2,,,,,,,,,,,,,,,,
,3886936726.14591,300.000991821289,-3739.54467773438,,,6,,,,34.6006521713563,,,10,,,,,,,,,,,,,,,,,,,,,,300.000518798828,300.003509521484,-3739.54467773438,-3739.54467773438,,,10.4416332244873,,1,0,0,0,0.013885498046875,29.8142719268799,1,1,1,300,0,4232057728,300.002061323686,,,-0.00489849232903845,0.000172674483551769,-0.00489982024000263,0.000172677321342633,0.936714768409729,0.940858662128449,34.687614440918,,30,2,200,-0.0212481375783682,-0.306449115276337,1.85918653011322,2,,,,,,,,,,,,,,,,
,3886936912.36824,299.99641418457,-3052.03344726562,,,6,,,,34.6006521713563,,,10,,,,,,,,,,,,,,,,,,,,,,299.995971679687,299.999572753906,-3052.03344726562,-3052.03344726562,,,10.4379453659058,,1,0,0,0,0,29.3255138397217,1,1,1,299.995300292969,0,4232057792,299.998002485795,,,-0.00474164679262168,0.000167135767459948,-0.00474258825305642,0.00016713766139218,0.937645256519318,0.940711736679077,34.675220489502,0.657986044883728,30,2,200,-0.0222674869000912,-0.322064965963364,1.78039276599884,2,,,,,,,,,,,,,,,,
,3886937095.77905,300.001266479492,-2364.17626953125,,,6,,,,34.6006521713563,,,10,,,,,,,,,,,,,,,,,,,,,,299.99951171875,300.003936767578,-2364.17626953125,-2364.17626953125,,,10.430962562561,,1,0,0,0,0.013885498046875,29.3255138397217,1,1,1,299.999450683594,0,4232057888,300.002001444499,,,-0.00453791610190071,0.000159948765296259,-0.0045384936606766,0.000159950089620026,0.938232719898224,0.940182745456696,34.6601181030273,0,30,2,200,-0.0231248270720243,-0.324260592460632,1.6953911781311,2,,,,,,,,,,,,,,,,
,3886937278.58409,300.002288818359,-1676.57836914062,,,6,,,,34.6006521713563,,,10,,,,,,,,,,,,,,,,,,,,,,300.002319335937,300.004547119141,-1676.57836914062,-1676.57836914062,,,10.4254570007324,,1,0,0,0,0.013885498046875,29.3255138397217,1,1,1,300.002258300781,0,4232057792,300.00355275472,,,-0.00418909970535358,0.000147649225195605,-0.00418938212103526,0.000147649887738857,0.938743412494659,0.939775586128235,34.6438980102539,0.133375927805901,30,2,200,-0.024722509086132,-0.298564851284027,1.56278669834137,2,,,,,,,,,,,,,,,,
,3886937462.16185,299.995895385742,-988.770385742188,,,6,,,,34.6006521713563,,,10,,,,,,,,,,,,,,,,,,,,,,299.993621826172,300.000061035156,-988.770385742188,-988.770385742188,,,10.4205989837646,,1,0,0,0,0.013885498046875,28.3479976654053,1,1,1,299.993621826172,0,4232057728,299.997021993001,,,-0.00342743507924387,0.000120802206792319,-0.00342748381746344,0.000120802347223298,0.938932716846466,0.939146161079407,34.6203575134277,,30,2,200,-0.0236613862216473,-0.233895868062973,1.30383002758026,2,,,,,,,,,,,,,,,,
,3886937648.06322,299.99658203125,-300.999664306641,,,6,,,,34.6006521713563,,,10,,,,,,,,,,,,,,,,,,,,,,299.996307373047,299.999725341797,-300.999664306641,-300.999664306641,,,10.4157905578613,,1,0,0,0,0.013885498046875,29.3255138397217,1,1,1,299.996856689453,0,4232057664,299.998374245383,,,-0.00168560320079634,5.94092465265247E-5,-0.00168564223045444,5.940935491661E-5,0.939197897911072,0.939548432826996,34.6258354187012,,30,2,200,-0.0256332755088806,-0.185527473688126,0.637549340724945,2,,,,,,,,,,,,,,,,
,3886937837.10952,300.00146484375,387.166442871094,,,6,,,,34.6006521713563,,,10,,,,,,,,,,,,,,,,,,,,,,299.997619628906,300.007354736328,387.166442871094,387.166442871094,,,10.409369468689,,1,0,0,0,0.013885498046875,28.8367557525635,1,1,1,299.996978759766,0,4232057408,300.002529368681,,,0.0015646780194729,5.51501413528272E-5,0.00156468004204922,5.51501336845903E-5,0.938336908817291,0.938360095024109,34.594123840332,0.133320838212967,30,2,200,-0.0196178890764713,-4.87155771255493,4.79926443099976,2,,,,,,,,,,,,,,,,
,3886938023.6963,300.000244140625,1074.83837890625,,,6,,,,34.6006521713563,,,10,,,,,,,,,,,,,,,,,,,,,,299.996520996094,300.006134033203,1074.83837890625,1074.83837890625,,,10.4045133590698,,1,0,0,0,0.013885498046875,28.8367557525635,1,1,1,299.996368408203,0,4232057696,300.002265930176,,,0.00351627534870723,0.000123928043102724,0.00351629042276514,0.000123928106976411,0.939651608467102,0.939713895320892,34.6112403869629,1,30,2,200,-0.0112973153591156,-1.39056015014648,0.192878156900406,2,,,,,,,,,,,,,,,,
,3886938209.11142,300.001815795898,1762.67102050781,,,6,,,,34.6006521713563,,,10,,,,,,,,,,,,,,,,,,,,,,300.000061035156,300.005004882812,1762.67102050781,1762.67102050781,,,10.400731086731,,1,0,0,0,0.013885498046875,28.8367557525635,1,1,1,300.003570556641,0,4232057824,300.003186543783,,,0.00421781416041976,0.000148655747823184,0.00421804880801772,0.000148656364286166,0.939363658428192,0.940215647220612,34.6397666931152,,30,2,200,-0.00321646989323199,-1.64256989955902,0.188958346843719,2,,,,,,,,,,,,,,,,
,3886938392.13258,299.997924804687,2450.25659179687,,,6,,,,34.6006521713563,,,10,,,,,,,,,,,,,,,,,,,,,,299.997619628906,300.000152587891,2450.25659179687,2450.25659179687,,,10.3955450057983,,1,0,0,0,0.013885498046875,29.3255138397217,1,1,1,299.997772216797,0,4232057728,299.999028986151,,,0.00453371968339071,0.000159797247135321,0.00453426327072524,0.000159798503581911,0.938585817813873,0.94043105840683,34.6583404541016,0.133379325270653,30,2,200,0.00293434085324407,-1.75729238986969,0.285714894533157,2,,,,,,,,,,,,,,,,
,3886938576.10037,300.000625610352,3137.82958984375,,,6,,,,34.6006521713563,,,10,,,,,,,,,,,,,,,,,,,,,,300.000518798828,300.003723144531,3137.82958984375,3137.82958984375,,,10.3917007446289,,1,0,0,0,0.013885498046875,29.3255138397217,1,1,1,299.999816894531,0,4232057728,300.001991965554,,,0.00473322171181825,0.000166836392747203,0.00473415573245917,0.000166838303179594,0.937879383563995,0.940935492515564,34.6749534606934,0,30,2,200,0.00357739673927426,-1.83562397956848,0.289950877428055,2,,,,,,,,,,,,,,,,
,3886938763.00153,300.00048828125,3825.6005859375,,,6,,,,34.6006521713563,,,10,,,,,,,,,,,,,,,,,,,,,,299.999298095703,300.004638671875,3825.6005859375,3825.6005859375,,,10.3866519927979,,1,0,0,0,0.013885498046875,29.3255138397217,1,1,1,299.999053955078,0,4232057664,300.002243041992,,,0.00489007917650686,0.000172373549555041,0.00489139916355126,0.000172376434596904,0.937113583087921,0.941261112689972,34.6873626708984,,30,2,200,-0.00708138942718506,-1.90563833713531,0.275283753871918,2,,,,,,,,,,,,,,,,
,3886938954.30815,299.998733520508,4513.09912109375,,,6,,,,34.6006521713563,,,100,,,,,,,,,,,,,,,,,,,,,,299.997497558594,300.001525878906,4513.09912109375,4513.09912109375,,,10.382007598877,,1,0,0,0,0.013885498046875,29.3255138397217,1,1,1,299.997955322266,0,4232057696,299.999409395106,,,0.00502474584638799,0.00017713611949757,0.00502656027635865,0.000177139539276467,0.935732364654541,0.941267848014831,34.7013816833496,,30,2,200,-0.0014274783898145,-1.98267781734467,0.211475044488907,2,,,,,,,,,,,,,,,,
,3886939149.38746,299.999649047852,5200.89501953125,,,6,,,,34.6006521713563,,,100,,,,,,,,,,,,,,,,,,,,,,299.989685058594,300.002532958984,5200.89501953125,5200.89501953125,,,10.3775625228882,,1,0,0,0,0.013885498046875,29.3255138397217,1,1,1,299.997253417969,0,4232057568,299.995774702592,,,0.00515134629979924,0.000181618349424417,0.00515373564906161,0.000181623118385025,0.934112250804901,0.941095948219299,34.7146301269531,,30,2,200,-0.00258769793435931,-0.201527267694473,0.0263622216880322,2,,,,,,,,,,,,,,,,
,3886939354.1004,299.999328613281,5888.59130859375,,,6,,,,34.6006521713563,,,100,,,,,,,,,,,,,,,,,,,,,,299.99658203125,300.000549316406,5888.59130859375,5888.59130859375,,,10.3735103607178,,1,0,0,0,0.013885498046875,28.8367557525635,1,1,1,299.998229980469,0,4232057856,299.998756408691,,,0.00526828166395796,0.000185743797317111,0.0052710711160798,0.000185749254762934,0.93389105796814,0.941910862922668,34.7224807739258,,30,2,200,-0.00177959178108722,-0.203710943460464,0.0388266667723656,2,,,,,,,,,,,,,,,,
,3886939540.50402,299.999572753906,6576.17724609375,,,6,,,,34.6006521713563,,,100,,,,,,,,,,,,,,,,,,,,,,299.999694824219,300.001678466797,6576.17724609375,6576.17724609375,,,10.3688669204712,,1,0,0,0,0.013885498046875,29.3255138397217,1,1,1,299.999359130859,0,4232057760,300.000628153483,,,0.00538299202454787,0.000189802325458215,0.00538634327574911,0.000189808818217726,0.932780265808105,0.942148506641388,34.732780456543,1.50693967952975E-5,30,2,200,-0.00197964534163475,-0.211275830864906,0.0292424373328686,2,,,,,,,,,,,,,,,,
,3886939741.15766,299.999450683594,7263.9853515625,,,6,,,,34.6006521713563,,,100,,,,,,,,,,,,,,,,,,,,,,299.998962402344,300.003814697266,7263.9853515625,7263.9853515625,,,10.3651208877563,,1,0,0,0,0.013885498046875,29.8142719268799,1,1,1,299.998809814453,0,4232057856,300.000890395221,,,0.0054933340048258,0.000193708245080264,0.00549729510052818,0.000193715740466492,0.931622803211212,0.942409574985504,34.7429237365723,0.133448049426079,30,2,200,-0.0016652891645208,-0.214859023690224,0.0307254418730736,2,,,,,,,,,,,,,,,,
,3886939931.84035,300.0029296875,7951.48388671875,,,6,,,,34.6006521713563,,,100,,,,,,,,,,,,,,,,,,,,,,300.002014160156,300.005767822266,7951.48388671875,7951.48388671875,,,10.3606262207031,,1,0,0,0,0.013885498046875,30.7917900085449,1,1,1,300.001892089844,0,4232057600,300.004079182943,,,0.00560221041132823,0.000197561159272436,0.00560676774420066,0.000197569508465288,0.93061763048172,0.942743062973022,34.7518882751465,1,30,2,200,-0.00185857759788632,-0.218310534954071,0.0263378247618675,2,,,,,,,,,,,,,,,,
,3886940118.8453,299.999130249023,8639.193359375,,,6,,,,34.6006521713563,,,100,,,,,,,,,,,,,,,,,,,,,,299.998992919922,300.003479003906,8639.193359375,8639.193359375,,,10.3559551239014,,1,0,0,0,0.013885498046875,29.3255138397217,1,1,1,299.9990234375,0,4232057952,300.001258850098,,,0.00570917366946504,0.000201350694325215,0.00571442052202592,0.000201360464964058,0.929385900497437,0.942961633205414,34.761302947998,7.03358459472656,30,2,200,-0.00194355368148535,-0.222272932529449,0.0270457677543163,2,,,,,,,,,,,,,,,,
,3886940307.18382,300.000061035156,9327.1123046875,,,6,,,,34.6006521713563,,,100,,,,,,,,,,,,,,,,,,,,,,299.999969482422,300.003265380859,9327.1123046875,9327.1123046875,,,10.3505191802979,,1,0,0,0,0.013885498046875,29.3255138397217,1,1,1,299.999938964844,0,4232057856,300.001408894857,,,0.00581459158564897,0.000205085630566841,0.0058205552060539,0.000205097519772573,0.928223311901092,0.943204522132873,34.77001953125,1.57435097207781E-5,30,2,200,-0.00203229184262454,-0.227041780948639,0.0292976312339306,2,,,,,,,,,,,,,,,,
,3886940495.1371,299.99755859375,10014.6845703125,,,6,,,,34.6006521713563,,,100,,,,,,,,,,,,,,,,,,,,,,299.996948242188,300.000915527344,10014.6845703125,10014.6845703125,,,10.3473024368286,,1,0,0,0,0.013885498046875,29.3255138397217,1,1,1,299.996643066406,0,4232057728,299.999117533366,,,0.00591869071441033,0.000208774976440826,0.00592535530550699,0.000208786916181025,0.927054941654205,0.943487465381622,34.778621673584,0,30,2,200,-0.00197543390095234,-0.231564432382584,0.0321087092161179,2,,,,,,,,,,,,,,,,
,3886940684.48288,299.997756958008,10702.3203125,,,6,,,,34.6006521713563,,,100,,,,,,,,,,,,,,,,,,,,,,299.997253417969,300.003753662109,10702.3203125,10702.3203125,,,10.3434085845947,,1,0,0,0,0.013885498046875,29.3255138397217,1,1,1,299.998260498047,0,4232058048,300.001116434733,,,0.00602224117236048,0.000212447137844881,0.00602971959000927,0.000212461506726495,0.925814092159271,0.943724513053894,34.787166595459,0.133504539728165,30,2,200,-0.00185031723231077,-0.23374280333519,0.0294393319636583,2,,,,,,,,,,,,,,,,
,3886940873.85933,300.002243041992,11389.9423828125,,,6,,,,34.6006521713563,,,100,,,,,,,,,,,,,,,,,,,,,,300.002349853516,300.005676269531,11389.9423828125,11389.9423828125,,,10.3391466140747,,1,0,0,0,0.0138092041015625,29.8142719268799,1,1,1,300.002014160156,0,4232057760,300.003870646159,,,0.00612500820755013,0.000216092770883308,0.00613329551698781,0.000216108306898939,0.924565434455872,0.943953216075897,34.7954597473145,1.58531656779814E-5,30,2,200,-0.00185619771946222,-0.236818328499794,0.0320809707045555,2,,,,,,,,,,,,,,,,
,3886941063.37783,300.000717163086,12077.7255859375,,,6,,,,34.6006521713563,,,100,,,,,,,,,,,,,,,,,,,,,,299.999450683594,300.004272460937,12077.7255859375,12077.7255859375,,,10.3357257843018,,1,0,0,0,0.013885498046875,28.8367557525635,1,1,1,299.999420166016,0,4232057728,300.002128601074,,,0.00622684485595522,0.000219703314045696,0.00623588511040185,0.000219719835729521,0.923510253429413,0.944215893745422,34.802562713623,0,30,2,200,-0.00191633147187531,-0.23987390100956,0.0335128754377365,2,,,,,,,,,,,,,,,,
,3886941253.17931,300.000839233398,12765.2001953125,,,6,,,,34.6006521713563,,,100,,,,,,,,,,,,,,,,,,,,,,300.000854492188,300.003723144531,12765.2001953125,12765.2001953125,,,10.3316688537598,,1,0,0,0,0.013885498046875,30.7917900085449,1,1,1,300.000823974609,0,4232057760,300.002113342285,,,0.0063288882218826,0.000223328245100185,0.00633888696721489,0.000223346251256091,0.922092735767364,0.944436609745026,34.8113212585449,,30,2,200,-0.00189050345215946,-0.247346892952919,0.0304189939051867,2,,,,,,,,,,,,,,,,
,3886941443.06493,299.998764038086,13452.958984375,,,6,,,,34.6006521713563,,,100,,,,,,,,,,,,,,,,,,,,,,299.998657226562,300.001281738281,13452.958984375,13452.958984375,,,10.3277559280396,,1,0,0,0,0.013885498046875,29.3255138397217,1,1,1,299.998687744141,0,4232057792,299.999958385121,,,0.00642959443885153,0.000226899701340303,0.00644035340302605,0.000226918122499327,0.921097636222839,0.944693446159363,34.8177375793457,0,30,2,200,-0.00176628597546369,-0.249877989292145,0.031654242426157,2,,,,,,,,,,,,,,,,
,3886941639.33176,300.001052856445,14140.7421875,,,6,,,,34.6006521713563,,,100,,,,,,,,,,,,,,,,,,,,,,300.001312255859,300.006164550781,14140.7421875,14140.7421875,,,10.3246059417725,,1,0,0,0,0.013885498046875,29.3255138397217,1,1,1,299.998870849609,0,4232057536,300.003568013509,,,0.00653097155707982,0.000230501252008647,0.00654269331229917,0.000230522068605147,0.919800698757172,0.94484293460846,34.8252410888672,5.90129137039185,30,2,200,-0.0016541569493711,-0.25513231754303,0.0305065736174583,2,,,,,,,,,,,,,,,,
,3886941827.24903,299.999145507812,14828.462890625,,,6,,,,34.6006521713563,,,100,,,,,,,,,,,,,,,,,,,,,,299.998596191406,300.001770019531,14828.462890625,14828.462890625,,,10.3223342895508,,1,0,0,0,0.013885498046875,29.8142719268799,1,1,1,299.999694824219,0,4232057696,300.000335693359,,,0.00663085361987403,0.000234045910605719,0.00664349239773363,0.000234068909694322,0.918776452541351,0.945203542709351,34.8319129943848,0,30,2,200,-0.00163419835735112,-0.257681876420975,0.053507849574089,2,,,,,,,,,,,,,,,,
,3886941874.25106,299.999816894531,15000.3837890625,,,6,,,,34.6006521713563,,,100,,,,,,,,,,,,,,,,,,,,,,299.998657226562,300.005310058594,15000.3837890625,15000.3837890625,,,10.3199024200439,,1,0,0,0,0.013885498046875,29.3255138397217,1,1,1,299.998138427734,0,4232057312,300.0029296875,,,0.006656370113069,0.000234954984917724,0.00666926915683838,0.000234977559708619,0.91833770275116,0.945166289806366,34.8340797424316,1.55115194502287E-5,30,2,200,-0.0015737732173875,-0.255395382642746,0.0361288823187351,2,,,,,,,,,,,,,,,,